Workbook

Sheet RESUMO
A2: Resumo dos investimentos
A3: BENEFÍCIO FISCAL DE PD&I 2023
G4: 2023-026 - NETZSCH MOAGEM
A5: NETZSCH INDUSTRIA E COMERCIO DE EQUIPAMENTOS DE MOAGEM LTDA | E5: CNPJ 07.389.050/0001-51 | G5: =TODAY() -> 46168
A6: Rua Emilio Marquardt, 300, Ribeirão Souto - SC - SUL - POMERODE - CEP 89.107-000
A8: Natureza | B8: 1º Trimestre | C8: 2º Trimestre | D8: 3º Trimestre | E8: 4º Trimestre | G8: TOTAL
A9: Material | B9: - | C9: - | D9: - | E9: - | G9: =sum(B9:E9) -> 0
A10: Terceiros | B10: =IFERROR(__xludf.DUMMYFUNCTION("iferror(sum(filter('Resumo - TERCEIROS'!$G:$G,'Resumo - TERCEIROS'!$K:$K=TRUE,month('Resumo - TERCEIROS'!$H:$H)>=1,month('Resumo - TERCEIROS'!$H:$H)<=3)))"),249643.17000000004) -> 249643.17 | C10: =IFERROR(__xludf.DUMMYFUNCTION("iferror(sum(filter('Resumo - TERCEIROS'!$G:$G,'Resumo - TERCEIROS'!$K:$K=TRUE,month('Resumo - TERCEIROS'!$H:$H)>=4,month('Resumo - TERCEIROS'!$H:$H)<=6)))"),270565.37) -> 270565.37 | D10: =IFERROR(__xludf.DUMMYFUNCTION("iferror(sum(filter('Resumo - TERCEIROS'!$G:$G,'Resumo - TERCEIROS'!$K:$K=TRUE,month('Resumo - TERCEIROS'!$H:$H)>=7,month('Resumo - TERCEIROS'!$H:$H)<=9)))"),436998.42) -> 436998.42 | E10: =IFERROR(__xludf.DUMMYFUNCTION("iferror(sum(filter('Resumo - TERCEIROS'!$G:$G,'Resumo - TERCEIROS'!$K:$K=TRUE,month('Resumo - TERCEIROS'!$H:$H)>=10,month('Resumo - TERCEIROS'!$H:$H)<=12)))"),364921.97) -> 364921.97 | G10: =sum(B10:E10) -> 1322128.9
A11: RH (Parcial inovação) | B11: =IFERROR(__xludf.DUMMYFUNCTION("iferror(sum(filter('Resumo - TIMESHEETS'!$L$12:$L49,'Resumo - TIMESHEETS'!$O$12:$O49=""Parcial"",month('Resumo - TIMESHEETS'!$G$12:$G49)>=1,month('Resumo - TIMESHEETS'!$G$12:$G49)<=3)),0)"),27955.666660157865) -> 27955.667 | C11: =IFERROR(__xludf.DUMMYFUNCTION("iferror(sum(filter('Resumo - TIMESHEETS'!$L$12:$L49,'Resumo - TIMESHEETS'!$O$12:$O49=""Parcial"",month('Resumo - TIMESHEETS'!$G$12:$G49)>=4,month('Resumo - TIMESHEETS'!$G$12:$G49)<=6)),0)"),219121.24926862077) -> 219121.25 | D11: =IFERROR(__xludf.DUMMYFUNCTION("iferror(sum(filter('Resumo - TIMESHEETS'!$L$12:$L49,'Resumo - TIMESHEETS'!$O$12:$O49=""Parcial"",month('Resumo - TIMESHEETS'!$G$12:$G49)>=7,month('Resumo - TIMESHEETS'!$G$12:$G49)<=9)),0)"),185946.35230050277) -> 185946.35 | E11: =IFERROR(__xludf.DUMMYFUNCTION("iferror(sum(filter('Resumo - TIMESHEETS'!$L$12:$L49,'Resumo - TIMESHEETS'!$O$12:$O49=""Parcial"",month('Resumo - TIMESHEETS'!$G$12:$G49)>=10,month('Resumo - TIMESHEETS'!$G$12:$G49)<=12)),0)"),121276.19605978376) -> 121276.2 | G11: =sum(B11:E11) -> 554299.46
A12: RH (Exclusivo inovação) | B12: =IFERROR(__xludf.DUMMYFUNCTION("iferror(sum(filter('Resumo - TIMESHEETS'!$L$12:$L49,'Resumo - TIMESHEETS'!$O$12:$O49=""Exclusivo"",month('Resumo - TIMESHEETS'!$G$12:$G49)>=1,month('Resumo - TIMESHEETS'!$G$12:$G49)<=3)),0)"),205663.2395166963) -> 205663.24 | C12: =IFERROR(__xludf.DUMMYFUNCTION("iferror(sum(filter('Resumo - TIMESHEETS'!$L$12:$L49,'Resumo - TIMESHEETS'!$O$12:$O49=""Exclusivo"",month('Resumo - TIMESHEETS'!$G$12:$G49)>=4,month('Resumo - TIMESHEETS'!$G$12:$G49)<=6)),0)"),227193.7884235887) -> 227193.79 | D12: =IFERROR(__xludf.DUMMYFUNCTION("iferror(sum(filter('Resumo - TIMESHEETS'!$L$12:$L49,'Resumo - TIMESHEETS'!$O$12:$O49=""Exclusivo"",month('Resumo - TIMESHEETS'!$G$12:$G49)>=7,month('Resumo - TIMESHEETS'!$G$12:$G49)<=9)),0)"),221950.78725329504) -> 221950.79 | E12: =IFERROR(__xludf.DUMMYFUNCTION("iferror(sum(filter('Resumo - TIMESHEETS'!$L$12:$L49,'Resumo - TIMESHEETS'!$O$12:$O49=""Exclusivo"",month('Resumo - TIMESHEETS'!$G$12:$G49)>=10,month('Resumo - TIMESHEETS'!$G$12:$G49)<=12)),0)"),217421.32573212715) -> 217421.33 | G12: =sum(B12:E12) -> 872229.14
A13: Total 1 | B13: =sum(B10:B12) -> 483262.08 | C13: =sum(C10:C12) -> 716880.41 | D13: =sum(D10:D12) -> 844895.56 | E13: =sum(E10:E12) -> 703619.49 | G13: =sum(G9:G12) -> 2748657.5
A14: Percentual Exclusão | B14: 0.6 | C14: 0.6 | D14: 0.6 | E14: 0.6 | G14: 0.6
A15: Exclusão da Base de cálculo do IRPJ e CSLL | B15: =B13*B14 -> 289957.25 | C15: =C13*C14 -> 430128.24 | D15: =D13*D14 -> 506937.34 | E15: =E13*E14 -> 422171.7 | G15: =G13*G14 -> 1649194.5
A17: Economia Estimada [34%] | B17: =B15*34% -> 98585.464 | C17: =C15*34% -> 146243.6 | D17: =D15*34% -> 172358.69 | E17: =E15*34% -> 143538.38 | G17: =G15*34% -> 560726.14
A18: Comissão McBenner | B18: =B17*0.05 -> 4929.2732 | C18: =C17*0.05 -> 7312.1802 | D18: =D17*0.05 -> 8617.9347 | E18: =E17*0.05 -> 7176.9188 | G18: =G17*0.05 -> 28036.307
A20: Observações:
A21: 1. Os dispêndios devem ser registrados na contabilidade em conta específica
A22: 2. O benefício deve ser aproveitado na ECF do respectivo ano/competência
A23: 3. O formulário do MCTIC (governo) será enviado até fim de Julho/2024
A24: 4. Os projetos estão descritos em arquivo a parte a ser anexado no FORM PD&I
A25: 5. Alguns benefícios previstos na Lei do Bem não foram utilizados:
A26: - 5.1. Depreciação acelerada
A27: - 5.2. Redução de IPI na aquisição de equipamento para PD&I
A28: - 5.3. Acréscimo de até 20% na exclusão por incrementar o número de pesquisadores contratados (exclusivos) em percentual acima de 5% ou até 5% em comparação ao ano-calendário anterior
A29: --- 5.3. Até 70% de exclusão por incrementar o numero de pesquisadores contratados em percentual até 5%
A31: Equipe de PD&I
A32: Quadro de resumo | B32: Dedicação Parcial | E32: Dedicação Exclusiva
B33: Qtd | C33: Valor gasto | D33: Horas | E33: Qtd | F33: Valor gasto | G33: Horas
A34: Técnico | B34: =IFERROR(__xludf.DUMMYFUNCTION("COUNTA(IFERROR(FILTER(RH!$F$13:$F$34,RH!$F$13:$F$34 = $A34,RH!$V$13:$V$34 = ""Parcial""),))"),5.0) -> 5 | C34: =IFERROR(__xludf.DUMMYFUNCTION("SUM(IFERROR(FILTER(RH!$U$49:$U$69,RH!$F$49:$F$69 = $A34,RH!$E$49:$E$69 = ""Parcial""),0))"),83136.24831155327) -> 83136.248 | D34: =IFERROR(__xludf.DUMMYFUNCTION("SUM(IFERROR(FILTER(RH!$T$13:$T$27,RH!$F$13:$F$27 = $A34,RH!$V$13:$V$27 = ""Parcial""),0))*24"),1861.0100000000002) -> 1861.01 | E34: =IFERROR(__xludf.DUMMYFUNCTION("COUNTA(IFERROR(FILTER(RH!$F$13:$F$27,RH!$F$13:$F$27 = $A34,RH!$V$13:$V$27 = ""Exclusivo""),))"),0.0) -> 0 | F34: =IFERROR(__xludf.DUMMYFUNCTION("SUM(IFERROR(FILTER(RH!$U$49:$U$69,RH!$F$49:$F$69 = $A34,RH!$E$49:$E$69 = ""Exclusivo""),0))"),0.0) -> 0 | G34: =IFERROR(__xludf.DUMMYFUNCTION("SUM(IFERROR(FILTER(RH!$T$13:$T$27,RH!$F$13:$F$27 = $A34,RH!$V$13:$V$27 = ""Exclusivo""),0))*24"),0.0) -> 0
A35: Tecnologo | B35: =IFERROR(__xludf.DUMMYFUNCTION("COUNTA(IFERROR(FILTER(RH!$F$13:$F$34,RH!$F$13:$F$34 = $A35,RH!$V$13:$V$34 = ""Parcial""),))"),0.0) -> 0 | C35: =IFERROR(__xludf.DUMMYFUNCTION("SUM(IFERROR(FILTER(RH!$U$49:$U$69,RH!$F$49:$F$69 = $A35,RH!$E$49:$E$69 = ""Parcial""),0))"),0.0) -> 0 | D35: =IFERROR(__xludf.DUMMYFUNCTION("SUM(IFERROR(FILTER(RH!$T$13:$T$27,RH!$F$13:$F$27 = $A35,RH!$V$13:$V$27 = ""Parcial""),0))*24"),0.0) -> 0 | E35: =IFERROR(__xludf.DUMMYFUNCTION("COUNTA(IFERROR(FILTER(RH!$F$13:$F$27,RH!$F$13:$F$27 = $A35,RH!$V$13:$V$27 = ""Exclusivo""),))"),0.0) -> 0 | F35: =IFERROR(__xludf.DUMMYFUNCTION("SUM(IFERROR(FILTER(RH!$U$49:$U$69,RH!$F$49:$F$69 = $A35,RH!$E$49:$E$69 = ""Exclusivo""),0))"),0.0) -> 0 | G35: =IFERROR(__xludf.DUMMYFUNCTION("SUM(IFERROR(FILTER(RH!$T$13:$T$27,RH!$F$13:$F$27 = $A35,RH!$V$13:$V$27 = ""Exclusivo""),0))*24"),0.0) -> 0
A36: Superior Completo | B36: =IFERROR(__xludf.DUMMYFUNCTION("COUNTA(IFERROR(FILTER(RH!$F$13:$F$34,RH!$F$13:$F$34 = $A36,RH!$V$13:$V$34 = ""Parcial""),))"),10.0) -> 10 | C36: =IFERROR(__xludf.DUMMYFUNCTION("SUM(IFERROR(FILTER(RH!$U$49:$U$69,RH!$F$49:$F$69 = $A36,RH!$E$49:$E$69 = ""Parcial""),0))"),380378.4030854129) -> 380378.4 | D36: =IFERROR(__xludf.DUMMYFUNCTION("SUM(IFERROR(FILTER(RH!$T$13:$T$27,RH!$F$13:$F$27 = $A36,RH!$V$13:$V$27 = ""Parcial""),0))*24"),4634.15) -> 4634.15 | E36: =IFERROR(__xludf.DUMMYFUNCTION("COUNTA(IFERROR(FILTER(RH!$F$13:$F$27,RH!$F$13:$F$27 = $A36,RH!$V$13:$V$27 = ""Exclusivo""),))"),4.0) -> 4 | F36: =IFERROR(__xludf.DUMMYFUNCTION("SUM(IFERROR(FILTER(RH!$U$49:$U$69,RH!$F$49:$F$69 = $A36,RH!$E$49:$E$69 = ""Exclusivo""),0))"),872229.1409257072) -> 872229.14 | G36: =IFERROR(__xludf.DUMMYFUNCTION("SUM(IFERROR(FILTER(RH!$T$13:$T$27,RH!$F$13:$F$27 = $A36,RH!$V$13:$V$27 = ""Exclusivo""),0))*24"),8326.0) -> 8326
A37: Pós graduado | B37: =IFERROR(__xludf.DUMMYFUNCTION("COUNTA(IFERROR(FILTER(RH!$F$13:$F$34,RH!$F$13:$F$34 = $A37,RH!$V$13:$V$34 = ""Parcial""),))"),0.0) -> 0 | C37: =IFERROR(__xludf.DUMMYFUNCTION("SUM(IFERROR(FILTER(RH!$U$49:$U$69,RH!$F$49:$F$69 = $A37,RH!$E$49:$E$69 = ""Parcial""),0))"),0.0) -> 0 | D37: =IFERROR(__xludf.DUMMYFUNCTION("SUM(IFERROR(FILTER(RH!$T$13:$T$27,RH!$F$13:$F$27 = $A37,RH!$V$13:$V$27 = ""Parcial""),0))*24"),0.0) -> 0 | E37: =IFERROR(__xludf.DUMMYFUNCTION("COUNTA(IFERROR(FILTER(RH!$F$13:$F$27,RH!$F$13:$F$27 = $A37,RH!$V$13:$V$27 = ""Exclusivo""),))"),0.0) -> 0 | F37: =IFERROR(__xludf.DUMMYFUNCTION("SUM(IFERROR(FILTER(RH!$U$49:$U$69,RH!$F$49:$F$69 = $A37,RH!$E$49:$E$69 = ""Exclusivo""),0))"),0.0) -> 0 | G37: =IFERROR(__xludf.DUMMYFUNCTION("SUM(IFERROR(FILTER(RH!$T$13:$T$27,RH!$F$13:$F$27 = $A37,RH!$V$13:$V$27 = ""Exclusivo""),0))*24"),0.0) -> 0
A38: Mestrado | B38: =IFERROR(__xludf.DUMMYFUNCTION("COUNTA(IFERROR(FILTER(RH!$F$13:$F$34,RH!$F$13:$F$34 = $A38,RH!$V$13:$V$34 = ""Parcial""),))"),1.0) -> 1 | C38: =IFERROR(__xludf.DUMMYFUNCTION("SUM(IFERROR(FILTER(RH!$U$49:$U$69,RH!$F$49:$F$69 = $A38,RH!$E$49:$E$69 = ""Parcial""),0))"),0.0) -> 0 | D38: =IFERROR(__xludf.DUMMYFUNCTION("SUM(IFERROR(FILTER(RH!$T$13:$T$27,RH!$F$13:$F$27 = $A38,RH!$V$13:$V$27 = ""Parcial""),0))*24"),0.0) -> 0 | E38: =IFERROR(__xludf.DUMMYFUNCTION("COUNTA(IFERROR(FILTER(RH!$F$13:$F$27,RH!$F$13:$F$27 = $A38,RH!$V$13:$V$27 = ""Exclusivo""),))"),0.0) -> 0 | F38: =IFERROR(__xludf.DUMMYFUNCTION("SUM(IFERROR(FILTER(RH!$U$49:$U$69,RH!$F$49:$F$69 = $A38,RH!$E$49:$E$69 = ""Exclusivo""),0))"),0.0) -> 0 | G38: =IFERROR(__xludf.DUMMYFUNCTION("SUM(IFERROR(FILTER(RH!$T$13:$T$27,RH!$F$13:$F$27 = $A38,RH!$V$13:$V$27 = ""Exclusivo""),0))*24"),0.0) -> 0
A39: Doutorado | B39: =IFERROR(__xludf.DUMMYFUNCTION("COUNTA(IFERROR(FILTER(RH!$F$13:$F$34,RH!$F$13:$F$34 = $A39,RH!$V$13:$V$34 = ""Parcial""),))"),0.0) -> 0 | C39: =IFERROR(__xludf.DUMMYFUNCTION("SUM(IFERROR(FILTER(RH!$U$49:$U$69,RH!$F$49:$F$69 = $A39,RH!$E$49:$E$69 = ""Parcial""),0))"),0.0) -> 0 | D39: =IFERROR(__xludf.DUMMYFUNCTION("SUM(IFERROR(FILTER(RH!$T$13:$T$27,RH!$F$13:$F$27 = $A39,RH!$V$13:$V$27 = ""Parcial""),0))*24"),0.0) -> 0 | E39: =IFERROR(__xludf.DUMMYFUNCTION("COUNTA(IFERROR(FILTER(RH!$F$13:$F$27,RH!$F$13:$F$27 = $A39,RH!$V$13:$V$27 = ""Exclusivo""),))"),0.0) -> 0 | F39: =IFERROR(__xludf.DUMMYFUNCTION("SUM(IFERROR(FILTER(RH!$U$49:$U$69,RH!$F$49:$F$69 = $A39,RH!$E$49:$E$69 = ""Exclusivo""),0))"),0.0) -> 0 | G39: =IFERROR(__xludf.DUMMYFUNCTION("SUM(IFERROR(FILTER(RH!$T$13:$T$27,RH!$F$13:$F$27 = $A39,RH!$V$13:$V$27 = ""Exclusivo""),0))*24"),0.0) -> 0
B40: =SUM(B34:B39) -> 16 | C40: =SUM(C34:C39) -> 463514.65 | D40: =SUM(D34:D39) -> 6495.16 | E40: =SUM(E34:E39) -> 4 | F40: =SUM(F34:F39) -> 872229.14 | G40: =SUM(G34:G39) -> 8326
A42: Valores por projeto de PD&I
A43: Projetos | B43: TOTAL | D43: Vlr materiais | E43: Vlr terceiros | F43: Vlr Rh parcial | G43: Vlr exclusivos
A44: {='Resumo - PROJETOS'!B12:B49} -> IRIS | B44: =sum(D44:G44) -> 422175.06 | D44: - | E44: =IFERROR(__xludf.DUMMYFUNCTION("iferror(sum(filter('Resumo - TERCEIROS'!$G:$G,'Resumo - TERCEIROS'!$K:$K=TRUE,'Resumo - TERCEIROS'!$B:$B=$A44)),0)"),105672.13) -> 105672.13 | F44: =IFERROR(__xludf.DUMMYFUNCTION("iferror(sum(filter('Resumo - TIMESHEETS'!$L$12:$L49,'Resumo - TIMESHEETS'!$O$12:$O49=""Parcial"",'Resumo - TIMESHEETS'!$C$12:$C49=$A44)),0)"),316502.92701534065) -> 316502.93 | G44: =IFERROR(__xludf.DUMMYFUNCTION("iferror(sum(filter('Resumo - TIMESHEETS'!$L$12:$L49,'Resumo - TIMESHEETS'!$O$12:$O49=""Exclusivo"",'Resumo - TIMESHEETS'!$C$12:$C49=$A44)),0)"),0.0) -> 0
A45: NOTIFY | B45: =sum(D45:G45) -> 2006004.4 | D45: - | E45: =IFERROR(__xludf.DUMMYFUNCTION("iferror(sum(filter('Resumo - TERCEIROS'!$G:$G,'Resumo - TERCEIROS'!$K:$K=TRUE,'Resumo - TERCEIROS'!$B:$B=$A45)),0)"),1063146.31) -> 1063146.3 | F45: =IFERROR(__xludf.DUMMYFUNCTION("iferror(sum(filter('Resumo - TIMESHEETS'!$L$12:$L49,'Resumo - TIMESHEETS'!$O$12:$O49=""Parcial"",'Resumo - TIMESHEETS'!$C$12:$C49=$A45)),0)"),70628.94894818438) -> 70628.949 | G45: =IFERROR(__xludf.DUMMYFUNCTION("iferror(sum(filter('Resumo - TIMESHEETS'!$L$12:$L49,'Resumo - TIMESHEETS'!$O$12:$O49=""Exclusivo"",'Resumo - TIMESHEETS'!$C$12:$C49=$A45)),0)"),872229.1409257068) -> 872229.14
A46: P&D_1 | B46: =sum(D46:G46) -> 100730.61 | D46: - | E46: =IFERROR(__xludf.DUMMYFUNCTION("iferror(sum(filter('Resumo - TERCEIROS'!$G:$G,'Resumo - TERCEIROS'!$K:$K=TRUE,'Resumo - TERCEIROS'!$B:$B=$A46)),0)"),0.0) -> 0 | F46: =IFERROR(__xludf.DUMMYFUNCTION("iferror(sum(filter('Resumo - TIMESHEETS'!$L$12:$L49,'Resumo - TIMESHEETS'!$O$12:$O49=""Parcial"",'Resumo - TIMESHEETS'!$C$12:$C49=$A46)),0)"),100730.61356324713) -> 100730.61 | G46: =IFERROR(__xludf.DUMMYFUNCTION("iferror(sum(filter('Resumo - TIMESHEETS'!$L$12:$L49,'Resumo - TIMESHEETS'!$O$12:$O49=""Exclusivo"",'Resumo - TIMESHEETS'!$C$12:$C49=$A46)),0)"),0.0) -> 0
...

Sheet Resumo - TERCEIROS
B2: NETZSCH
B3: Pesquisa, Desenvolvimento & Inovação
B4: Formulário de PD&I - Ano 2023
B5: - preencher somente os campos sombreados (cinza)
B8: Dossiê do projeto
B9: Investimentos com terceiros
B11: Projeto | C11: Etapa | D11: Fornecedor | E11: CNPJ | F11: Nota fiscal | G11: Valor | H11: Data | I11: Descrição da Atividade | J11: Objetivo do gasto e eventual info de rateio | K11: Projeto incentiv. | M11: CNPJ
B12: {={'IRIS TERCEIROS'!B12:J579;'NOTIFY TERCEIROS'!B12:J579;'P&D_1 TERCEIROS'!B12:J579;'P&D_2 TERCEIROS'!B12:J579;'P&D_3 TERCEIROS'!B12:J579}} -> IRIS | C12: IRISV3 - Desenvolvimento de bilbioteca de objetos | D12: KMCC Equipamentos Elétricos Ltda | E12: 05.974.479/0001-80 | F12: NFS-e2128 | G12: 572 | H12: 45017 | I12: Desenvolvimento IHM | J12: Total nota fiscal: R$ 8931. Rateio: 6,4 % | K12: {=xlookup($B$12:$B579,'Resumo - PROJETOS'!$B:$B,'Resumo - PROJETOS'!$C:$C,,0)} -> TRUE
B13: IRIS | C13: Todas as etapas | D13: JAV AUTOMACAO INDUSTRIAL LTDA | E13: 82.731.779/0002-60 | F13: NFS-e1363 | G13: 9963.35 | H13: 45065 | I13: Serviço de manutenção de acesso remoto TALK2M | J13: Total nota fiscal: R$ 9963,35. Rateio: 100 % | K13: TRUE
B14: IRIS | C14: Todas as etapas | D14: JAV AUTOMACAO INDUSTRIAL LTDA | E14: 82.731.779/0002-60 | F14: NFS-e1373 | G14: 28380.48 | H14: 45082 | I14: Licenças de desenvolvimento ROCKWELL | J14: Total nota fiscal: R$ 28380,48. Rateio: 100 % | K14: TRUE
B15: IRIS | C15: Todas as etapas | D15: SIEMENS INFRAESTRUTURA E INDÚSTRIA LTDA. | E15: 34.776.007/0003-83 | F15: NFS-e7876 | G15: 19768.3 | H15: 45141 | I15: Licenças de desenvolvimento SIEMENS | J15: Total nota fiscal: R$ 19768,3. Rateio: 100 % | K15: TRUE
B16: IRIS | C16: IRISV3 - Desenvolvimento de bilbioteca de objetos | D16: KMCC Equipamentos Elétricos Ltda | E16: 05.974.479/0001-80 | F16: NFS-e2193 | G16: 15123 | H16: 45170 | I16: Desenvolvimento IHM | J16: Total nota fiscal: R$ 17375. Rateio: 87,04 % | K16: TRUE
B17: IRIS | C17: IRISV3 - Desenvolvimento de bilbioteca de objetos | D17: KMCC Equipamentos Elétricos Ltda | E17: 05.974.479/0001-80 | F17: NFS-e2218 | G17: 15045 | H17: 45200 | I17: Desenvolvimento IHM | J17: Total nota fiscal: R$ 20052,5. Rateio: 75,03 % | K17: TRUE
B18: IRIS | C18: IRISV3 - Desenvolvimento de bilbioteca de objetos | D18: KMCC Equipamentos Elétricos Ltda | E18: 05.974.479/0001-80 | F18: NFS-e2228 | G18: 16820 | H18: 45231 | I18: Desenvolvimento IHM | J18: Total nota fiscal: R$ 17962,5. Rateio: 93,64 % | K18: TRUE
B19: Notify | C19: Criação de ordens de serviço | D19: Materialize Serviços Digitais Ltda | E19: 34.269.716/0001-00 | F19: 338 | G19: 34850 | H19: 44929 | I19: Agênciamento de serviços de desenvovimento de software | J19: Total nota fiscal: R$ 69700. Rateio: 50 % | K19: TRUE
B20: Notify | C20: Planejamento de manutenções preventivas | D20: Materialize Serviços Digitais Ltda | E20: 34.269.716/0001-00 | F20: 338 | G20: 34850 | H20: 44929 | I20: Agênciamento de serviços de desenvovimento de software | J20: Total nota fiscal: R$ 69700. Rateio: 50 % | K20: TRUE
B21: Notify | C21: Criação de ordens de serviço | D21: Amazon AWS Serviços Brasil Ltda | E21: 23.412.247/0001-10 | F21: 1684279_TRARB7GL | G21: 4059.07 | H21: 44959 | I21: Custo da infraestrutura em nuvem | J21: Total nota fiscal: R$ 8118,14. Rateio: 50 % | K21: TRUE
B22: Notify | C22: Planejamento de manutenções preventivas | D22: Amazon AWS Serviços Brasil Ltda | E22: 23.412.247/0001-10 | F22: 1684279_TRARB7GL | G22: 4059.07 | H22: 44959 | I22: Custo da infraestrutura em nuvem | J22: Total nota fiscal: R$ 8118,14. Rateio: 50 % | K22: TRUE
B23: Notify | C23: Teste de penetração (cybersegurança) | D23: XLABS ON SECURITY SEGURANCA DA INFORMACAO LTDA | E23: 30.162.109/0001-96 | F23: 202324 | G23: 4850 | H23: 44960 | I23: Serviços prestados em segurança da informação | J23: Total nota fiscal: R$ 4850. Rateio: 100 % | K23: TRUE
B24: Notify | C24: Criação de ordens de serviço | D24: Materialize Serviços Digitais Ltda | E24: 34.269.716/0001-00 | F24: 377 | G24: 34850 | H24: 44960 | I24: Agênciamento de serviços de desenvovimento de software | J24: Total nota fiscal: R$ 69700. Rateio: 50 % | K24: TRUE
B25: Notify | C25: Planejamento de manutenções preventivas | D25: Materialize Serviços Digitais Ltda | E25: 34.269.716/0001-00 | F25: 377 | G25: 34850 | H25: 44960 | I25: Agênciamento de serviços de desenvovimento de software | J25: Total nota fiscal: R$ 69700. Rateio: 50 % | K25: TRUE
B26: Notify | C26: Criação de ordens de serviço | D26: Amazon AWS Serviços Brasil Ltda | E26: 23.412.247/0001-10 | F26: 1834979_ZLH5AEKP | G26: 1907.88 | H26: 44987 | I26: Custo da infraestrutura em nuvem | J26: Total nota fiscal: R$ 7631,54. Rateio: 25 % | K26: TRUE
B27: Notify | C27: Planejamento de manutenções preventivas | D27: Amazon AWS Serviços Brasil Ltda | E27: 23.412.247/0001-10 | F27: 1834979_ZLH5AEKP | G27: 1907.88 | H27: 44987 | I27: Custo da infraestrutura em nuvem | J27: Total nota fiscal: R$ 7631,54. Rateio: 25 % | K27: TRUE
B28: Notify | C28: Gerencimeno de licenças | D28: Amazon AWS Serviços Brasil Ltda | E28: 23.412.247/0001-10 | F28: 1834979_ZLH5AEKP | G28: 1907.88 | H28: 44987 | I28: Custo da infraestrutura em nuvem | J28: Total nota fiscal: R$ 7631,54. Rateio: 25 % | K28: TRUE
B29: Notify | C29: Duplicar máquinas existentes | D29: Amazon AWS Serviços Brasil Ltda | E29: 23.412.247/0001-10 | F29: 1834979_ZLH5AEKP | G29: 1907.88 | H29: 44987 | I29: Custo da infraestrutura em nuvem | J29: Total nota fiscal: R$ 7631,54. Rateio: 25 % | K29: TRUE
B30: Notify | C30: Criação de ordens de serviço | D30: Materialize Serviços Digitais Ltda | E30: 34.269.716/0001-00 | F30: 408 | G30: 17425 | H30: 44991 | I30: Agênciamento de serviços de desenvovimento de software | J30: Total nota fiscal: R$ 69700. Rateio: 25 % | K30: TRUE
B31: Notify | C31: Planejamento de manutenções preventivas | D31: Materialize Serviços Digitais Ltda | E31: 34.269.716/0001-00 | F31: 408 | G31: 17425 | H31: 44991 | I31: Agênciamento de serviços de desenvovimento de software | J31: Total nota fiscal: R$ 69700. Rateio: 25 % | K31: TRUE
B32: Notify | C32: Gerencimeno de licenças | D32: Materialize Serviços Digitais Ltda | E32: 34.269.716/0001-00 | F32: 408 | G32: 17425 | H32: 44991 | I32: Agênciamento de serviços de desenvovimento de software | J32: Total nota fiscal: R$ 69700. Rateio: 25 % | K32: TRUE
B33: Notify | C33: Duplicar máquinas existentes | D33: Materialize Serviços Digitais Ltda | E33: 34.269.716/0001-00 | F33: 408 | G33: 17425 | H33: 44991 | I33: Agênciamento de serviços de desenvovimento de software | J33: Total nota fiscal: R$ 69700. Rateio: 25 % | K33: TRUE
B34: Notify | C34: Teste de penetração (cybersegurança) | D34: XLABS ON SECURITY SEGURANCA DA INFORMACAO LTDA | E34: 30.162.109/0001-96 | F34: 202369 | G34: 4850 | H34: 44992 | I34: Serviços prestados em segurança da informação | J34: Total nota fiscal: R$ 4850. Rateio: 100 % | K34: TRUE
B35: Notify | C35: Criação de ordens de serviço | D35: Amazon AWS Serviços Brasil Ltda | E35: 23.412.247/0001-10 | F35: 1851758_THE47Z4R | G35: 2101.47 | H35: 45018 | I35: Custo da infraestrutura em nuvem | J35: Total nota fiscal: R$ 8405,9. Rateio: 25 % | K35: TRUE
B36: Notify | C36: Planejamento de manutenções preventivas | D36: Amazon AWS Serviços Brasil Ltda | E36: 23.412.247/0001-10 | F36: 1851758_THE47Z4R | G36: 2101.47 | H36: 45018 | I36: Custo da infraestrutura em nuvem | J36: Total nota fiscal: R$ 8405,9. Rateio: 25 % | K36: TRUE
B37: Notify | C37: Gerencimeno de licenças | D37: Amazon AWS Serviços Brasil Ltda | E37: 23.412.247/0001-10 | F37: 1851758_THE47Z4R | G37: 2101.47 | H37: 45018 | I37: Custo da infraestrutura em nuvem | J37: Total nota fiscal: R$ 8405,9. Rateio: 25 % | K37: TRUE
B38: Notify | C38: Duplicar máquinas existentes | D38: Amazon AWS Serviços Brasil Ltda | E38: 23.412.247/0001-10 | F38: 1851758_THE47Z4R | G38: 2101.47 | H38: 45018 | I38: Custo da infraestrutura em nuvem | J38: Total nota fiscal: R$ 8405,9. Rateio: 25 % | K38: TRUE
B39: Notify | C39: Criação de ordens de serviço | D39: Materialize Serviços Digitais Ltda | E39: 34.269.716/0001-00 | F39: 439 | G39: 17425 | H39: 45022 | I39: Agênciamento de serviços de desenvovimento de software | J39: Total nota fiscal: R$ 69700. Rateio: 25 % | K39: TRUE
B40: Notify | C40: Planejamento de manutenções preventivas | D40: Materialize Serviços Digitais Ltda | E40: 34.269.716/0001-00 | F40: 439 | G40: 17425 | H40: 45022 | I40: Agênciamento de serviços de desenvovimento de software | J40: Total nota fiscal: R$ 69700. Rateio: 25 % | K40: TRUE
B41: Notify | C41: Gerencimeno de licenças | D41: Materialize Serviços Digitais Ltda | E41: 34.269.716/0001-00 | F41: 439 | G41: 17425 | H41: 45022 | I41: Agênciamento de serviços de desenvovimento de software | J41: Total nota fiscal: R$ 69700. Rateio: 25 % | K41: TRUE
B42: Notify | C42: Duplicar máquinas existentes | D42: Materialize Serviços Digitais Ltda | E42: 34.269.716/0001-00 | F42: 439 | G42: 17425 | H42: 45022 | I42: Agênciamento de serviços de desenvovimento de software | J42: Total nota fiscal: R$ 69700. Rateio: 25 % | K42: TRUE
B43: Notify | C43: Gerencimeno de licenças | D43: Amazon AWS Serviços Brasil Ltda | E43: 23.412.247/0001-10 | F43: 1974603_J4XEGDTG | G43: 3917.99 | H43: 45048 | I43: Custo da infraestrutura em nuvem | J43: Total nota fiscal: R$ 7835,98. Rateio: 50 % | K43: TRUE
B44: Notify | C44: Duplicar máquinas existentes | D44: Amazon AWS Serviços Brasil Ltda | E44: 23.412.247/0001-10 | F44: 1974603_J4XEGDTG | G44: 3917.99 | H44: 45048 | I44: Custo da infraestrutura em nuvem | J44: Total nota fiscal: R$ 7835,98. Rateio: 50 % | K44: TRUE
...

Sheet Resumo - PROJETOS
B2: NETZSCH
B3: Pesquisa, Desenvolvimento & Inovação
B4: Formulário de PD&I - Ano 2023
B5: - preencher somente os campos sombreados (cinza)
B8: Dossiê do projeto
B9: Investimentos com terceiros
B11: Projeto | C11: Incentivado pela Lei do Bem | D11: Objetiva tornar-se um Ativo | E11: Objetiva gerar patente/registro
B12: IRIS | C12: {=transpose(IRIS!M4:M6)} -> TRUE | D12: FALSE | E12: FALSE
B13: NOTIFY | C13: {=transpose(NOTIFY!M4:M6)} -> TRUE | D13: FALSE | E13: FALSE
B14: P&D_1 | C14: {=TRANSPOSE('P&D_1'!M4:M6)} -> TRUE | D14: FALSE | E14: FALSE
B15: P&D_2 | C15: {=TRANSPOSE('P&D_2'!M4:M6)} -> TRUE | D15: FALSE | E15: FALSE
B16: P&D_3 | C16: {=transpose('P&D_3'!M4:M6)} -> TRUE | D16: FALSE | E16: FALSE

Sheet Resumo - TIMESHEETS
B2: NETZSCH
B3: Pesquisa, Desenvolvimento & Inovação
B4: Formulário de PD&I - Ano 2023
B5: - preencher somente os campos sombreados (cinza)
J6: Treinamento
J7: Pesquisa
B8: Dossiê do projeto | J8: Desenvolvimento
B9: Atividades de Pesquisa, Desenvolvimento e Inovação | J9: Gestão e outros
B11: RowID | C11: Projeto | D11: Etapa | E11: Colaborador | F11: CPF | G11: Data | H11: Tempo (h) | J11: Classificação | K11: Descrição da atividade e observações | L11: Custo | M11: Atividade incentiv. | N11: Projeto incentiv. | O11: Dedic.
C12: IRIS | D12: Revisão protocolos de comissionamento | E12: Alexandre Baseggio | G12: 44927 | H12: 19.77 | I12: =H12/24 -> 0.82375 | J12: Desenvolvimento | K12: Desenvolvimento PLC | L12: =iferror(if(and($M12=TRUE,$N12=TRUE),vlookup($E12,RH!$B$48:$S$70,month($G12)+6,false)*$H12,0),0) -> 1057.0824 | M12: =if(OR(J12="Treinamento",J12="Pesquisa",J12="Desenvolvimento"),TRUE,FALSE) -> TRUE | N12: {=xlookup($C$12:$C273,'Resumo - PROJETOS'!$B:$B,'Resumo - PROJETOS'!$C:$C,,0)} -> TRUE | O12: {=xlookup($E$12:$E273,RH!$B:$B,RH!$V:$V,,0)} -> Parcial
C13: IRIS | D13: Revisão protocolos de comissionamento | E13: Eduardo Flohr | F13: 064.303.159-67 | G13: 44927 | H13: 2.5 | I13: =H13/24 -> 0.10416667 | J13: Gestão e outros | K13: Gestão | L13: =iferror(if(and($M13=TRUE,$N13=TRUE),vlookup($E13,RH!$B$48:$S$70,month($G13)+6,false)*$H13,0),0) -> 0 | M13: =if(OR(J13="Treinamento",J13="Pesquisa",J13="Desenvolvimento"),TRUE,FALSE) -> FALSE | N13: TRUE | O13: Parcial
C14: IRIS | D14: Revisão protocolos de comissionamento | E14: Gabriel Alves Ferraz | F14: 132.105.086-07 | G14: 44927 | H14: 28 | I14: =H14/24 -> 1.1666667 | J14: Desenvolvimento | K14: Desenvolvimento IHM | L14: =iferror(if(and($M14=TRUE,$N14=TRUE),vlookup($E14,RH!$B$48:$S$70,month($G14)+6,false)*$H14,0),0) -> 598.90009 | M14: =if(OR(J14="Treinamento",J14="Pesquisa",J14="Desenvolvimento"),TRUE,FALSE) -> TRUE | N14: TRUE | O14: Parcial
C15: IRIS | D15: Revisão protocolos de comissionamento | E15: Filipe Harbs | G15: 44927 | H15: 22 | I15: =H15/24 -> 0.91666667 | J15: Desenvolvimento | K15: Desenvolvimento IHM | L15: =iferror(if(and($M15=TRUE,$N15=TRUE),vlookup($E15,RH!$B$48:$S$70,month($G15)+6,false)*$H15,0),0) -> 929.56786 | M15: =if(OR(J15="Treinamento",J15="Pesquisa",J15="Desenvolvimento"),TRUE,FALSE) -> TRUE | N15: TRUE | O15: Parcial
C16: IRIS | D16: Revisão protocolos de comissionamento | E16: Ivo Ersching | G16: 44927 | H16: 11 | I16: =H16/24 -> 0.45833333 | J16: Pesquisa | K16: Desenvolvimento PLC | L16: =iferror(if(and($M16=TRUE,$N16=TRUE),vlookup($E16,RH!$B$48:$S$70,month($G16)+6,false)*$H16,0),0) -> 689.28516 | M16: =if(OR(J16="Treinamento",J16="Pesquisa",J16="Desenvolvimento"),TRUE,FALSE) -> TRUE | N16: TRUE | O16: Parcial
C17: IRIS | D17: Aprimorar dados de processo | E17: Filipe Harbs | G17: 44958 | H17: 4 | I17: =H17/24 -> 0.16666667 | J17: Desenvolvimento | K17: Desenvolvimento IHM | L17: =iferror(if(and($M17=TRUE,$N17=TRUE),vlookup($E17,RH!$B$48:$S$70,month($G17)+6,false)*$H17,0),0) -> 175.05405 | M17: =if(OR(J17="Treinamento",J17="Pesquisa",J17="Desenvolvimento"),TRUE,FALSE) -> TRUE | N17: TRUE | O17: Parcial
C18: IRIS | D18: Aprimorar dados de processo | E18: Ivo Ersching | G18: 44958 | H18: 5.5 | I18: =H18/24 -> 0.22916667 | J18: Desenvolvimento | K18: Desenvolvimento PLC | L18: =iferror(if(and($M18=TRUE,$N18=TRUE),vlookup($E18,RH!$B$48:$S$70,month($G18)+6,false)*$H18,0),0) -> 356.96257 | M18: =if(OR(J18="Treinamento",J18="Pesquisa",J18="Desenvolvimento"),TRUE,FALSE) -> TRUE | N18: TRUE | O18: Parcial
C19: IRIS | D19: Aprimorar dados de processo | E19: Eduardo Flohr | F19: 064.303.159-67 | G19: 44958 | H19: 5.5 | I19: =H19/24 -> 0.22916667 | J19: Gestão e outros | K19: Gestão | L19: =iferror(if(and($M19=TRUE,$N19=TRUE),vlookup($E19,RH!$B$48:$S$70,month($G19)+6,false)*$H19,0),0) -> 0 | M19: =if(OR(J19="Treinamento",J19="Pesquisa",J19="Desenvolvimento"),TRUE,FALSE) -> FALSE | N19: TRUE | O19: Parcial
C20: IRIS | D20: Configuração de dispositivo de acesso remoto | E20: Gabriel Alves Ferraz | F20: 132.105.086-07 | G20: 44958 | H20: 33 | I20: =H20/24 -> 1.375 | J20: Desenvolvimento | K20: Desenvolvimento IHM | L20: =iferror(if(and($M20=TRUE,$N20=TRUE),vlookup($E20,RH!$B$48:$S$70,month($G20)+6,false)*$H20,0),0) -> 731.07855 | M20: =if(OR(J20="Treinamento",J20="Pesquisa",J20="Desenvolvimento"),TRUE,FALSE) -> TRUE | N20: TRUE | O20: Parcial
C21: IRIS | D21: Configuração de dispositivo de acesso remoto | E21: Lucca Sardá Tonim Matos | F21: 123.342.589-70 | G21: 44958 | H21: 4.33 | I21: =H21/24 -> 0.18041667 | J21: Desenvolvimento | K21: Documentação | L21: =iferror(if(and($M21=TRUE,$N21=TRUE),vlookup($E21,RH!$B$48:$S$70,month($G21)+6,false)*$H21,0),0) -> 54.034242 | M21: =if(OR(J21="Treinamento",J21="Pesquisa",J21="Desenvolvimento"),TRUE,FALSE) -> TRUE | N21: TRUE | O21: Parcial
C22: IRIS | D22: Configuração de dispositivo de acesso remoto | E22: Eduardo Flohr | F22: 064.303.159-67 | G22: 44958 | H22: 6 | I22: =H22/24 -> 0.25 | J22: Gestão e outros | K22: Gestão | L22: =iferror(if(and($M22=TRUE,$N22=TRUE),vlookup($E22,RH!$B$48:$S$70,month($G22)+6,false)*$H22,0),0) -> 0 | M22: =if(OR(J22="Treinamento",J22="Pesquisa",J22="Desenvolvimento"),TRUE,FALSE) -> FALSE | N22: TRUE | O22: Parcial
C23: IRIS | D23: IRISV3 - Projetar novo sistema de automação | E23: Eduardo Flohr | F23: 064.303.159-67 | G23: 44958 | H23: 5 | I23: =H23/24 -> 0.20833333 | J23: Gestão e outros | K23: Gestão | L23: =iferror(if(and($M23=TRUE,$N23=TRUE),vlookup($E23,RH!$B$48:$S$70,month($G23)+6,false)*$H23,0),0) -> 0 | M23: =if(OR(J23="Treinamento",J23="Pesquisa",J23="Desenvolvimento"),TRUE,FALSE) -> FALSE | N23: TRUE | O23: Parcial
C24: IRIS | D24: IRISV3 - Projetar novo sistema de automação | E24: Johann Ribeiro | F24: 100.110.019-09 | G24: 44958 | H24: 24 | I24: =H24/24 -> 1 | J24: Desenvolvimento | K24: Documentação | L24: =iferror(if(and($M24=TRUE,$N24=TRUE),vlookup($E24,RH!$B$48:$S$70,month($G24)+6,false)*$H24,0),0) -> 299.49695 | M24: =if(OR(J24="Treinamento",J24="Pesquisa",J24="Desenvolvimento"),TRUE,FALSE) -> TRUE | N24: TRUE | O24: Parcial
C25: IRIS | D25: IRISV3 - Projetar novo sistema de automação | E25: Paulo Fernando Odwazny | F25: 035.705.119-01 | G25: 44958 | H25: 3 | I25: =H25/24 -> 0.125 | J25: Pesquisa | K25: Especificação da funcionalidade | L25: =iferror(if(and($M25=TRUE,$N25=TRUE),vlookup($E25,RH!$B$48:$S$70,month($G25)+6,false)*$H25,0),0) -> 320.4183 | M25: =if(OR(J25="Treinamento",J25="Pesquisa",J25="Desenvolvimento"),TRUE,FALSE) -> TRUE | N25: TRUE | O25: Parcial
C26: IRIS | D26: Aprimorar dados de processo | E26: Filipe Harbs | G26: 44986 | H26: 3.2 | I26: =H26/24 -> 0.13333333 | J26: Desenvolvimento | K26: Desenvolvimento IHM | L26: =iferror(if(and($M26=TRUE,$N26=TRUE),vlookup($E26,RH!$B$48:$S$70,month($G26)+6,false)*$H26,0),0) -> 121.71268 | M26: =if(OR(J26="Treinamento",J26="Pesquisa",J26="Desenvolvimento"),TRUE,FALSE) -> TRUE | N26: TRUE | O26: Parcial
C27: IRIS | D27: Aprimorar dados de processo | E27: Ivo Ersching | G27: 44986 | H27: 17.33 | I27: =H27/24 -> 0.72208333 | J27: Desenvolvimento | K27: Desenvolvimento PLC | L27: =iferror(if(and($M27=TRUE,$N27=TRUE),vlookup($E27,RH!$B$48:$S$70,month($G27)+6,false)*$H27,0),0) -> 977.53477 | M27: =if(OR(J27="Treinamento",J27="Pesquisa",J27="Desenvolvimento"),TRUE,FALSE) -> TRUE | N27: TRUE | O27: Parcial
C28: IRIS | D28: Aprimorar dados de processo | E28: Eduardo Flohr | F28: 064.303.159-67 | G28: 44986 | H28: 15 | I28: =H28/24 -> 0.625 | J28: Gestão e outros | L28: =iferror(if(and($M28=TRUE,$N28=TRUE),vlookup($E28,RH!$B$48:$S$70,month($G28)+6,false)*$H28,0),0) -> 0 | M28: =if(OR(J28="Treinamento",J28="Pesquisa",J28="Desenvolvimento"),TRUE,FALSE) -> FALSE | N28: TRUE | O28: Parcial
C29: IRIS | D29: Configuração de dispositivo de acesso remoto | E29: Gabriel Alves Ferraz | F29: 132.105.086-07 | G29: 44986 | H29: 30 | I29: =H29/24 -> 1.25 | J29: Desenvolvimento | K29: Desenvolvimento IHM | L29: =iferror(if(and($M29=TRUE,$N29=TRUE),vlookup($E29,RH!$B$48:$S$70,month($G29)+6,false)*$H29,0),0) -> 577.62371 | M29: =if(OR(J29="Treinamento",J29="Pesquisa",J29="Desenvolvimento"),TRUE,FALSE) -> TRUE | N29: TRUE | O29: Parcial
C30: IRIS | D30: Configuração de dispositivo de acesso remoto | E30: Lucca Sardá Tonim Matos | F30: 123.342.589-70 | G30: 44986 | H30: 15.75 | I30: =H30/24 -> 0.65625 | J30: Desenvolvimento | K30: Documentação | L30: =iferror(if(and($M30=TRUE,$N30=TRUE),vlookup($E30,RH!$B$48:$S$70,month($G30)+6,false)*$H30,0),0) -> 170.81869 | M30: =if(OR(J30="Treinamento",J30="Pesquisa",J30="Desenvolvimento"),TRUE,FALSE) -> TRUE | N30: TRUE | O30: Parcial
C31: IRIS | D31: Configuração de dispositivo de acesso remoto | E31: Eduardo Flohr | F31: 064.303.159-67 | G31: 44986 | H31: 17.5 | I31: =H31/24 -> 0.72916667 | J31: Gestão e outros | K31: Gestão | L31: =iferror(if(and($M31=TRUE,$N31=TRUE),vlookup($E31,RH!$B$48:$S$70,month($G31)+6,false)*$H31,0),0) -> 0 | M31: =if(OR(J31="Treinamento",J31="Pesquisa",J31="Desenvolvimento"),TRUE,FALSE) -> FALSE | N31: TRUE | O31: Parcial
C32: IRIS | D32: Criação de processo de liberação de versão | E32: Gabriel Alves Ferraz | F32: 132.105.086-07 | G32: 44986 | H32: 32.5 | I32: =H32/24 -> 1.3541667 | J32: Desenvolvimento | K32: Desenvolvimento IHM | L32: =iferror(if(and($M32=TRUE,$N32=TRUE),vlookup($E32,RH!$B$48:$S$70,month($G32)+6,false)*$H32,0),0) -> 625.75902 | M32: =if(OR(J32="Treinamento",J32="Pesquisa",J32="Desenvolvimento"),TRUE,FALSE) -> TRUE | N32: TRUE | O32: Parcial
C33: IRIS | D33: Criação de processo de liberação de versão | E33: Alexandre Baseggio | G33: 44986 | H33: 16.85 | I33: =H33/24 -> 0.70208333 | J33: Desenvolvimento | K33: Desenvolvimento PLC | L33: =iferror(if(and($M33=TRUE,$N33=TRUE),vlookup($E33,RH!$B$48:$S$70,month($G33)+6,false)*$H33,0),0) -> 811.01612 | M33: =if(OR(J33="Treinamento",J33="Pesquisa",J33="Desenvolvimento"),TRUE,FALSE) -> TRUE | N33: TRUE | O33: Parcial
C34: IRIS | D34: Criação de processo de liberação de versão | E34: Paulo Fernando Odwazny | F34: 035.705.119-01 | G34: 44986 | H34: 5.5 | I34: =H34/24 -> 0.22916667 | J34: Pesquisa | K34: Especificação da funcionalidade | L34: =iferror(if(and($M34=TRUE,$N34=TRUE),vlookup($E34,RH!$B$48:$S$70,month($G34)+6,false)*$H34,0),0) -> 510.5431 | M34: =if(OR(J34="Treinamento",J34="Pesquisa",J34="Desenvolvimento"),TRUE,FALSE) -> TRUE | N34: TRUE | O34: Parcial
C35: IRIS | D35: IRISV3 - Projetar novo sistema de automação | E35: Alexandre Baseggio | G35: 44986 | H35: 1.92 | I35: =H35/24 -> 0.08 | J35: Desenvolvimento | K35: Desenvolvimento PLC | L35: =iferror(if(and($M35=TRUE,$N35=TRUE),vlookup($E35,RH!$B$48:$S$70,month($G35)+6,false)*$H35,0),0) -> 92.412519 | M35: =if(OR(J35="Treinamento",J35="Pesquisa",J35="Desenvolvimento"),TRUE,FALSE) -> TRUE | N35: TRUE | O35: Parcial
C36: IRIS | D36: IRISV3 - Projetar novo sistema de automação | E36: Eduardo Flohr | F36: 064.303.159-67 | G36: 44986 | H36: 26.75 | I36: =H36/24 -> 1.1145833 | J36: Gestão e outros | K36: Gestão | L36: =iferror(if(and($M36=TRUE,$N36=TRUE),vlookup($E36,RH!$B$48:$S$70,month($G36)+6,false)*$H36,0),0) -> 0 | M36: =if(OR(J36="Treinamento",J36="Pesquisa",J36="Desenvolvimento"),TRUE,FALSE) -> FALSE | N36: TRUE | O36: Parcial
C37: IRIS | D37: IRISV3 - Projetar novo sistema de automação | E37: Johann Ribeiro | F37: 100.110.019-09 | G37: 44986 | H37: 86.58 | I37: =H37/24 -> 3.6075 | J37: Desenvolvimento | K37: Documentação | L37: =iferror(if(and($M37=TRUE,$N37=TRUE),vlookup($E37,RH!$B$48:$S$70,month($G37)+6,false)*$H37,0),0) -> 939.01474 | M37: =if(OR(J37="Treinamento",J37="Pesquisa",J37="Desenvolvimento"),TRUE,FALSE) -> TRUE | N37: TRUE | O37: Parcial
C38: IRIS | D38: IRISV3 - Projetar novo sistema de automação | E38: Paulo Fernando Odwazny | F38: 035.705.119-01 | G38: 44986 | H38: 61.98 | I38: =H38/24 -> 2.5825 | J38: Pesquisa | K38: Especificação da funcionalidade | L38: =iferror(if(and($M38=TRUE,$N38=TRUE),vlookup($E38,RH!$B$48:$S$70,month($G38)+6,false)*$H38,0),0) -> 5753.3566 | M38: =if(OR(J38="Treinamento",J38="Pesquisa",J38="Desenvolvimento"),TRUE,FALSE) -> TRUE | N38: TRUE | O38: Parcial
C39: IRIS | D39: Tradução da Interface para o idioma Estoniano | E39: Gabriel Alves Ferraz | F39: 132.105.086-07 | G39: 45017 | H39: 80.25 | I39: =H39/24 -> 3.34375 | J39: Desenvolvimento | K39: Desenvolvimento IHM | L39: =iferror(if(and($M39=TRUE,$N39=TRUE),vlookup($E39,RH!$B$48:$S$70,month($G39)+6,false)*$H39,0),0) -> 2124.3809 | M39: =if(OR(J39="Treinamento",J39="Pesquisa",J39="Desenvolvimento"),TRUE,FALSE) -> TRUE | N39: TRUE | O39: Parcial
C40: IRIS | D40: Tradução da Interface para o idioma Estoniano | E40: Lucca Sardá Tonim Matos | F40: 123.342.589-70 | G40: 45017 | H40: 15.58 | I40: =H40/24 -> 0.64916667 | J40: Desenvolvimento | K40: Documentação | L40: =iferror(if(and($M40=TRUE,$N40=TRUE),vlookup($E40,RH!$B$48:$S$70,month($G40)+6,false)*$H40,0),0) -> 232.31961 | M40: =if(OR(J40="Treinamento",J40="Pesquisa",J40="Desenvolvimento"),TRUE,FALSE) -> TRUE | N40: TRUE | O40: Parcial
C41: IRIS | D41: Tradução da Interface para o idioma Estoniano | E41: Johann Ribeiro | F41: 100.110.019-09 | G41: 45017 | H41: 25 | I41: =H41/24 -> 1.0416667 | J41: Desenvolvimento | K41: Documentação | L41: =iferror(if(and($M41=TRUE,$N41=TRUE),vlookup($E41,RH!$B$48:$S$70,month($G41)+6,false)*$H41,0),0) -> 372.78499 | M41: =if(OR(J41="Treinamento",J41="Pesquisa",J41="Desenvolvimento"),TRUE,FALSE) -> TRUE | N41: TRUE | O41: Parcial
C42: IRIS | D42: Tradução da Interface para o idioma Estoniano | E42: Eduardo Flohr | F42: 064.303.159-67 | G42: 45017 | H42: 16.58 | I42: =H42/24 -> 0.69083333 | J42: Gestão e outros | K42: Gestão | L42: =iferror(if(and($M42=TRUE,$N42=TRUE),vlookup($E42,RH!$B$48:$S$70,month($G42)+6,false)*$H42,0),0) -> 0 | M42: =if(OR(J42="Treinamento",J42="Pesquisa",J42="Desenvolvimento"),TRUE,FALSE) -> FALSE | N42: TRUE | O42: Parcial
...

Sheet Tabela dinâmica 1

Sheet RH
B2: NETZSCH
B3: Pesquisa ,Desenvolvimento & Inovação
B4: Formulário de PD&I - Ano 2022
B5: -preencher somente os campos sombreados (cinza)
B8: Dossiê do projeto
B9: Cálculo de custo - Pessoal
B11: Salário bruto | T11: =(U11/12)*24 -> 183.33333 | U11: =(SUM(H47:S47)*8.8)/24 -> 91.666667
B12: Nome Completo | C12: CPF | D12: notas | E12: Cargo/função | F12: Formação | G12: Attachments | H12: Salário 01 | I12: Salário 02 | J12: Salário 03 | K12: Salário 04 | L12: Salário 05 | M12: Salário 06 | N12: Salário 07 | O12: Salário 08 | P12: Salário 09 | Q12: Salário 10 | R12: Salário 11 | S12: Salário 12 | T12: PD&I time | U12: PD&I (%) | V12: Classificação | W12: Pesquisador
B13: Alberto Reuters | C13: 041.176.229-00 | E13: Gerente Desenv. Soft/Automação | F13: Mestrado | H13: 14837.22 | I13: 14837.22 | J13: 14837.22 | K13: 14837.22 | L13: 14837.22 | M13: 14837.22 | N13: 14837.22 | O13: 14837.22 | P13: 14837.22 | Q13: 24932.42 | R13: 26213.95 | S13: 26213.95 | T13: =IFERROR(__xludf.DUMMYFUNCTION("IFERROR(if(W13=true, SUM(FILTER('Resumo - TIMESHEETS'!$H:$H,'Resumo - TIMESHEETS'!M:M = TRUE,'Resumo - TIMESHEETS'!N:N = TRUE,'Resumo - TIMESHEETS'!E:E = B13))/24,0),0)"),0.0) -> 0 | U13: =T13/$U$11 -> 0 | V13: =IF(U13<80%,"Parcial","Exclusivo") -> Parcial | W13: TRUE
B14: Alexandre Baseggio | C14: 020.066.430-10 | E14: Analista de Automação | F14: Superior Completo | H14: 6923.08 | I14: 6923.08 | J14: 6923.08 | K14: 6923.08 | L14: 6923.08 | M14: 6923.08 | N14: 6923.08 | O14: 6923.08 | P14: 6923.08 | Q14: 6923.08 | R14: 7278.93 | S14: 7278.93 | T14: =IFERROR(__xludf.DUMMYFUNCTION("IFERROR(if(W14=true, SUM(FILTER('Resumo - TIMESHEETS'!$H:$H,'Resumo - TIMESHEETS'!M:M = TRUE,'Resumo - TIMESHEETS'!N:N = TRUE,'Resumo - TIMESHEETS'!E:E = B14))/24,0),0)"),2.56625) -> 2.56625 | U14: =T14/$U$11 -> 0.027995455 | V14: =IF(U14<80%,"Parcial","Exclusivo") -> Parcial | W14: TRUE
B15: Arthur Muniz | C15: 037.196.611-64 | E15: Desenvolvedor de Software | F15: Superior Completo | H15: 11291.29 | I15: 11291.29 | J15: 11291.29 | K15: 11291.29 | L15: 11291.29 | M15: 11291.29 | N15: 11868.23 | O15: 11868.23 | P15: 11868.23 | Q15: 11868.23 | R15: 12478.26 | S15: 12478.26 | T15: =IFERROR(__xludf.DUMMYFUNCTION("IFERROR(if(W15=true, SUM(FILTER('Resumo - TIMESHEETS'!$H:$H,'Resumo - TIMESHEETS'!M:M = TRUE,'Resumo - TIMESHEETS'!N:N = TRUE,'Resumo - TIMESHEETS'!E:E = B15))/24,0),0)"),81.08333333333333) -> 81.083333 | U15: =T15/$U$11 -> 0.88454545 | V15: =IF(U15<80%,"Parcial","Exclusivo") -> Exclusivo | W15: TRUE
B16: Bruno katzjarowksi | C16: 080.850.859-84 | E16: Desenvolvedor de Software | F16: Superior Completo | H16: 14024.96 | I16: 14024.96 | J16: 14024.96 | K16: 14024.96 | L16: 14024.96 | M16: 14024.96 | N16: 14300 | O16: 14300 | P16: 14300 | Q16: 14300 | R16: 15035.02 | S16: 15035.02 | T16: =IFERROR(__xludf.DUMMYFUNCTION("IFERROR(if(W16=true, SUM(FILTER('Resumo - TIMESHEETS'!$H:$H,'Resumo - TIMESHEETS'!M:M = TRUE,'Resumo - TIMESHEETS'!N:N = TRUE,'Resumo - TIMESHEETS'!E:E = B16))/24,0),0)"),88.33333333333333) -> 88.333333 | U16: =T16/$U$11 -> 0.96363636 | V16: =IF(U16<80%,"Parcial","Exclusivo") -> Exclusivo | W16: TRUE
B17: Cleiton Capristano | C17: 068.504.079-88 | E17: Desenvolvedor de Software | F17: Superior Completo | H17: 12500 | I17: 12500 | J17: 12500 | K17: 12500 | L17: 12500 | M17: 12500 | N17: 12500 | O17: 12629.01 | P17: 12629.01 | Q17: 12629.01 | R17: 13278.15 | S17: 13278.15 | T17: =IFERROR(__xludf.DUMMYFUNCTION("IFERROR(if(W17=true, SUM(FILTER('Resumo - TIMESHEETS'!$H:$H,'Resumo - TIMESHEETS'!M:M = TRUE,'Resumo - TIMESHEETS'!N:N = TRUE,'Resumo - TIMESHEETS'!E:E = B17))/24,0),0)"),95.625) -> 95.625 | U17: =T17/$U$11 -> 1.0431818 | V17: =IF(U17<80%,"Parcial","Exclusivo") -> Exclusivo | W17: TRUE
B18: Eduardo Flohr | C18: 064.303.159-67 | E18: Supervisor Automação | F18: Superior Completo | H18: 13351.79 | I18: 13351.79 | J18: 13351.79 | K18: 13351.79 | L18: 13351.79 | M18: 13351.79 | N18: 13351.79 | O18: 13351.79 | P18: 13351.79 | Q18: 18013.96 | R18: 18939.88 | S18: 18939.88 | T18: =IFERROR(__xludf.DUMMYFUNCTION("IFERROR(if(W18=true, SUM(FILTER('Resumo - TIMESHEETS'!$H:$H,'Resumo - TIMESHEETS'!M:M = TRUE,'Resumo - TIMESHEETS'!N:N = TRUE,'Resumo - TIMESHEETS'!E:E = B18))/24,0),0)"),5.53125) -> 5.53125 | U18: =T18/$U$11 -> 0.060340909 | V18: =IF(U18<80%,"Parcial","Exclusivo") -> Parcial | W18: TRUE
B19: Fernando Leal | C19: Bolsista | T19: =IFERROR(__xludf.DUMMYFUNCTION("IFERROR(if(W19=true, SUM(FILTER('Resumo - TIMESHEETS'!$H:$H,'Resumo - TIMESHEETS'!M:M = TRUE,'Resumo - TIMESHEETS'!N:N = TRUE,'Resumo - TIMESHEETS'!E:E = B19))/24,0),0)"),0.0) -> 0 | U19: =T19/$U$11 -> 0 | V19: =IF(U19<80%,"Parcial","Exclusivo") -> Parcial | W19: FALSE
B20: Filipe Harbs | C20: 087.609.209-12 | E20: Analista de Automação | F20: Técnico | H20: 5470.86 | I20: 5470.86 | J20: 5470.86 | K20: 5470.86 | L20: 5470.86 | M20: 5470.86 | N20: 5909.62 | O20: 5909.62 | P20: 5909.62 | Q20: 5909.62 | R20: 6213.38 | S20: 6213.38 | T20: =IFERROR(__xludf.DUMMYFUNCTION("IFERROR(if(W20=true, SUM(FILTER('Resumo - TIMESHEETS'!$H:$H,'Resumo - TIMESHEETS'!M:M = TRUE,'Resumo - TIMESHEETS'!N:N = TRUE,'Resumo - TIMESHEETS'!E:E = B20))/24,0),0)"),63.09625) -> 63.09625 | U20: =T20/$U$11 -> 0.68832273 | V20: =IF(U20<80%,"Parcial","Exclusivo") -> Parcial | W20: TRUE
B21: Gabriel Alves Ferraz | C21: 132.105.086-07 | E21: Analista de Automação | F21: Superior Completo | H21: 2769.45 | I21: 2769.45 | J21: 2769.45 | K21: 2769.45 | L21: 2769.45 | M21: 2769.45 | N21: 2963.31 | O21: 2963.31 | P21: 2963.31 | Q21: 2963.31 | R21: 3115.63 | S21: 3115.63 | T21: =IFERROR(__xludf.DUMMYFUNCTION("IFERROR(if(W21=true, SUM(FILTER('Resumo - TIMESHEETS'!$H:$H,'Resumo - TIMESHEETS'!M:M = TRUE,'Resumo - TIMESHEETS'!N:N = TRUE,'Resumo - TIMESHEETS'!E:E = B21))/24,0),0)"),20.992916666666666) -> 20.992917 | U21: =T21/$U$11 -> 0.22901364 | V21: =IF(U21<80%,"Parcial","Exclusivo") -> Parcial | W21: TRUE
B22: Gabriel Oliveira | C22: 085.943.039-12 | E22: UX/UI Designer | F22: Superior Completo | H22: 0 | I22: 0 | J22: 0 | K22: 10000 | L22: 10000 | M22: 10000 | N22: 10000 | O22: 10000 | P22: 10000 | Q22: 10000 | R22: 10514 | S22: 10514 | T22: =IFERROR(__xludf.DUMMYFUNCTION("IFERROR(if(W22=true, SUM(FILTER('Resumo - TIMESHEETS'!$H:$H,'Resumo - TIMESHEETS'!M:M = TRUE,'Resumo - TIMESHEETS'!N:N = TRUE,'Resumo - TIMESHEETS'!E:E = B22))/24,0),0)"),63.04749999999999) -> 63.0475 | U22: =T22/$U$11 -> 0.68779091 | V22: =IF(U22<80%,"Parcial","Exclusivo") -> Parcial | W22: TRUE
B23: Gabriel Possamai | C23: 085.815.809-47 | E23: Desenvolvedor de Software | F23: Superior Completo | H23: 14856.95 | I23: 14856.95 | J23: 14856.95 | K23: 14856.95 | L23: 14856.95 | M23: 14856.95 | N23: 15216.66 | O23: 15216.66 | P23: 15216.66 | Q23: 15216.66 | R23: 15998.8 | S23: 15998.8 | T23: =IFERROR(__xludf.DUMMYFUNCTION("IFERROR(if(W23=true, SUM(FILTER('Resumo - TIMESHEETS'!$H:$H,'Resumo - TIMESHEETS'!M:M = TRUE,'Resumo - TIMESHEETS'!N:N = TRUE,'Resumo - TIMESHEETS'!E:E = B23))/24,0),0)"),81.875) -> 81.875 | U23: =T23/$U$11 -> 0.89318182 | V23: =IF(U23<80%,"Parcial","Exclusivo") -> Exclusivo | W23: TRUE
B24: Guilherme Jacques | C24: 085.705.039-70 | E24: Analista de Automação | F24: Técnico | H24: 0 | I24: 0 | J24: 0 | K24: 5236.48 | L24: 5236.48 | M24: 5236.48 | N24: 5236.48 | O24: 5236.48 | P24: 5236.48 | Q24: 5236.48 | R24: 5505.64 | S24: 5505.64 | T24: =IFERROR(__xludf.DUMMYFUNCTION("IFERROR(if(W24=true, SUM(FILTER('Resumo - TIMESHEETS'!$H:$H,'Resumo - TIMESHEETS'!M:M = TRUE,'Resumo - TIMESHEETS'!N:N = TRUE,'Resumo - TIMESHEETS'!E:E = B24))/24,0),0)"),2.966666666666667) -> 2.9666667 | U24: =T24/$U$11 -> 0.032363636 | V24: =IF(U24<80%,"Parcial","Exclusivo") -> Parcial | W24: TRUE
B25: Italo Ebel | C25: 534.546.398-08 | E25: Estagiário | F25: Técnico | H25: 0 | I25: 0 | J25: 0 | K25: 0 | L25: 0 | M25: 0 | N25: 0 | O25: 1560 | P25: 1560 | Q25: 1560 | R25: 1641 | S25: 1641 | T25: =IFERROR(__xludf.DUMMYFUNCTION("IFERROR(if(W25=true, SUM(FILTER('Resumo - TIMESHEETS'!$H:$H,'Resumo - TIMESHEETS'!M:M = TRUE,'Resumo - TIMESHEETS'!N:N = TRUE,'Resumo - TIMESHEETS'!E:E = B25))/24,0),0)"),11.479166666666666) -> 11.479167 | U25: =T25/$U$11 -> 0.12522727 | V25: =IF(U25<80%,"Parcial","Exclusivo") -> Parcial | W25: TRUE
B26: Ivo Ersching | C26: 052.208.059-67 | E26: Analista de Automação | F26: Superior Completo | H26: 8113.41 | I26: 8113.41 | J26: 8113.41 | K26: 8113.41 | L26: 8113.41 | M26: 8113.41 | N26: 8113.41 | O26: 8113.41 | P26: 8113.41 | Q26: 8113.41 | R26: 8530.44 | S26: 8530.44 | T26: =IFERROR(__xludf.DUMMYFUNCTION("IFERROR(if(W26=true, SUM(FILTER('Resumo - TIMESHEETS'!$H:$H,'Resumo - TIMESHEETS'!M:M = TRUE,'Resumo - TIMESHEETS'!N:N = TRUE,'Resumo - TIMESHEETS'!E:E = B26))/24,0),0)"),44.840833333333336) -> 44.840833 | U26: =T26/$U$11 -> 0.48917273 | V26: =IF(U26<80%,"Parcial","Exclusivo") -> Parcial | W26: TRUE
B27: Jivago Rusch | C27: 091.530.489-97 | E27: Projetista Industrial | F27: Superior Completo | H27: 5971.56 | I27: 6518.08 | J27: 6518.08 | K27: 6518.08 | L27: 6518.08 | M27: 6518.08 | N27: 7028.31 | O27: 7028.31 | P27: 7028.31 | Q27: 7028.31 | R27: 7389.57 | S27: 7389.57 | T27: =IFERROR(__xludf.DUMMYFUNCTION("IFERROR(if(W27=true, SUM(FILTER('Resumo - TIMESHEETS'!$H:$H,'Resumo - TIMESHEETS'!M:M = TRUE,'Resumo - TIMESHEETS'!N:N = TRUE,'Resumo - TIMESHEETS'!E:E = B27))/24,0),0)"),56.110833333333325) -> 56.110833 | U27: =T27/$U$11 -> 0.61211818 | V27: =IF(U27<80%,"Parcial","Exclusivo") -> Parcial | W27: TRUE
B28: Johann Ribeiro | C28: 100.110.019-09 | E28: Estagiário | F28: Técnico | H28: 0 | I28: 1560 | J28: 1560 | K28: 1560 | L28: 1560 | M28: 1560 | N28: 1560 | O28: 1560 | P28: 1560 | Q28: 1560 | R28: 1641 | S28: 1641 | T28: =IFERROR(__xludf.DUMMYFUNCTION("IFERROR(if(W28=true, SUM(FILTER('Resumo - TIMESHEETS'!$H:$H,'Resumo - TIMESHEETS'!M:M = TRUE,'Resumo - TIMESHEETS'!N:N = TRUE,'Resumo - TIMESHEETS'!E:E = B28))/24,0),0)"),23.579583333333332) -> 23.579583 | U28: =T28/$U$11 -> 0.25723182 | V28: =IF(U28<80%,"Parcial","Exclusivo") -> Parcial | W28: TRUE
B29: Lucca Sardá Tonim Matos | C29: 123.342.589-70 | E29: Estagiário | F29: Técnico | H29: 1560 | I29: 1560 | J29: 1560 | K29: 1560 | L29: 1560 | M29: 1560 | N29: 1560 | O29: 0 | P29: 0 | Q29: 0 | R29: 0 | S29: 0 | T29: =IFERROR(__xludf.DUMMYFUNCTION("IFERROR(if(W29=true, SUM(FILTER('Resumo - TIMESHEETS'!$H:$H,'Resumo - TIMESHEETS'!M:M = TRUE,'Resumo - TIMESHEETS'!N:N = TRUE,'Resumo - TIMESHEETS'!E:E = B29))/24,0),0)"),6.430416666666666) -> 6.4304167 | U29: =T29/$U$11 -> 0.07015 | V29: =IF(U29<80%,"Parcial","Exclusivo") -> Parcial | W29: TRUE
B30: Marcos Tribess | C30: 057.903.319-80 | E30: Analista de Automação | F30: Superior Completo | H30: 6518.08 | I30: 6518.08 | J30: 6518.08 | K30: 6518.08 | L30: 6518.08 | M30: 6518.08 | N30: 7120.49 | O30: 7120.49 | P30: 7120.49 | Q30: 7120.49 | R30: 7486.49 | S30: 7486.49 | T30: =IFERROR(__xludf.DUMMYFUNCTION("IFERROR(if(W30=true, SUM(FILTER('Resumo - TIMESHEETS'!$H:$H,'Resumo - TIMESHEETS'!M:M = TRUE,'Resumo - TIMESHEETS'!N:N = TRUE,'Resumo - TIMESHEETS'!E:E = B30))/24,0),0)"),2.03125) -> 2.03125 | U30: =T30/$U$11 -> 0.022159091 | V30: =IF(U30<80%,"Parcial","Exclusivo") -> Parcial | W30: TRUE
B31: Paulo Fernando Odwazny | C31: 035.705.119-01 | E31: Supervisor Desenv. Software | F31: Superior Completo | H31: 13351.79 | I31: 13351.79 | J31: 13351.79 | K31: 13351.79 | L31: 13351.79 | M31: 13351.79 | N31: 13351.79 | O31: 13351.79 | P31: 13351.79 | Q31: 17357.33 | R31: 18249.5 | S31: 18249.5 | T31: =IFERROR(__xludf.DUMMYFUNCTION("IFERROR(if(W31=true, SUM(FILTER('Resumo - TIMESHEETS'!$H:$H,'Resumo - TIMESHEETS'!M:M = TRUE,'Resumo - TIMESHEETS'!N:N = TRUE,'Resumo - TIMESHEETS'!E:E = B31))/24,0),0)"),27.30333333333333) -> 27.303333 | U31: =T31/$U$11 -> 0.29785455 | V31: =IF(U31<80%,"Parcial","Exclusivo") -> Parcial | W31: TRUE
B32: Rafael Augusto Barbieri Lobato | C32: 374.320.848-23 | E32: Analista de Automação | F32: Superior Completo | H32: 0 | I32: 0 | J32: 0 | K32: 2769.45 | L32: 2769.45 | M32: 2769.45 | N32: 2769.45 | O32: 2769.45 | P32: 2769.45 | Q32: 2769.45 | R32: 2911.8 | S32: 2911.8 | T32: =IFERROR(__xludf.DUMMYFUNCTION("IFERROR(if(W32=true, SUM(FILTER('Resumo - TIMESHEETS'!$H:$H,'Resumo - TIMESHEETS'!M:M = TRUE,'Resumo - TIMESHEETS'!N:N = TRUE,'Resumo - TIMESHEETS'!E:E = B32))/24,0),0)"),27.10833333333333) -> 27.108333 | U32: =T32/$U$11 -> 0.29572727 | V32: =IF(U32<80%,"Parcial","Exclusivo") -> Parcial | W32: TRUE
B33: Ricardo Bordin | C33: 029.623.950-07 | E33: Analista de Automação | F33: Superior Completo | H33: 0 | I33: 0 | J33: 0 | K33: 5236.48 | L33: 5236.48 | M33: 5236.48 | N33: 5236.48 | O33: 5236.48 | P33: 5236.48 | Q33: 5236.48 | R33: 5505.64 | S33: 5505.64 | T33: =IFERROR(__xludf.DUMMYFUNCTION("IFERROR(if(W33=true, SUM(FILTER('Resumo - TIMESHEETS'!$H:$H,'Resumo - TIMESHEETS'!M:M = TRUE,'Resumo - TIMESHEETS'!N:N = TRUE,'Resumo - TIMESHEETS'!E:E = B33))/24,0),0)"),0.7883333333333334) -> 0.78833333 | U33: =T33/$U$11 -> 0.0086 | V33: =IF(U33<80%,"Parcial","Exclusivo") -> Parcial | W33: TRUE
B34: Theron Wolfgang Harbs | C34: PJ | E34: Consultor | K34: 50000 | L34: 25000 | M34: 25000 | N34: 25000 | O34: 25000 | P34: 25000 | Q34: 25000 | R34: 25000 | S34: 25000 | T34: =IFERROR(__xludf.DUMMYFUNCTION("IFERROR(if(W34=true, SUM(FILTER('Resumo - TIMESHEETS'!$H:$H,'Resumo - TIMESHEETS'!M:M = TRUE,'Resumo - TIMESHEETS'!N:N = TRUE,'Resumo - TIMESHEETS'!E:E = B34))/24,0),0)"),12.777499999999998) -> 12.7775 | U34: =T34/$U$11 -> 0.13939091 | V34: =IF(U34<80%,"Parcial","Exclusivo") -> Parcial | W34: TRUE
F38: Cálculo do custo/hora | G38: Patronal | H38: 0.0286 | I38: 0.01238 | J38: 0.01176 | K38: 0.03086 | L38: 0.02374 | M38: 0.02114 | N38: 0.07246 | O38: 0.0228 | P38: 0.0446 | Q38: 0.02436 | R38: 0.02 | S38: 0.03624 | T38: // Informações recebidas por e-mail do RH
G39: Terceiros | H39: 0.058 | I39: 0.058 | J39: 0.058 | K39: 0.058 | L39: 0.058 | M39: 0.058 | N39: 0.058 | O39: 0.058 | P39: 0.058 | Q39: 0.058 | R39: 0.058 | S39: 0.058
G40: RAT | H40: 0.02832 | I40: 0.02832 | J40: 0.02832 | K40: 0.02832 | L40: 0.02832 | M40: 0.02832 | N40: 0.02832 | O40: 0.02832 | P40: 0.02832 | Q40: 0.02832 | R40: 0.02832 | S40: 0.02832
G41: INSS | H41: =SUM(H38:H40) -> 0.11492 | I41: =SUM(I38:I40) -> 0.0987 | J41: =SUM(J38:J40) -> 0.09808 | K41: =SUM(K38:K40) -> 0.11718 | L41: =SUM(L38:L40) -> 0.11006 | M41: =SUM(M38:M40) -> 0.10746 | N41: =SUM(N38:N40) -> 0.15878 | O41: =SUM(O38:O40) -> 0.10912 | ... S41: =SUM(S38:S40) -> 0.12256
G42: FGTS | H42: 0.08 | I42: 0.08 | J42: 0.08 | K42: 0.08 | L42: 0.08 | M42: 0.08 | N42: 0.08 | O42: 0.08 | P42: 0.08 | Q42: 0.08 | R42: 0.08 | S42: 0.08
G43: Férias | H43: =((1+(1/3))*(1+H41+H42)/12) -> 0.13276889 | I43: =((1+(1/3))*(1+I41+I42)/12) -> 0.13096667 | J43: =((1+(1/3))*(1+J41+J42)/12) -> 0.13089778 | K43: =((1+(1/3))*(1+K41+K42)/12) -> 0.13302 | L43: =((1+(1/3))*(1+L41+L42)/12) -> 0.13222889 | M43: =((1+(1/3))*(1+M41+M42)/12) -> 0.13194 | N43: =((1+(1/3))*(1+N41+N42)/12) -> 0.13764222 | O43: =((1+(1/3))*(1+O41+O42)/12) -> 0.13212444 | ... S43: =((1+(1/3))*(1+S41+S42)/12) -> 0.13361778
G44: 13º | H44: =(1/12)*(1+H41+H42) -> 0.099576667 | I44: =(1/12)*(1+I41+I42) -> 0.098225 | J44: =(1/12)*(1+J41+J42) -> 0.098173333 | K44: =(1/12)*(1+K41+K42) -> 0.099765 | L44: =(1/12)*(1+L41+L42) -> 0.099171667 | M44: =(1/12)*(1+M41+M42) -> 0.098955 | N44: =(1/12)*(1+N41+N42) -> 0.10323167 | O44: =(1/12)*(1+O41+O42) -> 0.099093333 | ... S44: =(1/12)*(1+S41+S42) -> 0.10021333
G45: TOTAL | H45: =SUM(H41:H44) -> 0.42726556 | I45: =SUM(I41:I44) -> 0.40789167 | J45: =SUM(J41:J44) -> 0.40715111 | K45: =SUM(K41:K44) -> 0.429965 | L45: =SUM(L41:L44) -> 0.42146056 | M45: =SUM(M41:M44) -> 0.418355 | N45: =SUM(N41:N44) -> 0.47965389 | O45: =SUM(O41:O44) -> 0.42033778 | ... S45: =SUM(S41:S44) -> 0.43639111
H47: 21 | I47: 20 | J47: 23 | K47: 17 | L47: 22 | M47: 21 | N47: 21 | O47: 23 | P47: 21 | Q47: 19 | R47: 20 | S47: 22 | T47: =sum(T49:T68) -> 1334869.8 | U47: =sum(U49:U68) -> 1334869.8 | V47: =U47-T47 -> 0
B48: Nome Completo | E48: Classificação | F48: Formação | H48: 44592 | I48: 44620 | J48: 44651 | K48: 44681 | L48: 44712 | M48: 44742 | N48: 44773 | O48: 44804 | P48: 44834 | Q48: 44865 | R48: 44895 | S48: 44926 | T48: PD&I R$ | U48: Aprovado R$ | V48: Pesquisador
...

Sheet IRIS
B2: Netzsch Moagem
B3: Pesquisa, Desenvolvimento & Inovação
B4: Formulário de PD&I - Ano 2023 | J4: Incentivado pela Lei do Bem | M4: TRUE
B5: - preencher somente os campos sombreados (cinza) e - adicionar cronograma no formato de imagem ao fim do formulário - preencher um deste para cada projeto de PD&I | J5: Objetiva tornar-se um Ativo | M5: FALSE
J6: Objetiva gerar patente/registro | M6: FALSE
B8: Dossiê do projeto
B9: Dados gerais para identificação e validação do projeto de PD&I
B11: Nome do projeto | E11: IRIS -> IRIS V3
J12: Pesquisa básica | M12: 📑
B13: Classificação do projeto | E13: Pesquisa aplicada | J13: Pesquisa aplicada | M13: 📑
J14: Desenvolvimento experimental | M14: 📑
B15: Objetivos do projeto | E15: O projeto visa reformular o software de automação para equipamentos de moagem a úmido, introduzindo novas funcionalidades e melhorias. O objetivo é revisar e aprimorar os protocolos de comissionamento, configurar dispositivos de acesso remoto, e desenvolver o IRIS V3, um novo sistema de automação. Além disso, o projeto abrange a tradução da interface para o idioma Estoniano e Italiano, a unificação do software para a plataforma Rockwell, e a implementação de funcionalidades avançadas como controle de receita, gerenciamento de falhas, análise de gráficos avançada, e testes de estresse do software.
J16: Inovação tecnológica de produto | M16: 📑
B17: Tipo de inovação | E17: Inovação tecnológica de produto | J17: Inovação tecnológica de processo | M17: 📑
J18: Inovação tecnológica de serviços | M18: 📑
B19: Elemento inovador | E19: O elemento inovador deste projeto é a criação do IRIS V3, um sistema de automação avançado que traz o desenvolvimento de uma biblioteca de objetos, a refatoração de scripts para C#, e a implementação de operações por lotes com controle de receita avançado. A unificação do software para a plataforma Rockwell e a tradução da interface para diferentes idiomas representam um esforço para padronizar e globalizar o software, tornando-o mais acessível e eficiente para um público mais amplo. | J19: - Não podem ser consideradas as inovações organizacionais, comerciais e de marketing
J20: Empresa ou segmento regional | M20: 📑
B21: Nível de inovação | E21: Empresa ou segmento regional | J21: Inovador para o Brasil | M21: 📑
J22: Inovador para o Mundo | M22: 📑
B23: Risco tecnológico | E23: Os riscos tecnológicos incluem desafios na integração de novas funcionalidades com o sistema existente, garantindo a compatibilidade e a estabilidade operacional. A refatoração de scripts para C# e a unificação para a plataforma Rockwell podem apresentar desafios técnicos e riscos de compatibilidade. Além disso, o desenvolvimento de um sistema de automação avançado como o IRIS V3 exige um elevado nível de precisão e confiabilidade, implicando riscos em termos de gerenciamento de falhas e análise de gráficos. A tradução precisa para idiomas estrangeiros também é um desafio, dada a necessidade de manter a clareza técnica e a usabilidade.
B25: Metodologias | E25: A metodologia do projeto segue um processo estruturado e iterativo: Classificação de Feedbacks: Coleta e classificação de sugestões e requisitos dos clientes para entender as necessidades e expectativas. Criação e Validação de Protótipos: Desenvolvimento de protótipos com base nos feedbacks coletados e validação destes com usuários para garantir que as novas funcionalidades atendam às expectativas e requisitos. Desenvolvimento da Funcionalidade: Construção das funcionalidades conforme especificado, com foco na integração eficaz com o sistema existente e na aderência aos padrões de qualidade. Validação em Ambiente de Teste: Testes rigorosos em um ambiente controlado para garantir a estabilidade, segurança e desempenho do software antes da implantação. Liberação para Todos os Usuários: Após a validação bem-sucedida, o software atualizado é disponibilizado para todos os usuários, garantindo uma transição suave e eficaz para a nova versão.
B27: Equipe | E27: Nome Completo | F27: Cargo/Função | G27: Qualificação | H27: !
E28: Alexandre Baseggio | F28: Desenvolvedor | G28: Pós-graduação | H28: FALSE | L28: Técnico | M28: 📑
E29: Eduardo Flohr | F29: Supervisor de Automação | G29: Pós-graduação | H29: FALSE | L29: Graduação
E30: Gabriel Alves Ferraz | F30: Desenvolvedor | G30: Graduação | H30: FALSE | L30: Pós-graduação
E31: Filipe Harbs | F31: Desenvolvedor | G31: Técnico | H31: FALSE | L31: Mestrado
E32: Ivo Ersching | F32: Desenvolvedor | G32: Graduação | H32: FALSE | L32: Doutorado
E33: Lucca Sardá Tonim Matos | F33: Desenvolvedor | G33: Técnico | H33: FALSE
E34: Paulo Fernando Odwazny | F34: Supervisor de Desenvolvimento | G34: Graduação | H34: FALSE
E35: Johann Ribeiro | F35: Desenvolvedor | G35: Técnico | H35: FALSE
E36: Marcos Tribess | F36: Desenvolvedor | G36: Graduação | H36: FALSE
E37: Guilherme Jacques | F37: Desenvolvedor | G37: Graduação | H37: FALSE
E38: Ricardo Bordin | F38: Desenvolvedor | G38: Graduação | H38: FALSE
E39: Gabriel Oliveira | F39: Designer | G39: Graduação | H39: FALSE
E40: Rafael Augusto Barbieri Lobato | F40: Desenvolvedor | G40: Graduação | H40: FALSE
E41: Italo Ebel | F41: Desenvolvedor | G41: Graduação | H41: FALSE
B43: Cronograma
B44: [anexar imagem - preferencialmente Gantt]

Sheet IRIS  TIMESHEET
B2: NETZSCH
B3: Pesquisa, Desenvolvimento & Inovação
B4: Formulário de PD&I - Ano 2023
B5: - preencher somente os campos sombreados (cinza)
I6: Treinamento
I7: Pesquisa
B8: Dossiê do projeto | I8: Desenvolvimento
B9: Atividades de Pesquisa, Desenvolvimento e Inovação | I9: Gestão e outros
H10: =SUM(H12:H57) -> 980.12
B11: RowID | C11: Projeto | D11: Etapa | E11: Colaborador | F11: CPF | G11: Data | H11: Tempo (h) | I11: Classificação | J11: Descrição da atividade e observações
C12: IRIS | D12: Revisão protocolos de comissionamento | E12: Alexandre Baseggio | G12: 44927 | H12: 19.77 | I12: Desenvolvimento | J12: Desenvolvimento PLC
C13: IRIS | D13: Revisão protocolos de comissionamento | E13: Eduardo Flohr | F13: 064.303.159-67 | G13: 44927 | H13: 2.5 | I13: Gestão e outros | J13: Gestão
C14: IRIS | D14: Revisão protocolos de comissionamento | E14: Gabriel Alves Ferraz | F14: 132.105.086-07 | G14: 44927 | H14: 28 | I14: Desenvolvimento | J14: Desenvolvimento IHM
