Workbook

Sheet RESUMO
A2: Resumo dos investimentos
A3: BENEFÍCIO FISCAL DE PD&I 2024
A5: NETZSCH INDUSTRIA E COMERCIO DE EQUIPAMENTOS DE MOAGEM LTDA | E5: CNPJ 07.389.050/0001-51 | G5: 2023-026 - NETZSCH MOAGEM
A6: Rua Emilio Marquardt, 300, Ribeirão Souto - SC - SUL - POMERODE - CEP 89.107-000 | G6: =TODAY() -> 46168
A8: Natureza | B8: 1º Trimestre | C8: 2º Trimestre | D8: 3º Trimestre | E8: 4º Trimestre | G8: TOTAL
A9: Material | B9: - | C9: - | D9: - | E9: - | G9: =sum(B9:E9) -> 0
A10: Terceiros | B10: 306712.34 | C10: 337695.39 | D10: 230052.05 | E10: 247145.2 | G10: =sum(B10:E10) -> 1121605
A11: RH (Parcial inovação) | B11: 340510.15 | C11: 322717.47 | D11: 318597.36 | E11: 302109.18 | G11: =sum(B11:E11) -> 1283934.2
A12: RH (Exclusivo inovação) | B12: 0 | C12: 0 | D12: 0 | E12: 0 | G12: =sum(B12:E12) -> 0
A13: Total 1 | B13: =sum(B10:B12) -> 647222.49 | C13: =sum(C10:C12) -> 660412.86 | D13: =sum(D10:D12) -> 548649.41 | E13: =sum(E10:E12) -> 549254.38 | G13: =sum(G9:G12) -> 2405539.1
A14: Percentual Exclusão | B14: 0.6 | C14: 0.6 | D14: 0.6 | E14: 0.6 | G14: 0.6
A15: Exclusão da Base de cálculo do IRPJ e CSLL | B15: =B13*B14 -> 388333.49 | C15: =C13*C14 -> 396247.72 | D15: =D13*D14 -> 329189.65 | E15: =E13*E14 -> 329552.63 | G15: =G13*G14 -> 1443323.5
A17: Economia Estimada [34%] | B17: =B15*34% -> 132033.39 | C17: =C15*34% -> 134724.22 | D17: =D15*34% -> 111924.48 | E17: =E15*34% -> 112047.89 | G17: =G15*34% -> 490729.98
A18: Comissão McBenner | B18: =B17*0.05 -> 6601.6694 | C18: =C17*0.05 -> 6736.2112 | D18: =D17*0.05 -> 5596.224 | E18: =E17*0.05 -> 5602.3947 | G18: =G17*0.05 -> 24536.499
A20: Observações:
A21: 1. Os dispêndios devem ser registrados na contabilidade em conta específica
A22: 2. O benefício deve ser aproveitado na ECF do respectivo ano/competência
A23: 3. O formulário do MCTIC (governo) será enviado até fim de Julho/2025
A24: 4. Os projetos estão descritos em arquivo a parte a ser anexado no FORM PD&I
A25: 5. Alguns benefícios previstos na Lei do Bem não foram utilizados:
A26: - 5.1. Depreciação acelerada
A27: - 5.2. Redução de IPI na aquisição de equipamento para PD&I
A28: - 5.3. Acréscimo de até 20% na exclusão por incrementar o número de pesquisadores contratados (exclusivos) em percentual acima de 5% ou até 5% em comparação ao ano-calendário anterior
A29: --- 5.3. Até 70% de exclusão por incrementar o numero de pesquisadores contratados em percentual até 5%
A31: Equipe de PD&I
A32: Quadro de resumo | B32: Dedicação Parcial | E32: Dedicação Exclusiva
B33: Qtd | C33: Valor gasto | D33: Horas | E33: Qtd | F33: Valor gasto | G33: Horas
A34: Técnico | B34: =IFERROR(__xludf.DUMMYFUNCTION("COUNTA(IFERROR(FILTER(RH!$F$13:$F$33,RH!$F$13:$F$33 = $A34,RH!$V$13:$V$33 = ""Parcial""),))"),3.0) -> 3 | C34: =IFERROR(__xludf.DUMMYFUNCTION("SUM(IFERROR(FILTER(RH!$U$47:$U$66,RH!$F$47:$F$66 = $A34,RH!$E$47:$E$66 = ""Parcial""),0))"),37828.2767842249) -> 37828.277 | D34: =IFERROR(__xludf.DUMMYFUNCTION("SUM(IFERROR(FILTER(RH!$T$13:$T$33,RH!$F$13:$F$33 = $A34,RH!$V$13:$V$33 = ""Parcial""),0))*24"),1252.13) -> 1252.13 | E34: =IFERROR(__xludf.DUMMYFUNCTION("COUNTA(IFERROR(FILTER(RH!$F$13:$F$26,RH!$F$13:$F$26 = $A34,RH!$V$13:$V$26 = ""Exclusivo""),))"),0.0) -> 0 | F34: =IFERROR(__xludf.DUMMYFUNCTION("SUM(IFERROR(FILTER(RH!$U$47:$U$66,RH!$F$47:$F$66 = $A34,RH!$E$47:$E$66 = ""Exclusivo""),0))"),0.0) -> 0 | G34: =IFERROR(__xludf.DUMMYFUNCTION("SUM(IFERROR(FILTER(RH!$T$13:$T$33,RH!$F$13:$F$33 = $A34,RH!$V$13:$V$33 = ""Exclusivo""),0))*24"),0.0) -> 0
A35: Tecnologo | B35: =IFERROR(__xludf.DUMMYFUNCTION("COUNTA(IFERROR(FILTER(RH!$F$13:$F$30,RH!$F$13:$F$30 = $A35,RH!$V$13:$V$30 = ""Parcial""),))"),0.0) -> 0 | C35: =IFERROR(__xludf.DUMMYFUNCTION("SUM(IFERROR(FILTER(RH!$U$47:$U$66,RH!$F$47:$F$66 = $A35,RH!$E$47:$E$66 = ""Parcial""),0))"),0.0) -> 0 | D35: =IFERROR(__xludf.DUMMYFUNCTION("SUM(IFERROR(FILTER(RH!$T$13:$T$26,RH!$F$13:$F$26 = $A35,RH!$V$13:$V$26 = ""Parcial""),0))*24"),0.0) -> 0 | E35: =IFERROR(__xludf.DUMMYFUNCTION("COUNTA(IFERROR(FILTER(RH!$F$13:$F$26,RH!$F$13:$F$26 = $A35,RH!$V$13:$V$26 = ""Exclusivo""),))"),0.0) -> 0 | F35: =IFERROR(__xludf.DUMMYFUNCTION("SUM(IFERROR(FILTER(RH!$U$47:$U$66,RH!$F$47:$F$66 = $A35,RH!$E$47:$E$66 = ""Exclusivo""),0))"),0.0) -> 0 | G35: =IFERROR(__xludf.DUMMYFUNCTION("SUM(IFERROR(FILTER(RH!$T$13:$T$26,RH!$F$13:$F$26 = $A35,RH!$V$13:$V$26 = ""Exclusivo""),0))*24"),0.0) -> 0
A36: Superior Completo | B36: =IFERROR(__xludf.DUMMYFUNCTION("COUNTA(IFERROR(FILTER(RH!$F$13:$F$33,RH!$F$13:$F$33 = $A36,RH!$V$13:$V$33 = ""Parcial""),))"),10.0) -> 10 | C36: 1229924.4 | D36: 15203.96 | E36: 0 | F36: 0 | G36: 0
A37: Pós graduado | B37: =IFERROR(__xludf.DUMMYFUNCTION("COUNTA(IFERROR(FILTER(RH!$F$13:$F$33,RH!$F$13:$F$33 = $A37,RH!$V$13:$V$33 = ""Parcial""),))"),3.0) -> 3 | C37: =IFERROR(__xludf.DUMMYFUNCTION("SUM(IFERROR(FILTER(RH!$U$47:$U$66,RH!$F$47:$F$66 = $A37,RH!$E$47:$E$66 = ""Parcial""),0))"),18521.516312461263) -> 18521.516 | D37: =IFERROR(__xludf.DUMMYFUNCTION("SUM(IFERROR(FILTER(RH!$T$13:$T$33,RH!$F$13:$F$33 = $A37,RH!$V$13:$V$33 = ""Parcial""),0))*24"),362.2) -> 362.2 | E37: =IFERROR(__xludf.DUMMYFUNCTION("COUNTA(IFERROR(FILTER(RH!$F$13:$F$26,RH!$F$13:$F$26 = $A37,RH!$V$13:$V$26 = ""Exclusivo""),))"),0.0) -> 0 | F37: =IFERROR(__xludf.DUMMYFUNCTION("SUM(IFERROR(FILTER(RH!$U$47:$U$66,RH!$F$47:$F$66 = $A37,RH!$E$47:$E$66 = ""Exclusivo""),0))"),0.0) -> 0 | G37: =IFERROR(__xludf.DUMMYFUNCTION("SUM(IFERROR(FILTER(RH!$T$13:$T$33,RH!$F$13:$F$33 = $A37,RH!$V$13:$V$33 = ""Exclusivo""),0))*24"),0.0) -> 0
A38: Mestrado | B38: =IFERROR(__xludf.DUMMYFUNCTION("COUNTA(IFERROR(FILTER(RH!$F$13:$F$33,RH!$F$13:$F$33 = $A38,RH!$V$13:$V$33 = ""Parcial""),))"),1.0) -> 1 | C38: =IFERROR(__xludf.DUMMYFUNCTION("SUM(IFERROR(FILTER(RH!$U$47:$U$66,RH!$F$47:$F$66 = $A38,RH!$E$47:$E$66 = ""Parcial""),0))"),0.0) -> 0 | D38: =IFERROR(__xludf.DUMMYFUNCTION("SUM(IFERROR(FILTER(RH!$T$13:$T$33,RH!$F$13:$F$33 = $A38,RH!$V$13:$V$33 = ""Parcial""),0))*24"),0.0) -> 0 | E38: =IFERROR(__xludf.DUMMYFUNCTION("COUNTA(IFERROR(FILTER(RH!$F$13:$F$26,RH!$F$13:$F$26 = $A38,RH!$V$13:$V$26 = ""Exclusivo""),))"),0.0) -> 0 | F38: =IFERROR(__xludf.DUMMYFUNCTION("SUM(IFERROR(FILTER(RH!$U$47:$U$66,RH!$F$47:$F$66 = $A38,RH!$E$47:$E$66 = ""Exclusivo""),0))"),0.0) -> 0 | G38: =IFERROR(__xludf.DUMMYFUNCTION("SUM(IFERROR(FILTER(RH!$T$13:$T$33,RH!$F$13:$F$33 = $A38,RH!$V$13:$V$33 = ""Exclusivo""),0))*24"),0.0) -> 0
A39: Doutorado | B39: =IFERROR(__xludf.DUMMYFUNCTION("COUNTA(IFERROR(FILTER(RH!$F$13:$F$30,RH!$F$13:$F$30 = $A39,RH!$V$13:$V$30 = ""Parcial""),))"),0.0) -> 0 | C39: =IFERROR(__xludf.DUMMYFUNCTION("SUM(IFERROR(FILTER(RH!$U$47:$U$66,RH!$F$47:$F$66 = $A39,RH!$E$47:$E$66 = ""Parcial""),0))"),0.0) -> 0 | D39: =IFERROR(__xludf.DUMMYFUNCTION("SUM(IFERROR(FILTER(RH!$T$13:$T$26,RH!$F$13:$F$26 = $A39,RH!$V$13:$V$26 = ""Parcial""),0))*24"),0.0) -> 0 | E39: =IFERROR(__xludf.DUMMYFUNCTION("COUNTA(IFERROR(FILTER(RH!$F$13:$F$26,RH!$F$13:$F$26 = $A39,RH!$V$13:$V$26 = ""Exclusivo""),))"),0.0) -> 0 | F39: =IFERROR(__xludf.DUMMYFUNCTION("SUM(IFERROR(FILTER(RH!$U$47:$U$66,RH!$F$47:$F$66 = $A39,RH!$E$47:$E$66 = ""Exclusivo""),0))"),0.0) -> 0 | G39: =IFERROR(__xludf.DUMMYFUNCTION("SUM(IFERROR(FILTER(RH!$T$13:$T$26,RH!$F$13:$F$26 = $A39,RH!$V$13:$V$26 = ""Exclusivo""),0))*24"),0.0) -> 0
B40: =SUM(B34:B39) -> 17 | C40: =SUM(C34:C39) -> 1286274.2 | D40: =SUM(D34:D39) -> 16818.29 | E40: =SUM(E34:E39) -> 0 | F40: =SUM(F34:F39) -> 0 | G40: =SUM(G34:G39) -> 0
A42: Valores por projeto de PD&I
A43: Projetos | B43: TOTAL | D43: Vlr materiais | E43: Vlr terceiros | F43: Vlr Rh parcial | G43: Vlr exclusivos
A44: {='Resumo - PROJETOS'!B12:B49} -> IRIS | B44: =sum(D44:G44) -> 381031.46 | D44: - | E44: =IFERROR(__xludf.DUMMYFUNCTION("iferror(sum(filter('Resumo - TERCEIROS'!$G:$G,'Resumo - TERCEIROS'!$K:$K=TRUE,'Resumo - TERCEIROS'!$L:$L=TRUE,'Resumo - TERCEIROS'!$B:$B=$A44)),0)"),98396.55) -> 98396.55 | F44: =IFERROR(__xludf.DUMMYFUNCTION("iferror(sum(filter('Resumo - TIMESHEETS'!$L$12:$L49,'Resumo - TIMESHEETS'!$O$12:$O49=""Parcial"",'Resumo - TIMESHEETS'!$C$12:$C49=$A44)),0)"),282634.90880039515) -> 282634.91 | G44: =IFERROR(__xludf.DUMMYFUNCTION("iferror(sum(filter('Resumo - TIMESHEETS'!$L$12:$L49,'Resumo - TIMESHEETS'!$O$12:$O49=""Exclusivo"",'Resumo - TIMESHEETS'!$C$12:$C49=$A44)),0)"),0.0) -> 0
A45: NOTIFY | B45: =sum(D45:G45) -> 1989512.5 | D45: - | E45: =IFERROR(__xludf.DUMMYFUNCTION("iferror(sum(filter('Resumo - TERCEIROS'!$G:$G,'Resumo - TERCEIROS'!$K:$K=TRUE,'Resumo - TERCEIROS'!$L:$L=TRUE,'Resumo - TERCEIROS'!$B:$B=$A45)),0)"),990309.0100000002) -> 990309.01 | F45: 999203.49 | G45: 0
A46: P&D_1 | B46: =sum(D46:G46) -> 0 | D46: - | E46: =IFERROR(__xludf.DUMMYFUNCTION("iferror(sum(filter('Resumo - TERCEIROS'!$G:$G,'Resumo - TERCEIROS'!$L:$L=TRUE,'Resumo - TERCEIROS'!$B:$B=$A46)),0)"),0.0) -> 0 | F46: =IFERROR(__xludf.DUMMYFUNCTION("iferror(sum(filter('Resumo - TIMESHEETS'!$L$12:$L49,'Resumo - TIMESHEETS'!$O$12:$O49=""Parcial"",'Resumo - TIMESHEETS'!$C$12:$C49=$A46)),0)"),0.0) -> 0 | G46: =IFERROR(__xludf.DUMMYFUNCTION("iferror(sum(filter('Resumo - TIMESHEETS'!$L$12:$L49,'Resumo - TIMESHEETS'!$O$12:$O49=""Exclusivo"",'Resumo - TIMESHEETS'!$C$12:$C49=$A46)),0)"),0.0) -> 0
A47: P&D_2 | B47: =sum(D47:G47) -> 0 | D47: - | E47: =IFERROR(__xludf.DUMMYFUNCTION("iferror(sum(filter('Resumo - TERCEIROS'!$G:$G,'Resumo - TERCEIROS'!$L:$L=TRUE,'Resumo - TERCEIROS'!$B:$B=$A47)),0)"),0.0) -> 0 | F47: =IFERROR(__xludf.DUMMYFUNCTION("iferror(sum(filter('Resumo - TIMESHEETS'!$L$12:$L49,'Resumo - TIMESHEETS'!$O$12:$O49=""Parcial"",'Resumo - TIMESHEETS'!$C$12:$C49=$A47)),0)"),0.0) -> 0 | G47: =IFERROR(__xludf.DUMMYFUNCTION("iferror(sum(filter('Resumo - TIMESHEETS'!$L$12:$L49,'Resumo - TIMESHEETS'!$O$12:$O49=""Exclusivo"",'Resumo - TIMESHEETS'!$C$12:$C49=$A47)),0)"),0.0) -> 0
...

Sheet Resumo - PROJETOS
B2: NETZSCH
B3: Pesquisa, Desenvolvimento & Inovação
B4: Formulário de PD&I - Ano 2024
B5: - preencher somente os campos sombreados (cinza)
B8: Dossiê do projeto
B9: Investimentos com terceiros
B11: Projeto | C11: Incentivado pela Lei do Bem | D11: Objetiva tornar-se um Ativo | E11: Objetiva gerar patente/registro
B12: IRIS | C12: {=TRANSPOSE(IRIS!M4:M6)} -> TRUE | D12: FALSE | E12: FALSE
B13: NOTIFY | C13: {=TRANSPOSE(NOTIFY!M4:M6)} -> TRUE | D13: FALSE | E13: FALSE
B14: P&D_1 | C14: FALSE
B15: P&D_2 | C15: FALSE
B16: P&D_3 | C16: TRUE

Sheet Resumo - TIMESHEETS
B2: NETZSCH
B3: Pesquisa, Desenvolvimento & Inovação
B4: Formulário de PD&I - Ano 2024
B5: - preencher somente os campos sombreados (cinza)
I6: Treinamento
I7: Pesquisa
B8: Dossiê do projeto | I8: Desenvolvimento
B9: Atividades de Pesquisa, Desenvolvimento e Inovação | I9: Gestão e outros
B11: RowID | C11: Projeto | D11: Etapa | E11: Colaborador | F11: CPF | G11: Data | H11: Tempo (h) | I11: Classificação | J11: Descrição da atividade e observações | K11: Custo/hora | L11: Custo total | M11: Atividade incentiv. | N11: Projeto incentiv. | O11: Dedic.
B12: {={'IRIS TIMESHEET'!B12:J1778;'NOTIFY TIMESHEET'!B12:J1778;'P&D_1 TIMESHEET'!B12:J1778;'P&D_2 TIMESHEET'!B12:J1778;'P&D_3 TIMESHEET'!B12:J1778}} | C12: IRIS | D12: Processo aprimorado de moagem no modo passada | E12: Gabriel Alves Ferraz | G12: 45313 | H12: 76.9 | I12: Desenvolvimento | J12: Desenvolvimento IHM | K12: =IF(AND($M12=TRUE,$N12=TRUE),VLOOKUP($E12,RH!$B$47:$S$67,MONTH($G12)+6,FALSE)) -> 22.246026 | L12: =IFERROR(IF(AND($M12=TRUE,$N12=TRUE),VLOOKUP($E12,RH!$B$47:$S$67,MONTH($G12)+6,FALSE)*$H12,0),0) -> 1710.7194 | M12: =IF(OR(I12="Treinamento",I12="Pesquisa",I12="Desenvolvimento"),TRUE,FALSE) -> TRUE | N12: {=XLOOKUP($C$12:$C1778,'Resumo - PROJETOS'!$B:$B,'Resumo - PROJETOS'!$C:$C,,0)} -> TRUE | O12: {=XLOOKUP($E$12:$E1778,RH!$B:$B,RH!$V:$V,,0)} -> Parcial
C13: IRIS | D13: Processo aprimorado de moagem no modo passada | E13: Gabriel Oliveira | G13: 45294 | H13: 166.5 | I13: Desenvolvimento | J13: Design UX/UI | K13: =IF(AND($M13=TRUE,$N13=TRUE),VLOOKUP($E13,RH!$B$47:$S$67,MONTH($G13)+6,FALSE)) -> 75.071402 | L13: =IFERROR(IF(AND($M13=TRUE,$N13=TRUE),VLOOKUP($E13,RH!$B$47:$S$67,MONTH($G13)+6,FALSE)*$H13,0),0) -> 12499.388 | M13: =IF(OR(I13="Treinamento",I13="Pesquisa",I13="Desenvolvimento"),TRUE,FALSE) -> TRUE | N13: TRUE | O13: Parcial
C14: IRIS | D14: Processo aprimorado de moagem no modo passada | E14: Guilherme Jacques | G14: 45320 | H14: 4.5 | I14: Desenvolvimento | J14: Desenvolvimento PLC | K14: =IF(AND($M14=TRUE,$N14=TRUE),VLOOKUP($E14,RH!$B$47:$S$67,MONTH($G14)+6,FALSE)) -> 39.311025 | L14: =IFERROR(IF(AND($M14=TRUE,$N14=TRUE),VLOOKUP($E14,RH!$B$47:$S$67,MONTH($G14)+6,FALSE)*$H14,0),0) -> 176.89961 | M14: =IF(OR(I14="Treinamento",I14="Pesquisa",I14="Desenvolvimento"),TRUE,FALSE) -> TRUE | N14: TRUE | O14: Parcial
C15: IRIS | D15: Processo aprimorado de moagem no modo passada | E15: Filipe Harbs | G15: 45299 | H15: 186.75 | I15: Desenvolvimento | J15: Desenvolvimento IHM | K15: =IF(AND($M15=TRUE,$N15=TRUE),VLOOKUP($E15,RH!$B$47:$S$67,MONTH($G15)+6,FALSE)) -> 44.364385 | L15: =IFERROR(IF(AND($M15=TRUE,$N15=TRUE),VLOOKUP($E15,RH!$B$47:$S$67,MONTH($G15)+6,FALSE)*$H15,0),0) -> 8285.049 | M15: =IF(OR(I15="Treinamento",I15="Pesquisa",I15="Desenvolvimento"),TRUE,FALSE) -> TRUE | N15: TRUE | O15: Parcial
C16: IRIS | D16: Processo aprimorado de moagem no modo passada | E16: Italo Ebel | G16: 45295 | H16: 43 | I16: Desenvolvimento | J16: Documentação | K16: =IF(AND($M16=TRUE,$N16=TRUE),VLOOKUP($E16,RH!$B$47:$S$67,MONTH($G16)+6,FALSE)) -> 11.716965 | L16: =IFERROR(IF(AND($M16=TRUE,$N16=TRUE),VLOOKUP($E16,RH!$B$47:$S$67,MONTH($G16)+6,FALSE)*$H16,0),0) -> 503.8295 | M16: =IF(OR(I16="Treinamento",I16="Pesquisa",I16="Desenvolvimento"),TRUE,FALSE) -> TRUE | N16: TRUE | O16: Parcial
C17: IRIS | D17: Processo aprimorado de moagem no modo passada | E17: Ivo Ersching | G17: 45299 | H17: 140 | I17: Desenvolvimento | J17: Desenvolvimento PLC | K17: =IF(AND($M17=TRUE,$N17=TRUE),VLOOKUP($E17,RH!$B$47:$S$67,MONTH($G17)+6,FALSE)) -> 60.908512 | L17: =IFERROR(IF(AND($M17=TRUE,$N17=TRUE),VLOOKUP($E17,RH!$B$47:$S$67,MONTH($G17)+6,FALSE)*$H17,0),0) -> 8527.1916 | M17: =IF(OR(I17="Treinamento",I17="Pesquisa",I17="Desenvolvimento"),TRUE,FALSE) -> TRUE | N17: TRUE | O17: Parcial
C18: IRIS | D18: Processo aprimorado de moagem no modo passada | E18: Johann Ribeiro | G18: 45299 | H18: 43.5 | I18: Desenvolvimento | J18: Documentação | K18: =IF(AND($M18=TRUE,$N18=TRUE),VLOOKUP($E18,RH!$B$47:$S$67,MONTH($G18)+6,FALSE)) -> 12.916508 | L18: =IFERROR(IF(AND($M18=TRUE,$N18=TRUE),VLOOKUP($E18,RH!$B$47:$S$67,MONTH($G18)+6,FALSE)*$H18,0),0) -> 561.8681 | M18: =IF(OR(I18="Treinamento",I18="Pesquisa",I18="Desenvolvimento"),TRUE,FALSE) -> TRUE | N18: TRUE | O18: Parcial
C19: IRIS | D19: Processo aprimorado de moagem no modo passada | E19: Rafael Augusto Barbieri Lobato | G19: 45313 | H19: 2.8 | I19: Desenvolvimento | J19: Desenvolvimento PLC | K19: =IF(AND($M19=TRUE,$N19=TRUE),VLOOKUP($E19,RH!$B$47:$S$67,MONTH($G19)+6,FALSE)) -> 20.790651 | L19: =IFERROR(IF(AND($M19=TRUE,$N19=TRUE),VLOOKUP($E19,RH!$B$47:$S$67,MONTH($G19)+6,FALSE)*$H19,0),0) -> 58.213824 | M19: =IF(OR(I19="Treinamento",I19="Pesquisa",I19="Desenvolvimento"),TRUE,FALSE) -> TRUE | N19: TRUE | O19: Parcial
C20: IRIS | D20: Processo aprimorado de moagem no modo circulação | E20: Alexandre Baseggio | G20: 45344 | H20: 6.75 | I20: Desenvolvimento | J20: Desenvolvimento PLC | K20: =IF(AND($M20=TRUE,$N20=TRUE),VLOOKUP($E20,RH!$B$47:$S$67,MONTH($G20)+6,FALSE)) -> 54.32512 | L20: =IFERROR(IF(AND($M20=TRUE,$N20=TRUE),VLOOKUP($E20,RH!$B$47:$S$67,MONTH($G20)+6,FALSE)*$H20,0),0) -> 366.69456 | M20: =IF(OR(I20="Treinamento",I20="Pesquisa",I20="Desenvolvimento"),TRUE,FALSE) -> TRUE | N20: TRUE | O20: Parcial
C21: IRIS | D21: Processo aprimorado de moagem no modo circulação | E21: Gabriel Alves Ferraz | G21: 45323 | H21: 71.8 | I21: Desenvolvimento | J21: Desenvolvimento IHM | K21: =IF(AND($M21=TRUE,$N21=TRUE),VLOOKUP($E21,RH!$B$47:$S$67,MONTH($G21)+6,FALSE)) -> 23.253002 | L21: =IFERROR(IF(AND($M21=TRUE,$N21=TRUE),VLOOKUP($E21,RH!$B$47:$S$67,MONTH($G21)+6,FALSE)*$H21,0),0) -> 1669.5656 | M21: =IF(OR(I21="Treinamento",I21="Pesquisa",I21="Desenvolvimento"),TRUE,FALSE) -> TRUE | N21: TRUE | O21: Parcial
C22: IRIS | D22: Processo aprimorado de moagem no modo circulação | E22: Gabriel Oliveira | G22: 45323 | H22: 189.92 | I22: Desenvolvimento | J22: Design UX/UI | K22: =IF(AND($M22=TRUE,$N22=TRUE),VLOOKUP($E22,RH!$B$47:$S$67,MONTH($G22)+6,FALSE)) -> 78.469544 | L22: =IFERROR(IF(AND($M22=TRUE,$N22=TRUE),VLOOKUP($E22,RH!$B$47:$S$67,MONTH($G22)+6,FALSE)*$H22,0),0) -> 14902.936 | M22: =IF(OR(I22="Treinamento",I22="Pesquisa",I22="Desenvolvimento"),TRUE,FALSE) -> TRUE | N22: TRUE | O22: Parcial
C23: IRIS | D23: Processo aprimorado de moagem no modo circulação | E23: Guilherme Jacques | G23: 45327 | H23: 115.65 | I23: Desenvolvimento | J23: Desenvolvimento PLC | K23: =IF(AND($M23=TRUE,$N23=TRUE),VLOOKUP($E23,RH!$B$47:$S$67,MONTH($G23)+6,FALSE)) -> 41.090456 | L23: =IFERROR(IF(AND($M23=TRUE,$N23=TRUE),VLOOKUP($E23,RH!$B$47:$S$67,MONTH($G23)+6,FALSE)*$H23,0),0) -> 4752.1113 | M23: =IF(OR(I23="Treinamento",I23="Pesquisa",I23="Desenvolvimento"),TRUE,FALSE) -> TRUE | N23: TRUE | O23: Parcial
C24: IRIS | D24: Processo aprimorado de moagem no modo circulação | E24: Italo Ebel | G24: 45324 | H24: 33 | I24: Desenvolvimento | J24: Documentação | K24: =IF(AND($M24=TRUE,$N24=TRUE),VLOOKUP($E24,RH!$B$47:$S$67,MONTH($G24)+6,FALSE)) -> 12.247339 | L24: =IFERROR(IF(AND($M24=TRUE,$N24=TRUE),VLOOKUP($E24,RH!$B$47:$S$67,MONTH($G24)+6,FALSE)*$H24,0),0) -> 404.16218 | M24: =IF(OR(I24="Treinamento",I24="Pesquisa",I24="Desenvolvimento"),TRUE,FALSE) -> TRUE | N24: TRUE | O24: Parcial
... C149: IRIS | D149: IRIS V3 BeadMill Inview - Advance Training video | E149: Johann Ribeiro | G149: 45628 | H149: 30 | I149: Desenvolvimento | J149: Gravação de videos | K149: =IF(AND($M149=TRUE,$N149=TRUE),VLOOKUP($E149,RH!$B$47:$S$67,MONTH($G149)+6,FALSE)) -> 14.249843 | L149: =IFERROR(IF(AND($M149=TRUE,$N149=TRUE),VLOOKUP($E149,RH!$B$47:$S$67,MONTH($G149)+6,FALSE)*$H149,0),0) -> 427.49529 | M149: =IF(OR(I149="Treinamento",I149="Pesquisa",I149="Desenvolvimento"),TRUE,FALSE) -> TRUE | N149: TRUE | O149: Parcial
C150: Notify | D150: Relatório de lotes | E150: Gabriel Oliveira | F150: 085.943.039-12 | G150: 45292 | H150: 20 | I150: Desenvolvimento | J150: Desenvolvimento dos designs (UI/UX) | K150: =IF(AND($M150=TRUE,$N150=TRUE),VLOOKUP($E150,RH!$B$47:$S$67,MONTH($G150)+6,FALSE)) -> 75.071402 | L150: =IFERROR(IF(AND($M150=TRUE,$N150=TRUE),VLOOKUP($E150,RH!$B$47:$S$67,MONTH($G150)+6,FALSE)*$H150,0),0) -> 1501.428 | M150: =IF(OR(I150="Treinamento",I150="Pesquisa",I150="Desenvolvimento"),TRUE,FALSE) -> TRUE | N150: TRUE | O150: Parcial
C151: Notify | D151: Configuração Gateway para o IRIS V3 | E151: Arthur Muniz | F151: 037.196.611-64 | G151: 45292 | H151: 191 | I151: Desenvolvimento | J151: Desenvolvimento Beckend | K151: =IF(AND($M151=TRUE,$N151=TRUE),VLOOKUP($E151,RH!$B$47:$S$67,MONTH($G151)+6,FALSE)) -> 89.096488 | L151: =IFERROR(IF(AND($M151=TRUE,$N151=TRUE),VLOOKUP($E151,RH!$B$47:$S$67,MONTH($G151)+6,FALSE)*$H151,0),0) -> 17017.429 | M151: =IF(OR(I151="Treinamento",I151="Pesquisa",I151="Desenvolvimento"),TRUE,FALSE) -> TRUE | N151: TRUE | O151: Exclusivo
C152: Notify | D152: Exportar dados para o Excel | E152: Italo Ebel | F152: 534.546.398-08 | G152: 45292 | H152: 4 | I152: Desenvolvimento | J152: Testes | K152: =IF(AND($M152=TRUE,$N152=TRUE),VLOOKUP($E152,RH!$B$47:$S$67,MONTH($G152)+6,FALSE)) -> 11.716965 | L152: =IFERROR(IF(AND($M152=TRUE,$N152=TRUE),VLOOKUP($E152,RH!$B$47:$S$67,MONTH($G152)+6,FALSE)*$H152,0),0) -> 46.86786 | M152: =IF(OR(I152="Treinamento",I152="Pesquisa",I152="Desenvolvimento"),TRUE,FALSE) -> TRUE | N152: TRUE | O152: Parcial
C153: Notify | D153: Adequação do Gateway para o IRIS V3 | E153: Bruno katzjarowksi | F153: 080.850.859-84 | G153: 45292 | H153: 198 | I153: Desenvolvimento | J153: Desenvolvimento Beckend | K153: =IF(AND($M153=TRUE,$N153=TRUE),VLOOKUP($E153,RH!$B$47:$S$67,MONTH($G153)+6,FALSE)) -> 107.35211 | L153: =IFERROR(IF(AND($M153=TRUE,$N153=TRUE),VLOOKUP($E153,RH!$B$47:$S$67,MONTH($G153)+6,FALSE)*$H153,0),0) -> 21255.717 | M153: =IF(OR(I153="Treinamento",I153="Pesquisa",I153="Desenvolvimento"),TRUE,FALSE) -> TRUE | N153: TRUE | O153: Exclusivo
C154: Notify | D154: Templates de gráficos | E154: Cleiton Capristano | F154: 068.504.079-88 | G154: 45292 | H154: 122 | I154: Desenvolvimento | J154: Desenvolvimento Fronend | K154: =IF(AND($M154=TRUE,$N154=TRUE),VLOOKUP($E154,RH!$B$47:$S$67,MONTH($G154)+6,FALSE)) -> 94.807812 | L154: =IFERROR(IF(AND($M154=TRUE,$N154=TRUE),VLOOKUP($E154,RH!$B$47:$S$67,MONTH($G154)+6,FALSE)*$H154,0),0) -> 11566.553 | M154: =IF(OR(I154="Treinamento",I154="Pesquisa",I154="Desenvolvimento"),TRUE,FALSE) -> TRUE | N154: TRUE | O154: Exclusivo
C155: Notify | D155: Configuração Gateway para o IRIS V3 | E155: Gabriel Possamai | F155: 085.815.809-47 | G155: 45292 | H155: 120 | I155: Pesquisa | J155: Especificação da funcionalidade | K155: =IF(AND($M155=TRUE,$N155=TRUE),VLOOKUP($E155,RH!$B$47:$S$67,MONTH($G155)+6,FALSE)) -> 114.23363 | L155: =IFERROR(IF(AND($M155=TRUE,$N155=TRUE),VLOOKUP($E155,RH!$B$47:$S$67,MONTH($G155)+6,FALSE)*$H155,0),0) -> 13708.035 | M155: =IF(OR(I155="Treinamento",I155="Pesquisa",I155="Desenvolvimento"),TRUE,FALSE) -> TRUE | N155: TRUE | O155: Exclusivo
C156: Notify | D156: Configuração Gateway para o IRIS V3 | E156: Paulo Odwazny | F156: 035.705.119-01 | G156: 45292 | H156: 5 | I156: Pesquisa | J156: Especificação da funcionalidade | K156: =IF(AND($M156=TRUE,$N156=TRUE),VLOOKUP($E156,RH!$B$47:$S$67,MONTH($G156)+6,FALSE)) -> 130.30393 | L156: =IFERROR(IF(AND($M156=TRUE,$N156=TRUE),VLOOKUP($E156,RH!$B$47:$S$67,MONTH($G156)+6,FALSE)*$H156,0),0) -> 651.51967 | M156: =IF(OR(I156="Treinamento",I156="Pesquisa",I156="Desenvolvimento"),TRUE,FALSE) -> TRUE | N156: TRUE | O156: Parcial
C157: Notify | D157: Templates de gráficos | E157: Cristiano Schroeder | F157: 080.335.889-00 | G157: 45292 | H157: 168 | I157: Desenvolvimento | J157: Testes | K157: =IF(AND($M157=TRUE,$N157=TRUE),VLOOKUP($E157,RH!$B$47:$S$67,MONTH($G157)+6,FALSE)) -> 55.69307 | L157: =IFERROR(IF(AND($M157=TRUE,$N157=TRUE),VLOOKUP($E157,RH!$B$47:$S$67,MONTH($G157)+6,FALSE)*$H157,0),0) -> 9356.4357 | M157: =IF(OR(I157="Treinamento",I157="Pesquisa",I157="Desenvolvimento"),TRUE,FALSE) -> TRUE | N157: TRUE | O157: Parcial
C158: Notify | D158: Relatório de lotes | E158: Gabriel Oliveira | F158: 085.943.039-12 | G158: 45323 | H158: 17 | I158: Desenvolvimento | J158: Desenvolvimento dos designs (UI/UX) | K158: =IF(AND($M158=TRUE,$N158=TRUE),VLOOKUP($E158,RH!$B$47:$S$67,MONTH($G158)+6,FALSE)) -> 78.469544 | L158: =IFERROR(IF(AND($M158=TRUE,$N158=TRUE),VLOOKUP($E158,RH!$B$47:$S$67,MONTH($G158)+6,FALSE)*$H158,0),0) -> 1333.9822 | M158: =IF(OR(I158="Treinamento",I158="Pesquisa",I158="Desenvolvimento"),TRUE,FALSE) -> TRUE | N158: TRUE | O158: Parcial
C159: Notify | D159: Configuração Gateway para o IRIS V3 | E159: Arthur Muniz | F159: 037.196.611-64 | G159: 45323 | H159: 89 | I159: Desenvolvimento | J159: Desenvolvimento Beckend | K159: =IF(AND($M159=TRUE,$N159=TRUE),VLOOKUP($E159,RH!$B$47:$S$67,MONTH($G159)+6,FALSE)) -> 93.129481 | L159: =IFERROR(IF(AND($M159=TRUE,$N159=TRUE),VLOOKUP($E159,RH!$B$47:$S$67,MONTH($G159)+6,FALSE)*$H159,0),0) -> 8288.5238 | M159: =IF(OR(I159="Treinamento",I159="Pesquisa",I159="Desenvolvimento"),TRUE,FALSE) -> TRUE | N159: TRUE | O159: Exclusivo
C160: Notify | D160: Templates de gráficos | E160: Italo Ebel | F160: 534.546.398-08 | G160: 45323 | H160: 36 | I160: Desenvolvimento | J160: Testes | K160: =IF(AND($M160=TRUE,$N160=TRUE),VLOOKUP($E160,RH!$B$47:$S$67,MONTH($G160)+6,FALSE)) -> 12.247339 | L160: =IFERROR(IF(AND($M160=TRUE,$N160=TRUE),VLOOKUP($E160,RH!$B$47:$S$67,MONTH($G160)+6,FALSE)*$H160,0),0) -> 440.9042 | M160: =IF(OR(I160="Treinamento",I160="Pesquisa",I160="Desenvolvimento"),TRUE,FALSE) -> TRUE | N160: TRUE | O160: Parcial
C161: Notify | D161: Adequação do Gateway para o IRIS V3 | E161: Bruno katzjarowksi | F161: 080.850.859-84 | G161: 45323 | H161: 193 | I161: Desenvolvimento | J161: Desenvolvimento Beckend | K161: =IF(AND($M161=TRUE,$N161=TRUE),VLOOKUP($E161,RH!$B$47:$S$67,MONTH($G161)+6,FALSE)) -> 112.21145 | L161: =IFERROR(IF(AND($M161=TRUE,$N161=TRUE),VLOOKUP($E161,RH!$B$47:$S$67,MONTH($G161)+6,FALSE)*$H161,0),0) -> 21656.809 | M161: =IF(OR(I161="Treinamento",I161="Pesquisa",I161="Desenvolvimento"),TRUE,FALSE) -> TRUE | N161: TRUE | O161: Exclusivo
... C241: Notify | D241: Adequação do Gateway para o IRIS V3 | E241: Italo Ebel | F241: 534.546.398-08 | G241: 45627 | H241: 154 | I241: Desenvolvimento | J241: Testes | K241: =IF(AND($M241=TRUE,$N241=TRUE),VLOOKUP($E241,RH!$B$47:$S$67,MONTH($G241)+6,FALSE)) -> 14.249843 | L241: =IFERROR(IF(AND($M241=TRUE,$N241=TRUE),VLOOKUP($E241,RH!$B$47:$S$67,MONTH($G241)+6,FALSE)*$H241,0),0) -> 2194.4758 | M241: =IF(OR(I241="Treinamento",I241="Pesquisa",I241="Desenvolvimento"),TRUE,FALSE) -> TRUE | N241: TRUE | O241: Parcial
K242: =IF(AND($M242=TRUE,$N242=TRUE),VLOOKUP($E242,RH!$B$47:$S$67,MONTH($G242)+6,FALSE)) -> FALSE | L242: =IFERROR(IF(AND($M242=TRUE,$N242=TRUE),VLOOKUP($E242,RH!$B$47:$S$67,MONTH($G242)+6,FALSE)*$H242,0),0) -> 0 | M242: =IF(OR(I242="Treinamento",I242="Pesquisa",I242="Desenvolvimento"),TRUE,FALSE) -> FALSE
C243: P&D_2 | D243: Outros tamanhos e geometrias de dentes das ferramentas, outros materiais | E243: Jivago Rusch | G243: 45314 | H243: 16 | I243: Desenvolvimento | J243: Teste com ferramentas de 5mm com amendoim | K243: =IF(AND($M243=TRUE,$N243=TRUE),VLOOKUP($E243,RH!$B$47:$S$67,MONTH($G243)+6,FALSE)) -> FALSE | L243: =IFERROR(IF(AND($M243=TRUE,$N243=TRUE),VLOOKUP($E243,RH!$B$47:$S$67,MONTH($G243)+6,FALSE)*$H243,0),0) -> 0 | M243: =IF(OR(I243="Treinamento",I243="Pesquisa",I243="Desenvolvimento"),TRUE,FALSE) -> TRUE | N243: FALSE | O243: Parcial
C244: P&D_2 | D244: Ferramentas resistente ao desgaste | E244: Jivago Rusch | G244: 45338 | H244: 8 | I244: Desenvolvimento | J244: Modelamento de ferramenta com novo design progressivo para maior resistencia ao desgaste | K244: =IF(AND($M244=TRUE,$N244=TRUE),VLOOKUP($E244,RH!$B$47:$S$67,MONTH($G244)+6,FALSE)) -> FALSE | L244: =IFERROR(IF(AND($M244=TRUE,$N244=TRUE),VLOOKUP($E244,RH!$B$47:$S$67,MONTH($G244)+6,FALSE)*$H244,0),0) -> 0 | M244: =IF(OR(I244="Treinamento",I244="Pesquisa",I244="Desenvolvimento"),TRUE,FALSE) -> TRUE | N244: FALSE | O244: Parcial
C245: P&D_2 | D245: Melhorias do MasterCream MINI | E245: Jivago Rusch | G245: 45343 | H245: 40 | I245: Desenvolvimento | J245: Testes com novas ferramentas | K245: =IF(AND($M245=TRUE,$N245=TRUE),VLOOKUP($E245,RH!$B$47:$S$67,MONTH($G245)+6,FALSE)) -> FALSE | L245: =IFERROR(IF(AND($M245=TRUE,$N245=TRUE),VLOOKUP($E245,RH!$B$47:$S$67,MONTH($G245)+6,FALSE)*$H245,0),0) -> 0 | M245: =IF(OR(I245="Treinamento",I245="Pesquisa",I245="Desenvolvimento"),TRUE,FALSE) -> TRUE | N245: FALSE | O245: Parcial
...

Sheet Tabela dinâmica 1
E2: Ok
E3: 185 | F3: =E3-D3 -> -1.75
E4: Ok
E5: Ok
E6: 408 | F6: =E6-D6 -> -0.95
E7: 422 | F7: =E7-D7 -> -48.25
E8: 1027 | F8: =E8-D8 -> -1.08
E9: 373 | F9: =E9-D9 -> -30
E10: Ok
E11: 613 | F11: =E11-D11 -> -0.7
E12: 381 | F12: =E12-D12 -> -2.38
E14: Ok
E15: Ok
E16: Ok
E17: 1176 | F17: =E17-D17 -> -600
E18: 100 | F18: =E18-D18 -> -2
E19: Ok
E20: Ok
E21: 236 | F21: =E21-D21 -> -43
E22: 17 | F22: =E22-D22 -> -4
E24: 8 | F24: =E24-D24 -> -16
E25: 8 | F25: =E25-D25 -> -72

Sheet RH
B2: NETZSCH
B3: Pesquisa ,Desenvolvimento & Inovação
B4: Formulário de PD&I - Ano 2024
B5: -preencher somente os campos sombreados (cinza)
B8: Dossiê do projeto
B9: Cálculo de custo - Pessoal
B11: Salário bruto | T11: =(U11/12)*24 -> 185.53333 | U11: =(SUM(H45:S45)*8.8)/24 -> 92.766667
B12: Nome Completo | C12: CPF | D12: notas | E12: Cargo/função | F12: Formação | G12: Attachments | H12: Salário 01 | I12: Salário 02 | J12: Salário 03 | K12: Salário 04 | L12: Salário 05 | M12: Salário 06 | N12: Salário 07 | O12: Salário 08 | P12: Salário 09 | Q12: Salário 10 | R12: Salário 11 | S12: Salário 12 | T12: PD&I time | U12: PD&I (%) | V12: Classificação | W12: Pesquisador
B13: Alberto Reuters | C13: 041.176.229-00 | E13: Gerente de Desenvolvimento e Automação | F13: Mestrado | H13: 26213.95 | I13: 26213.95 | J13: 26213.95 | K13: 26213.95 | L13: 26213.95 | M13: 26213.95 | N13: 26213.95 | O13: 26213.95 | P13: 26213.95 | Q13: 26213.95 | R13: 27629.51 | S13: 27629.51 | T13: =IFERROR(__xludf.DUMMYFUNCTION("IFERROR(IF(W13=TRUE, SUM(FILTER('Resumo - TIMESHEETS'!$H:$H,'Resumo - TIMESHEETS'!M:M = TRUE,'Resumo - TIMESHEETS'!N:N = TRUE,'Resumo - TIMESHEETS'!E:E = B13))/24,0),0)"),0.0) -> 0 | U13: =T13/$U$11 -> 0 | V13: =IF(U13<80%,"Parcial","Exclusivo") -> Parcial | W13: TRUE
B14: Alexandre Baseggio | C14: 020.066.430-10 | E14: Desenvolvedor | F14: Pós graduado | H14: 7278.93 | I14: 7278.93 | J14: 7278.93 | K14: 7278.93 | L14: 7278.93 | M14: 7278.93 | N14: 7278.93 | O14: 7278.93 | P14: 7278.93 | Q14: 7278.93 | R14: 7672 | S14: 7672 | T14: =IFERROR(__xludf.DUMMYFUNCTION("IFERROR(IF(W14=TRUE, SUM(FILTER('Resumo - TIMESHEETS'!$H:$H,'Resumo - TIMESHEETS'!M:M = TRUE,'Resumo - TIMESHEETS'!N:N = TRUE,'Resumo - TIMESHEETS'!E:E = B14))/24,0),0)"),14.091666666666667) -> 14.091667 | U14: =T14/$U$11 -> 0.15190442 | V14: =IF(U14<80%,"Parcial","Exclusivo") -> Parcial | W14: TRUE
B15: Arthur Muniz | C15: 037.196.611-64 | E15: Desenvolvedor | F15: Superior Completo | H15: 12478.26 | I15: 12478.26 | J15: 12478.26 | K15: 12478.26 | L15: 12478.26 | M15: 12478.26 | N15: 13278.14 | O15: 13278.14 | P15: 13278.14 | Q15: 13278.14 | R15: 13995.16 | S15: 13995.16 | T15: =IFERROR(__xludf.DUMMYFUNCTION("IFERROR(IF(W15=TRUE, SUM(FILTER('Resumo - TIMESHEETS'!$H:$H,'Resumo - TIMESHEETS'!M:M = TRUE,'Resumo - TIMESHEETS'!N:N = TRUE,'Resumo - TIMESHEETS'!E:E = B15))/24,0),0)"),94.375) -> 94.375 | U15: =T15/$U$11 -> 1.0173374 | V15: =IF(U15<80%,"Parcial","Exclusivo") -> Exclusivo | W15: TRUE
B16: Bruno katzjarowksi | C16: 080.850.859-84 | E16: Desenvolvedor | F16: Superior Completo | H16: 15035.02 | I16: 15035.02 | J16: 15035.02 | K16: 15035.02 | L16: 15035.02 | M16: 15035.02 | N16: 15035.02 | O16: 15035.02 | P16: 15035.02 | Q16: 15035.02 | R16: 15846.92 | S16: 15846.92 | T16: =IFERROR(__xludf.DUMMYFUNCTION("IFERROR(IF(W16=TRUE, SUM(FILTER('Resumo - TIMESHEETS'!$H:$H,'Resumo - TIMESHEETS'!M:M = TRUE,'Resumo - TIMESHEETS'!N:N = TRUE,'Resumo - TIMESHEETS'!E:E = B16))/24,0),0)"),83.75) -> 83.75 | U16: =T16/$U$11 -> 0.90280273 | V16: =IF(U16<80%,"Parcial","Exclusivo") -> Exclusivo | W16: TRUE
B17: Cleiton Capristano | C17: 068.504.079-88 | E17: Desenvolvedor | F17: Superior Completo | H17: 13278.15 | I17: 14129.3 | J17: 14129.3 | K17: 14129.3 | L17: 14129.3 | M17: 14129.3 | N17: 14129.3 | O17: 14129.3 | P17: 14129.3 | Q17: 14129.3 | R17: 14892.29 | S17: 14892.29 | T17: =IFERROR(__xludf.DUMMYFUNCTION("IFERROR(IF(W17=TRUE, SUM(FILTER('Resumo - TIMESHEETS'!$H:$H,'Resumo - TIMESHEETS'!M:M = TRUE,'Resumo - TIMESHEETS'!N:N = TRUE,'Resumo - TIMESHEETS'!E:E = B17))/24,0),0)"),79.66666666666667) -> 79.666667 | U17: =T17/$U$11 -> 0.85878548 | V17: =IF(U17<80%,"Parcial","Exclusivo") -> Exclusivo | W17: TRUE
B18: Cristiano Schroeder | C18: 080.335.889-00 | E18: Desenvolvedor | F18: Superior Completo | H18: 7800 | I18: 7800 | J18: 7800 | K18: 7800 | L18: 7800 | M18: 7800 | N18: 7800 | O18: 7800 | P18: 7800 | Q18: 7800 | R18: 8221.2 | S18: 8221.2 | T18: =IFERROR(__xludf.DUMMYFUNCTION("IFERROR(IF(W18=TRUE, SUM(FILTER('Resumo - TIMESHEETS'!$H:$H,'Resumo - TIMESHEETS'!M:M = TRUE,'Resumo - TIMESHEETS'!N:N = TRUE,'Resumo - TIMESHEETS'!E:E = B18))/24,0),0)"),74.0) -> 74 | U18: =T18/$U$11 -> 0.79770032 | V18: =IF(U18<80%,"Parcial","Exclusivo") -> Parcial | W18: TRUE
B19: Eduardo Flohr | C19: 064.303.159-67 | E19: Supervisor de Automação | F19: Pós graduado | H19: 18939.88 | I19: 18939.88 | J19: 18939.88 | K19: 18939.88 | L19: 18939.88 | M19: 18939.88 | N19: 18939.88 | O19: 18939.88 | P19: 18939.88 | Q19: 18939.88 | R19: 19962.64 | S19: 19962.64 | T19: =IFERROR(__xludf.DUMMYFUNCTION("IFERROR(IF(W19=TRUE, SUM(FILTER('Resumo - TIMESHEETS'!$H:$H,'Resumo - TIMESHEETS'!M:M = TRUE,'Resumo - TIMESHEETS'!N:N = TRUE,'Resumo - TIMESHEETS'!E:E = B19))/24,0),0)"),0.0) -> 0 | U19: =T19/$U$11 -> 0 | V19: =IF(U19<80%,"Parcial","Exclusivo") -> Parcial | W19: TRUE
B20: Filipe Harbs | C20: 087.609.209-12 | E20: Desenvolvedor | F20: Técnico | H20: 6213.38 | T20: =IFERROR(__xludf.DUMMYFUNCTION("IFERROR(IF(W20=TRUE, SUM(FILTER('Resumo - TIMESHEETS'!$H:$H,'Resumo - TIMESHEETS'!M:M = TRUE,'Resumo - TIMESHEETS'!N:N = TRUE,'Resumo - TIMESHEETS'!E:E = B20))/24,0),0)"),7.78125) -> 7.78125 | U20: =T20/$U$11 -> 0.083879806 | V20: =IF(U20<80%,"Parcial","Exclusivo") -> Parcial | W20: TRUE
B21: Gabriel Alves Ferraz | C21: 132.105.086-07 | E21: Desenvolvedor | F21: Superior Completo | H21: 3115.63 | I21: 3115.63 | J21: 3115.63 | K21: 3115.63 | L21: 3115.63 | M21: 3115.63 | N21: 3338.07 | O21: 3338.07 | P21: 3338.07 | Q21: 3338.07 | R21: 3518.33 | S21: 3518.33 | T21: =IFERROR(__xludf.DUMMYFUNCTION("IFERROR(IF(W21=TRUE, SUM(FILTER('Resumo - TIMESHEETS'!$H:$H,'Resumo - TIMESHEETS'!M:M = TRUE,'Resumo - TIMESHEETS'!N:N = TRUE,'Resumo - TIMESHEETS'!E:E = B21))/24,0),0)"),29.767083333333332) -> 29.767083 | U21: =T21/$U$11 -> 0.32088124 | V21: =IF(U21<80%,"Parcial","Exclusivo") -> Parcial | W21: TRUE
B22: Gabriel Oliveira | C22: 085.943.039-12 | E22: Designer | F22: Superior Completo | H22: 10514 | I22: 10514 | J22: 10514 | K22: 10514 | L22: 10514 | M22: 10514 | N22: 10514 | O22: 10514 | P22: 10514 | Q22: 10514 | R22: 11081.76 | S22: 11081.76 | T22: =IFERROR(__xludf.DUMMYFUNCTION("IFERROR(IF(W22=TRUE, SUM(FILTER('Resumo - TIMESHEETS'!$H:$H,'Resumo - TIMESHEETS'!M:M = TRUE,'Resumo - TIMESHEETS'!N:N = TRUE,'Resumo - TIMESHEETS'!E:E = B22))/24,0),0)"),58.298750000000005) -> 58.29875 | U22: =T22/$U$11 -> 0.62844502 | V22: =IF(U22<80%,"Parcial","Exclusivo") -> Parcial | W22: TRUE
B23: Gabriel Possamai | C23: 085.815.809-47 | E23: Desenvolvedor | F23: Superior Completo | H23: 15998.8 | I23: 15998.8 | J23: 15998.8 | K23: 15998.8 | L23: 15998.8 | M23: 15998.8 | N23: 15998.8 | O23: 15998.8 | P23: 15998.8 | Q23: 15998.8 | R23: 16862.74 | S23: 16862.74 | T23: =IFERROR(__xludf.DUMMYFUNCTION("IFERROR(IF(W23=TRUE, SUM(FILTER('Resumo - TIMESHEETS'!$H:$H,'Resumo - TIMESHEETS'!M:M = TRUE,'Resumo - TIMESHEETS'!N:N = TRUE,'Resumo - TIMESHEETS'!E:E = B23))/24,0),0)"),78.54166666666667) -> 78.541667 | U23: =T23/$U$11 -> 0.84665828 | V23: =IF(U23<80%,"Parcial","Exclusivo") -> Exclusivo | W23: TRUE
B24: Guilherme Jacques | C24: 085.705.039-70 | E24: Desenvolvedor | F24: Superior Completo | H24: 5505.64 | I24: 5505.64 | J24: 5505.64 | K24: 5505.64 | L24: 5505.64 | M24: 5505.64 | N24: 6213.37 | O24: 6213.37 | P24: 6213.37 | Q24: 6213.37 | R24: 6548.9 | S24: 6548.9 | T24: =IFERROR(__xludf.DUMMYFUNCTION("IFERROR(IF(W24=TRUE, SUM(FILTER('Resumo - TIMESHEETS'!$H:$H,'Resumo - TIMESHEETS'!M:M = TRUE,'Resumo - TIMESHEETS'!N:N = TRUE,'Resumo - TIMESHEETS'!E:E = B24))/24,0),0)"),17.039583333333333) -> 17.039583 | U24: =T24/$U$11 -> 0.18368218 | V24: =IF(U24<80%,"Parcial","Exclusivo") -> Parcial | W24: TRUE
B25: Italo Ebel | C25: 534.546.398-08 | E25: Desenvolvedor | F25: Superior Completo | H25: 1641 | I25: 1641 | J25: 1641 | K25: 1641 | L25: 1641 | M25: 1641 | N25: 1641 | O25: 1809 | P25: 1809 | Q25: 1809 | R25: 1907 | S25: 1907 | T25: =IFERROR(__xludf.DUMMYFUNCTION("IFERROR(IF(W25=TRUE, SUM(FILTER('Resumo - TIMESHEETS'!$H:$H,'Resumo - TIMESHEETS'!M:M = TRUE,'Resumo - TIMESHEETS'!N:N = TRUE,'Resumo - TIMESHEETS'!E:E = B25))/24,0),0)"),43.510416666666664) -> 43.510417 | U25: =T25/$U$11 -> 0.46903072 | V25: =IF(U25<80%,"Parcial","Exclusivo") -> Parcial | W25: TRUE
B26: Ivo Ersching | C26: 052.208.059-67 | E26: Desenvolvedor | F26: Superior Completo | H26: 8530.44 | I26: 8530.44 | J26: 8530.44 | K26: 8530.44 | L26: 8530.44 | M26: 8530.44 | N26: 9020.43 | O26: 9020.43 | P26: 9020.43 | Q26: 9020.43 | R26: 9507.54 | S26: 9507.54 | T26: =IFERROR(__xludf.DUMMYFUNCTION("IFERROR(IF(W26=TRUE, SUM(FILTER('Resumo - TIMESHEETS'!$H:$H,'Resumo - TIMESHEETS'!M:M = TRUE,'Resumo - TIMESHEETS'!N:N = TRUE,'Resumo - TIMESHEETS'!E:E = B26))/24,0),0)"),42.836666666666666) -> 42.836667 | U26: =T26/$U$11 -> 0.46176788 | V26: =IF(U26<80%,"Parcial","Exclusivo") -> Parcial | W26: TRUE
B27: Johann Ribeiro | C27: 100.110.019-09 | E27: Desenvolvedor | F27: Técnico | H27: 1809 | I27: 1809 | J27: 1809 | K27: 1809 | L27: 1809 | M27: 1809 | N27: 1809 | O27: 1809 | P27: 1809 | Q27: 1809 | R27: 1907 | S27: 1907 | T27: =IFERROR(__xludf.DUMMYFUNCTION("IFERROR(IF(W27=TRUE, SUM(FILTER('Resumo - TIMESHEETS'!$H:$H,'Resumo - TIMESHEETS'!M:M = TRUE,'Resumo - TIMESHEETS'!N:N = TRUE,'Resumo - TIMESHEETS'!E:E = B27))/24,0),0)"),28.416666666666668) -> 28.416667 | U27: =T27/$U$11 -> 0.30632411 | V27: =IF(U27<80%,"Parcial","Exclusivo") -> Parcial | W27: TRUE
B28: Marcos Tribess | C28: 057.903.319-80 | E28: Desenvolvedor | F28: Superior Completo | H28: 7486.49 | I28: 7486.49 | J28: 7486.49 | K28: 7486.49 | L28: 7486.49 | M28: 7486.49 | N28: 7486.49 | O28: 7486.49 | P28: 7486.49 | Q28: 7486.79 | R28: 7890.76 | S28: 7890.76 | T28: =IFERROR(__xludf.DUMMYFUNCTION("IFERROR(IF(W28=TRUE, SUM(FILTER('Resumo - TIMESHEETS'!$H:$H,'Resumo - TIMESHEETS'!M:M = TRUE,'Resumo - TIMESHEETS'!N:N = TRUE,'Resumo - TIMESHEETS'!E:E = B28))/24,0),0)"),1.9333333333333333) -> 1.9333333 | U28: =T28/$U$11 -> 0.020840819 | V28: =IF(U28<80%,"Parcial","Exclusivo") -> Parcial | W28: TRUE
B29: Paulo Odwazny | C29: 035.705.119-01 | E29: Supervisor de Desenvolvimento | F29: Superior Completo | H29: 18249.5 | I29: 18249.5 | J29: 18249.5 | K29: 18249.5 | L29: 18249.5 | M29: 18249.5 | N29: 18249.5 | O29: 18249.5 | P29: 18249.5 | Q29: 18249.5 | R29: 19234.98 | S29: 19234.98 | T29: =IFERROR(__xludf.DUMMYFUNCTION("IFERROR(IF(W29=TRUE, SUM(FILTER('Resumo - TIMESHEETS'!$H:$H,'Resumo - TIMESHEETS'!M:M = TRUE,'Resumo - TIMESHEETS'!N:N = TRUE,'Resumo - TIMESHEETS'!E:E = B29))/24,0),0)"),0.875) -> 0.875 | U29: =T29/$U$11 -> 0.0094322673 | V29: =IF(U29<80%,"Parcial","Exclusivo") -> Parcial | W29: TRUE
B30: Rafael Augusto Barbieri Lobato | C30: 374.320.848-23 | E30: Desenvolvedor | F30: Superior Completo | H30: 2911.8 | I30: 2911.8 | J30: 2911.8 | K30: 2911.8 | L30: 2911.8 | M30: 2911.8 | N30: 3338.07 | O30: 3338.07 | P30: 3338.07 | Q30: 3338.07 | R30: 3518.33 | S30: 3518.33 | T30: =IFERROR(__xludf.DUMMYFUNCTION("IFERROR(IF(W30=TRUE, SUM(FILTER('Resumo - TIMESHEETS'!$H:$H,'Resumo - TIMESHEETS'!M:M = TRUE,'Resumo - TIMESHEETS'!N:N = TRUE,'Resumo - TIMESHEETS'!E:E = B30))/24,0),0)"),25.57083333333333) -> 25.570833 | U30: =T30/$U$11 -> 0.27564678 | V30: =IF(U30<80%,"Parcial","Exclusivo") -> Parcial | W30: TRUE
B31: Jivago Rusch | C31: 091.530.489-97 | E31: Projetista | F31: Superior Completo | H31: 7389.57 | I31: 7389.57 | J31: 7389.57 | K31: 7389.57 | L31: 7389.57 | M31: 7389.57 | N31: 7389.57 | O31: 7389.57 | P31: 7389.57 | Q31: 7389.57 | R31: 7788.61 | S31: 7788.61 | T31: =IFERROR(__xludf.DUMMYFUNCTION("IFERROR(IF(W31=TRUE, SUM(FILTER('Resumo - TIMESHEETS'!$H:$H,'Resumo - TIMESHEETS'!M:M = TRUE,'Resumo - TIMESHEETS'!N:N = TRUE,'Resumo - TIMESHEETS'!E:E = B31))/24,0),0)"),3.3333333333333335) -> 3.3333333 | U31: =T31/$U$11 -> 0.035932447 | V31: =IF(U31<80%,"Parcial","Exclusivo") -> Parcial | W31: TRUE
B32: William Buttenberg | C32: 091.530.489-97 | E32: Analista de Automação | F32: Técnico | Q32: 6611.67 | R32: 6968.7 | S32: 6968.7 | T32: =IFERROR(__xludf.DUMMYFUNCTION("IFERROR(IF(W32=TRUE, SUM(FILTER('Resumo - TIMESHEETS'!$H:$H,'Resumo - TIMESHEETS'!M:M = TRUE,'Resumo - TIMESHEETS'!N:N = TRUE,'Resumo - TIMESHEETS'!E:E = B32))/24,0),0)"),15.974166666666667) -> 15.974167 | U32: =T32/$U$11 -> 0.17219727 | V32: =IF(U32<80%,"Parcial","Exclusivo") -> Parcial | W32: TRUE
B33: Fernando Leal | C33: 416.012.648-01 | E33: Bolsista | F33: Pós graduado | H33: 4500 | I33: 4500 | J33: 4500 | K33: 4500 | L33: 4500 | M33: 4500 | N33: 4500 | O33: 4500 | P33: 4500 | Q33: 4500 | R33: 4500 | S33: 7000 | T33: =IFERROR(__xludf.DUMMYFUNCTION("IFERROR(IF(W33=TRUE, SUM(FILTER('Resumo - TIMESHEETS'!$H:$H,'Resumo - TIMESHEETS'!M:M = TRUE,'Resumo - TIMESHEETS'!N:N = TRUE,'Resumo - TIMESHEETS'!E:E = B33))/24,0),0)"),1.0) -> 1 | U33: =T33/$U$11 -> 0.010779734 | V33: =IF(U33<80%,"Parcial","Exclusivo") -> Parcial | W33: TRUE
F36: Cálculo do custo/hora | G36: Patronal | H36: 0.0043 | I36: 0.0017 | J36: 0.0007 | K36: 0.0083 | L36: 0.0076 | M36: 0.0043 | N36: 0.0118 | O36: 0.0125 | P36: 0.0076 | Q36: 0.0043 | R36: 0.0063 | S36: 0.0031 | T36: // Informações recebidas por e-mail do RH
G37: Terceiros | H37: 0.058 | I37: 0.058 | J37: 0.058 | K37: 0.058 | L37: 0.058 | M37: 0.058 | N37: 0.058 | O37: 0.058 | P37: 0.058 | Q37: 0.058 | R37: 0.058 | S37: 0.058
G38: RAT | H38: 0.015 | I38: 0.015 | J38: 0.015 | K38: 0.015 | L38: 0.015 | M38: 0.015 | N38: 0.015 | O38: 0.015 | P38: 0.015 | Q38: 0.015 | R38: 0.015 | S38: 0.015
G39: INSS | H39: =SUM(H36:H38) -> 0.0773 | I39: =SUM(I36:I38) -> 0.0747 | J39: =SUM(J36:J38) -> 0.0737 | K39: =SUM(K36:K38) -> 0.0813 | L39: =SUM(L36:L38) -> 0.0806 | M39: =SUM(M36:M38) -> 0.0773 | N39: =SUM(N36:N38) -> 0.0848 | O39: =SUM(O36:O38) -> 0.0855 | ... S39: =SUM(S36:S38) -> 0.0761
G40: FGTS | H40: 0.08 | I40: 0.08 | J40: 0.08 | K40: 0.08 | L40: 0.08 | M40: 0.08 | N40: 0.08 | O40: 0.08 | P40: 0.08 | Q40: 0.08 | R40: 0.08 | S40: 0.08
G41: Férias | H41: =((1+(1/3))*(1+H39+H40)/12) -> 0.12858889 | I41: =((1+(1/3))*(1+I39+I40)/12) -> 0.1283 | J41: =((1+(1/3))*(1+J39+J40)/12) -> 0.12818889 | K41: =((1+(1/3))*(1+K39+K40)/12) -> 0.12903333 | L41: =((1+(1/3))*(1+L39+L40)/12) -> 0.12895556 | M41: =((1+(1/3))*(1+M39+M40)/12) -> 0.12858889 | N41: =((1+(1/3))*(1+N39+N40)/12) -> 0.12942222 | O41: =((1+(1/3))*(1+O39+O40)/12) -> 0.1295 | ... S41: =((1+(1/3))*(1+S39+S40)/12) -> 0.12845556
G42: 13º | H42: =(1/12)*(1+H39+H40) -> 0.096441667 | I42: =(1/12)*(1+I39+I40) -> 0.096225 | J42: =(1/12)*(1+J39+J40) -> 0.096141667 | K42: =(1/12)*(1+K39+K40) -> 0.096775 | L42: =(1/12)*(1+L39+L40) -> 0.096716667 | M42: =(1/12)*(1+M39+M40) -> 0.096441667 | N42: =(1/12)*(1+N39+N40) -> 0.097066667 | O42: =(1/12)*(1+O39+O40) -> 0.097125 | ... S42: =(1/12)*(1+S39+S40) -> 0.096341667
G43: TOTAL | H43: =sum(H39:H42) -> 0.38233056 | I43: =sum(I39:I42) -> 0.379225 | J43: =sum(J39:J42) -> 0.37803056 | K43: =sum(K39:K42) -> 0.38710833 | L43: =sum(L39:L42) -> 0.38627222 | M43: =sum(M39:M42) -> 0.38233056 | N43: =sum(N39:N42) -> 0.39128889 | O43: =sum(O39:O42) -> 0.392125 | ... S43: =sum(S39:S42) -> 0.38089722
H45: =NETWORKDAYS(DATE(year(H46),month(H46),1),DATE(year(H46),month(H46)+1,0),$B$70:$B$82) -> 22 | I45: =NETWORKDAYS(DATE(year(I46),month(I46),1),DATE(year(I46),month(I46)+1,0),$B$70:$B$82) -> 21 | J45: =NETWORKDAYS(DATE(year(J46),month(J46),1),DATE(year(J46),month(J46)+1,0),$B$70:$B$82) -> 20 | K45: =NETWORKDAYS(DATE(year(K46),month(K46),1),DATE(year(K46),month(K46)+1,0),$B$70:$B$82) -> 21 | L45: =NETWORKDAYS(DATE(year(L46),month(L46),1),DATE(year(L46),month(L46)+1,0),$B$70:$B$82) -> 21 | M45: =NETWORKDAYS(DATE(year(M46),month(M46),1),DATE(year(M46),month(M46)+1,0),$B$70:$B$82) -> 20 | N45: =NETWORKDAYS(DATE(year(N46),month(N46),1),DATE(year(N46),month(N46)+1,0),$B$70:$B$82) -> 23 | O45: =NETWORKDAYS(DATE(year(O46),month(O46),1),DATE(year(O46),month(O46)+1,0),$B$70:$B$82) -> 22 | ... S45: =NETWORKDAYS(DATE(year(S46),month(S46),1),DATE(year(S46),month(S46)+1,0),$B$70:$B$82) -> 21 | T45: =sum(T47:T66) -> 1286274.2 | U45: =sum(U47:U66) -> 1286274.2 | V45: =U45-T45 -> 0
B46: Nome Completo | E46: Classificação | F46: Formação | H46: 45322 | I46: 45350 | J46: 45382 | K46: 45412 | L46: 45443 | M46: 45473 | N46: 45504 | O46: 45535 | P46: 45565 | Q46: 45596 | R46: 45626 | S46: 45657 | T46: PD&I R$ | U46: Aprovado R$ | V46: Pesquisador
B47: {=unique(B13:B33)} -> Alberto Reuters | E47: {=V13:V33} -> Parcial | F47: {=F13:F33} -> Mestrado | H47: =iferror((xlookup($B47,$B$13:$B$33,H$13:H$33)*(1+H$43))/(H$45*8.8),"") -> 187.1712 | I47: =iferror((xlookup($B47,$B$13:$B$33,I$13:I$33)*(1+I$43))/(I$45*8.8),"") -> 195.64359 | J47: =iferror((xlookup($B47,$B$13:$B$33,J$13:J$33)*(1+J$43))/(J$45*8.8),"") -> 205.24786 | K47: =iferror((xlookup($B47,$B$13:$B$33,K$13:K$33)*(1+K$43))/(K$45*8.8),"") -> 196.76184 | L47: =iferror((xlookup($B47,$B$13:$B$33,L$13:L$33)*(1+L$43))/(L$45*8.8),"") -> 196.64324 | M47: =iferror((xlookup($B47,$B$13:$B$33,M$13:M$33)*(1+M$43))/(M$45*8.8),"") -> 205.88832 | N47: =iferror((xlookup($B47,$B$13:$B$33,N$13:N$33)*(1+N$43))/(N$45*8.8),"") -> 180.19356 | O47: =iferror((xlookup($B47,$B$13:$B$33,O$13:O$33)*(1+O$43))/(O$45*8.8),"") -> 188.49739 | ... S47: =iferror((xlookup($B47,$B$13:$B$33,S$13:S$33)*(1+S$43))/(S$45*8.8),"") -> 206.45841 | T47: =SUMIF('Resumo - TIMESHEETS'!E:E,B47,'Resumo - TIMESHEETS'!L:L) -> 0 | U47: =SUMIF(V47,TRUE,T47) -> 0 | V47: TRUE
...

Sheet Resumo - TERCEIROS
B2: NETZSCH
B3: Pesquisa, Desenvolvimento & Inovação
B4: Formulário de PD&I - Ano 2024
B5: - preencher somente os campos sombreados (cinza)
B8: Dossiê do projeto
B9: Investimentos com terceiros
B11: Projeto | C11: Etapa | D11: Fornecedor | E11: CNPJ | F11: Nota fiscal | G11: Valor | H11: Data | I11: Descrição da Atividade | J11: Objetivo do gasto e eventual info de rateio | K11: Gasto incentiv. | L11: Projeto incentiv.
B12: {={'IRIS TERCEIROS'!B12:K579;'NOTIFY TERCEIROS'!B12:K579;'P&D_1 TERCEIROS'!B12:K579;'P&D_2 TERCEIROS'!B12:K579;'P&D_3 TERCEIROS'!B12:K579}} -> IRIS | C12: Processo aprimorado de moagem no modo passada | D12: KMCC Equipamentos Elétricos Ltda | E12: 07.389.050/0001-51 | F12: 2288 | G12: 10353.48 | H12: 45307 | I12: Desenvolvimento IHM | J12: Pedido 2304662. Total do pedido: R$ 10.451,00. Percentual no projeto: 99% | K12: TRUE | L12: {=XLOOKUP($B$12:$B579,'Resumo - PROJETOS'!$B:$B,'Resumo - PROJETOS'!$C:$C,,0)} -> TRUE
B13: IRIS | C13: Processo aprimorado de moagem no modo circulação | D13: KMCC Equipamentos Elétricos Ltda | E13: 07.389.050/0001-51 | F13: 2268 | G13: 18491 | H13: 45323 | I13: Desenvolvimento IHM | J13: Pedido 2302666. Total do pedido: R$ 18.491,00. Percentual no projeto: 100 % | K13: TRUE | L13: TRUE
B14: IRIS | C14: Registro avançado de dados de processo | D14: KMCC Equipamentos Elétricos Ltda | E14: 07.389.050/0001-51 | F14: 2287 | G14: 16965.07 | H14: 45352 | I14: Desenvolvimento IHM | J14: Pedido 2304623. Total do pedido: R$ 17.467,00. Percentual no projeto: 97 % | K14: TRUE | L14: TRUE
B15: IRIS | C15: Portabilidade para funcionamento com CLP da Rockwell | D15: KMCC Equipamentos Elétricos Ltda | E15: 07.389.050/0001-51 | F15: NFS 2292 | G15: 275 | H15: 45383 | I15: Desenvolvimento IHM | K15: TRUE | L15: TRUE
B16: IRIS | C16: Gerenciamento de dados remanecentes | D16: KMCC Equipamentos Elétricos Ltda | E16: 07.389.050/0001-51 | F16: NFS 2292 | G16: 14235 | H16: 45383 | I16: Desenvolvimento IHM | K16: TRUE | L16: TRUE
B17: IRIS | C17: Portabilidade para funcionamento com CLP da Rockwell | D17: KMCC Equipamentos Elétricos Ltda | E17: 07.389.050/0001-51 | F17: NFS 2310 | G17: 4508 | H17: 45413 | I17: Desenvolvimento IHM | K17: TRUE | L17: TRUE
B18: IRIS | C18: Implementação de sistema automático de gerenciamento de garantia | D18: KMCC Equipamentos Elétricos Ltda | E18: 07.389.050/0001-51 | F18: NFS 2310 | G18: 6595 | H18: 45413 | I18: Desenvolvimento IHM | K18: TRUE | L18: TRUE
B19: IRIS | C19: Portabilidade para funcionamento com CLP da Rockwell | D19: KMCC Equipamentos Elétricos Ltda | E19: 07.389.050/0001-51 | F19: NFS 2311 | G19: 10940 | H19: 45444 | I19: Desenvolvimento IHM | K19: TRUE | L19: TRUE
B20: IRIS | C20: IRIS V3 Epsilon InView - Desenvolvimento | D20: KMCC Equipamentos Elétricos Ltda | E20: 07.389.050/0001-51 | F20: NFS 21013 | G20: 1180 | H20: 45474 | I20: Desenvolvimento IHM | J20: Percentual no projeto: 7,6 % | K20: TRUE | L20: TRUE
B21: IRIS | C21: IRIS V3 for Confectionary - Prototipação | D21: KMCC Equipamentos Elétricos Ltda | E21: 07.389.050/0001-51 | F21: NFS 21013 | G21: 1607 | H21: 45474 | I21: Documentação | J21: Percentual no projeto: 10,4 % | K21: TRUE | L21: TRUE
B22: IRIS | C22: IRIS V3 Epsilon InView - Desenvolvimento | D22: KMCC Equipamentos Elétricos Ltda | E22: 07.389.050/0001-51 | F22: Requisição de pedido: 4401020 | G22: 2623 | H22: 45505 | I22: Desenvolvimento IHM | J22: Percentual no projeto: 16,8 % | K22: TRUE | L22: TRUE
B23: IRIS | C23: IRIS V3 for Confectionary - Prototipação | D23: KMCC Equipamentos Elétricos Ltda | E23: 07.389.050/0001-51 | F23: Requisição de pedido: 4401020 | G23: 2357 | H23: 45505 | I23: Documentação | J23: Percentual no projeto: 15,1 % | K23: TRUE | L23: TRUE
B24: IRIS | C24: IRIS V3 Epsilon InView - Recontrole | D24: KMCC Equipamentos Elétricos Ltda | E24: 07.389.050/0001-51 | F24: Pedido: 2316035 | G24: 2332 | H24: 45536 | I24: Desenvolvimento IHM | J24: Percentual no projeto: 13,4 % | K24: TRUE | L24: TRUE
B25: IRIS | C25: IRIS V3 for Confectionary - Prototipação | D25: KMCC Equipamentos Elétricos Ltda | E25: 07.389.050/0001-51 | F25: Pedido: 2316035 | G25: 5935 | H25: 45536 | I25: Documentação | J25: Percentual no projeto: 34 % | K25: TRUE | L25: TRUE
B26: Notify | C26: Relatório de lotes | D26: Materialize Serviços Digitais Ltda | E26: 34.269.716/0001-00 | F26: 650 | G26: 32040 | H26: 45293 | I26: Agenciamento de serviços de desenvovimento de software | J26: Total nota fiscal: R$ 32040. Rateio: 100 % | K26: TRUE | L26: TRUE
B27: Notify | C27: Templates de gráficos | D27: Mout´s Soluçõesem Tecnologia da Informação Ltda. | E27: 5.056.849/0001-08 | F27: 3169 | G27: 19849.28 | H27: 45308 | I27: Agenciamento de serviços de desenvovimento de software | J27: Total nota fiscal: R$ 39698,55. Rateio: 50 % | K27: TRUE | L27: TRUE
B28: Notify | C28: Relatório de lotes | D28: Mout´s Soluçõesem Tecnologia da Informação Ltda. | E28: 5.056.849/0001-08 | F28: 3169 | G28: 19849.28 | H28: 45308 | I28: Agenciamento de serviços de desenvovimento de software | J28: Total nota fiscal: R$ 39698,55. Rateio: 50 % | K28: TRUE | L28: TRUE
B29: Notify | C29: Templates de gráficos | D29: Amazon AWS Serviços Brasil Ltda | E29: 23.412.247/0001-10 | F29: 2709240_ECNZ6XB8 | G29: 5412.76 | H29: 45293 | I29: Custo da infraestrutura em nuvem | J29: Total nota fiscal: R$ 10825,52. Rateio: 50 % | K29: TRUE | L29: TRUE
B30: Notify | C30: Relatório de lotes | D30: Amazon AWS Serviços Brasil Ltda | E30: 23.412.247/0001-10 | F30: 2709240_ECNZ6XB8 | G30: 5412.76 | H30: 45293 | I30: Custo da infraestrutura em nuvem | J30: Total nota fiscal: R$ 10825,52. Rateio: 50 % | K30: TRUE | L30: TRUE
B31: Notify | C31: Templates de gráficos | D31: Materialize Serviços Digitais Ltda | E31: 34.269.716/0001-00 | F31: 684 | G31: 32040 | H31: 45323 | I31: Agenciamento de serviços de desenvovimento de software | J31: Total nota fiscal: R$ 32040. Rateio: 100 % | K31: TRUE | L31: TRUE
B32: Notify | C32: Templates de gráficos | D32: Mout´s Soluçõesem Tecnologia da Informação Ltda. | E32: 5.056.849/0001-08 | F32: 3188 | G32: 22059.44 | H32: 45328 | I32: Agenciamento de serviços de desenvovimento de software | J32: Total nota fiscal: R$ 44118,88. Rateio: 50 % | K32: TRUE | L32: TRUE
B33: Notify | C33: Relatório de lotes | D33: Mout´s Soluçõesem Tecnologia da Informação Ltda. | E33: 5.056.849/0001-08 | F33: 3188 | G33: 22059.44 | H33: 45328 | I33: Agenciamento de serviços de desenvovimento de software | J33: Total nota fiscal: R$ 44118,88. Rateio: 50 % | K33: TRUE | L33: TRUE
B34: Notify | C34: Templates de gráficos | D34: Amazon AWS Serviços Brasil Ltda | E34: 23.412.247/0001-10 | F34: 2845975_9ZHR17CA | G34: 5496.54 | H34: 45324 | I34: Custo da infraestrutura em nuvem | J34: Total nota fiscal: R$ 10993,07. Rateio: 50 % | K34: TRUE | L34: TRUE
B35: Notify | C35: Relatório de lotes | D35: Amazon AWS Serviços Brasil Ltda | E35: 23.412.247/0001-10 | F35: 2845975_9ZHR17CA | G35: 5496.54 | H35: 45324 | I35: Custo da infraestrutura em nuvem | J35: Total nota fiscal: R$ 10993,07. Rateio: 50 % | K35: TRUE | L35: TRUE
B36: Notify | C36: Templates de gráficos | D36: Materialize Serviços Digitais Ltda | E36: 34.269.716/0001-00 | F36: 710 | G36: 32040 | H36: 45355 | I36: Agenciamento de serviços de desenvovimento de software | J36: Total nota fiscal: R$ 32040. Rateio: 100 % | K36: TRUE | L36: TRUE
B37: Notify | C37: Templates de gráficos | D37: Mout´s Soluçõesem Tecnologia da Informação Ltda. | E37: 5.056.849/0001-08 | F37: 3225 | G37: 16057.73 | H37: 45359 | I37: Agenciamento de serviços de desenvovimento de software | J37: Total nota fiscal: R$ 48173,2. Rateio: 33,33 % | K37: TRUE | L37: TRUE
B38: Notify | C38: Configuração Gateway para o IRIS V3 | D38: Mout´s Soluçõesem Tecnologia da Informação Ltda. | E38: 5.056.849/0001-08 | F38: 3228 | G38: 16057.73 | H38: 45359 | I38: Agenciamento de serviços de desenvovimento de software | J38: Total nota fiscal: R$ 48173,2. Rateio: 33,33 % | K38: TRUE | L38: TRUE
B39: Notify | C39: Design System | D39: Mout´s Soluçõesem Tecnologia da Informação Ltda. | E39: 5.056.849/0001-08 | F39: 3228 | G39: 16057.73 | H39: 45359 | I39: Agenciamento de serviços de desenvovimento de software | J39: Total nota fiscal: R$ 48173,2. Rateio: 33,33 % | K39: TRUE | L39: TRUE
B40: Notify | C40: Templates de gráficos | D40: Amazon AWS Serviços Brasil Ltda | E40: 23.412.247/0001-10 | F40: 2901379_BRL69BTP | G40: 5486.78 | H40: 45353 | I40: Custo da infraestrutura em nuvem | J40: Total nota fiscal: R$ 10973,56. Rateio: 50 % | K40: TRUE | L40: TRUE
B41: Notify | C41: Configuração Gateway para o IRIS V3 | D41: Amazon AWS Serviços Brasil Ltda | E41: 23.412.247/0001-10 | F41: 2901379_BRL69BTP | G41: 5486.78 | H41: 45353 | I41: Custo da infraestrutura em nuvem | J41: Total nota fiscal: R$ 10973,56. Rateio: 50 % | K41: TRUE | L41: TRUE
B42: Notify | C42: Templates de gráficos | D42: Materialize Serviços Digitais Ltda | E42: 34.269.716/0001-00 | F42: 729 | G42: 32040 | H42: 45383 | I42: Agênciamento de serviços de desenvovimento de software | J42: Total nota fiscal: R$ 32040. Rateio: 100 % | K42: TRUE | L42: TRUE
B43: Notify | C43: Templates de gráficos | D43: Mout´s Soluçõesem Tecnologia da Informação Ltda. | E43: 5.056.849/0001-08 | F43: 3266 | G43: 14884.61 | H43: 45386 | I43: Agênciamento de serviços de desenvovimento de software | J43: Total nota fiscal: R$ 44653,83. Rateio: 33,33 % | K43: TRUE | L43: TRUE
B44: Notify | C44: Configuração Gateway para o IRIS V3 | D44: Mout´s Soluçõesem Tecnologia da Informação Ltda. | E44: 5.056.849/0001-08 | F44: 3266 | G44: 14884.61 | H44: 45386 | I44: Agênciamento de serviços de desenvovimento de software | J44: Total nota fiscal: R$ 44653,83. Rateio: 33,33 % | K44: TRUE | L44: TRUE
...

Sheet Tabela dinâmica 2

Sheet IRIS
B2: Netzsch Moagem
B3: Pesquisa, Desenvolvimento & Inovação
B4: Formulário de PD&I - Ano 2024 | J4: Incentivado pela Lei do Bem | M4: TRUE
B5: - preencher somente os campos sombreados (cinza) e - adicionar cronograma no formato de imagem ao fim do formulário - preencher um deste para cada projeto de PD&I | J5: Objetiva tornar-se um Ativo | M5: FALSE
J6: Objetiva gerar patente/registro | M6: FALSE
B8: Dossiê do projeto
B9: Dados gerais para identificação e validação do projeto de PD&I
B11: Nome do projeto | E11: IRIS -> IRIS V3
J12: Pesquisa básica | M12: 📑
B13: Classificação do projeto | E13: Desenvolvimento experimental | J13: Pesquisa aplicada | M13: 📑
J14: Desenvolvimento experimental | M14: 📑
B15: Objetivos do projeto | E15: Desenvolver uma série de funcionalidades inovadoras para o software de automação de equipamento de moagem a úmido, que permitam maior precisão e eficiência no processo de moagem, reduzindo o consumo de energia e aumentando a produtividade. O projeto visa implementar algoritmos avançados de controle de processos e análise preditiva para otimizar as operações de moagem em tempo real.
J16: Inovação tecnológica de produto | M16: 📑
B17: Tipo de inovação | E17: Inovação tecnológica de produto | J17: Inovação tecnológica de processo | M17: 📑
J18: Inovação tecnológica de serviços | M18: 📑
B19: Elemento inovador | E19: O software incorporará algoritmos de aprendizado de máquina para adaptar automaticamente os parâmetros de moagem com base em variações de matéria-prima e condições de operação. Essa abordagem inovadora permite uma resposta dinâmica do sistema, introduzindo um nível de automação e inteligência artificial que atualmente não é utilizado nesta indústria em nossa região. | J19: - Não podem ser consideradas as inovações organizacionais, comerciais e de marketing
J20: Empresa ou segmento regional | M20: 📑
B21: Nível de inovação | E21: Empresa ou segmento regional | J21: Inovador para o Brasil | M21: 📑
J22: Inovador para o Mundo | M22: 📑
B23: Risco tecnológico | E23: "Processo aprimorado de moagem no modo passada; Processo aprimorado de moagem no modo circulação; Registro avançado de dados de processo Portabilidade para funcionamento com CLP da Rockwell; Gerenciamento de dados remanecentes; Portabilidade para funcionamento com CLP da Rockwell; Implementação de sistema automático de gerenciamento de garantia; Portabilidade para funcionamento com CLP da Rockwell; IRIS V3 Epsilon InView - Desenvolvimento; IRIS V3 for Confectionary - Prototipação; IRIS V3 Epsilon InView - Desenvolvimento; IRIS V3 for Confectionary - Prototipação; IRIS V3 Epsilon InView - Recontrole; IRIS V3 for Confectionary - Prototipação"
B25: Metodologias | E25: Classificação e Análise de Feedback de Clientes: Utilização de técnicas de análise de dados para classificar e priorizar as sugestões e necessidades dos clientes em termos de funcionalidades de software. Desenvolvimento e Validação de Protótipos: Protótipos serão desenvolvidos usando métodos ágeis para iterar rapidamente com base no feedback do usuário. Implementação de Funcionalidades: Desenvolvimento de novas funcionalidades utilizando programação orientada a objetos e práticas de desenvolvimento de software seguro. Testes em Ambiente Controlado e Validação com Usuários: Testes rigorosos em ambientes simulados e em condições reais de operação para garantir a funcionalidade e segurança. Lançamento de Funcionalidades: Implementação gradual das novas funcionalidades para todos os usuários, com monitoramento contínuo de performance e coleta de feedback para futuras melhorias.
B27: Equipe | E27: Nome Completo | F27: Cargo/Função | G27: Qualificação | H27: !
E28: Ivo Ersching | F28: Desenvolvedor | G28: Graduação | L28: Técnico | M28: 📑
E29: Filipe Harbs | F29: Desenvolvedor | G29: Técnico | L29: Graduação
E30: Gabriel Oliveira | F30: Designer | G30: Graduação | L30: Pós-graduação
E31: Gabriel Alves Ferraz | F31: Desenvolvedor | G31: Graduação | L31: Mestrado
E32: Johann Ribeiro | F32: Desenvolvedor | G32: Técnico | L32: Doutorado
E33: Guilherme Jacques | F33: Desenvolvedor | G33: Graduação
E34: Rafael Augusto Barbieri Lobato | F34: Desenvolvedor | G34: Graduação
E35: Italo Ebel | F35: Desenvolvedor | G35: Graduação
E36: Alexandre Baseggio | F36: Desenvolvedor | G36: Pós-graduação
E37: Marcos Tribess | F37: Desenvolvedor | G37: Graduação
E38: Gabriel Oliveira
E39: Arthur Muniz
E40: Italo Ebel
E41: Bruno katzjarowksi
E42: Cleiton Capristano
B43: Cronograma | E43: Gabriel Possamai
B44: [anexar imagem - preferencialmente Gantt] | E44: Paulo Odwazny
E45: Cristiano Schroeder
...

Sheet IRIS MILESTONES
B2: NETZSCH
B3: Pesquisa, Desenvolvimento & Inovação
B4: Formulário de PD&I - Ano 2024
B5: - preencher somente os campos sombreados (cinza)
B8: Dossiê do projeto | E8: Um objetivo a ser concluído durante esta etapa. Podemos ter vários em cada etapa. | G8: Uma data estimada que atualizará após etapa concluída
B9: Etapas e Milestones
B11: Projeto | C11: Etapa | D11: Principais atividades | E11: Milestones | F11: Data inicial | G11: Data conclusão | H11: Observações do gestor
