Workbook

Sheet RESUMO
A2: Resumo dos investimentos
A3: BENEFÍCIO FISCAL DE PD&I 2020
G4: 2019-088 PRODIET
A5: PRODIET NUTRIÇÃO CLINICA LTDA | E5: CNPJ 08.183.359/0001-53 | G5: =TODAY() -> 46168
A6: Rua General Potiguara, 1428, Lotes 20 e 21, Novo Mundo - PR - SUL - CURITIBA - CEP 81.050-500 - fone: (41) 3342-2825
A8: Natureza | B8: Totalizadores | C8: ( i ) Origem dos dados
A9: Material | B9: =D48 -> 5084.71 | C9: (a1) Material consumido - planilha Investimentos
A10: Terceiros | B10: =E48 -> 372736.95 | C10: (a2) Serviços contratados - planilha Investimentos
A11: RH (Parcial inovação) | B11: =Pessoal!T32 -> 300723.97 | C11: (b) Dispêndio com funcionários de dedicação parcial - planilha Timesheet
A12: RH (Exclusivo inovação) | B12: =Pessoal!T33 -> 0 | C12: (c) Custo total dos funcionários com dedicação exclusiva - planilha Salários
A13: Total | B13: =SUM(B9:B12) -> 678545.63
A14: Percentual Exclusão | B14: 0.6 | D14: 60% | E14: +10% | F14: +20% | G14: +20%
A15: Exclusão da Base de cálculo do IRPJ e CSLL | B15: =B13*B14 -> 407127.38 | D15: Benefício padrão | E15: Incremento <5% de pesquisadores exclusivos | F15: Incremento >5% de pesquisadores exclusivos | G15: Dispendios com registro de patente
A17: Economia Estimada [34%] | B17: =B15*34% -> 138423.31
A18: Comissão McBenner | B18: =B17*0.1 -> 13842.331
A20: Observações:
A21: 1. Os dispêndios devem ser registrados na contabilidade em conta específica
A22: 2. O benefício deve ser aproveitado na ECF do respectivo ano/competência
A23: 3. O formulário do MCTIC (governo) deve ser enviado até fim de setembro/2021
A24: 4. Os projetos estão descritos em arquivo a parte a ser anexado no FORM PD&I
A25: 5. Alguns benefícios previstos na Lei do Bem não foram utilizados:
A26: --- 5.1. Depreciação acelerada
A27: --- 5.2. Redução de IPI na aquisição de equipamento para PD&I
A30: Equipe de PD&I
A31: Quadro de resumo | B31: Dedicação Parcial | E31: Dedicação Exclusiva
B32: Qtd | C32: Valor gasto | D32: Horas | E32: Qtd | F32: Valor gasto | G32: Horas
A33: Técnico | B33: =IFERROR(__xludf.DUMMYFUNCTION("COUNTA(IFERROR(FILTER(Pessoal!$E$6:$E$26,Pessoal!$E$6:$E$26 = $A33,Pessoal!$U$6:$U$26 = ""Parcial"",Pessoal!$U$37:$U$57 = TRUE),))"),0.0) -> 0 | C33: =IFERROR(__xludf.DUMMYFUNCTION("SUM(IFERROR(FILTER(Pessoal!$T$37:$T$57,Pessoal!$E$37:$E$57 = $A33,Pessoal!$D$37:$D$57 = ""Parcial""),0))"),0.0) -> 0 | D33: =IFERROR(__xludf.DUMMYFUNCTION("SUM(IFERROR(FILTER(Pessoal!$S$6:$S$26,Pessoal!$E$6:$E$26 = $A33,Pessoal!$U$6:$U$26 = ""Parcial""),0))*24"),0.0) -> 0 | E33: =IFERROR(__xludf.DUMMYFUNCTION("COUNTA(IFERROR(FILTER(Pessoal!$E$6:$E$26,Pessoal!$E$6:$E$26 = $A33,Pessoal!$U$6:$U$26 = ""Exclusivo"",Pessoal!$U$37:$U$57 = TRUE),))"),0.0) -> 0 | F33: =IFERROR(__xludf.DUMMYFUNCTION("SUM(IFERROR(FILTER(Pessoal!$T$37:$T$57,Pessoal!$E$37:$E$57 = $A33,Pessoal!$D$37:$D$57 = ""Exclusivo""),0))"),0.0) -> 0 | G33: =IFERROR(__xludf.DUMMYFUNCTION("SUM(IFERROR(FILTER(Pessoal!$S$6:$S$26,Pessoal!$E$6:$E$26 = $A33,Pessoal!$U$6:$U$26 = ""Exclusivo""),0))*24"),0.0) -> 0
A34: Tecnologo | B34: =IFERROR(__xludf.DUMMYFUNCTION("COUNTA(IFERROR(FILTER(Pessoal!$E$6:$E$26,Pessoal!$E$6:$E$26 = $A34,Pessoal!$U$6:$U$26 = ""Parcial"",Pessoal!$U$37:$U$57 = TRUE),))"),0.0) -> 0 | C34: =IFERROR(__xludf.DUMMYFUNCTION("SUM(IFERROR(FILTER(Pessoal!$T$37:$T$57,Pessoal!$E$37:$E$57 = $A34,Pessoal!$D$37:$D$57 = ""Parcial""),0))"),0.0) -> 0 | D34: =IFERROR(__xludf.DUMMYFUNCTION("SUM(IFERROR(FILTER(Pessoal!$S$6:$S$26,Pessoal!$E$6:$E$26 = $A34,Pessoal!$U$6:$U$26 = ""Parcial""),0))*24"),0.0) -> 0 | E34: =IFERROR(__xludf.DUMMYFUNCTION("COUNTA(IFERROR(FILTER(Pessoal!$E$6:$E$26,Pessoal!$E$6:$E$26 = $A34,Pessoal!$U$6:$U$26 = ""Exclusivo"",Pessoal!$U$37:$U$57 = TRUE),))"),0.0) -> 0 | F34: =IFERROR(__xludf.DUMMYFUNCTION("SUM(IFERROR(FILTER(Pessoal!$T$37:$T$57,Pessoal!$E$37:$E$57 = $A34,Pessoal!$D$37:$D$57 = ""Exclusivo""),0))"),0.0) -> 0 | G34: =IFERROR(__xludf.DUMMYFUNCTION("SUM(IFERROR(FILTER(Pessoal!$S$6:$S$26,Pessoal!$E$6:$E$26 = $A34,Pessoal!$U$6:$U$26 = ""Exclusivo""),0))*24"),0.0) -> 0
A35: Superior Completo | B35: =IFERROR(__xludf.DUMMYFUNCTION("COUNTA(IFERROR(FILTER(Pessoal!$E$6:$E$26,Pessoal!$E$6:$E$26 = $A35,Pessoal!$U$6:$U$26 = ""Parcial"",Pessoal!$U$37:$U$57 = TRUE),))"),3.0) -> 3 | C35: =IFERROR(__xludf.DUMMYFUNCTION("SUM(IFERROR(FILTER(Pessoal!$T$37:$T$57,Pessoal!$E$37:$E$57 = $A35,Pessoal!$D$37:$D$57 = ""Parcial""),0))"),82186.17763465601) -> 82186.178 | D35: =IFERROR(__xludf.DUMMYFUNCTION("SUM(IFERROR(FILTER(Pessoal!$S$6:$S$26,Pessoal!$E$6:$E$26 = $A35,Pessoal!$U$6:$U$26 = ""Parcial""),0))*24"),2533.283333333333) -> 2533.2833 | E35: =IFERROR(__xludf.DUMMYFUNCTION("COUNTA(IFERROR(FILTER(Pessoal!$E$6:$E$26,Pessoal!$E$6:$E$26 = $A35,Pessoal!$U$6:$U$26 = ""Exclusivo"",Pessoal!$U$37:$U$57 = TRUE),))"),0.0) -> 0 | F35: =IFERROR(__xludf.DUMMYFUNCTION("SUM(IFERROR(FILTER(Pessoal!$T$37:$T$57,Pessoal!$E$37:$E$57 = $A35,Pessoal!$D$37:$D$57 = ""Exclusivo""),0))"),0.0) -> 0 | G35: =IFERROR(__xludf.DUMMYFUNCTION("SUM(IFERROR(FILTER(Pessoal!$S$6:$S$26,Pessoal!$E$6:$E$26 = $A35,Pessoal!$U$6:$U$26 = ""Exclusivo""),0))*24"),0.0) -> 0
A36: Pós graduado | B36: =IFERROR(__xludf.DUMMYFUNCTION("COUNTA(IFERROR(FILTER(Pessoal!$E$6:$E$26,Pessoal!$E$6:$E$26 = $A36,Pessoal!$U$6:$U$26 = ""Parcial"",Pessoal!$U$37:$U$57 = TRUE),))"),6.0) -> 6 | C36: =IFERROR(__xludf.DUMMYFUNCTION("SUM(IFERROR(FILTER(Pessoal!$T$37:$T$57,Pessoal!$E$37:$E$57 = $A36,Pessoal!$D$37:$D$57 = ""Parcial""),0))"),66486.16777574933) -> 66486.168 | D36: =IFERROR(__xludf.DUMMYFUNCTION("SUM(IFERROR(FILTER(Pessoal!$S$6:$S$26,Pessoal!$E$6:$E$26 = $A36,Pessoal!$U$6:$U$26 = ""Parcial""),0))*24"),528.3833333333332) -> 528.38333 | E36: =IFERROR(__xludf.DUMMYFUNCTION("COUNTA(IFERROR(FILTER(Pessoal!$E$6:$E$26,Pessoal!$E$6:$E$26 = $A36,Pessoal!$U$6:$U$26 = ""Exclusivo"",Pessoal!$U$37:$U$57 = TRUE),))"),0.0) -> 0 | F36: =IFERROR(__xludf.DUMMYFUNCTION("SUM(IFERROR(FILTER(Pessoal!$T$37:$T$57,Pessoal!$E$37:$E$57 = $A36,Pessoal!$D$37:$D$57 = ""Exclusivo""),0))"),0.0) -> 0 | G36: =IFERROR(__xludf.DUMMYFUNCTION("SUM(IFERROR(FILTER(Pessoal!$S$6:$S$26,Pessoal!$E$6:$E$26 = $A36,Pessoal!$U$6:$U$26 = ""Exclusivo""),0))*24"),0.0) -> 0
A37: Mestrado | B37: =IFERROR(__xludf.DUMMYFUNCTION("COUNTA(IFERROR(FILTER(Pessoal!$E$6:$E$26,Pessoal!$E$6:$E$26 = $A37,Pessoal!$U$6:$U$26 = ""Parcial"",Pessoal!$U$37:$U$57 = TRUE),))"),2.0) -> 2 | C37: =IFERROR(__xludf.DUMMYFUNCTION("SUM(IFERROR(FILTER(Pessoal!$T$37:$T$57,Pessoal!$E$37:$E$57 = $A37,Pessoal!$D$37:$D$57 = ""Parcial""),0))"),152051.6233288585) -> 152051.62 | D37: =IFERROR(__xludf.DUMMYFUNCTION("SUM(IFERROR(FILTER(Pessoal!$S$6:$S$26,Pessoal!$E$6:$E$26 = $A37,Pessoal!$U$6:$U$26 = ""Parcial""),0))*24"),2312.1166666666672) -> 2312.1167 | E37: =IFERROR(__xludf.DUMMYFUNCTION("COUNTA(IFERROR(FILTER(Pessoal!$E$6:$E$26,Pessoal!$E$6:$E$26 = $A37,Pessoal!$U$6:$U$26 = ""Exclusivo"",Pessoal!$U$37:$U$57 = TRUE),))"),0.0) -> 0 | F37: =IFERROR(__xludf.DUMMYFUNCTION("SUM(IFERROR(FILTER(Pessoal!$T$37:$T$57,Pessoal!$E$37:$E$57 = $A37,Pessoal!$D$37:$D$57 = ""Exclusivo""),0))"),0.0) -> 0 | G37: =IFERROR(__xludf.DUMMYFUNCTION("SUM(IFERROR(FILTER(Pessoal!$S$6:$S$26,Pessoal!$E$6:$E$26 = $A37,Pessoal!$U$6:$U$26 = ""Exclusivo""),0))*24"),0.0) -> 0
A38: Doutorado | B38: =IFERROR(__xludf.DUMMYFUNCTION("COUNTA(IFERROR(FILTER(Pessoal!$E$6:$E$26,Pessoal!$E$6:$E$26 = $A38,Pessoal!$U$6:$U$26 = ""Parcial"",Pessoal!$U$37:$U$57 = TRUE),))"),0.0) -> 0 | C38: =IFERROR(__xludf.DUMMYFUNCTION("SUM(IFERROR(FILTER(Pessoal!$T$37:$T$57,Pessoal!$E$37:$E$57 = $A38,Pessoal!$D$37:$D$57 = ""Parcial""),0))"),0.0) -> 0 | D38: =IFERROR(__xludf.DUMMYFUNCTION("SUM(IFERROR(FILTER(Pessoal!$S$6:$S$26,Pessoal!$E$6:$E$26 = $A38,Pessoal!$U$6:$U$26 = ""Parcial""),0))*24"),0.0) -> 0 | E38: =IFERROR(__xludf.DUMMYFUNCTION("COUNTA(IFERROR(FILTER(Pessoal!$E$6:$E$26,Pessoal!$E$6:$E$26 = $A38,Pessoal!$U$6:$U$26 = ""Exclusivo"",Pessoal!$U$37:$U$57 = TRUE),))"),0.0) -> 0 | F38: =IFERROR(__xludf.DUMMYFUNCTION("SUM(IFERROR(FILTER(Pessoal!$T$37:$T$57,Pessoal!$E$37:$E$57 = $A38,Pessoal!$D$37:$D$57 = ""Exclusivo""),0))"),0.0) -> 0 | G38: =IFERROR(__xludf.DUMMYFUNCTION("SUM(IFERROR(FILTER(Pessoal!$S$6:$S$26,Pessoal!$E$6:$E$26 = $A38,Pessoal!$U$6:$U$26 = ""Exclusivo""),0))*24"),0.0) -> 0
B39: =SUM(B33:B38) -> 11 | C39: =SUM(C33:C38) -> 300723.97 | D39: =SUM(D33:D38) -> 5373.7833 | E39: =SUM(E33:E38) -> 0 | F39: =SUM(F33:F38) -> 0 | G39: =SUM(G33:G38) -> 0
A41: Valores por projeto de PD&I
A42: Projetos | B42: Identificação | D42: Vlr materiais | E42: Vlr terceiros | F42: Vlr Rh parcial | G42: Vlr exclusivos
A43: Novos Produtos | B43: NP | D43: =IFERROR(__xludf.DUMMYFUNCTION("SUM(FILTER(Investimentos!$O:$O,Investimentos!$N:$N = ""Material"",Investimentos!$L:$L = TRUE))"),1511.75) -> 1511.75 | E43: =IFERROR(__xludf.DUMMYFUNCTION("SUM(FILTER(Investimentos!$O:$O,Investimentos!$N:$N = ""Serviço"",Investimentos!$L:$L = TRUE))"),274463.99) -> 274463.99 | F43: =$B$11*(E43/$E$48) -> 221437.4 | G43: =$B$12*(E43/$E$48) -> 0
A44: Novas Matérias-primas | B44: Nmp | D44: =IFERROR(__xludf.DUMMYFUNCTION("SUM(FILTER(Investimentos!$P:$P,Investimentos!$N:$N = ""Material"",Investimentos!$L:$L = TRUE,Investimentos!$W:$W = TRUE))"),0.0) -> 0 | E44: =IFERROR(__xludf.DUMMYFUNCTION("SUM(FILTER(Investimentos!$P:$P,Investimentos!$N:$N = ""Serviço"",Investimentos!$L:$L = TRUE))"),0.0) -> 0 | F44: =$B$11*(E44/$E$48) -> 0 | G44: =$B$12*(E44/$E$48) -> 0
A45: Melhoria de Produto | B45: Mprod | D45: =IFERROR(__xludf.DUMMYFUNCTION("SUM(FILTER(Investimentos!$Q:$Q,Investimentos!$N:$N = ""Material"",Investimentos!$L:$L = TRUE()))"),362.9) -> 362.9 | E45: =IFERROR(__xludf.DUMMYFUNCTION("SUM(FILTER(Investimentos!$Q:$Q,Investimentos!$N:$N = ""Serviço"",Investimentos!$L:$L = TRUE))"),84741.82000000002) -> 84741.82 | F45: =$B$11*(E45/$E$48) -> 68369.654 | G45: =$B$12*(E45/$E$48) -> 0
A46: Melhoria de Processos | B46: Mproc | D46: =IFERROR(__xludf.DUMMYFUNCTION("SUM(FILTER(Investimentos!$R:$R,Investimentos!$N:$N = ""Material"",Investimentos!$L:$L = TRUE))"),3210.06) -> 3210.06 | E46: =IFERROR(__xludf.DUMMYFUNCTION("SUM(FILTER(Investimentos!$R:$R,Investimentos!$N:$N = ""Serviço"",Investimentos!$L:$L = TRUE))"),13531.140000000001) -> 13531.14 | F46: =$B$11*(E46/$E$48) -> 10916.916 | G46: =$B$12*(E46/$E$48) -> 0
A47: Segurança Alimentar | B47: SgAlim | D47: =IFERROR(__xludf.DUMMYFUNCTION("SUM(FILTER(Investimentos!$S:$S,Investimentos!$N:$N = ""Material"",Investimentos!$L:$L = TRUE,Investimentos!$W:$W = TRUE))"),0.0) -> 0 | E47: =IFERROR(__xludf.DUMMYFUNCTION("SUM(FILTER(Investimentos!$S:$S,Investimentos!$N:$N = ""Serviço"",Investimentos!$L:$L = TRUE,Investimentos!$W:$W <> FALSE))"),0.0) -> 0 | F47: =$B$11*(E47/$E$48) -> 0 | G47: =$B$12*(E47/$E$48) -> 0
...

Sheet Projetos
A2: Projetos
A3: BENEFÍCIO FISCAL DE PD&I 2019
A5: Projeto | B5: Agrupamento | C5: Categoria do projeto | D5: Elemento tecnologicamente novo ou inovador | E5: Barreira ou desafio tecnológico a superar | F5: Metodologia empregada | G5: Data início | H5: Data de término (estimada) | I5: Descrição | J5: Attachments | K5: Timesheet | L5: Lei do Bem
A6: {=SORT(UNIQUE({Timesheet!C7:C42;PrjAdd!A2:A10}),1,true)} -> Bemmax Sabor Neutro | L6: TRUE
A7: CarboCH | L7: TRUE
A8: Centro de Inovação | L8: FALSE
A9: Cicatrização | L9: TRUE
A10: Congresso ESPEN | L10: TRUE
A11: Congresso Ganepão | L11: TRUE
A12: Congressos | L12: TRUE
A13: Diamax IG | L13: TRUE
A14: Dieta artesanal | L14: TRUE
A15: EE - 2020 | L15: TRUE
A16: Energyzip 1.0 | L16: TRUE
A17: Energyzip baunilha | L17: TRUE
A18: Energyzip Chocolate | L18: TRUE
... A42: Vulcano (pote jumbo e sachês a vácuo) | L42: FALSE

Sheet PrjAdd
A1: Concorrente
A2: Energyzip baunilha
A3: Trophic Basic pó
A4: Energyzip morango
A5: Energyzip 1.0
A6: Energyzip Chocolate
A7: Energyzip Fiber
A8: HDmax 1.5
A9: ProteinPT
A10: CarboCH

Sheet Timesheet
A2: Timesheet
A3: BENEFÍCIO FISCAL DE PD&I 2019 | I3: Parcial | J3: =J5-J4 -> 312686.56
I4: Exclusivo | J4: =IFERROR(__xludf.DUMMYFUNCTION("SUMIF($B$7:$B3492,FILTER(Pessoal!$A$10:$A$26,Pessoal!$U$10:$U$26 = ""Exclusivo"",MATCH(Pessoal!$A$10:$A$26,FILTER(Pessoal!$A$37:$A$57,Pessoal!$U$37:$U$57 = TRUE),0)),$J$7:$J3492)"),0.0) -> 0
I5: TOTAL | J5: =SUM(J7:J3492) -> 312686.56
A6: Cod | B6: Pessoa | C6: Projeto | D6: Descrição | E6: Start | F6: Tempo aplicado | G6: Atividade incentivada | H6: Attachments | I6: Valor (R$) | J6: Custo | K6: checkprojetos
A7: 1 | B7: Ademir Mararangoni | C7: Immax - etapa final da Pesquisa Clínica | D7: Coordenar pesagem e produção | E7: 43846 | F7: 0.041666667 | G7: TRUE | H7: =IF(VLOOKUP(C7,Projetos!A:L,12,false)=TRUE,TRUE,FALSE) -> TRUE | I7: {=VLOOKUP(B7:B3492,Pessoal!$A$36:$R$57,MONTH(E7:E3492)+6,false)} -> 63.065873 | J7: =IFERROR(IF(AND(G7=TRUE,YEAR(E7)<2021),F7,"")*(I7*24),0) -> 63.065873 | K7: {=VLOOKUP(C7:C3492,Projetos!A6:L3492,12,false)} -> TRUE
A8: 2 | B8: Ademir Mararangoni | C8: InstanTH NEO | D8: Coordenar separação, emissão de NF e envio dos materiais para produção | E8: 43840 | F8: 0.083333333 | G8: TRUE | H8: =IF(VLOOKUP(C8,Projetos!A:L,12,false)=TRUE,TRUE,FALSE) -> TRUE | I8: 63.065873 | J8: =IFERROR(IF(AND(G8=TRUE,YEAR(E8)<2021),F8,"")*(I8*24),0) -> 126.13175 | K8: TRUE
A9: 3 | B9: Ademir Mararangoni | C9: InstanTH CLEAR (espessante) | D9: Adequação da linha de produção para o envase (Novo Twister, Envasadora, Esteira tampadora Plock off) | E9: 43850 | F9: 0.40625 | G9: TRUE | H9: =IF(VLOOKUP(C9,Projetos!A:L,12,false)=TRUE,TRUE,FALSE) -> TRUE | I9: 63.065873 | J9: =IFERROR(IF(AND(G9=TRUE,YEAR(E9)<2021),F9,"")*(I9*24),0) -> 614.89226 | K9: TRUE
A10: 4 | B10: Ademir Mararangoni | C10: Inovação industrial - misturas secas | D10: Implementação do projeto balança onde integraliza a pesagem do fracionamento com o estrutura do sistema para minimizar erros | E10: 43843 | F10: 0.40625 | G10: FALSE | H10: =IF(VLOOKUP(C10,Projetos!A:L,12,false)=TRUE,TRUE,FALSE) -> FALSE | I10: 63.065873 | J10: =IFERROR(IF(AND(G10=TRUE,YEAR(E10)<2021),F10,"")*(I10*24),0) -> 0 | K10: FALSE
A11: 5 | B11: Ademir Mararangoni | C11: Inovação industrial - misturas secas | D11: Teste de n² com enertizado da Brasilata | E11: 43845 | F11: 0.23958333 | G11: FALSE | H11: =IF(VLOOKUP(C11,Projetos!A:L,12,false)=TRUE,TRUE,FALSE) -> FALSE | I11: 63.065873 | J11: =IFERROR(IF(AND(G11=TRUE,YEAR(E11)<2021),F11,"")*(I11*24),0) -> 0 | K11: FALSE
A12: 6 | B12: Ademir Mararangoni | C12: InstanTH CLEAR (espessante) | D12: Primeira produção do Instant clear | E12: 43872 | F12: 0.083333333 | G12: TRUE | H12: =IF(VLOOKUP(C12,Projetos!A:L,12,false)=TRUE,TRUE,FALSE) -> TRUE | I12: 60.199242 | J12: =IFERROR(IF(AND(G12=TRUE,YEAR(E12)<2021),F12,"")*(I12*24),0) -> 120.39848 | K12: TRUE
A13: 7 | B13: Ademir Mararangoni | C13: InstanTH NEO | D13: Apontamento, triangulazação de NF | E13: 43888 | F13: 0.083333333 | G13: FALSE | H13: =IF(VLOOKUP(C13,Projetos!A:L,12,false)=TRUE,TRUE,FALSE) -> TRUE | I13: 60.199242 | J13: =IFERROR(IF(AND(G13=TRUE,YEAR(E13)<2021),F13,"")*(I13*24),0) -> 0 | K13: TRUE
A14: 8 | B14: Ademir Mararangoni | C14: Bemmax Sabor Neutro | D14: Teste de envase -peso alcançado 350g | E14: 43879 | F14: 0.10416667 | G14: TRUE | H14: =IF(VLOOKUP(C14,Projetos!A:L,12,false)=TRUE,TRUE,FALSE) -> TRUE | I14: 60.199242 | J14: =IFERROR(IF(AND(G14=TRUE,YEAR(E14)<2021),F14,"")*(I14*24),0) -> 150.49811 | K14: TRUE
A15: 9 | B15: Ademir Mararangoni | C15: Retort (Sistema Fechado) | D15: Separação de MP fisico e sistema para pesagem de teste | E15: 43876 | F15: 0.083333333 | G15: FALSE | H15: =IF(VLOOKUP(C15,Projetos!A:L,12,false)=TRUE,TRUE,FALSE) -> TRUE | I15: 60.199242 | J15: =IFERROR(IF(AND(G15=TRUE,YEAR(E15)<2021),F15,"")*(I15*24),0) -> 0 | K15: TRUE
A16: 10 | B16: Ademir Mararangoni | C16: HDmax 2.0 | D16: Separação de MP fisico e sistema para pesagem de teste | E16: 43874 | F16: 0.083333333 | G16: TRUE | H16: =IF(VLOOKUP(C16,Projetos!A:L,12,false)=TRUE,TRUE,FALSE) -> TRUE | I16: 60.199242 | J16: =IFERROR(IF(AND(G16=TRUE,YEAR(E16)<2021),F16,"")*(I16*24),0) -> 120.39848 | K16: TRUE
A17: 11 | B17: Ademir Mararangoni | C17: Inovação industrial - misturas secas | D17: Validação com comercial e manutenção pra aquisição de strechadeira automática | E17: 43886 | F17: 0.083333333 | G17: FALSE | H17: =IF(VLOOKUP(C17,Projetos!A:L,12,false)=TRUE,TRUE,FALSE) -> FALSE | I17: 60.199242 | J17: =IFERROR(IF(AND(G17=TRUE,YEAR(E17)<2021),F17,"")*(I17*24),0) -> 0 | K17: FALSE
A18: 12 | B18: Ademir Mararangoni | C18: Inovação industrial - misturas secas | D18: Alinhamento do projeto balança onde integraliza a pesagem do fracionamento com o estrutura do sistema para minimizar erros | E18: 43865 | F18: 0.041666667 | G18: FALSE | H18: =IF(VLOOKUP(C18,Projetos!A:L,12,false)=TRUE,TRUE,FALSE) -> FALSE | I18: 60.199242 | J18: =IFERROR(IF(AND(G18=TRUE,YEAR(E18)<2021),F18,"")*(I18*24),0) -> 0 | K18: FALSE
A19: 13 | B19: Ademir Mararangoni | C19: Inovação industrial - misturas secas | D19: Alinhamento do projeto balança onde integraliza a pesagem do fracionamento com o estrutura do sistema para minimizar erros | E19: 43875 | F19: 0.083333333 | G19: FALSE | H19: =IF(VLOOKUP(C19,Projetos!A:L,12,false)=TRUE,TRUE,FALSE) -> FALSE | I19: 60.199242 | J19: =IFERROR(IF(AND(G19=TRUE,YEAR(E19)<2021),F19,"")*(I19*24),0) -> 0 | K19: FALSE
... A856: 850 | B856: Ana Paula Celes | C856: InstanTH NEO | D856: Discussão de linhas de pesquisa clinica | E856: 43844 | F856: 0.020833333 | G856: TRUE | H856: =IF(VLOOKUP(C856,Projetos!A:L,12,false)=TRUE,TRUE,FALSE) -> TRUE | I856: 169.03747 | J856: =IFERROR(IF(AND(G856=TRUE,YEAR(E856)<2021),F856,"")*(I856*24),0) -> 84.518733 | K856: TRUE
A857: 851 | B857: Ana Paula Celes | C857: InstanTH NEO | D857: Discussão de linhas de pesquisa clinica | F857: 0 | G857: FALSE | H857: =IF(VLOOKUP(C857,Projetos!A:L,12,false)=TRUE,TRUE,FALSE) -> TRUE | I857: 169.03747 | J857: =IFERROR(IF(AND(G857=TRUE,YEAR(E857)<2021),F857,"")*(I857*24),0) -> 0 | K857: TRUE
A858: 852 | B858: Ana Paula Celes | C858: Retort (Sistema Fechado) | D858: Planejamento das embalagens | E858: 43837 | F858: 0.0625 | G858: FALSE | H858: =IF(VLOOKUP(C858,Projetos!A:L,12,false)=TRUE,TRUE,FALSE) -> TRUE | I858: 169.03747 | J858: =IFERROR(IF(AND(G858=TRUE,YEAR(E858)<2021),F858,"")*(I858*24),0) -> 0 | K858: TRUE
A859: 853 | B859: Ana Paula Celes | C859: Retort (Sistema Fechado) | D859: Direcionamento global de todo sitema de tratamento termico | E859: 43838 | F859: 0.083333333 | G859: FALSE | H859: =IF(VLOOKUP(C859,Projetos!A:L,12,false)=TRUE,TRUE,FALSE) -> TRUE | I859: 169.03747 | J859: =IFERROR(IF(AND(G859=TRUE,YEAR(E859)<2021),F859,"")*(I859*24),0) -> 0 | K859: TRUE
A860: 854 | B860: Ana Paula Celes | C860: Retort (Sistema Fechado) | D860: Diretrizes e cmposição micronutrientes das fórmulas | E860: 43858 | F860: 0.041666667 | G860: FALSE | H860: =IF(VLOOKUP(C860,Projetos!A:L,12,false)=TRUE,TRUE,FALSE) -> TRUE | I860: 169.03747 | J860: =IFERROR(IF(AND(G860=TRUE,YEAR(E860)<2021),F860,"")*(I860*24),0) -> 0 | K860: TRUE
A861: 855 | B861: Ana Paula Celes | C861: Sarcopenia | D861: Definição do conceito de inovação e nutrientes da formula | E861: 43837 | F861: 0.041666667 | G861: TRUE | H861: =IF(VLOOKUP(C861,Projetos!A:L,12,false)=TRUE,TRUE,FALSE) -> TRUE | I861: 169.03747 | J861: =IFERROR(IF(AND(G861=TRUE,YEAR(E861)<2021),F861,"")*(I861*24),0) -> 169.03747 | K861: TRUE
A862: 856 | B862: Ana Paula Celes | C862: InstanTH NEO | D862: Análise e discussão da comunicção de inovação ao mercado | E862: 43873 | F862: 0.041666667 | G862: TRUE | H862: =IF(VLOOKUP(C862,Projetos!A:L,12,false)=TRUE,TRUE,FALSE) -> TRUE | I862: 161.35394 | J862: =IFERROR(IF(AND(G862=TRUE,YEAR(E862)<2021),F862,"")*(I862*24),0) -> 161.35394 | K862: TRUE
A863: 857 | B863: Ana Paula Celes | C863: Retort (Sistema Fechado) | D863: Planejamento para teste piloto | E863: 43866 | F863: 0.041666667 | G863: TRUE | H863: =IF(VLOOKUP(C863,Projetos!A:L,12,false)=TRUE,TRUE,FALSE) -> TRUE | I863: 161.35394 | J863: =IFERROR(IF(AND(G863=TRUE,YEAR(E863)<2021),F863,"")*(I863*24),0) -> 161.35394 | K863: TRUE
A864: 858 | B864: Ana Paula Celes | C864: Retort (Sistema Fechado) | D864: Atualizações do projeto | E864: 43871 | F864: 0.0625 | G864: FALSE | H864: =IF(VLOOKUP(C864,Projetos!A:L,12,false)=TRUE,TRUE,FALSE) -> TRUE | I864: 161.35394 | J864: =IFERROR(IF(AND(G864=TRUE,YEAR(E864)<2021),F864,"")*(I864*24),0) -> 0 | K864: TRUE
A865: 859 | B865: Ana Paula Celes | C865: Retort (Sistema Fechado) | D865: Discussão de linhas de pesquisa clinica | E865: 43872 | F865: 0.041666667 | G865: TRUE | H865: =IF(VLOOKUP(C865,Projetos!A:L,12,false)=TRUE,TRUE,FALSE) -> TRUE | I865: 161.35394 | J865: =IFERROR(IF(AND(G865=TRUE,YEAR(E865)<2021),F865,"")*(I865*24),0) -> 161.35394 | K865: TRUE
A866: 860 | B866: Ana Paula Celes | C866: Retort (Sistema Fechado) | D866: Fechamento de diretrizes do teste piloto | E866: 43873 | F866: 0.020833333 | G866: TRUE | H866: =IF(VLOOKUP(C866,Projetos!A:L,12,false)=TRUE,TRUE,FALSE) -> TRUE | I866: 161.35394 | J866: =IFERROR(IF(AND(G866=TRUE,YEAR(E866)<2021),F866,"")*(I866*24),0) -> 80.676972 | K866: TRUE
A867: 861 | B867: Ana Paula Celes | C867: Retort (Sistema Fechado) | D867: Execução de tetes em planta piloto | E867: 43878 | F867: 0.41666667 | G867: TRUE | H867: =IF(VLOOKUP(C867,Projetos!A:L,12,false)=TRUE,TRUE,FALSE) -> TRUE | I867: 161.35394 | J867: =IFERROR(IF(AND(G867=TRUE,YEAR(E867)<2021),F867,"")*(I867*24),0) -> 1613.5394 | K867: TRUE
A868: 862 | B868: Ana Paula Celes | C868: Retort (Sistema Fechado) | D868: Execução de tetes em planta piloto | E868: 43879 | F868: 0.41666667 | G868: TRUE | H868: =IF(VLOOKUP(C868,Projetos!A:L,12,false)=TRUE,TRUE,FALSE) -> TRUE | I868: 161.35394 | J868: =IFERROR(IF(AND(G868=TRUE,YEAR(E868)<2021),F868,"")*(I868*24),0) -> 1613.5394 | K868: TRUE
A869: 863 | B869: Ana Paula Celes | C869: Retort (Sistema Fechado) | D869: Monitoramento dos resultados de testes FQ | E869: 43889 | F869: 0.041666667 | G869: TRUE | H869: =IF(VLOOKUP(C869,Projetos!A:L,12,false)=TRUE,TRUE,FALSE) -> TRUE | I869: 161.35394 | J869: =IFERROR(IF(AND(G869=TRUE,YEAR(E869)<2021),F869,"")*(I869*24),0) -> 161.35394 | K869: TRUE
... A1058: 1052 | B1058: Ana Paula Celes | C1058: Vulcano (pote jumbo e sachês a vácuo) | D1058: Definições de ações do projeto Jumbo e sache vacuo | E1058: 44194 | F1058: 0.083333333 | G1058: FALSE | H1058: =IF(VLOOKUP(C1058,Projetos!A:L,12,false)=TRUE,TRUE,FALSE) -> FALSE | I1058: 169.03747 | J1058: =IFERROR(IF(AND(G1058=TRUE,YEAR(E1058)<2021),F1058,"")*(I1058*24),0) -> 0 | K1058: FALSE
A1059: 1053 | B1059: Ana Paula Celes | C1059: Centro de Inovação | D1059: Análise de atividades de P&D | F1059: 0.0625 | G1059: FALSE | H1059: =IF(VLOOKUP(C1059,Projetos!A:L,12,false)=TRUE,TRUE,FALSE) -> FALSE | I1059: 169.03747 | J1059: =IFERROR(IF(AND(G1059=TRUE,YEAR(E1059)<2021),F1059,"")*(I1059*24),0) -> 0 | K1059: FALSE
A1060: 1054 | B1060: Ana Claudia Zanini | C1060: Sarcopenia | D1060: Desenvolvimento de protocolo de pesquisa clinica | E1060: 43895 | F1060: 0.1875 | G1060: TRUE | H1060: =IF(VLOOKUP(C1060,Projetos!A:L,12,false)=TRUE,TRUE,FALSE) -> TRUE | I1060: 29.312396 | J1060: =IFERROR(IF(AND(G1060=TRUE,YEAR(E1060)<2021),F1060,"")*(I1060*24),0) -> 131.90578 | K1060: TRUE
A1061: 1055 | B1061: Ana Claudia Zanini | C1061: Sarcopenia | D1061: Desenvolvimento de protocolo de pesquisa clinica | E1061: 43896 | F1061: 0.16666667 | G1061: TRUE | H1061: =IF(VLOOKUP(C1061,Projetos!A:L,12,false)=TRUE,TRUE,FALSE) -> TRUE | I1061: 29.312396 | J1061: =IFERROR(IF(AND(G1061=TRUE,YEAR(E1061)<2021),F1061,"")*(I1061*24),0) -> 117.24959 | K1061: TRUE
A1062: 1056 | B1062: Ana Claudia Zanini | C1062: Sarcopenia | D1062: Desenvolvimento de protocolo de pesquisa clinica | E1062: 43901 | F1062: 0.1875 | G1062: TRUE | H1062: =IF(VLOOKUP(C1062,Projetos!A:L,12,false)=TRUE,TRUE,FALSE) -> TRUE | I1062: 29.312396 | J1062: =IFERROR(IF(AND(G1062=TRUE,YEAR(E1062)<2021),F1062,"")*(I1062*24),0) -> 131.90578 | K1062: TRUE
A1063: 1057 | B1063: Ana Claudia Zanini | C1063: Sarcopenia | D1063: Desenvolvimento de protocolo de pesquisa clinica | E1063: 43903 | F1063: 0.10416667 | G1063: TRUE | H1063: =IF(VLOOKUP(C1063,Projetos!A:L,12,false)=TRUE,TRUE,FALSE) -> TRUE | I1063: 29.312396 | J1063: =IFERROR(IF(AND(G1063=TRUE,YEAR(E1063)<2021),F1063,"")*(I1063*24),0) -> 73.280991 | K1063: TRUE
A1064: 1058 | B1064: Ana Claudia Zanini | C1064: Sarcopenia | D1064: Desenvolvimento de protocolo de pesquisa clinica | E1064: 43903 | F1064: 0.083333333 | G1064: TRUE | H1064: =IF(VLOOKUP(C1064,Projetos!A:L,12,false)=TRUE,TRUE,FALSE) -> TRUE | I1064: 29.312396 | J1064: =IFERROR(IF(AND(G1064=TRUE,YEAR(E1064)<2021),F1064,"")*(I1064*24),0) -> 58.624793 | K1064: TRUE
A1065: 1059 | B1065: Ana Claudia Zanini | C1065: InstanTH NEO | D1065: Pesquisa sobre profissionais para estudo de caso | E1065: 43907 | F1065: 0.041666667 | G1065: TRUE | H1065: =IF(VLOOKUP(C1065,Projetos!A:L,12,false)=TRUE,TRUE,FALSE) -> TRUE | I1065: 29.312396 | J1065: =IFERROR(IF(AND(G1065=TRUE,YEAR(E1065)<2021),F1065,"")*(I1065*24),0) -> 29.312396 | K1065: TRUE
...

Sheet Cópia de Timesheet
A2: Timesheet
A3: BENEFÍCIO FISCAL DE PD&I 2019 | I3: Parcial | J3: =J5-J4 -> 312686.56
I4: Exclusivo | J4: =IFERROR(__xludf.DUMMYFUNCTION("SUMIF($B$7:$B3492,FILTER(Pessoal!$A$10:$A$26,Pessoal!$U$10:$U$26 = ""Exclusivo"",MATCH(Pessoal!$A$10:$A$26,FILTER(Pessoal!$A$37:$A$57,Pessoal!$U$37:$U$57 = TRUE),0)),$J$7:$J3492)"),0.0) -> 0
I5: TOTAL | J5: =SUM(J7:J3492) -> 312686.56
A6: Cod | B6: Pessoa | C6: Projeto | D6: Descrição | E6: Start | F6: Tempo aplicado | G6: Atividade incentivada | H6: Attachments | I6: Valor (R$) | J6: Custo | K6: checkprojetos
A7: 1 | B7: Ademir Mararangoni | C7: Immax - etapa final da Pesquisa Clínica | D7: Coordenar pesagem e produção | E7: 43846 | F7: 0.041666667 | G7: TRUE | H7: =IF(VLOOKUP(C7,Projetos!A:L,12,false)=TRUE,TRUE,FALSE) -> TRUE | I7: {=VLOOKUP(B7:B3492,Pessoal!$A$36:$R$57,MONTH(E7:E3492)+6,false)} -> 63.065873 | J7: =IFERROR(IF(AND(G7=TRUE,YEAR(E7)<2021),F7,"")*(I7*24),0) -> 63.065873 | K7: {=VLOOKUP(C7:C3492,Projetos!A6:L3492,12,false)} -> TRUE
A8: 2 | B8: Ademir Mararangoni | C8: InstanTH NEO | D8: Coordenar separação, emissão de NF e envio dos materiais para produção | E8: 43840 | F8: 0.083333333 | G8: TRUE | H8: =IF(VLOOKUP(C8,Projetos!A:L,12,false)=TRUE,TRUE,FALSE) -> TRUE | I8: 63.065873 | J8: =IFERROR(IF(AND(G8=TRUE,YEAR(E8)<2021),F8,"")*(I8*24),0) -> 126.13175 | K8: TRUE
A9: 3 | B9: Ademir Mararangoni | C9: InstanTH CLEAR (espessante) | D9: Adequação da linha de produção para o envase (Novo Twister, Envasadora, Esteira tampadora Plock off) | E9: 43850 | F9: 0.40625 | G9: TRUE | H9: =IF(VLOOKUP(C9,Projetos!A:L,12,false)=TRUE,TRUE,FALSE) -> TRUE | I9: 63.065873 | J9: =IFERROR(IF(AND(G9=TRUE,YEAR(E9)<2021),F9,"")*(I9*24),0) -> 614.89226 | K9: TRUE
A10: 4 | B10: Ademir Mararangoni | C10: Inovação industrial - misturas secas | D10: Implementação do projeto balança onde integraliza a pesagem do fracionamento com o estrutura do sistema para minimizar erros | E10: 43843 | F10: 0.40625 | G10: FALSE | H10: =IF(VLOOKUP(C10,Projetos!A:L,12,false)=TRUE,TRUE,FALSE) -> FALSE | I10: 63.065873 | J10: =IFERROR(IF(AND(G10=TRUE,YEAR(E10)<2021),F10,"")*(I10*24),0) -> 0 | K10: FALSE
A11: 5 | B11: Ademir Mararangoni | C11: Inovação industrial - misturas secas | D11: Teste de n² com enertizado da Brasilata | E11: 43845 | F11: 0.23958333 | G11: FALSE | H11: =IF(VLOOKUP(C11,Projetos!A:L,12,false)=TRUE,TRUE,FALSE) -> FALSE | I11: 63.065873 | J11: =IFERROR(IF(AND(G11=TRUE,YEAR(E11)<2021),F11,"")*(I11*24),0) -> 0 | K11: FALSE
A12: 6 | B12: Ademir Mararangoni | C12: InstanTH CLEAR (espessante) | D12: Primeira produção do Instant clear | E12: 43872 | F12: 0.083333333 | G12: TRUE | H12: =IF(VLOOKUP(C12,Projetos!A:L,12,false)=TRUE,TRUE,FALSE) -> TRUE | I12: 60.199242 | J12: =IFERROR(IF(AND(G12=TRUE,YEAR(E12)<2021),F12,"")*(I12*24),0) -> 120.39848 | K12: TRUE
A13: 7 | B13: Ademir Mararangoni | C13: InstanTH NEO | D13: Apontamento, triangulazação de NF | E13: 43888 | F13: 0.083333333 | G13: FALSE | H13: =IF(VLOOKUP(C13,Projetos!A:L,12,false)=TRUE,TRUE,FALSE) -> TRUE | I13: 60.199242 | J13: =IFERROR(IF(AND(G13=TRUE,YEAR(E13)<2021),F13,"")*(I13*24),0) -> 0 | K13: TRUE
A14: 8 | B14: Ademir Mararangoni | C14: Bemmax Sabor Neutro | D14: Teste de envase -peso alcançado 350g | E14: 43879 | F14: 0.10416667 | G14: TRUE | H14: =IF(VLOOKUP(C14,Projetos!A:L,12,false)=TRUE,TRUE,FALSE) -> TRUE | I14: 60.199242 | J14: =IFERROR(IF(AND(G14=TRUE,YEAR(E14)<2021),F14,"")*(I14*24),0) -> 150.49811 | K14: TRUE
A15: 9 | B15: Ademir Mararangoni | C15: Retort (Sistema Fechado) | D15: Separação de MP fisico e sistema para pesagem de teste | E15: 43876 | F15: 0.083333333 | G15: FALSE | H15: =IF(VLOOKUP(C15,Projetos!A:L,12,false)=TRUE,TRUE,FALSE) -> TRUE | I15: 60.199242 | J15: =IFERROR(IF(AND(G15=TRUE,YEAR(E15)<2021),F15,"")*(I15*24),0) -> 0 | K15: TRUE
A16: 10 | B16: Ademir Mararangoni | C16: HDmax 2.0 | D16: Separação de MP fisico e sistema para pesagem de teste | E16: 43874 | F16: 0.083333333 | G16: TRUE | H16: =IF(VLOOKUP(C16,Projetos!A:L,12,false)=TRUE,TRUE,FALSE) -> TRUE | I16: 60.199242 | J16: =IFERROR(IF(AND(G16=TRUE,YEAR(E16)<2021),F16,"")*(I16*24),0) -> 120.39848 | K16: TRUE
A17: 11 | B17: Ademir Mararangoni | C17: Inovação industrial - misturas secas | D17: Validação com comercial e manutenção pra aquisição de strechadeira automática | E17: 43886 | F17: 0.083333333 | G17: FALSE | H17: =IF(VLOOKUP(C17,Projetos!A:L,12,false)=TRUE,TRUE,FALSE) -> FALSE | I17: 60.199242 | J17: =IFERROR(IF(AND(G17=TRUE,YEAR(E17)<2021),F17,"")*(I17*24),0) -> 0 | K17: FALSE
A18: 12 | B18: Ademir Mararangoni | C18: Inovação industrial - misturas secas | D18: Alinhamento do projeto balança onde integraliza a pesagem do fracionamento com o estrutura do sistema para minimizar erros | E18: 43865 | F18: 0.041666667 | G18: FALSE | H18: =IF(VLOOKUP(C18,Projetos!A:L,12,false)=TRUE,TRUE,FALSE) -> FALSE | I18: 60.199242 | J18: =IFERROR(IF(AND(G18=TRUE,YEAR(E18)<2021),F18,"")*(I18*24),0) -> 0 | K18: FALSE
A19: 13 | B19: Ademir Mararangoni | C19: Inovação industrial - misturas secas | D19: Alinhamento do projeto balança onde integraliza a pesagem do fracionamento com o estrutura do sistema para minimizar erros | E19: 43875 | F19: 0.083333333 | G19: FALSE | H19: =IF(VLOOKUP(C19,Projetos!A:L,12,false)=TRUE,TRUE,FALSE) -> FALSE | I19: 60.199242 | J19: =IFERROR(IF(AND(G19=TRUE,YEAR(E19)<2021),F19,"")*(I19*24),0) -> 0 | K19: FALSE
... A856: 850 | B856: Ana Paula Celes | C856: InstanTH NEO | D856: Discussão de linhas de pesquisa clinica | E856: 43844 | F856: 0.020833333 | G856: TRUE | H856: =IF(VLOOKUP(C856,Projetos!A:L,12,false)=TRUE,TRUE,FALSE) -> TRUE | I856: 169.03747 | J856: =IFERROR(IF(AND(G856=TRUE,YEAR(E856)<2021),F856,"")*(I856*24),0) -> 84.518733 | K856: TRUE
A857: 851 | B857: Ana Paula Celes | C857: InstanTH NEO | D857: Discussão de linhas de pesquisa clinica | F857: 0 | G857: FALSE | H857: =IF(VLOOKUP(C857,Projetos!A:L,12,false)=TRUE,TRUE,FALSE) -> TRUE | I857: 169.03747 | J857: =IFERROR(IF(AND(G857=TRUE,YEAR(E857)<2021),F857,"")*(I857*24),0) -> 0 | K857: TRUE
A858: 852 | B858: Ana Paula Celes | C858: Retort (Sistema Fechado) | D858: Planejamento das embalagens | E858: 43837 | F858: 0.0625 | G858: FALSE | H858: =IF(VLOOKUP(C858,Projetos!A:L,12,false)=TRUE,TRUE,FALSE) -> TRUE | I858: 169.03747 | J858: =IFERROR(IF(AND(G858=TRUE,YEAR(E858)<2021),F858,"")*(I858*24),0) -> 0 | K858: TRUE
A859: 853 | B859: Ana Paula Celes | C859: Retort (Sistema Fechado) | D859: Direcionamento global de todo sitema de tratamento termico | E859: 43838 | F859: 0.083333333 | G859: FALSE | H859: =IF(VLOOKUP(C859,Projetos!A:L,12,false)=TRUE,TRUE,FALSE) -> TRUE | I859: 169.03747 | J859: =IFERROR(IF(AND(G859=TRUE,YEAR(E859)<2021),F859,"")*(I859*24),0) -> 0 | K859: TRUE
A860: 854 | B860: Ana Paula Celes | C860: Retort (Sistema Fechado) | D860: Diretrizes e cmposição micronutrientes das fórmulas | E860: 43858 | F860: 0.041666667 | G860: FALSE | H860: =IF(VLOOKUP(C860,Projetos!A:L,12,false)=TRUE,TRUE,FALSE) -> TRUE | I860: 169.03747 | J860: =IFERROR(IF(AND(G860=TRUE,YEAR(E860)<2021),F860,"")*(I860*24),0) -> 0 | K860: TRUE
A861: 855 | B861: Ana Paula Celes | C861: Sarcopenia | D861: Definição do conceito de inovação e nutrientes da formula | E861: 43837 | F861: 0.041666667 | G861: TRUE | H861: =IF(VLOOKUP(C861,Projetos!A:L,12,false)=TRUE,TRUE,FALSE) -> TRUE | I861: 169.03747 | J861: =IFERROR(IF(AND(G861=TRUE,YEAR(E861)<2021),F861,"")*(I861*24),0) -> 169.03747 | K861: TRUE
A862: 856 | B862: Ana Paula Celes | C862: InstanTH NEO | D862: Análise e discussão da comunicção de inovação ao mercado | E862: 43873 | F862: 0.041666667 | G862: TRUE | H862: =IF(VLOOKUP(C862,Projetos!A:L,12,false)=TRUE,TRUE,FALSE) -> TRUE | I862: 161.35394 | J862: =IFERROR(IF(AND(G862=TRUE,YEAR(E862)<2021),F862,"")*(I862*24),0) -> 161.35394 | K862: TRUE
A863: 857 | B863: Ana Paula Celes | C863: Retort (Sistema Fechado) | D863: Planejamento para teste piloto | E863: 43866 | F863: 0.041666667 | G863: TRUE | H863: =IF(VLOOKUP(C863,Projetos!A:L,12,false)=TRUE,TRUE,FALSE) -> TRUE | I863: 161.35394 | J863: =IFERROR(IF(AND(G863=TRUE,YEAR(E863)<2021),F863,"")*(I863*24),0) -> 161.35394 | K863: TRUE
A864: 858 | B864: Ana Paula Celes | C864: Retort (Sistema Fechado) | D864: Atualizações do projeto | E864: 43871 | F864: 0.0625 | G864: FALSE | H864: =IF(VLOOKUP(C864,Projetos!A:L,12,false)=TRUE,TRUE,FALSE) -> TRUE | I864: 161.35394 | J864: =IFERROR(IF(AND(G864=TRUE,YEAR(E864)<2021),F864,"")*(I864*24),0) -> 0 | K864: TRUE
A865: 859 | B865: Ana Paula Celes | C865: Retort (Sistema Fechado) | D865: Discussão de linhas de pesquisa clinica | E865: 43872 | F865: 0.041666667 | G865: TRUE | H865: =IF(VLOOKUP(C865,Projetos!A:L,12,false)=TRUE,TRUE,FALSE) -> TRUE | I865: 161.35394 | J865: =IFERROR(IF(AND(G865=TRUE,YEAR(E865)<2021),F865,"")*(I865*24),0) -> 161.35394 | K865: TRUE
A866: 860 | B866: Ana Paula Celes | C866: Retort (Sistema Fechado) | D866: Fechamento de diretrizes do teste piloto | E866: 43873 | F866: 0.020833333 | G866: TRUE | H866: =IF(VLOOKUP(C866,Projetos!A:L,12,false)=TRUE,TRUE,FALSE) -> TRUE | I866: 161.35394 | J866: =IFERROR(IF(AND(G866=TRUE,YEAR(E866)<2021),F866,"")*(I866*24),0) -> 80.676972 | K866: TRUE
A867: 861 | B867: Ana Paula Celes | C867: Retort (Sistema Fechado) | D867: Execução de tetes em planta piloto | E867: 43878 | F867: 0.41666667 | G867: TRUE | H867: =IF(VLOOKUP(C867,Projetos!A:L,12,false)=TRUE,TRUE,FALSE) -> TRUE | I867: 161.35394 | J867: =IFERROR(IF(AND(G867=TRUE,YEAR(E867)<2021),F867,"")*(I867*24),0) -> 1613.5394 | K867: TRUE
A868: 862 | B868: Ana Paula Celes | C868: Retort (Sistema Fechado) | D868: Execução de tetes em planta piloto | E868: 43879 | F868: 0.41666667 | G868: TRUE | H868: =IF(VLOOKUP(C868,Projetos!A:L,12,false)=TRUE,TRUE,FALSE) -> TRUE | I868: 161.35394 | J868: =IFERROR(IF(AND(G868=TRUE,YEAR(E868)<2021),F868,"")*(I868*24),0) -> 1613.5394 | K868: TRUE
A869: 863 | B869: Ana Paula Celes | C869: Retort (Sistema Fechado) | D869: Monitoramento dos resultados de testes FQ | E869: 43889 | F869: 0.041666667 | G869: TRUE | H869: =IF(VLOOKUP(C869,Projetos!A:L,12,false)=TRUE,TRUE,FALSE) -> TRUE | I869: 161.35394 | J869: =IFERROR(IF(AND(G869=TRUE,YEAR(E869)<2021),F869,"")*(I869*24),0) -> 161.35394 | K869: TRUE
... A1058: 1052 | B1058: Ana Paula Celes | C1058: Vulcano (pote jumbo e sachês a vácuo) | D1058: Definições de ações do projeto Jumbo e sache vacuo | E1058: 44194 | F1058: 0.083333333 | G1058: FALSE | H1058: =IF(VLOOKUP(C1058,Projetos!A:L,12,false)=TRUE,TRUE,FALSE) -> FALSE | I1058: 169.03747 | J1058: =IFERROR(IF(AND(G1058=TRUE,YEAR(E1058)<2021),F1058,"")*(I1058*24),0) -> 0 | K1058: FALSE
A1059: 1053 | B1059: Ana Paula Celes | C1059: Centro de Inovação | D1059: Análise de atividades de P&D | F1059: 0.0625 | G1059: FALSE | H1059: =IF(VLOOKUP(C1059,Projetos!A:L,12,false)=TRUE,TRUE,FALSE) -> FALSE | I1059: 169.03747 | J1059: =IFERROR(IF(AND(G1059=TRUE,YEAR(E1059)<2021),F1059,"")*(I1059*24),0) -> 0 | K1059: FALSE
A1060: 1054 | B1060: Ana Claudia Zanini | C1060: Sarcopenia | D1060: Desenvolvimento de protocolo de pesquisa clinica | E1060: 43895 | F1060: 0.1875 | G1060: TRUE | H1060: =IF(VLOOKUP(C1060,Projetos!A:L,12,false)=TRUE,TRUE,FALSE) -> TRUE | I1060: 29.312396 | J1060: =IFERROR(IF(AND(G1060=TRUE,YEAR(E1060)<2021),F1060,"")*(I1060*24),0) -> 131.90578 | K1060: TRUE
A1061: 1055 | B1061: Ana Claudia Zanini | C1061: Sarcopenia | D1061: Desenvolvimento de protocolo de pesquisa clinica | E1061: 43896 | F1061: 0.16666667 | G1061: TRUE | H1061: =IF(VLOOKUP(C1061,Projetos!A:L,12,false)=TRUE,TRUE,FALSE) -> TRUE | I1061: 29.312396 | J1061: =IFERROR(IF(AND(G1061=TRUE,YEAR(E1061)<2021),F1061,"")*(I1061*24),0) -> 117.24959 | K1061: TRUE
A1062: 1056 | B1062: Ana Claudia Zanini | C1062: Sarcopenia | D1062: Desenvolvimento de protocolo de pesquisa clinica | E1062: 43901 | F1062: 0.1875 | G1062: TRUE | H1062: =IF(VLOOKUP(C1062,Projetos!A:L,12,false)=TRUE,TRUE,FALSE) -> TRUE | I1062: 29.312396 | J1062: =IFERROR(IF(AND(G1062=TRUE,YEAR(E1062)<2021),F1062,"")*(I1062*24),0) -> 131.90578 | K1062: TRUE
A1063: 1057 | B1063: Ana Claudia Zanini | C1063: Sarcopenia | D1063: Desenvolvimento de protocolo de pesquisa clinica | E1063: 43903 | F1063: 0.10416667 | G1063: TRUE | H1063: =IF(VLOOKUP(C1063,Projetos!A:L,12,false)=TRUE,TRUE,FALSE) -> TRUE | I1063: 29.312396 | J1063: =IFERROR(IF(AND(G1063=TRUE,YEAR(E1063)<2021),F1063,"")*(I1063*24),0) -> 73.280991 | K1063: TRUE
A1064: 1058 | B1064: Ana Claudia Zanini | C1064: Sarcopenia | D1064: Desenvolvimento de protocolo de pesquisa clinica | E1064: 43903 | F1064: 0.083333333 | G1064: TRUE | H1064: =IF(VLOOKUP(C1064,Projetos!A:L,12,false)=TRUE,TRUE,FALSE) -> TRUE | I1064: 29.312396 | J1064: =IFERROR(IF(AND(G1064=TRUE,YEAR(E1064)<2021),F1064,"")*(I1064*24),0) -> 58.624793 | K1064: TRUE
A1065: 1059 | B1065: Ana Claudia Zanini | C1065: InstanTH NEO | D1065: Pesquisa sobre profissionais para estudo de caso | E1065: 43907 | F1065: 0.041666667 | G1065: TRUE | H1065: =IF(VLOOKUP(C1065,Projetos!A:L,12,false)=TRUE,TRUE,FALSE) -> TRUE | I1065: 29.312396 | J1065: =IFERROR(IF(AND(G1065=TRUE,YEAR(E1065)<2021),F1065,"")*(I1065*24),0) -> 29.312396 | K1065: TRUE
...

Sheet Pessoal
A2: Pessoal
A4: Salario bruto | G4: planilha RH | H4: planilha RH | I4: planilha RH | J4: planilha RH | K4: planilha RH | L4: planilha RH | M4: planilha RH | N4: planilha RH | O4: planilha RH | P4: planilha RH | Q4: RH atualizou online | R4: RH atualizou online | S4: =(T4/12)*24 -> 171.33333 | T4: =(SUM(G35:R35)*8)/24 -> 85.666667
A5: Nome Completo | B5: CPF | C5: notas | D5: Cargo/função | E5: Formação | F5: Attachments | G5: Salário 01 | H5: Salário 02 | I5: Salário 03 | J5: Salário 04 | K5: Salário 05 | L5: Salário 06 | M5: Salário 07 | N5: Salário 08 | O5: Salário 09 | P5: Salário 10 | Q5: Salário 11 | R5: Salário 12 | S5: PD&I time | T5: PD&I (%) | U5: Classificação | V5: Pesquisador
A6: Ademir Mararangoni | B6: 018.764.779-89 | D6: Coord. PCP | E6: Superior Completo | G6: 7255.64 | H6: 7255.64 | I6: 7255.64 | J6: 7255.64 | K6: 7255.64 | L6: 7255.64 | M6: 7255.64 | N6: 7255.64 | O6: 7618.42 | P6: 7618.42 | Q6: 7743.36 | R6: =Q6 -> 7743.36 | S6: =IFERROR(__xludf.DUMMYFUNCTION("IFERROR(if(V6=true, SUM(FILTER(Timesheet!$F:$F,Timesheet!G:G = TRUE,Timesheet!B:B = A6,Timesheet!E:E < DATE(2021,1,1))),0),0)"),0.0) -> 0 | T6: =S6/$T$4 -> 0 | U6: =IF(T6<80%,"Parcial","Exclusivo") -> Parcial | V6: FALSE
A7: Ana Claudia Zanini | B7: 076.046.519-33 | D7: Analista Científico | E7: Mestrado | I7: 3372.35 | J7: 3372.35 | K7: 3372.35 | L7: 3372.35 | M7: 3372.35 | N7: 3372.35 | O7: 3372.35 | P7: 3372.35 | Q7: 3599.04 | R7: =Q7 -> 3599.04 | S7: =IFERROR(__xludf.DUMMYFUNCTION("IFERROR(if(V7=true, SUM(FILTER(Timesheet!$F:$F,Timesheet!G:G = TRUE,Timesheet!B:B = A7,Timesheet!E:E < DATE(2021,1,1))),0),0)"),38.302083333333314) -> 38.302083 | T7: =S7/$T$4 -> 0.44710603 | U7: =IF(T7<80%,"Parcial","Exclusivo") -> Parcial | V7: TRUE
A8: Ana Paula Celes | B8: 759.837.297-72 | D8: Diretora Técnica | E8: Pós graduado | F8: PJ | G8: 30393.85 | H8: 30393.85 | I8: 30393.85 | J8: 30393.85 | K8: 30393.85 | L8: 30393.85 | M8: 30393.85 | N8: 30393.85 | O8: 30393.85 | P8: 30393.85 | Q8: =P8 -> 30393.85 | R8: =Q8 -> 30393.85 | S8: =IFERROR(__xludf.DUMMYFUNCTION("IFERROR(if(V8=true, SUM(FILTER(Timesheet!$F:$F,Timesheet!G:G = TRUE,Timesheet!B:B = A8,Timesheet!E:E < DATE(2021,1,1))),0),0)"),5.503472222222221) -> 5.5034722 | T8: =S8/$T$4 -> 0.064242866 | U8: =IF(T8<80%,"Parcial","Exclusivo") -> Parcial | V8: TRUE
A9: Arianna Schreiber | B9: 066.466.799-67 | D9: Gerente Mkt | E9: Pós graduado | G9: 7869.54 | H9: 7869.54 | I9: 7869.54 | J9: 7869.54 | K9: 7869.54 | L9: 7869.54 | M9: 7869.54 | N9: 7869.54 | O9: 8735.19 | P9: 8735.19 | Q9: 8878.45 | R9: =Q9 -> 8878.45 | S9: =IFERROR(__xludf.DUMMYFUNCTION("IFERROR(if(V9=true, SUM(FILTER(Timesheet!$F:$F,Timesheet!G:G = TRUE,Timesheet!B:B = A9,Timesheet!E:E < DATE(2021,1,1))),0),0)"),1.2500000000000002) -> 1.25 | T9: =S9/$T$4 -> 0.01459144 | U9: =IF(T9<80%,"Parcial","Exclusivo") -> Parcial | V9: TRUE
A10: Camila Mendes Pereira | B10: 083.832.289-10 | D10: Assistente de P&D | E10: Superior Completo | G10: 2493.03 | H10: 2493.03 | I10: 2493.03 | J10: 2493.03 | K10: 2493.03 | L10: 2493.03 | M10: 2493.03 | N10: 2493.03 | O10: 2771.24 | P10: 2771.24 | Q10: 2816.69 | R10: =Q10 -> 2816.69 | S10: =IFERROR(__xludf.DUMMYFUNCTION("IFERROR(if(V10=true, SUM(FILTER(Timesheet!$F:$F,Timesheet!G:G = TRUE,Timesheet!B:B = A10,Timesheet!E:E < DATE(2021,1,1))),0),0)"),30.124305555555548) -> 30.124306 | T10: =S10/$T$4 -> 0.35164559 | U10: =IF(T10<80%,"Parcial","Exclusivo") -> Parcial | V10: TRUE
A11: Denise Barros Ferreira | B11: 796.047.576-87 | D11: Coord. CQ | E11: Superior Completo | G11: 5010.94 | H11: 5010.94 | I11: 5010.94 | J11: 5010.94 | K11: 5010.94 | L11: 5010.94 | M11: 5010.94 | N11: 5010.94 | O11: 5010.94 | P11: 5010.94 | Q11: 5093.12 | R11: =Q11 -> 5093.12 | S11: =IFERROR(__xludf.DUMMYFUNCTION("IFERROR(if(V11=true, SUM(FILTER(Timesheet!$F:$F,Timesheet!G:G = TRUE,Timesheet!B:B = A11,Timesheet!E:E < DATE(2021,1,1))),0),0)"),0.0) -> 0 | T11: =S11/$T$4 -> 0 | U11: =IF(T11<80%,"Parcial","Exclusivo") -> Parcial | V11: FALSE
A12: Emanuela Adam Bechlin Picheki | B12: 065.358.929-80 | D12: Compradora | E12: Pós graduado | G12: 6215.73 | H12: 6215.73 | I12: 6215.73 | J12: 6215.73 | K12: 6215.73 | L12: 6215.73 | M12: 6215.73 | N12: 6215.73 | O12: 6215.73 | P12: 6215.73 | Q12: 6949.43 | R12: =Q12 -> 6949.43 | S12: =IFERROR(__xludf.DUMMYFUNCTION("IFERROR(if(V12=true, SUM(FILTER(Timesheet!$F:$F,Timesheet!G:G = TRUE,Timesheet!B:B = A12,Timesheet!E:E < DATE(2021,1,1))),0),0)"),3.3541666666666647) -> 3.3541667 | T12: =S12/$T$4 -> 0.039153697 | U12: =IF(T12<80%,"Parcial","Exclusivo") -> Parcial | V12: TRUE
A13: Fabiano Ribeiro da Silva | B13: 023.493.009-86 | D13: Coord. Manutenção | E13: Pós graduado | G13: 5566.87 | H13: 5566.87 | I13: 5566.87 | J13: 5566.87 | K13: 5566.87 | L13: 5566.87 | M13: 5566.87 | N13: 5566.87 | O13: 6012.22 | P13: 6012.22 | Q13: 6110.82 | R13: =Q13 -> 6110.82 | S13: =IFERROR(__xludf.DUMMYFUNCTION("IFERROR(if(V13=true, SUM(FILTER(Timesheet!$F:$F,Timesheet!G:G = TRUE,Timesheet!B:B = A13,Timesheet!E:E < DATE(2021,1,1))),0),0)"),0.0) -> 0 | T13: =S13/$T$4 -> 0 | U13: =IF(T13<80%,"Parcial","Exclusivo") -> Parcial | V13: FALSE
A14: Flavia Firmano Coelho | B14: 029.717.539-48 | D14: Analista AR | E14: Pós graduado | G14: 4650.77 | H14: 4765.42 | I14: 4765.42 | J14: 4765.42 | K14: 4765.42 | L14: 4765.42 | M14: 4765.42 | N14: 4765.42 | O14: 4765.42 | S14: =IFERROR(__xludf.DUMMYFUNCTION("IFERROR(if(V14=true, SUM(FILTER(Timesheet!$F:$F,Timesheet!G:G = TRUE,Timesheet!B:B = A14,Timesheet!E:E < DATE(2021,1,1))),0),0)"),0.0) -> 0 | T14: =S14/$T$4 -> 0 | U14: =IF(T14<80%,"Parcial","Exclusivo") -> Parcial | V14: FALSE
A15: Gabriela Faria de Oliveira | B15: 087.823.469-17 | D15: Analista Científico | E15: Superior Completo | G15: 3372.35 | H15: 3372.35 | I15: 3372.35 | J15: 3372.35 | K15: 3372.35 | L15: 3372.35 | M15: 3372.35 | N15: 3372.35 | O15: 3713 | P15: 3713 | Q15: 3773.89 | R15: =Q15 -> 3773.89 | S15: =IFERROR(__xludf.DUMMYFUNCTION("IFERROR(if(V15=true, SUM(FILTER(Timesheet!$F:$F,Timesheet!G:G = TRUE,Timesheet!B:B = A15,Timesheet!E:E < DATE(2021,1,1))),0),0)"),19.577083333333338) -> 19.577083 | T15: =S15/$T$4 -> 0.22852626 | U15: =IF(T15<80%,"Parcial","Exclusivo") -> Parcial | V15: TRUE
A16: Hellin dos Santos | B16: 058.544.839-63 | D16: Gerente Cientifico | E16: Mestrado | G16: 10111.64 | H16: 10111.64 | I16: 10111.64 | J16: 10111.64 | K16: 10111.64 | L16: 10111.64 | M16: 10111.64 | N16: 10111.64 | O16: 12286.23 | P16: 12286.23 | Q16: 12487.72 | R16: =Q16 -> 12487.72 | S16: =IFERROR(__xludf.DUMMYFUNCTION("IFERROR(if(V16=true, SUM(FILTER(Timesheet!$F:$F,Timesheet!G:G = TRUE,Timesheet!B:B = A16,Timesheet!E:E < DATE(2021,1,1))),0),0)"),58.036111111111154) -> 58.036111 | T16: =S16/$T$4 -> 0.67746433 | U16: =IF(T16<80%,"Parcial","Exclusivo") -> Parcial | V16: TRUE
A17: Kézia Rithássia Piccoli | B17: 077.680.169-47 | D17: Analista de GQ | E17: Pós graduado | G17: 3708.73 | H17: 3708.73 | I17: 3708.73 | J17: 3708.73 | K17: 3708.73 | L17: 3708.73 | M17: 3708.73 | N17: 3708.73 | O17: 4005.43 | P17: 4005.43 | Q17: 4071.12 | R17: =Q17 -> 4071.12 | S17: =IFERROR(__xludf.DUMMYFUNCTION("IFERROR(if(V17=true, SUM(FILTER(Timesheet!$F:$F,Timesheet!G:G = TRUE,Timesheet!B:B = A17,Timesheet!E:E < DATE(2021,1,1))),0),0)"),0.0) -> 0 | T17: =S17/$T$4 -> 0 | U17: =IF(T17<80%,"Parcial","Exclusivo") -> Parcial | V17: FALSE
A18: Lizianne Shmeil | B18: 052.485.199-93 | D18: Analista P&D | E18: Superior Completo | G18: 4332.79 | H18: 4332.79 | I18: 4332.79 | J18: 4332.79 | K18: 4332.79 | L18: 4332.79 | M18: 4332.79 | N18: 4332.79 | O18: 4914.94 | P18: 4914.94 | Q18: 4995.55 | R18: =Q18 -> 4995.55 | S18: =IFERROR(__xludf.DUMMYFUNCTION("IFERROR(if(V18=true, SUM(FILTER(Timesheet!$F:$F,Timesheet!G:G = TRUE,Timesheet!B:B = A18,Timesheet!E:E < DATE(2021,1,1))),0),0)"),55.85208333333332) -> 55.852083 | T18: =S18/$T$4 -> 0.65196984 | U18: =IF(T18<80%,"Parcial","Exclusivo") -> Parcial | V18: TRUE
A19: Luciana Dutra | B19: 186.586.978-35 | D19: Gerente Técnica | E19: Pós graduado | G19: 17326.88 | H19: 17326.88 | I19: 17326.88 | J19: 17326.88 | K19: 17326.88 | L19: 17326.88 | M19: 17326.88 | N19: 17326.88 | O19: 17326.88 | P19: 17326.88 | Q19: 17611.04 | R19: =Q19 -> 17611.04 | S19: =IFERROR(__xludf.DUMMYFUNCTION("IFERROR(if(V19=true, SUM(FILTER(Timesheet!$F:$F,Timesheet!G:G = TRUE,Timesheet!B:B = A19,Timesheet!E:E < DATE(2021,1,1))),0),0)"),10.304166666666664) -> 10.304167 | T19: =S19/$T$4 -> 0.1202821 | U19: =IF(T19<80%,"Parcial","Exclusivo") -> Parcial | V19: TRUE
A20: Lucimari Reway dos Santos | B20: 022.396.139-63 | C20: Técnico em Alimentos | D20: Analista CQ | E20: Técnico | G20: 2493.04 | H20: 2493.04 | I20: 2493.04 | J20: 2493.04 | K20: 2493.04 | L20: 2493.04 | M20: 2493.04 | N20: 2493.04 | O20: 3034.9 | P20: 3034.9 | Q20: 3084.67 | R20: =Q20 -> 3084.67 | S20: =IFERROR(__xludf.DUMMYFUNCTION("IFERROR(if(V20=true, SUM(FILTER(Timesheet!$F:$F,Timesheet!G:G = TRUE,Timesheet!B:B = A20,Timesheet!E:E < DATE(2021,1,1))),0),0)"),0.0) -> 0 | T20: =S20/$T$4 -> 0 | U20: =IF(T20<80%,"Parcial","Exclusivo") -> Parcial | V20: FALSE
A21: Marcella Malucelli Baltazar | B21: 098.146.729-63 | D21: Superv. produção | E21: Superior Completo | G21: 3708.73 | H21: 3708.73 | I21: 3708.73 | J21: 3708.73 | K21: 3708.73 | L21: 3708.73 | M21: 3708.73 | N21: 3708.73 | O21: 3708.73 | P21: 3708.73 | Q21: 3769.55 | R21: =Q21 -> 3769.55 | S21: =IFERROR(__xludf.DUMMYFUNCTION("IFERROR(if(V21=true, SUM(FILTER(Timesheet!$F:$F,Timesheet!G:G = TRUE,Timesheet!B:B = A21,Timesheet!E:E < DATE(2021,1,1))),0),0)"),0.0) -> 0 | T21: =S21/$T$4 -> 0 | U21: =IF(T21<80%,"Parcial","Exclusivo") -> Parcial | V21: FALSE
A22: Marianne Stigar | B22: 066.424.199-95 | D22: Coord. GQ | E22: Pós graduado | G22: 4640.42 | H22: 5010.94 | I22: 5010.94 | J22: 5010.94 | K22: 5010.94 | L22: 5010.94 | M22: 5010.94 | N22: 5010.94 | O22: 5010.94 | P22: 5010.94 | Q22: 5093.12 | R22: =Q22 -> 5093.12 | S22: =IFERROR(__xludf.DUMMYFUNCTION("IFERROR(if(V22=true, SUM(FILTER(Timesheet!$F:$F,Timesheet!G:G = TRUE,Timesheet!B:B = A22,Timesheet!E:E < DATE(2021,1,1))),0),0)"),0.125) -> 0.125 | T22: =S22/$T$4 -> 0.001459144 | U22: =IF(T22<80%,"Parcial","Exclusivo") -> Parcial | V22: TRUE
A23: Naíssa Previde Bernardo | B23: 215.916.758-47 | D23: Especisalista EEE | E23: Mestrado | P23: 9000 | Q23: =P23 -> 9000 | S23: =IFERROR(__xludf.DUMMYFUNCTION("IFERROR(if(V23=true, SUM(FILTER(Timesheet!$F:$F,Timesheet!G:G = TRUE,Timesheet!B:B = A23,Timesheet!E:E < DATE(2021,1,1))),0),0)"),0.0) -> 0 | T23: =S23/$T$4 -> 0 | U23: =IF(T23<80%,"Parcial","Exclusivo") -> Parcial | V23: FALSE
A24: Tahuany Leite | B24: 086.481.459-37 | D24: Analista MKT | E24: Pós graduado | G24: 3899.08 | H24: 3899.08 | I24: 3899.08 | J24: 3899.08 | K24: 3899.08 | L24: 3899.08 | M24: 3899.08 | N24: 3899.08 | O24: 3899.08 | P24: 3899.08 | Q24: 3963.02 | R24: =Q24 -> 3963.02 | S24: =IFERROR(__xludf.DUMMYFUNCTION("IFERROR(if(V24=true, SUM(FILTER(Timesheet!$F:$F,Timesheet!G:G = TRUE,Timesheet!B:B = A24,Timesheet!E:E < DATE(2021,1,1))),0),0)"),1.4791666666666665) -> 1.4791667 | T24: =S24/$T$4 -> 0.017266537 | U24: =IF(T24<80%,"Parcial","Exclusivo") -> Parcial | V24: TRUE
A25: Tais Carlotto | B25: 034.226.309-96 | D25: Coord. AR | E25: Superior Completo | G25: 5566.87 | H25: 6123.88 | I25: 6123.88 | J25: 6123.88 | K25: 6123.88 | L25: 6123.88 | M25: 6123.88 | N25: 6123.88 | O25: 6123.88 | P25: 6123.88 | Q25: 6224.31 | R25: =Q25 -> 6224.31 | S25: =IFERROR(__xludf.DUMMYFUNCTION("IFERROR(if(V25=true, SUM(FILTER(Timesheet!$F:$F,Timesheet!G:G = TRUE,Timesheet!B:B = A25,Timesheet!E:E < DATE(2021,1,1))),0),0)"),0.0) -> 0 | T25: =S25/$T$4 -> 0 | U25: =IF(T25<80%,"Parcial","Exclusivo") -> Parcial | V25: FALSE
S26: =IFERROR(__xludf.DUMMYFUNCTION("IFERROR(if(V26=true, SUM(FILTER(Timesheet!$F:$F,Timesheet!G:G = TRUE,Timesheet!B:B = A26,Timesheet!E:E < DATE(2021,1,1))),0),0)"),0.0) -> 0 | T26: =S26/$T$4 -> 0 | U26: =IF(T26<80%,"Parcial","Exclusivo") -> Parcial | V26: FALSE
A29: Cálculo do custo/hora
A31: Encargos sobre folha | H31: INSS | I31: Patronal | J31: 0.2
A32: INSS | B32: FGTS | C32: Férias | D32: 13º | E32: Total | I32: Terceiros | J32: 0.058 | T32: =IFERROR(__xludf.DUMMYFUNCTION("sum(FILTER(T37:T56,match(A37:A56,FILTER(A6:A25,U6:U25 = ""Parcial""))))"),300723.96873926383) -> 300723.97
A33: =sum(J31:J33) -> 0.273 | B33: 0.08 | C33: =((1+(1/3))+A33+B33)/12 -> 0.14052778 | D33: =(1+A33+B33)/12 -> 0.11275 | E33: =sum(A33:D33) -> 0.60627778 | I33: RAT | J33: 0.015 | T33: =IFERROR(__xludf.DUMMYFUNCTION("IFERROR(sum(FILTER(T37:T56,match(A37:A56,FILTER(A6:A25,U6:U25 = ""Exclusivo"")))),0)"),0.0) -> 0
G35: =NETWORKDAYS(DATE(2020,(LEFT(G$36,2)+0),1),DATE(2020,(LEFT(G$36,2)+0)+1,0),$A$62:$A$74) -> 21 | H35: =NETWORKDAYS(DATE(2020,(LEFT(H$36,2)+0),1),DATE(2020,(LEFT(H$36,2)+0)+1,0),$A$62:$A$74) -> 22 | I35: =NETWORKDAYS(DATE(2020,(LEFT(I$36,2)+0),1),DATE(2020,(LEFT(I$36,2)+0)+1,0),$A$62:$A$74) -> 21 | J35: =NETWORKDAYS(DATE(2020,(LEFT(J$36,2)+0),1),DATE(2020,(LEFT(J$36,2)+0)+1,0),$A$62:$A$74) -> 22 | K35: =NETWORKDAYS(DATE(2020,(LEFT(K$36,2)+0),1),DATE(2020,(LEFT(K$36,2)+0)+1,0),$A$62:$A$74) -> 21 | L35: =NETWORKDAYS(DATE(2020,(LEFT(L$36,2)+0),1),DATE(2020,(LEFT(L$36,2)+0)+1,0),$A$62:$A$74) -> 22 | M35: =NETWORKDAYS(DATE(2020,(LEFT(M$36,2)+0),1),DATE(2020,(LEFT(M$36,2)+0)+1,0),$A$62:$A$74) -> 21 | N35: =NETWORKDAYS(DATE(2020,(LEFT(N$36,2)+0),1),DATE(2020,(LEFT(N$36,2)+0)+1,0),$A$62:$A$74) -> 21 | ... R35: =NETWORKDAYS(DATE(2020,(LEFT(R$36,2)+0),1),DATE(2020,(LEFT(R$36,2)+0)+1,0),$A$62:$A$74) -> 21 | S35: =sum(S37:S56) -> 312686.56 | T35: =sum(T37:T56) -> 300723.97 | U35: =T35-S35 -> -11962.592
A36: Nome Completo | D36: {=U5:U26} -> Classificação | E36: {=E5:E26} -> Formação | F36: Custo / Hora | G36: 43861 | H36: 43890 | I36: 43921 | J36: 43951 | K36: 43982 | L36: 44012 | M36: 44043 | N36: 44074 | O36: 44104 | P36: 44135 | Q36: 44165 | R36: 44196 | S36: PD&I R$ | T36: Aprovado R$ | U36: Pesquisador
A37: {=unique(A6:A26)} -> Ademir Mararangoni | D37: Parcial | E37: Superior Completo | G37: =vlookup($A37,$A$6:$R$26,month(G$36)+6)*(1+$E$33)/(G$35*8.8) -> 63.065873 | H37: =vlookup($A37,$A$6:$R$26,month(H$36)+6)*(1+$E$33)/(H$35*8.8) -> 60.199242 | I37: =vlookup($A37,$A$6:$R$26,month(I$36)+6)*(1+$E$33)/(I$35*8.8) -> 63.065873 | J37: =vlookup($A37,$A$6:$R$26,month(J$36)+6)*(1+$E$33)/(J$35*8.8) -> 60.199242 | K37: =vlookup($A37,$A$6:$R$26,month(K$36)+6)*(1+$E$33)/(K$35*8.8) -> 63.065873 | L37: =vlookup($A37,$A$6:$R$26,month(L$36)+6)*(1+$E$33)/(L$35*8.8) -> 60.199242 | M37: =vlookup($A37,$A$6:$R$26,month(M$36)+6)*(1+$E$33)/(M$35*8.8) -> 63.065873 | N37: =vlookup($A37,$A$6:$R$26,month(N$36)+6)*(1+$E$33)/(N$35*8.8) -> 63.065873 | ... R37: =vlookup($A37,$A$6:$R$26,month(R$36)+6)*(1+$E$33)/(R$35*8.8) -> 67.305125 | S37: =SUMIF(Timesheet!B:B,A37,Timesheet!J:J) -> 4540.3755 | T37: =SUMIF(U37,TRUE,S37) -> 0 | U37: FALSE
A38: Ana Claudia Zanini | D38: Parcial | E38: Mestrado | G38: =vlookup($A38,$A$6:$R$26,month(G$36)+6)*(1+$E$33)/(G$35*8.8) -> 0 | H38: =vlookup($A38,$A$6:$R$26,month(H$36)+6)*(1+$E$33)/(H$35*8.8) -> 0 | I38: =vlookup($A38,$A$6:$R$26,month(I$36)+6)*(1+$E$33)/(I$35*8.8) -> 29.312396 | J38: =vlookup($A38,$A$6:$R$26,month(J$36)+6)*(1+$E$33)/(J$35*8.8) -> 27.980015 | K38: =vlookup($A38,$A$6:$R$26,month(K$36)+6)*(1+$E$33)/(K$35*8.8) -> 29.312396 | L38: =vlookup($A38,$A$6:$R$26,month(L$36)+6)*(1+$E$33)/(L$35*8.8) -> 27.980015 | M38: =vlookup($A38,$A$6:$R$26,month(M$36)+6)*(1+$E$33)/(M$35*8.8) -> 29.312396 | N38: =vlookup($A38,$A$6:$R$26,month(N$36)+6)*(1+$E$33)/(N$35*8.8) -> 29.312396 | ... R38: =vlookup($A38,$A$6:$R$26,month(R$36)+6)*(1+$E$33)/(R$35*8.8) -> 31.282781 | S38: =SUMIF(Timesheet!B:B,A38,Timesheet!J:J) -> 26660.389 | T38: =SUMIF(U38,TRUE,S38) -> 26660.389 | U38: TRUE
A39: Ana Paula Celes | D39: Parcial | E39: Pós graduado | G39: =G8*(((1/3)*1/12)+1)/(G35*(44/5)) -> 169.03747 | H39: =H8*(((1/3)*1/12)+1)/(H35*(44/5)) -> 161.35394 | I39: =I8*(((1/3)*1/12)+1)/(I35*(44/5)) -> 169.03747 | J39: =J8*(((1/3)*1/12)+1)/(J35*(44/5)) -> 161.35394 | K39: =K8*(((1/3)*1/12)+1)/(K35*(44/5)) -> 169.03747 | L39: =L8*(((1/3)*1/12)+1)/(L35*(44/5)) -> 161.35394 | M39: =M8*(((1/3)*1/12)+1)/(M35*(44/5)) -> 169.03747 | N39: =N8*(((1/3)*1/12)+1)/(N35*(44/5)) -> 169.03747 | ... R39: =R8*(((1/3)*1/12)+1)/(R35*(44/5)) -> 169.03747 | S39: =SUMIF(Timesheet!B:B,A39,Timesheet!J:J) -> 21958.223 | T39: =SUMIF(U39,TRUE,S39) -> 21958.223 | U39: TRUE
A40: Arianna Schreiber | D40: Parcial | E40: Pós graduado | G40: =vlookup($A40,$A$6:$R$26,month(G$36)+6)*(1+$E$33)/(G$35*8.8) -> 68.401879 | H40: =vlookup($A40,$A$6:$R$26,month(H$36)+6)*(1+$E$33)/(H$35*8.8) -> 65.292703 | I40: =vlookup($A40,$A$6:$R$26,month(I$36)+6)*(1+$E$33)/(I$35*8.8) -> 68.401879 | J40: =vlookup($A40,$A$6:$R$26,month(J$36)+6)*(1+$E$33)/(J$35*8.8) -> 65.292703 | K40: =vlookup($A40,$A$6:$R$26,month(K$36)+6)*(1+$E$33)/(K$35*8.8) -> 68.401879 | L40: =vlookup($A40,$A$6:$R$26,month(L$36)+6)*(1+$E$33)/(L$35*8.8) -> 65.292703 | M40: =vlookup($A40,$A$6:$R$26,month(M$36)+6)*(1+$E$33)/(M$35*8.8) -> 68.401879 | N40: =vlookup($A40,$A$6:$R$26,month(N$36)+6)*(1+$E$33)/(N$35*8.8) -> 68.401879 | ... R40: =vlookup($A40,$A$6:$R$26,month(R$36)+6)*(1+$E$33)/(R$35*8.8) -> 77.171304 | S40: =SUMIF(Timesheet!B:B,A40,Timesheet!J:J) -> 2106.8997 | T40: =SUMIF(U40,TRUE,S40) -> 2106.8997 | U40: TRUE
A41: Camila Mendes Pereira | D41: Parcial | E41: Superior Completo | G41: =vlookup($A41,$A$6:$R$26,month(G$36)+6)*(1+$E$33)/(G$35*8.8) -> 21.669365 | H41: =vlookup($A41,$A$6:$R$26,month(H$36)+6)*(1+$E$33)/(H$35*8.8) -> 20.684394 | I41: =vlookup($A41,$A$6:$R$26,month(I$36)+6)*(1+$E$33)/(I$35*8.8) -> 21.669365 | J41: =vlookup($A41,$A$6:$R$26,month(J$36)+6)*(1+$E$33)/(J$35*8.8) -> 20.684394 | K41: =vlookup($A41,$A$6:$R$26,month(K$36)+6)*(1+$E$33)/(K$35*8.8) -> 21.669365 | L41: =vlookup($A41,$A$6:$R$26,month(L$36)+6)*(1+$E$33)/(L$35*8.8) -> 20.684394 | M41: =vlookup($A41,$A$6:$R$26,month(M$36)+6)*(1+$E$33)/(M$35*8.8) -> 21.669365 | N41: =vlookup($A41,$A$6:$R$26,month(N$36)+6)*(1+$E$33)/(N$35*8.8) -> 21.669365 | ... R41: =vlookup($A41,$A$6:$R$26,month(R$36)+6)*(1+$E$33)/(R$35*8.8) -> 24.482611 | S41: =SUMIF(Timesheet!B:B,A41,Timesheet!J:J) -> 16066.77 | T41: =SUMIF(U41,TRUE,S41) -> 16066.77 | U41: TRUE
A42: Denise Barros Ferreira | D42: Parcial | E42: Superior Completo | G42: =vlookup($A42,$A$6:$R$26,month(G$36)+6)*(1+$E$33)/(G$35*8.8) -> 43.554987 | H42: =vlookup($A42,$A$6:$R$26,month(H$36)+6)*(1+$E$33)/(H$35*8.8) -> 41.575215 | I42: =vlookup($A42,$A$6:$R$26,month(I$36)+6)*(1+$E$33)/(I$35*8.8) -> 43.554987 | J42: =vlookup($A42,$A$6:$R$26,month(J$36)+6)*(1+$E$33)/(J$35*8.8) -> 41.575215 | K42: =vlookup($A42,$A$6:$R$26,month(K$36)+6)*(1+$E$33)/(K$35*8.8) -> 43.554987 | L42: =vlookup($A42,$A$6:$R$26,month(L$36)+6)*(1+$E$33)/(L$35*8.8) -> 41.575215 | M42: =vlookup($A42,$A$6:$R$26,month(M$36)+6)*(1+$E$33)/(M$35*8.8) -> 43.554987 | N42: =vlookup($A42,$A$6:$R$26,month(N$36)+6)*(1+$E$33)/(N$35*8.8) -> 43.554987 | ... R42: =vlookup($A42,$A$6:$R$26,month(R$36)+6)*(1+$E$33)/(R$35*8.8) -> 44.269294 | S42: =SUMIF(Timesheet!B:B,A42,Timesheet!J:J) -> 1032.825 | T42: =SUMIF(U42,TRUE,S42) -> 0 | U42: FALSE
A43: Emanuela Adam Bechlin Picheki | D43: Parcial | E43: Pós graduado | G43: =vlookup($A43,$A$6:$R$26,month(G$36)+6)*(1+$E$33)/(G$35*8.8) -> 54.026997 | H43: =vlookup($A43,$A$6:$R$26,month(H$36)+6)*(1+$E$33)/(H$35*8.8) -> 51.571224 | I43: =vlookup($A43,$A$6:$R$26,month(I$36)+6)*(1+$E$33)/(I$35*8.8) -> 54.026997 | J43: =vlookup($A43,$A$6:$R$26,month(J$36)+6)*(1+$E$33)/(J$35*8.8) -> 51.571224 | K43: =vlookup($A43,$A$6:$R$26,month(K$36)+6)*(1+$E$33)/(K$35*8.8) -> 54.026997 | L43: =vlookup($A43,$A$6:$R$26,month(L$36)+6)*(1+$E$33)/(L$35*8.8) -> 51.571224 | M43: =vlookup($A43,$A$6:$R$26,month(M$36)+6)*(1+$E$33)/(M$35*8.8) -> 54.026997 | N43: =vlookup($A43,$A$6:$R$26,month(N$36)+6)*(1+$E$33)/(N$35*8.8) -> 54.026997 | ... R43: =vlookup($A43,$A$6:$R$26,month(R$36)+6)*(1+$E$33)/(R$35*8.8) -> 60.404302 | S43: =SUMIF(Timesheet!B:B,A43,Timesheet!J:J) -> 4335.8203 | T43: =SUMIF(U43,TRUE,S43) -> 4335.8203 | U43: TRUE
A44: Fabiano Ribeiro da Silva | D44: Parcial | E44: Pós graduado | G44: =vlookup($A44,$A$6:$R$26,month(G$36)+6)*(1+$E$33)/(G$35*8.8) -> 48.387119 | H44: =vlookup($A44,$A$6:$R$26,month(H$36)+6)*(1+$E$33)/(H$35*8.8) -> 46.187704 | I44: =vlookup($A44,$A$6:$R$26,month(I$36)+6)*(1+$E$33)/(I$35*8.8) -> 48.387119 | J44: =vlookup($A44,$A$6:$R$26,month(J$36)+6)*(1+$E$33)/(J$35*8.8) -> 46.187704 | K44: =vlookup($A44,$A$6:$R$26,month(K$36)+6)*(1+$E$33)/(K$35*8.8) -> 48.387119 | L44: =vlookup($A44,$A$6:$R$26,month(L$36)+6)*(1+$E$33)/(L$35*8.8) -> 46.187704 | M44: =vlookup($A44,$A$6:$R$26,month(M$36)+6)*(1+$E$33)/(M$35*8.8) -> 48.387119 | N44: =vlookup($A44,$A$6:$R$26,month(N$36)+6)*(1+$E$33)/(N$35*8.8) -> 48.387119 | ... R44: =vlookup($A44,$A$6:$R$26,month(R$36)+6)*(1+$E$33)/(R$35*8.8) -> 53.115121 | S44: =SUMIF(Timesheet!B:B,A44,Timesheet!J:J) -> 2223.1351 | T44: =SUMIF(U44,TRUE,S44) -> 0 | U44: FALSE
A45: Flavia Firmano Coelho | D45: Parcial | E45: Pós graduado | G45: =vlookup($A45,$A$6:$R$26,month(G$36)+6)*(1+$E$33)/(G$35*8.8) -> 40.424397 | H45: =vlookup($A45,$A$6:$R$26,month(H$36)+6)*(1+$E$33)/(H$35*8.8) -> 39.538162 | I45: =vlookup($A45,$A$6:$R$26,month(I$36)+6)*(1+$E$33)/(I$35*8.8) -> 41.420932 | J45: =vlookup($A45,$A$6:$R$26,month(J$36)+6)*(1+$E$33)/(J$35*8.8) -> 39.538162 | K45: =vlookup($A45,$A$6:$R$26,month(K$36)+6)*(1+$E$33)/(K$35*8.8) -> 41.420932 | L45: =vlookup($A45,$A$6:$R$26,month(L$36)+6)*(1+$E$33)/(L$35*8.8) -> 39.538162 | M45: =vlookup($A45,$A$6:$R$26,month(M$36)+6)*(1+$E$33)/(M$35*8.8) -> 41.420932 | N45: =vlookup($A45,$A$6:$R$26,month(N$36)+6)*(1+$E$33)/(N$35*8.8) -> 41.420932 | ... R45: =vlookup($A45,$A$6:$R$26,month(R$36)+6)*(1+$E$33)/(R$35*8.8) -> 0 | S45: =SUMIF(Timesheet!B:B,A45,Timesheet!J:J) -> 0 | T45: =SUMIF(U45,TRUE,S45) -> 0 | U45: FALSE
