Workbook

Sheet RESUMO
A2: Resumo dos investimentos
A3: BENEFÍCIO FISCAL DE PD&I 2021
G4: 2019-088 PRODIET
A5: PRODIET NUTRIÇÃO CLINICA LTDA | E5: CNPJ 08.183.359/0001-53 | G5: =TODAY() -> 46168
A6: Rua General Potiguara, 1428, Lotes 20 e 21, Novo Mundo - PR - SUL - CURITIBA - CEP 81.050-500 - fone: (41) 3342-2825
A8: Natureza | B8: Totalizadores | C8: ( i ) Origem dos dados
A9: Material | B9: =D54 -> 0 | C9: (a1) Material consumido - planilha Investimentos
A10: Terceiros | B10: =E54 -> 503579.72 | C10: (a2) Serviços contratados - planilha Investimentos
A11: RH (Parcial inovação) | B11: =Pessoal!T24 -> 356413.4 | C11: (b) Dispêndio com funcionários de dedicação parcial - planilha Timesheet
A12: RH (Exclusivo inovação) | B12: =Pessoal!T25 -> 0 | C12: (c) Custo total dos funcionários com dedicação exclusiva - planilha Salários
A13: Total 1 | B13: =sum(B9:B12) -> 859993.12
A14: Percentual Exclusão | B14: 0.6 | D14: 60% | E14: +10% | F14: +20% | G14: +20%
A15: Exclusão da Base de cálculo do IRPJ e CSLL | B15: =B13*B14 -> 515995.87 | D15: Benefício padrão | E15: Incremento <5% de pesquisadores exclusivos | F15: Incremento >5% de pesquisadores exclusivos | G15: Dispendios com registro de patente
A17: Patente (Gastos "InstanTH Neo") | B17: =IFERROR(__xludf.DUMMYFUNCTION("importrange(""1yvA7oQIjfgmieoV6G0WRoHhQ2zeDLsO5Kom90H_sfJU"",""Resumo geral!J16"")"),333294.53749999974) -> 333294.54
A18: Percentual Exclusão | B18: 0.2
A19: Exclusão da Base de cálculo do IRPJ e CSLL | B19: =B17*B18 -> 66658.908
A21: Total exclusão | B21: =sum(B15,B19) -> 582654.78
A23: Economia Estimada [34%] | B23: =B21*34% -> 198102.63
A24: Comissão McBenner | B24: =B23*0.1 -> 19810.263
A26: Observações:
A27: 1. Os dispêndios devem ser registrados na contabilidade em conta específica
A28: 2. O benefício deve ser aproveitado na ECF do respectivo ano/competência
A29: 3. O formulário do MCTIC (governo) deve ser enviado até fim de setembro/2021
A30: 4. Os projetos estão descritos em arquivo a parte a ser anexado no FORM PD&I
A31: 5. Alguns benefícios previstos na Lei do Bem não foram utilizados:
A32: --- 5.1. Depreciação acelerada
A33: --- 5.2. Redução de IPI na aquisição de equipamento para PD&I
A36: Equipe de PD&I
A37: Quadro de resumo | B37: Dedicação Parcial | E37: Dedicação Exclusiva
B38: Qtd | C38: Valor gasto | D38: Horas | E38: Qtd | F38: Valor gasto | G38: Horas
A39: Técnico | B39: =IFERROR(__xludf.DUMMYFUNCTION("COUNTA(IFERROR(FILTER(Pessoal!$E$6:$E$18,Pessoal!$E$6:$E$18 = $A39,Pessoal!$U$6:$U$18 = ""Parcial"",Pessoal!$U$29:$U$41 = TRUE),))"),0.0) -> 0 | C39: =IFERROR(__xludf.DUMMYFUNCTION("SUM(IFERROR(FILTER(Pessoal!$T$29:$T$41,Pessoal!$E$29:$E$41 = $A39,Pessoal!$D$29:$D$41 = ""Parcial""),0))"),0.0) -> 0 | D39: =IFERROR(__xludf.DUMMYFUNCTION("SUM(IFERROR(FILTER(Pessoal!$S$6:$S$18,Pessoal!$E$6:$E$18 = $A39,Pessoal!$U$6:$U$18 = ""Parcial""),0))*24"),0.0) -> 0 | E39: =IFERROR(__xludf.DUMMYFUNCTION("COUNTA(IFERROR(FILTER(Pessoal!$E$6:$E$18,Pessoal!$E$6:$E$18 = $A39,Pessoal!$U$6:$U$18 = ""Exclusivo"",Pessoal!$U$29:$U$40 = TRUE),))"),0.0) -> 0 | F39: =IFERROR(__xludf.DUMMYFUNCTION("SUM(IFERROR(FILTER(Pessoal!$T$29:$T$40,Pessoal!$E$29:$E$40 = $A39,Pessoal!$D$29:$D$40 = ""Exclusivo""),0))"),0.0) -> 0 | G39: =IFERROR(__xludf.DUMMYFUNCTION("SUM(IFERROR(FILTER(Pessoal!$S$6:$S$18,Pessoal!$E$6:$E$18 = $A39,Pessoal!$U$6:$U$18 = ""Exclusivo""),0))*24"),0.0) -> 0
A40: Tecnologo | B40: =IFERROR(__xludf.DUMMYFUNCTION("COUNTA(IFERROR(FILTER(Pessoal!$E$6:$E$18,Pessoal!$E$6:$E$18 = $A40,Pessoal!$U$6:$U$18 = ""Parcial"",Pessoal!$U$29:$U$41 = TRUE),))"),0.0) -> 0 | C40: =IFERROR(__xludf.DUMMYFUNCTION("SUM(IFERROR(FILTER(Pessoal!$T$29:$T$41,Pessoal!$E$29:$E$41 = $A40,Pessoal!$D$29:$D$41 = ""Parcial""),0))"),0.0) -> 0 | D40: =IFERROR(__xludf.DUMMYFUNCTION("SUM(IFERROR(FILTER(Pessoal!$S$6:$S$18,Pessoal!$E$6:$E$18 = $A40,Pessoal!$U$6:$U$18 = ""Parcial""),0))*24"),0.0) -> 0 | E40: =IFERROR(__xludf.DUMMYFUNCTION("COUNTA(IFERROR(FILTER(Pessoal!$E$6:$E$18,Pessoal!$E$6:$E$18 = $A40,Pessoal!$U$6:$U$18 = ""Exclusivo"",Pessoal!$U$29:$U$40 = TRUE),))"),0.0) -> 0 | F40: =IFERROR(__xludf.DUMMYFUNCTION("SUM(IFERROR(FILTER(Pessoal!$T$29:$T$40,Pessoal!$E$29:$E$40 = $A40,Pessoal!$D$29:$D$40 = ""Exclusivo""),0))"),0.0) -> 0 | G40: =IFERROR(__xludf.DUMMYFUNCTION("SUM(IFERROR(FILTER(Pessoal!$S$6:$S$18,Pessoal!$E$6:$E$18 = $A40,Pessoal!$U$6:$U$18 = ""Exclusivo""),0))*24"),0.0) -> 0
A41: Superior Completo | B41: =IFERROR(__xludf.DUMMYFUNCTION("COUNTA(IFERROR(FILTER(Pessoal!$E$6:$E$18,Pessoal!$E$6:$E$18 = $A41,Pessoal!$U$6:$U$18 = ""Parcial"",Pessoal!$U$29:$U$41 = TRUE),))"),3.0) -> 3 | C41: =IFERROR(__xludf.DUMMYFUNCTION("SUM(IFERROR(FILTER(Pessoal!$T$29:$T$41,Pessoal!$E$29:$E$41 = $A41,Pessoal!$D$29:$D$41 = ""Parcial""),0))"),120218.49720611384) -> 120218.5 | D41: =IFERROR(__xludf.DUMMYFUNCTION("SUM(IFERROR(FILTER(Pessoal!$S$6:$S$18,Pessoal!$E$6:$E$18 = $A41,Pessoal!$U$6:$U$18 = ""Parcial""),0))*24"),2782.1666666666647) -> 2782.1667 | E41: =IFERROR(__xludf.DUMMYFUNCTION("COUNTA(IFERROR(FILTER(Pessoal!$E$6:$E$18,Pessoal!$E$6:$E$18 = $A41,Pessoal!$U$6:$U$18 = ""Exclusivo"",Pessoal!$U$29:$U$40 = TRUE),))"),0.0) -> 0 | F41: =IFERROR(__xludf.DUMMYFUNCTION("SUM(IFERROR(FILTER(Pessoal!$T$29:$T$40,Pessoal!$E$29:$E$40 = $A41,Pessoal!$D$29:$D$40 = ""Exclusivo""),0))"),0.0) -> 0 | G41: =IFERROR(__xludf.DUMMYFUNCTION("SUM(IFERROR(FILTER(Pessoal!$S$6:$S$18,Pessoal!$E$6:$E$18 = $A41,Pessoal!$U$6:$U$18 = ""Exclusivo""),0))*24"),0.0) -> 0
A42: Pós graduado | B42: =IFERROR(__xludf.DUMMYFUNCTION("COUNTA(IFERROR(FILTER(Pessoal!$E$6:$E$18,Pessoal!$E$6:$E$18 = $A42,Pessoal!$U$6:$U$18 = ""Parcial"",Pessoal!$U$29:$U$41 = TRUE),))"),8.0) -> 8 | C42: =IFERROR(__xludf.DUMMYFUNCTION("SUM(IFERROR(FILTER(Pessoal!$T$29:$T$41,Pessoal!$E$29:$E$41 = $A42,Pessoal!$D$29:$D$41 = ""Parcial""),0))"),197945.15917924847) -> 197945.16 | D42: =IFERROR(__xludf.DUMMYFUNCTION("SUM(IFERROR(FILTER(Pessoal!$S$6:$S$18,Pessoal!$E$6:$E$18 = $A42,Pessoal!$U$6:$U$18 = ""Parcial""),0))*24"),3332.116666666666) -> 3332.1167 | E42: =IFERROR(__xludf.DUMMYFUNCTION("COUNTA(IFERROR(FILTER(Pessoal!$E$6:$E$18,Pessoal!$E$6:$E$18 = $A42,Pessoal!$U$6:$U$18 = ""Exclusivo"",Pessoal!$U$29:$U$40 = TRUE),))"),0.0) -> 0 | F42: =IFERROR(__xludf.DUMMYFUNCTION("SUM(IFERROR(FILTER(Pessoal!$T$29:$T$40,Pessoal!$E$29:$E$40 = $A42,Pessoal!$D$29:$D$40 = ""Exclusivo""),0))"),0.0) -> 0 | G42: =IFERROR(__xludf.DUMMYFUNCTION("SUM(IFERROR(FILTER(Pessoal!$S$6:$S$18,Pessoal!$E$6:$E$18 = $A42,Pessoal!$U$6:$U$18 = ""Exclusivo""),0))*24"),0.0) -> 0
A43: Mestrado | B43: =IFERROR(__xludf.DUMMYFUNCTION("COUNTA(IFERROR(FILTER(Pessoal!$E$6:$E$18,Pessoal!$E$6:$E$18 = $A43,Pessoal!$U$6:$U$18 = ""Parcial"",Pessoal!$U$29:$U$41 = TRUE),))"),2.0) -> 2 | C43: =IFERROR(__xludf.DUMMYFUNCTION("SUM(IFERROR(FILTER(Pessoal!$T$29:$T$41,Pessoal!$E$29:$E$41 = $A43,Pessoal!$D$29:$D$41 = ""Parcial""),0))"),38249.74538828467) -> 38249.745 | D43: =IFERROR(__xludf.DUMMYFUNCTION("SUM(IFERROR(FILTER(Pessoal!$S$6:$S$18,Pessoal!$E$6:$E$18 = $A43,Pessoal!$U$6:$U$18 = ""Parcial""),0))*24"),1153.499999999999) -> 1153.5 | E43: =IFERROR(__xludf.DUMMYFUNCTION("COUNTA(IFERROR(FILTER(Pessoal!$E$6:$E$18,Pessoal!$E$6:$E$18 = $A43,Pessoal!$U$6:$U$18 = ""Exclusivo"",Pessoal!$U$29:$U$40 = TRUE),))"),0.0) -> 0 | F43: =IFERROR(__xludf.DUMMYFUNCTION("SUM(IFERROR(FILTER(Pessoal!$T$29:$T$40,Pessoal!$E$29:$E$40 = $A43,Pessoal!$D$29:$D$40 = ""Exclusivo""),0))"),0.0) -> 0 | G43: =IFERROR(__xludf.DUMMYFUNCTION("SUM(IFERROR(FILTER(Pessoal!$S$6:$S$18,Pessoal!$E$6:$E$18 = $A43,Pessoal!$U$6:$U$18 = ""Exclusivo""),0))*24"),0.0) -> 0
A44: Doutorado | B44: =IFERROR(__xludf.DUMMYFUNCTION("COUNTA(IFERROR(FILTER(Pessoal!$E$6:$E$18,Pessoal!$E$6:$E$18 = $A44,Pessoal!$U$6:$U$18 = ""Parcial"",Pessoal!$U$29:$U$41 = TRUE),))"),0.0) -> 0 | C44: =IFERROR(__xludf.DUMMYFUNCTION("SUM(IFERROR(FILTER(Pessoal!$T$29:$T$41,Pessoal!$E$29:$E$41 = $A44,Pessoal!$D$29:$D$41 = ""Parcial""),0))"),0.0) -> 0 | D44: =IFERROR(__xludf.DUMMYFUNCTION("SUM(IFERROR(FILTER(Pessoal!$S$6:$S$18,Pessoal!$E$6:$E$18 = $A44,Pessoal!$U$6:$U$18 = ""Parcial""),0))*24"),0.0) -> 0 | E44: =IFERROR(__xludf.DUMMYFUNCTION("COUNTA(IFERROR(FILTER(Pessoal!$E$6:$E$18,Pessoal!$E$6:$E$18 = $A44,Pessoal!$U$6:$U$18 = ""Exclusivo"",Pessoal!$U$29:$U$40 = TRUE),))"),0.0) -> 0 | F44: =IFERROR(__xludf.DUMMYFUNCTION("SUM(IFERROR(FILTER(Pessoal!$T$29:$T$40,Pessoal!$E$29:$E$40 = $A44,Pessoal!$D$29:$D$40 = ""Exclusivo""),0))"),0.0) -> 0 | G44: =IFERROR(__xludf.DUMMYFUNCTION("SUM(IFERROR(FILTER(Pessoal!$S$6:$S$18,Pessoal!$E$6:$E$18 = $A44,Pessoal!$U$6:$U$18 = ""Exclusivo""),0))*24"),0.0) -> 0
B45: =SUM(B39:B44) -> 13 | C45: =SUM(C39:C44) -> 356413.4 | D45: =SUM(D39:D44) -> 7267.7833 | E45: =SUM(E39:E44) -> 0 | F45: =SUM(F39:F44) -> 0 | G45: =SUM(G39:G44) -> 0
A47: Valores por projeto de PD&I
A48: Projetos | B48: Identificação | D48: Vlr materiais | E48: Vlr terceiros | F48: Vlr Rh parcial | G48: Vlr exclusivos
A49: Novos Produtos | B49: NP | D49: =IFERROR(__xludf.DUMMYFUNCTION("iferror(SUM(FILTER(Investimentos!$M:$M,Investimentos!$L:$L = ""Material"",Investimentos!$J:$J = TRUE)),0)"),0.0) -> 0 | E49: =IFERROR(__xludf.DUMMYFUNCTION("SUM(FILTER(Investimentos!$M:$M,Investimentos!$L:$L = ""Serviço"",Investimentos!$J:$J = TRUE,Investimentos!$U:$U = TRUE))"),239212.73000000004) -> 239212.73 | F49: =$B$11*(E49/$E$54) -> 169305.12 | G49: =$B$12*(E49/$E$54) -> 0
...

Sheet Projetos
A2: Projetos
A3: BENEFÍCIO FISCAL DE PD&I 2021
A5: Projeto | B5: Agrupamento | C5: Categoria do projeto | D5: Elemento tecnologicamente novo ou inovador | E5: Barreira ou desafio tecnológico a superar | F5: Metodologia empregada | G5: Data início | H5: Data de término (estimada) | I5: Descrição | J5: Attachments | K5: Timesheet | L5: Lei do Bem
A6: {=SORT(UNIQUE({Timesheet!C7:C56;PrjAdd!A2:A10}),1,true)} -> Bemmax sabor neutro | L6: TRUE
A7: CarboCH | L7: TRUE
A8: Centro de Inovação / Novos laboratórios | L8: FALSE
A9: Cicatrização | L9: TRUE
A10: Congresso ESPEN | L10: TRUE
A11: Congresso Ganepão | L11: TRUE
A12: Diamax IG | L12: TRUE
A13: Diamax pó | K13: Novo | L13: TRUE
A14: Dieta artesanal | L14: TRUE
A15: EE - 2020 | L15: TRUE
A16: Energyzip 1.0 | L16: TRUE
A17: Energyzip baunilha | K17: Novo | L17: TRUE
A18: Energyzip Chocolate | L18: TRUE
A19: Energyzip Fiber | L19: TRUE
A20: Energyzip morango | L20: TRUE
A21: Energyzip pó | L21: TRUE
A22: EnergyZIP Protein | K22: Novo | L22: TRUE
A23: Energyzip Sênior | L23: TRUE
A24: Estabilidade misturas secas | L24: TRUE
A25: HDmax - pesquisa | K25: Novo | L25: TRUE
A26: HDmax 1.5 | L26: TRUE
A27: HDmax 2.0 | L27: TRUE
A28: Immax - etapa final da Pesquisa Clínica | L28: TRUE
A29: Inovação industrial - misturas secas | L29: TRUE
A30: InstanTH CLEAR (espessante) | L30: TRUE
A31: InstanTH Neo | L31: TRUE
A32: Jumbo UHT | K32: Novo | L32: TRUE
A33: Licenciamento | K33: Novo | L33: FALSE
A34: Linha Soya pó | K34: Novo | L34: FALSE
A35: Marca própria - Enterfiber Prebiotic | K35: Novo | L35: FALSE
A36: Novos produtos Turquia | L36: TRUE
A37: Pasta de Amendoim - RUTF | K37: Novo | L37: TRUE
A38: Peptimax - pesquisa | K38: Novo | L38: TRUE
A39: ProteinPT | L39: TRUE
A40: Retort (Sistema Fechado) | L40: TRUE
A41: Sachê | L41: TRUE
A42: Sarcopenia | L42: TRUE
...

Sheet Timesheet
A2: Timesheet
A3: BENEFÍCIO FISCAL DE PD&I 2021 | M3: Parcial | N3: =N5-N4 -> 356413.4
M4: Exclusivo | N4: =IFERROR(__xludf.DUMMYFUNCTION("SUMIF($B$7:$B4641,FILTER(Pessoal!$A$9:$A$18,Pessoal!$U$9:$U$18 = ""Exclusivo"",MATCH(Pessoal!$A$9:$A$18,FILTER(Pessoal!$A$29:$A$40,Pessoal!$U$29:$U$40 = TRUE),0)),$N$7:$N4641)"),0.0) -> 0
M5: TOTAL | N5: =SUM(N7:N4641) -> 356413.4
A6: Cod | B6: Pessoa | C6: Projeto | E6: Descrição | F6: Start | G6: End | H6: Tempo aplicado | I6: Data | J6: Atividade incentivada | L6: Attachments | M6: Valor (R$) | N6: Custo | O6: checkprojetos
B7: Ana Claudia Zanini | C7: Trophic Soya 1.5 Fiber | D7: =vlookup(C7,'Classificação p pessoal'!F:G,2,false) -> NP | E7: Pesquisa basica para Produção de material cientifico | F7: 0.5625 | G7: 0.75 | H7: 0.1875 | I7: 44200 | J7: TRUE | L7: =IF(VLOOKUP(C7,Projetos!A:L,12,false)=TRUE,TRUE,FALSE) -> TRUE | M7: {=VLOOKUP(B7:B4641,Pessoal!$A$28:$R$40,MONTH(F7:F4641)+6,false)} -> 33.159727 | N7: =IFERROR(IF(AND(J7=TRUE,O7=TRUE,YEAR(F7)<2021),H7,"")*(M7*24),0) -> 149.21877 | O7: {=VLOOKUP(C7:C4641,Projetos!A6:L4641,12,false)} -> TRUE
B8: Ana Claudia Zanini | C8: Trophic Soya 1.5 Fiber | D8: =vlookup(C8,'Classificação p pessoal'!F:G,2,false) -> NP | E8: Pesquisa basica para Produção de material cientifico | F8: 0.34375 | G8: 0.51041667 | H8: 0.16666667 | I8: 44201 | J8: TRUE | L8: =IF(VLOOKUP(C8,Projetos!A:L,12,false)=TRUE,TRUE,FALSE) -> TRUE | M8: 33.159727 | N8: =IFERROR(IF(AND(J8=TRUE,O8=TRUE,YEAR(F8)<2021),H8,"")*(M8*24),0) -> 132.63891 | O8: TRUE
B9: Ana Claudia Zanini | C9: Suplemento hiperproteico líquido | D9: =vlookup(C9,'Classificação p pessoal'!F:G,2,false) -> NP | E9: Pesquisa e desenvolvimento de nova fórmula | F9: 0.5625 | G9: 0.75 | H9: 0.1875 | I9: 44201 | J9: TRUE | L9: =IF(VLOOKUP(C9,Projetos!A:L,12,false)=TRUE,TRUE,FALSE) -> TRUE | M9: 33.159727 | N9: =IFERROR(IF(AND(J9=TRUE,O9=TRUE,YEAR(F9)<2021),H9,"")*(M9*24),0) -> 149.21877 | O9: TRUE
B10: Ana Claudia Zanini | C10: Trophic Soya 1.5 Fiber | D10: =vlookup(C10,'Classificação p pessoal'!F:G,2,false) -> NP | E10: Pesquisa basica para Produção de material cientifico | F10: 0.35416667 | G10: 0.5625 | H10: 0.20833333 | I10: 44202 | J10: TRUE | L10: =IF(VLOOKUP(C10,Projetos!A:L,12,false)=TRUE,TRUE,FALSE) -> TRUE | M10: 33.159727 | N10: =IFERROR(IF(AND(J10=TRUE,O10=TRUE,YEAR(F10)<2021),H10,"")*(M10*24),0) -> 165.79864 | O10: TRUE
B11: Ana Claudia Zanini | C11: Suplemento hiperproteico líquido | D11: =vlookup(C11,'Classificação p pessoal'!F:G,2,false) -> NP | E11: Pesquisa e desenvolvimento de nova fórmula | F11: 0.625 | G11: 0.75 | H11: 0.125 | I11: 44202 | J11: TRUE | L11: =IF(VLOOKUP(C11,Projetos!A:L,12,false)=TRUE,TRUE,FALSE) -> TRUE | M11: 33.159727 | N11: =IFERROR(IF(AND(J11=TRUE,O11=TRUE,YEAR(F11)<2021),H11,"")*(M11*24),0) -> 99.479182 | O11: TRUE
B12: Ana Claudia Zanini | C12: Trophic Soya 1.5 Fiber | D12: =vlookup(C12,'Classificação p pessoal'!F:G,2,false) -> NP | E12: Pesquisa basica para Produção de material cientifico | F12: 0.35416667 | G12: 0.45833333 | H12: 0.10416667 | I12: 44203 | J12: TRUE | L12: =IF(VLOOKUP(C12,Projetos!A:L,12,false)=TRUE,TRUE,FALSE) -> TRUE | M12: 33.159727 | N12: =IFERROR(IF(AND(J12=TRUE,O12=TRUE,YEAR(F12)<2021),H12,"")*(M12*24),0) -> 82.899318 | O12: TRUE
B13: Ana Claudia Zanini | C13: Suplemento hiperproteico líquido | D13: =vlookup(C13,'Classificação p pessoal'!F:G,2,false) -> NP | E13: Pesquisa e desenvolvimento de nova fórmula | F13: 0.5625 | G13: 0.75 | H13: 0.1875 | I13: 44203 | J13: TRUE | L13: =IF(VLOOKUP(C13,Projetos!A:L,12,false)=TRUE,TRUE,FALSE) -> TRUE | M13: 33.159727 | N13: =IFERROR(IF(AND(J13=TRUE,O13=TRUE,YEAR(F13)<2021),H13,"")*(M13*24),0) -> 149.21877 | O13: TRUE
B14: Ana Claudia Zanini | C14: Trophic Soya 1.5 Fiber | D14: =vlookup(C14,'Classificação p pessoal'!F:G,2,false) -> NP | E14: Pesquisa basica para Produção de material cientifico | F14: 0.35416667 | G14: 0.5625 | H14: 0.20833333 | I14: 44204 | J14: TRUE | L14: =IF(VLOOKUP(C14,Projetos!A:L,12,false)=TRUE,TRUE,FALSE) -> TRUE | M14: 33.159727 | N14: =IFERROR(IF(AND(J14=TRUE,O14=TRUE,YEAR(F14)<2021),H14,"")*(M14*24),0) -> 165.79864 | O14: TRUE
B15: Ana Claudia Zanini | C15: Trophic Soya 1.5 Fiber | D15: =vlookup(C15,'Classificação p pessoal'!F:G,2,false) -> NP | E15: Pesquisa basica para Produção de material cientifico | F15: 0.35416667 | G15: 0.54166667 | H15: 0.1875 | I15: 44207 | J15: TRUE | L15: =IF(VLOOKUP(C15,Projetos!A:L,12,false)=TRUE,TRUE,FALSE) -> TRUE | M15: 33.159727 | N15: =IFERROR(IF(AND(J15=TRUE,O15=TRUE,YEAR(F15)<2021),H15,"")*(M15*24),0) -> 149.21877 | O15: TRUE
B16: Ana Claudia Zanini | C16: InstanTH Neo | E16: Desenvolvimento de comunicação da fórmula do produto | F16: 0.72916667 | G16: 0.75 | H16: 0.020833333 | I16: 44208 | J16: FALSE | K16: Não entra | L16: =IF(VLOOKUP(C16,Projetos!A:L,12,false)=TRUE,TRUE,FALSE) -> TRUE | M16: 33.159727 | N16: =IFERROR(IF(AND(J16=TRUE,O16=TRUE,YEAR(F16)<2021),H16,"")*(M16*24),0) -> 0 | O16: TRUE
B17: Ana Claudia Zanini | C17: Trophic Soya 1.5 Fiber | D17: =vlookup(C17,'Classificação p pessoal'!F:G,2,false) -> NP | E17: Pesquisa basica para Produção de material cientifico | F17: 0.5625 | G17: 0.70833333 | H17: 0.14583333 | I17: 44208 | J17: TRUE | L17: =IF(VLOOKUP(C17,Projetos!A:L,12,false)=TRUE,TRUE,FALSE) -> TRUE | M17: 33.159727 | N17: =IFERROR(IF(AND(J17=TRUE,O17=TRUE,YEAR(F17)<2021),H17,"")*(M17*24),0) -> 116.05905 | O17: TRUE
B18: Ana Claudia Zanini | C18: InstanTH Neo | E18: Desenvolvimento de comunicação da fórmula do produto | F18: 0.41666667 | G18: 0.45833333 | H18: 0.041666667 | I18: 44209 | J18: FALSE | K18: Não entra | L18: =IF(VLOOKUP(C18,Projetos!A:L,12,false)=TRUE,TRUE,FALSE) -> TRUE | M18: 33.159727 | N18: =IFERROR(IF(AND(J18=TRUE,O18=TRUE,YEAR(F18)<2021),H18,"")*(M18*24),0) -> 0 | O18: TRUE
B19: Ana Claudia Zanini | C19: Trophic Soya 1.5 Fiber | D19: =vlookup(C19,'Classificação p pessoal'!F:G,2,false) -> NP | E19: Pesquisa basica para Produção de material cientifico | F19: 0.5625 | G19: 0.75 | H19: 0.1875 | I19: 44209 | J19: TRUE | L19: =IF(VLOOKUP(C19,Projetos!A:L,12,false)=TRUE,TRUE,FALSE) -> TRUE | M19: 33.159727 | N19: =IFERROR(IF(AND(J19=TRUE,O19=TRUE,YEAR(F19)<2021),H19,"")*(M19*24),0) -> 149.21877 | O19: TRUE
B20: Ana Claudia Zanini | C20: Suplemento hiperproteico líquido | D20: =vlookup(C20,'Classificação p pessoal'!F:G,2,false) -> NP | E20: Pesquisa e desenvolvimento de nova fórmula | F20: 0.35416667 | G20: 0.52083333 | H20: 0.16666667 | I20: 44210 | J20: TRUE | L20: =IF(VLOOKUP(C20,Projetos!A:L,12,false)=TRUE,TRUE,FALSE) -> TRUE | M20: 33.159727 | N20: =IFERROR(IF(AND(J20=TRUE,O20=TRUE,YEAR(F20)<2021),H20,"")*(M20*24),0) -> 132.63891 | O20: TRUE
B21: Ana Claudia Zanini | C21: Trophic Soya 1.5 Fiber | D21: =vlookup(C21,'Classificação p pessoal'!F:G,2,false) -> NP | E21: Pesquisa basica para Produção de material cientifico | F21: 0.58333333 | G21: 0.75 | H21: 0.16666667 | I21: 44210 | J21: TRUE | L21: =IF(VLOOKUP(C21,Projetos!A:L,12,false)=TRUE,TRUE,FALSE) -> TRUE | M21: 33.159727 | N21: =IFERROR(IF(AND(J21=TRUE,O21=TRUE,YEAR(F21)<2021),H21,"")*(M21*24),0) -> 132.63891 | O21: TRUE
B22: Ana Claudia Zanini | C22: Trophic Soya 1.5 Fiber | D22: =vlookup(C22,'Classificação p pessoal'!F:G,2,false) -> NP | E22: Pesquisa basica para Produção de material cientifico | F22: 0.35416667 | G22: 0.4375 | H22: 0.083333333 | I22: 44211 | J22: TRUE | L22: =IF(VLOOKUP(C22,Projetos!A:L,12,false)=TRUE,TRUE,FALSE) -> TRUE | M22: 33.159727 | N22: =IFERROR(IF(AND(J22=TRUE,O22=TRUE,YEAR(F22)<2021),H22,"")*(M22*24),0) -> 66.319455 | O22: TRUE
B23: Ana Claudia Zanini | C23: Trophic Junior Líquido 1.0 (ARB) | D23: =vlookup(C23,'Classificação p pessoal'!F:G,2,false) -> NP | E23: Pesquisa e desenvolvimento de nova fórmula | F23: 0.54166667 | G23: 0.75 | H23: 0.20833333 | I23: 44214 | J23: TRUE | L23: =IF(VLOOKUP(C23,Projetos!A:L,12,false)=TRUE,TRUE,FALSE) -> TRUE | M23: 33.159727 | N23: =IFERROR(IF(AND(J23=TRUE,O23=TRUE,YEAR(F23)<2021),H23,"")*(M23*24),0) -> 165.79864 | O23: TRUE
B24: Ana Claudia Zanini | C24: Suplemento hiperproteico líquido | D24: =vlookup(C24,'Classificação p pessoal'!F:G,2,false) -> NP | E24: Pesquisa e desenvolvimento de nova fórmula | F24: 0.35416667 | G24: 0.5625 | H24: 0.20833333 | I24: 44215 | J24: TRUE | L24: =IF(VLOOKUP(C24,Projetos!A:L,12,false)=TRUE,TRUE,FALSE) -> TRUE | M24: 33.159727 | N24: =IFERROR(IF(AND(J24=TRUE,O24=TRUE,YEAR(F24)<2021),H24,"")*(M24*24),0) -> 165.79864 | O24: TRUE
B25: Ana Claudia Zanini | C25: Suplemento hiperproteico líquido | D25: =vlookup(C25,'Classificação p pessoal'!F:G,2,false) -> NP | E25: Pesquisa e desenvolvimento de nova fórmula | F25: 0.35416667 | G25: 0.54166667 | H25: 0.1875 | I25: 44216 | J25: TRUE | L25: =IF(VLOOKUP(C25,Projetos!A:L,12,false)=TRUE,TRUE,FALSE) -> TRUE | M25: 33.159727 | N25: =IFERROR(IF(AND(J25=TRUE,O25=TRUE,YEAR(F25)<2021),H25,"")*(M25*24),0) -> 149.21877 | O25: TRUE
B26: Ana Claudia Zanini | C26: Diamax IG | E26: Desenvolvimento de comunicação da fórmula do produto | F26: 0.5625 | G26: 0.75 | H26: 0.1875 | I26: 44217 | J26: FALSE | K26: Não entra | L26: =IF(VLOOKUP(C26,Projetos!A:L,12,false)=TRUE,TRUE,FALSE) -> TRUE | M26: 33.159727 | N26: =IFERROR(IF(AND(J26=TRUE,O26=TRUE,YEAR(F26)<2021),H26,"")*(M26*24),0) -> 0 | O26: TRUE
B27: Ana Claudia Zanini | C27: Diamax IG | E27: Desenvolvimento de comunicação da fórmula do produto | F27: 0.52083333 | G27: 0.75 | H27: 0.22916667 | I27: 44218 | J27: FALSE | K27: Não entra | L27: =IF(VLOOKUP(C27,Projetos!A:L,12,false)=TRUE,TRUE,FALSE) -> TRUE | M27: 33.159727 | N27: =IFERROR(IF(AND(J27=TRUE,O27=TRUE,YEAR(F27)<2021),H27,"")*(M27*24),0) -> 0 | O27: TRUE
B28: Ana Claudia Zanini | C28: Diamax IG | E28: Desenvolvimento de comunicação da fórmula do produto | F28: 0.34375 | G28: 0.54166667 | H28: 0.19791667 | I28: 44221 | J28: FALSE | K28: Não entra | L28: =IF(VLOOKUP(C28,Projetos!A:L,12,false)=TRUE,TRUE,FALSE) -> TRUE | M28: 33.159727 | N28: =IFERROR(IF(AND(J28=TRUE,O28=TRUE,YEAR(F28)<2021),H28,"")*(M28*24),0) -> 0 | O28: TRUE
B29: Ana Claudia Zanini | C29: Suplemento hiperproteico líquido | D29: =vlookup(C29,'Classificação p pessoal'!F:G,2,false) -> NP | E29: Pesquisa e desenvolvimento de nova fórmula | F29: 0.58333333 | G29: 0.75 | H29: 0.16666667 | I29: 44221 | J29: TRUE | L29: =IF(VLOOKUP(C29,Projetos!A:L,12,false)=TRUE,TRUE,FALSE) -> TRUE | M29: 33.159727 | N29: =IFERROR(IF(AND(J29=TRUE,O29=TRUE,YEAR(F29)<2021),H29,"")*(M29*24),0) -> 132.63891 | O29: TRUE
B30: Ana Claudia Zanini | C30: Suplemento hiperproteico líquido | D30: =vlookup(C30,'Classificação p pessoal'!F:G,2,false) -> NP | E30: Pesquisa e desenvolvimento de nova fórmula | F30: 0.34375 | G30: 0.54166667 | H30: 0.19791667 | I30: 44222 | J30: TRUE | L30: =IF(VLOOKUP(C30,Projetos!A:L,12,false)=TRUE,TRUE,FALSE) -> TRUE | M30: 33.159727 | N30: =IFERROR(IF(AND(J30=TRUE,O30=TRUE,YEAR(F30)<2021),H30,"")*(M30*24),0) -> 157.5087 | O30: TRUE
B31: Ana Claudia Zanini | C31: Diamax IG | E31: Desenvolvimento de comunicação da fórmula do produto | F31: 0.58333333 | G31: 0.75 | H31: 0.16666667 | I31: 44222 | J31: FALSE | K31: Não entra | L31: =IF(VLOOKUP(C31,Projetos!A:L,12,false)=TRUE,TRUE,FALSE) -> TRUE | M31: 33.159727 | N31: =IFERROR(IF(AND(J31=TRUE,O31=TRUE,YEAR(F31)<2021),H31,"")*(M31*24),0) -> 0 | O31: TRUE
B32: Ana Claudia Zanini | C32: Suplemento hiperproteico líquido | D32: =vlookup(C32,'Classificação p pessoal'!F:G,2,false) -> NP | E32: Pesquisa e desenvolvimento de nova fórmula | F32: 0.34375 | G32: 0.54166667 | H32: 0.19791667 | I32: 44223 | J32: TRUE | L32: =IF(VLOOKUP(C32,Projetos!A:L,12,false)=TRUE,TRUE,FALSE) -> TRUE | M32: 33.159727 | N32: =IFERROR(IF(AND(J32=TRUE,O32=TRUE,YEAR(F32)<2021),H32,"")*(M32*24),0) -> 157.5087 | O32: TRUE
B33: Ana Claudia Zanini | C33: Suplemento hiperproteico líquido | D33: =vlookup(C33,'Classificação p pessoal'!F:G,2,false) -> NP | E33: Pesquisa e desenvolvimento de nova fórmula | F33: 0.34375 | G33: 0.54166667 | H33: 0.19791667 | I33: 44224 | J33: TRUE | L33: =IF(VLOOKUP(C33,Projetos!A:L,12,false)=TRUE,TRUE,FALSE) -> TRUE | M33: 33.159727 | N33: =IFERROR(IF(AND(J33=TRUE,O33=TRUE,YEAR(F33)<2021),H33,"")*(M33*24),0) -> 157.5087 | O33: TRUE
B34: Ana Claudia Zanini | C34: Suplemento hiperproteico líquido | D34: =vlookup(C34,'Classificação p pessoal'!F:G,2,false) -> NP | E34: Pesquisa e desenvolvimento de nova fórmula | F34: 0.34375 | G34: 0.41666667 | H34: 0.072916667 | I34: 44225 | J34: TRUE | L34: =IF(VLOOKUP(C34,Projetos!A:L,12,false)=TRUE,TRUE,FALSE) -> TRUE | M34: 33.159727 | N34: =IFERROR(IF(AND(J34=TRUE,O34=TRUE,YEAR(F34)<2021),H34,"")*(M34*24),0) -> 58.029523 | O34: TRUE
B35: Ana Claudia Zanini | C35: Trophic Soya 1.5 Fiber | D35: =vlookup(C35,'Classificação p pessoal'!F:G,2,false) -> NP | E35: Pesquisa basica para Produção de material cientifico | F35: 0.5 | G35: 0.70833333 | H35: 0.20833333 | I35: 44225 | J35: TRUE | L35: =IF(VLOOKUP(C35,Projetos!A:L,12,false)=TRUE,TRUE,FALSE) -> TRUE | M35: 33.159727 | N35: =IFERROR(IF(AND(J35=TRUE,O35=TRUE,YEAR(F35)<2021),H35,"")*(M35*24),0) -> 165.79864 | O35: TRUE
B36: Ana Claudia Zanini | C36: Trophic Soya 1.5 Fiber | D36: =vlookup(C36,'Classificação p pessoal'!F:G,2,false) -> NP | E36: Pesquisa basica para Produção de material cientifico | F36: 0.35416667 | G36: 0.52083333 | H36: 0.16666667 | I36: 44228 | J36: TRUE | L36: =IF(VLOOKUP(C36,Projetos!A:L,12,false)=TRUE,TRUE,FALSE) -> TRUE | M36: 33.159727 | N36: =IFERROR(IF(AND(J36=TRUE,O36=TRUE,YEAR(F36)<2021),H36,"")*(M36*24),0) -> 132.63891 | O36: TRUE
B37: Ana Claudia Zanini | C37: Trophic Junior Líquido 1.0 (ARB) | D37: =vlookup(C37,'Classificação p pessoal'!F:G,2,false) -> NP | E37: Pesquisa e desenvolvimento de nova fórmula | F37: 0.625 | G37: 0.75 | H37: 0.125 | I37: 44228 | J37: TRUE | L37: =IF(VLOOKUP(C37,Projetos!A:L,12,false)=TRUE,TRUE,FALSE) -> TRUE | M37: 33.159727 | N37: =IFERROR(IF(AND(J37=TRUE,O37=TRUE,YEAR(F37)<2021),H37,"")*(M37*24),0) -> 99.479182 | O37: TRUE
B38: Ana Claudia Zanini | C38: Trophic Junior Líquido 1.0 (ARB) | D38: =vlookup(C38,'Classificação p pessoal'!F:G,2,false) -> NP | E38: Pesquisa e desenvolvimento de nova fórmula | F38: 0.34375 | G38: 0.55208333 | H38: 0.20833333 | I38: 44229 | J38: TRUE | L38: =IF(VLOOKUP(C38,Projetos!A:L,12,false)=TRUE,TRUE,FALSE) -> TRUE | M38: 33.159727 | N38: =IFERROR(IF(AND(J38=TRUE,O38=TRUE,YEAR(F38)<2021),H38,"")*(M38*24),0) -> 165.79864 | O38: TRUE
B39: Ana Claudia Zanini | C39: Trophic Junior Líquido 1.0 (ARB) | D39: =vlookup(C39,'Classificação p pessoal'!F:G,2,false) -> NP | E39: Pesquisa e desenvolvimento de nova fórmula | F39: 0.34375 | G39: 0.46875 | H39: 0.125 | I39: 44230 | J39: TRUE | L39: =IF(VLOOKUP(C39,Projetos!A:L,12,false)=TRUE,TRUE,FALSE) -> TRUE | M39: 33.159727 | N39: =IFERROR(IF(AND(J39=TRUE,O39=TRUE,YEAR(F39)<2021),H39,"")*(M39*24),0) -> 99.479182 | O39: TRUE
B40: Ana Claudia Zanini | C40: Trophic Soya 1.5 Fiber | D40: =vlookup(C40,'Classificação p pessoal'!F:G,2,false) -> NP | E40: Pesquisa basica para Produção de material cientifico | F40: 0.625 | G40: 0.75 | H40: 0.125 | I40: 44230 | J40: TRUE | L40: =IF(VLOOKUP(C40,Projetos!A:L,12,false)=TRUE,TRUE,FALSE) -> TRUE | M40: 33.159727 | N40: =IFERROR(IF(AND(J40=TRUE,O40=TRUE,YEAR(F40)<2021),H40,"")*(M40*24),0) -> 99.479182 | O40: TRUE
B41: Ana Claudia Zanini | C41: Trophic Soya 1.5 Fiber | D41: =vlookup(C41,'Classificação p pessoal'!F:G,2,false) -> NP | E41: Pesquisa basica para Produção de material cientifico | F41: 0.34375 | G41: 0.46875 | H41: 0.125 | I41: 44231 | J41: TRUE | L41: =IF(VLOOKUP(C41,Projetos!A:L,12,false)=TRUE,TRUE,FALSE) -> TRUE | M41: 33.159727 | N41: =IFERROR(IF(AND(J41=TRUE,O41=TRUE,YEAR(F41)<2021),H41,"")*(M41*24),0) -> 99.479182 | O41: TRUE
...

Sheet Cópia de Timesheet
A2: Timesheet | N2: =SUMPRODUCT(H16:H4641,M16:M4597) -> #VALUE!
A3: BENEFÍCIO FISCAL DE PD&I 2021 | M3: Parcial | N3: =N5-N4 -> 356413.4
M4: Exclusivo | N4: =IFERROR(__xludf.DUMMYFUNCTION("SUMIF($B$7:$B4641,FILTER(Pessoal!$A$9:$A$18,Pessoal!$U$9:$U$18 = ""Exclusivo"",MATCH(Pessoal!$A$9:$A$18,FILTER(Pessoal!$A$29:$A$40,Pessoal!$U$29:$U$40 = TRUE),0)),$N$7:$N4641)"),0.0) -> 0
M5: TOTAL | N5: =SUM(N7:N4641) -> 356413.4
A6: Cod | B6: Pessoa | C6: Projeto | E6: Descrição | F6: Start | G6: End | H6: Tempo aplicado | I6: Data | J6: Atividade incentivada | L6: Attachments | M6: Valor (R$) | N6: Custo | O6: checkprojetos
B7: Ana Claudia Zanini | C7: Trophic Soya 1.5 Fiber | D7: =vlookup(C7,'Classificação p pessoal'!F:G,2,false) -> NP | E7: Pesquisa basica para Produção de material cientifico | F7: 0.5625 | G7: 0.75 | H7: 0.1875 | I7: 44200 | J7: TRUE | L7: =IF(VLOOKUP(C7,Projetos!A:L,12,false)=TRUE,TRUE,FALSE) -> TRUE | M7: {=VLOOKUP(B7:B4641,Pessoal!$A$28:$R$40,MONTH(F7:F4641)+6,false)} -> 33.159727 | N7: =IFERROR(IF(AND(J7=TRUE,O7=TRUE,YEAR(F7)<2021),H7,"")*(M7*24),0) -> 149.21877 | O7: {=VLOOKUP(C7:C4641,Projetos!A6:L4641,12,false)} -> TRUE
B8: Ana Claudia Zanini | C8: Trophic Soya 1.5 Fiber | D8: =vlookup(C8,'Classificação p pessoal'!F:G,2,false) -> NP | E8: Pesquisa basica para Produção de material cientifico | F8: 0.34375 | G8: 0.51041667 | H8: 0.16666667 | I8: 44201 | J8: TRUE | L8: =IF(VLOOKUP(C8,Projetos!A:L,12,false)=TRUE,TRUE,FALSE) -> TRUE | M8: 33.159727 | N8: =IFERROR(IF(AND(J8=TRUE,O8=TRUE,YEAR(F8)<2021),H8,"")*(M8*24),0) -> 132.63891 | O8: TRUE
B9: Ana Claudia Zanini | C9: Suplemento hiperproteico líquido | D9: =vlookup(C9,'Classificação p pessoal'!F:G,2,false) -> NP | E9: Pesquisa e desenvolvimento de nova fórmula | F9: 0.5625 | G9: 0.75 | H9: 0.1875 | I9: 44201 | J9: TRUE | L9: =IF(VLOOKUP(C9,Projetos!A:L,12,false)=TRUE,TRUE,FALSE) -> TRUE | M9: 33.159727 | N9: =IFERROR(IF(AND(J9=TRUE,O9=TRUE,YEAR(F9)<2021),H9,"")*(M9*24),0) -> 149.21877 | O9: TRUE
B10: Ana Claudia Zanini | C10: Trophic Soya 1.5 Fiber | D10: =vlookup(C10,'Classificação p pessoal'!F:G,2,false) -> NP | E10: Pesquisa basica para Produção de material cientifico | F10: 0.35416667 | G10: 0.5625 | H10: 0.20833333 | I10: 44202 | J10: TRUE | L10: =IF(VLOOKUP(C10,Projetos!A:L,12,false)=TRUE,TRUE,FALSE) -> TRUE | M10: 33.159727 | N10: =IFERROR(IF(AND(J10=TRUE,O10=TRUE,YEAR(F10)<2021),H10,"")*(M10*24),0) -> 165.79864 | O10: TRUE
B11: Ana Claudia Zanini | C11: Suplemento hiperproteico líquido | D11: =vlookup(C11,'Classificação p pessoal'!F:G,2,false) -> NP | E11: Pesquisa e desenvolvimento de nova fórmula | F11: 0.625 | G11: 0.75 | H11: 0.125 | I11: 44202 | J11: TRUE | L11: =IF(VLOOKUP(C11,Projetos!A:L,12,false)=TRUE,TRUE,FALSE) -> TRUE | M11: 33.159727 | N11: =IFERROR(IF(AND(J11=TRUE,O11=TRUE,YEAR(F11)<2021),H11,"")*(M11*24),0) -> 99.479182 | O11: TRUE
B12: Ana Claudia Zanini | C12: Trophic Soya 1.5 Fiber | D12: =vlookup(C12,'Classificação p pessoal'!F:G,2,false) -> NP | E12: Pesquisa basica para Produção de material cientifico | F12: 0.35416667 | G12: 0.45833333 | H12: 0.10416667 | I12: 44203 | J12: TRUE | L12: =IF(VLOOKUP(C12,Projetos!A:L,12,false)=TRUE,TRUE,FALSE) -> TRUE | M12: 33.159727 | N12: =IFERROR(IF(AND(J12=TRUE,O12=TRUE,YEAR(F12)<2021),H12,"")*(M12*24),0) -> 82.899318 | O12: TRUE
B13: Ana Claudia Zanini | C13: Suplemento hiperproteico líquido | D13: =vlookup(C13,'Classificação p pessoal'!F:G,2,false) -> NP | E13: Pesquisa e desenvolvimento de nova fórmula | F13: 0.5625 | G13: 0.75 | H13: 0.1875 | I13: 44203 | J13: TRUE | L13: =IF(VLOOKUP(C13,Projetos!A:L,12,false)=TRUE,TRUE,FALSE) -> TRUE | M13: 33.159727 | N13: =IFERROR(IF(AND(J13=TRUE,O13=TRUE,YEAR(F13)<2021),H13,"")*(M13*24),0) -> 149.21877 | O13: TRUE
B14: Ana Claudia Zanini | C14: Trophic Soya 1.5 Fiber | D14: =vlookup(C14,'Classificação p pessoal'!F:G,2,false) -> NP | E14: Pesquisa basica para Produção de material cientifico | F14: 0.35416667 | G14: 0.5625 | H14: 0.20833333 | I14: 44204 | J14: TRUE | L14: =IF(VLOOKUP(C14,Projetos!A:L,12,false)=TRUE,TRUE,FALSE) -> TRUE | M14: 33.159727 | N14: =IFERROR(IF(AND(J14=TRUE,O14=TRUE,YEAR(F14)<2021),H14,"")*(M14*24),0) -> 165.79864 | O14: TRUE
B15: Ana Claudia Zanini | C15: Trophic Soya 1.5 Fiber | D15: =vlookup(C15,'Classificação p pessoal'!F:G,2,false) -> NP | E15: Pesquisa basica para Produção de material cientifico | F15: 0.35416667 | G15: 0.54166667 | H15: 0.1875 | I15: 44207 | J15: TRUE | L15: =IF(VLOOKUP(C15,Projetos!A:L,12,false)=TRUE,TRUE,FALSE) -> TRUE | M15: 33.159727 | N15: =IFERROR(IF(AND(J15=TRUE,O15=TRUE,YEAR(F15)<2021),H15,"")*(M15*24),0) -> 149.21877 | O15: TRUE
B16: Ana Claudia Zanini | C16: InstanTH Neo | E16: Desenvolvimento de comunicação da fórmula do produto | F16: 0.72916667 | G16: 0.75 | H16: 0.020833333 | I16: 44208 | J16: FALSE | K16: Não entra | L16: =IF(VLOOKUP(C16,Projetos!A:L,12,false)=TRUE,TRUE,FALSE) -> TRUE | M16: 33.159727 | N16: =IFERROR(IF(AND(J16=TRUE,O16=TRUE,YEAR(F16)<2021),H16,"")*(M16*24),0) -> 0 | O16: TRUE
B17: Ana Claudia Zanini | C17: Trophic Soya 1.5 Fiber | D17: =vlookup(C17,'Classificação p pessoal'!F:G,2,false) -> NP | E17: Pesquisa basica para Produção de material cientifico | F17: 0.5625 | G17: 0.70833333 | H17: 0.14583333 | I17: 44208 | J17: TRUE | L17: =IF(VLOOKUP(C17,Projetos!A:L,12,false)=TRUE,TRUE,FALSE) -> TRUE | M17: 33.159727 | N17: =IFERROR(IF(AND(J17=TRUE,O17=TRUE,YEAR(F17)<2021),H17,"")*(M17*24),0) -> 116.05905 | O17: TRUE
B18: Ana Claudia Zanini | C18: InstanTH Neo | E18: Desenvolvimento de comunicação da fórmula do produto | F18: 0.41666667 | G18: 0.45833333 | H18: 0.041666667 | I18: 44209 | J18: FALSE | K18: Não entra | L18: =IF(VLOOKUP(C18,Projetos!A:L,12,false)=TRUE,TRUE,FALSE) -> TRUE | M18: 33.159727 | N18: =IFERROR(IF(AND(J18=TRUE,O18=TRUE,YEAR(F18)<2021),H18,"")*(M18*24),0) -> 0 | O18: TRUE
B19: Ana Claudia Zanini | C19: Trophic Soya 1.5 Fiber | D19: =vlookup(C19,'Classificação p pessoal'!F:G,2,false) -> NP | E19: Pesquisa basica para Produção de material cientifico | F19: 0.5625 | G19: 0.75 | H19: 0.1875 | I19: 44209 | J19: TRUE | L19: =IF(VLOOKUP(C19,Projetos!A:L,12,false)=TRUE,TRUE,FALSE) -> TRUE | M19: 33.159727 | N19: =IFERROR(IF(AND(J19=TRUE,O19=TRUE,YEAR(F19)<2021),H19,"")*(M19*24),0) -> 149.21877 | O19: TRUE
B20: Ana Claudia Zanini | C20: Suplemento hiperproteico líquido | D20: =vlookup(C20,'Classificação p pessoal'!F:G,2,false) -> NP | E20: Pesquisa e desenvolvimento de nova fórmula | F20: 0.35416667 | G20: 0.52083333 | H20: 0.16666667 | I20: 44210 | J20: TRUE | L20: =IF(VLOOKUP(C20,Projetos!A:L,12,false)=TRUE,TRUE,FALSE) -> TRUE | M20: 33.159727 | N20: =IFERROR(IF(AND(J20=TRUE,O20=TRUE,YEAR(F20)<2021),H20,"")*(M20*24),0) -> 132.63891 | O20: TRUE
B21: Ana Claudia Zanini | C21: Trophic Soya 1.5 Fiber | D21: =vlookup(C21,'Classificação p pessoal'!F:G,2,false) -> NP | E21: Pesquisa basica para Produção de material cientifico | F21: 0.58333333 | G21: 0.75 | H21: 0.16666667 | I21: 44210 | J21: TRUE | L21: =IF(VLOOKUP(C21,Projetos!A:L,12,false)=TRUE,TRUE,FALSE) -> TRUE | M21: 33.159727 | N21: =IFERROR(IF(AND(J21=TRUE,O21=TRUE,YEAR(F21)<2021),H21,"")*(M21*24),0) -> 132.63891 | O21: TRUE
B22: Ana Claudia Zanini | C22: Trophic Soya 1.5 Fiber | D22: =vlookup(C22,'Classificação p pessoal'!F:G,2,false) -> NP | E22: Pesquisa basica para Produção de material cientifico | F22: 0.35416667 | G22: 0.4375 | H22: 0.083333333 | I22: 44211 | J22: TRUE | L22: =IF(VLOOKUP(C22,Projetos!A:L,12,false)=TRUE,TRUE,FALSE) -> TRUE | M22: 33.159727 | N22: =IFERROR(IF(AND(J22=TRUE,O22=TRUE,YEAR(F22)<2021),H22,"")*(M22*24),0) -> 66.319455 | O22: TRUE
B23: Ana Claudia Zanini | C23: Trophic Junior Líquido 1.0 (ARB) | D23: =vlookup(C23,'Classificação p pessoal'!F:G,2,false) -> NP | E23: Pesquisa e desenvolvimento de nova fórmula | F23: 0.54166667 | G23: 0.75 | H23: 0.20833333 | I23: 44214 | J23: TRUE | L23: =IF(VLOOKUP(C23,Projetos!A:L,12,false)=TRUE,TRUE,FALSE) -> TRUE | M23: 33.159727 | N23: =IFERROR(IF(AND(J23=TRUE,O23=TRUE,YEAR(F23)<2021),H23,"")*(M23*24),0) -> 165.79864 | O23: TRUE
B24: Ana Claudia Zanini | C24: Suplemento hiperproteico líquido | D24: =vlookup(C24,'Classificação p pessoal'!F:G,2,false) -> NP | E24: Pesquisa e desenvolvimento de nova fórmula | F24: 0.35416667 | G24: 0.5625 | H24: 0.20833333 | I24: 44215 | J24: TRUE | L24: =IF(VLOOKUP(C24,Projetos!A:L,12,false)=TRUE,TRUE,FALSE) -> TRUE | M24: 33.159727 | N24: =IFERROR(IF(AND(J24=TRUE,O24=TRUE,YEAR(F24)<2021),H24,"")*(M24*24),0) -> 165.79864 | O24: TRUE
B25: Ana Claudia Zanini | C25: Suplemento hiperproteico líquido | D25: =vlookup(C25,'Classificação p pessoal'!F:G,2,false) -> NP | E25: Pesquisa e desenvolvimento de nova fórmula | F25: 0.35416667 | G25: 0.54166667 | H25: 0.1875 | I25: 44216 | J25: TRUE | L25: =IF(VLOOKUP(C25,Projetos!A:L,12,false)=TRUE,TRUE,FALSE) -> TRUE | M25: 33.159727 | N25: =IFERROR(IF(AND(J25=TRUE,O25=TRUE,YEAR(F25)<2021),H25,"")*(M25*24),0) -> 149.21877 | O25: TRUE
B26: Ana Claudia Zanini | C26: Diamax IG | E26: Desenvolvimento de comunicação da fórmula do produto | F26: 0.5625 | G26: 0.75 | H26: 0.1875 | I26: 44217 | J26: FALSE | K26: Não entra | L26: =IF(VLOOKUP(C26,Projetos!A:L,12,false)=TRUE,TRUE,FALSE) -> TRUE | M26: 33.159727 | N26: =IFERROR(IF(AND(J26=TRUE,O26=TRUE,YEAR(F26)<2021),H26,"")*(M26*24),0) -> 0 | O26: TRUE
B27: Ana Claudia Zanini | C27: Diamax IG | E27: Desenvolvimento de comunicação da fórmula do produto | F27: 0.52083333 | G27: 0.75 | H27: 0.22916667 | I27: 44218 | J27: FALSE | K27: Não entra | L27: =IF(VLOOKUP(C27,Projetos!A:L,12,false)=TRUE,TRUE,FALSE) -> TRUE | M27: 33.159727 | N27: =IFERROR(IF(AND(J27=TRUE,O27=TRUE,YEAR(F27)<2021),H27,"")*(M27*24),0) -> 0 | O27: TRUE
B28: Ana Claudia Zanini | C28: Diamax IG | E28: Desenvolvimento de comunicação da fórmula do produto | F28: 0.34375 | G28: 0.54166667 | H28: 0.19791667 | I28: 44221 | J28: FALSE | K28: Não entra | L28: =IF(VLOOKUP(C28,Projetos!A:L,12,false)=TRUE,TRUE,FALSE) -> TRUE | M28: 33.159727 | N28: =IFERROR(IF(AND(J28=TRUE,O28=TRUE,YEAR(F28)<2021),H28,"")*(M28*24),0) -> 0 | O28: TRUE
B29: Ana Claudia Zanini | C29: Suplemento hiperproteico líquido | D29: =vlookup(C29,'Classificação p pessoal'!F:G,2,false) -> NP | E29: Pesquisa e desenvolvimento de nova fórmula | F29: 0.58333333 | G29: 0.75 | H29: 0.16666667 | I29: 44221 | J29: TRUE | L29: =IF(VLOOKUP(C29,Projetos!A:L,12,false)=TRUE,TRUE,FALSE) -> TRUE | M29: 33.159727 | N29: =IFERROR(IF(AND(J29=TRUE,O29=TRUE,YEAR(F29)<2021),H29,"")*(M29*24),0) -> 132.63891 | O29: TRUE
B30: Ana Claudia Zanini | C30: Suplemento hiperproteico líquido | D30: =vlookup(C30,'Classificação p pessoal'!F:G,2,false) -> NP | E30: Pesquisa e desenvolvimento de nova fórmula | F30: 0.34375 | G30: 0.54166667 | H30: 0.19791667 | I30: 44222 | J30: TRUE | L30: =IF(VLOOKUP(C30,Projetos!A:L,12,false)=TRUE,TRUE,FALSE) -> TRUE | M30: 33.159727 | N30: =IFERROR(IF(AND(J30=TRUE,O30=TRUE,YEAR(F30)<2021),H30,"")*(M30*24),0) -> 157.5087 | O30: TRUE
B31: Ana Claudia Zanini | C31: Diamax IG | E31: Desenvolvimento de comunicação da fórmula do produto | F31: 0.58333333 | G31: 0.75 | H31: 0.16666667 | I31: 44222 | J31: FALSE | K31: Não entra | L31: =IF(VLOOKUP(C31,Projetos!A:L,12,false)=TRUE,TRUE,FALSE) -> TRUE | M31: 33.159727 | N31: =IFERROR(IF(AND(J31=TRUE,O31=TRUE,YEAR(F31)<2021),H31,"")*(M31*24),0) -> 0 | O31: TRUE
B32: Ana Claudia Zanini | C32: Suplemento hiperproteico líquido | D32: =vlookup(C32,'Classificação p pessoal'!F:G,2,false) -> NP | E32: Pesquisa e desenvolvimento de nova fórmula | F32: 0.34375 | G32: 0.54166667 | H32: 0.19791667 | I32: 44223 | J32: TRUE | L32: =IF(VLOOKUP(C32,Projetos!A:L,12,false)=TRUE,TRUE,FALSE) -> TRUE | M32: 33.159727 | N32: =IFERROR(IF(AND(J32=TRUE,O32=TRUE,YEAR(F32)<2021),H32,"")*(M32*24),0) -> 157.5087 | O32: TRUE
B33: Ana Claudia Zanini | C33: Suplemento hiperproteico líquido | D33: =vlookup(C33,'Classificação p pessoal'!F:G,2,false) -> NP | E33: Pesquisa e desenvolvimento de nova fórmula | F33: 0.34375 | G33: 0.54166667 | H33: 0.19791667 | I33: 44224 | J33: TRUE | L33: =IF(VLOOKUP(C33,Projetos!A:L,12,false)=TRUE,TRUE,FALSE) -> TRUE | M33: 33.159727 | N33: =IFERROR(IF(AND(J33=TRUE,O33=TRUE,YEAR(F33)<2021),H33,"")*(M33*24),0) -> 157.5087 | O33: TRUE
B34: Ana Claudia Zanini | C34: Suplemento hiperproteico líquido | D34: =vlookup(C34,'Classificação p pessoal'!F:G,2,false) -> NP | E34: Pesquisa e desenvolvimento de nova fórmula | F34: 0.34375 | G34: 0.41666667 | H34: 0.072916667 | I34: 44225 | J34: TRUE | L34: =IF(VLOOKUP(C34,Projetos!A:L,12,false)=TRUE,TRUE,FALSE) -> TRUE | M34: 33.159727 | N34: =IFERROR(IF(AND(J34=TRUE,O34=TRUE,YEAR(F34)<2021),H34,"")*(M34*24),0) -> 58.029523 | O34: TRUE
B35: Ana Claudia Zanini | C35: Trophic Soya 1.5 Fiber | D35: =vlookup(C35,'Classificação p pessoal'!F:G,2,false) -> NP | E35: Pesquisa basica para Produção de material cientifico | F35: 0.5 | G35: 0.70833333 | H35: 0.20833333 | I35: 44225 | J35: TRUE | L35: =IF(VLOOKUP(C35,Projetos!A:L,12,false)=TRUE,TRUE,FALSE) -> TRUE | M35: 33.159727 | N35: =IFERROR(IF(AND(J35=TRUE,O35=TRUE,YEAR(F35)<2021),H35,"")*(M35*24),0) -> 165.79864 | O35: TRUE
B36: Ana Claudia Zanini | C36: Trophic Soya 1.5 Fiber | D36: =vlookup(C36,'Classificação p pessoal'!F:G,2,false) -> NP | E36: Pesquisa basica para Produção de material cientifico | F36: 0.35416667 | G36: 0.52083333 | H36: 0.16666667 | I36: 44228 | J36: TRUE | L36: =IF(VLOOKUP(C36,Projetos!A:L,12,false)=TRUE,TRUE,FALSE) -> TRUE | M36: 33.159727 | N36: =IFERROR(IF(AND(J36=TRUE,O36=TRUE,YEAR(F36)<2021),H36,"")*(M36*24),0) -> 132.63891 | O36: TRUE
B37: Ana Claudia Zanini | C37: Trophic Junior Líquido 1.0 (ARB) | D37: =vlookup(C37,'Classificação p pessoal'!F:G,2,false) -> NP | E37: Pesquisa e desenvolvimento de nova fórmula | F37: 0.625 | G37: 0.75 | H37: 0.125 | I37: 44228 | J37: TRUE | L37: =IF(VLOOKUP(C37,Projetos!A:L,12,false)=TRUE,TRUE,FALSE) -> TRUE | M37: 33.159727 | N37: =IFERROR(IF(AND(J37=TRUE,O37=TRUE,YEAR(F37)<2021),H37,"")*(M37*24),0) -> 99.479182 | O37: TRUE
B38: Ana Claudia Zanini | C38: Trophic Junior Líquido 1.0 (ARB) | D38: =vlookup(C38,'Classificação p pessoal'!F:G,2,false) -> NP | E38: Pesquisa e desenvolvimento de nova fórmula | F38: 0.34375 | G38: 0.55208333 | H38: 0.20833333 | I38: 44229 | J38: TRUE | L38: =IF(VLOOKUP(C38,Projetos!A:L,12,false)=TRUE,TRUE,FALSE) -> TRUE | M38: 33.159727 | N38: =IFERROR(IF(AND(J38=TRUE,O38=TRUE,YEAR(F38)<2021),H38,"")*(M38*24),0) -> 165.79864 | O38: TRUE
B39: Ana Claudia Zanini | C39: Trophic Junior Líquido 1.0 (ARB) | D39: =vlookup(C39,'Classificação p pessoal'!F:G,2,false) -> NP | E39: Pesquisa e desenvolvimento de nova fórmula | F39: 0.34375 | G39: 0.46875 | H39: 0.125 | I39: 44230 | J39: TRUE | L39: =IF(VLOOKUP(C39,Projetos!A:L,12,false)=TRUE,TRUE,FALSE) -> TRUE | M39: 33.159727 | N39: =IFERROR(IF(AND(J39=TRUE,O39=TRUE,YEAR(F39)<2021),H39,"")*(M39*24),0) -> 99.479182 | O39: TRUE
B40: Ana Claudia Zanini | C40: Trophic Soya 1.5 Fiber | D40: =vlookup(C40,'Classificação p pessoal'!F:G,2,false) -> NP | E40: Pesquisa basica para Produção de material cientifico | F40: 0.625 | G40: 0.75 | H40: 0.125 | I40: 44230 | J40: TRUE | L40: =IF(VLOOKUP(C40,Projetos!A:L,12,false)=TRUE,TRUE,FALSE) -> TRUE | M40: 33.159727 | N40: =IFERROR(IF(AND(J40=TRUE,O40=TRUE,YEAR(F40)<2021),H40,"")*(M40*24),0) -> 99.479182 | O40: TRUE
B41: Ana Claudia Zanini | C41: Trophic Soya 1.5 Fiber | D41: =vlookup(C41,'Classificação p pessoal'!F:G,2,false) -> NP | E41: Pesquisa basica para Produção de material cientifico | F41: 0.34375 | G41: 0.46875 | H41: 0.125 | I41: 44231 | J41: TRUE | L41: =IF(VLOOKUP(C41,Projetos!A:L,12,false)=TRUE,TRUE,FALSE) -> TRUE | M41: 33.159727 | N41: =IFERROR(IF(AND(J41=TRUE,O41=TRUE,YEAR(F41)<2021),H41,"")*(M41*24),0) -> 99.479182 | O41: TRUE
...

Sheet Pessoal
A2: Pessoal
A4: Salario bruto | G4: planilha RH | H4: planilha RH | I4: planilha RH | J4: planilha RH | K4: planilha RH | L4: planilha RH | M4: planilha RH | N4: planilha RH | O4: planilha RH | P4: planilha RH | Q4: RH atualizou online | R4: RH atualizou online | S4: =(T4/12)*24 -> 170 | T4: =(SUM(G27:R27)*8)/24 -> 85
A5: Nome Completo | B5: CPF | C5: notas | D5: Cargo/função | E5: Formação | F5: Attachments | G5: Salário 01 | H5: Salário 02 | I5: Salário 03 | J5: Salário 04 | K5: Salário 05 | L5: Salário 06 | M5: Salário 07 | N5: Salário 08 | O5: Salário 09 | P5: Salário 10 | Q5: Salário 11 | R5: Salário 12 | S5: PD&I time | T5: PD&I (%) | U5: Classificação | V5: Pesquisador
A6: Ana Claudia Zanini | B6: 076.046.519-33 | D6: Analista Científico | E6: Mestrado | G6: 3599.04 | H6: 3599.04 | I6: 3599.04 | J6: 3599.04 | K6: 3814.98 | L6: 3814.98 | M6: 3814.98 | N6: 3814.98 | O6: 3814.98 | P6: 3814.98 | Q6: 3814.98 | R6: 3814.98 | S6: =IFERROR(__xludf.DUMMYFUNCTION("IFERROR(if(V6=true, SUM(FILTER(Timesheet!$H:$H,Timesheet!J:J = TRUE,Timesheet!O:O = TRUE,Timesheet!B:B = A6,Timesheet!F:F < DATE(2022,1,1))),0),0)"),48.062499999999964) -> 48.0625 | T6: =S6/$T$4 -> 0.56544118 | U6: =IF(T6<80%,"Parcial","Exclusivo") -> Parcial | V6: TRUE
A7: Ana Paula Celes | B7: 759.837.297-72 | D7: Diretora Técnica | E7: Pós graduado | F7: PJ | G7: 31767.65 | H7: 31767.65 | I7: 316767.65 | J7: 31767.65 | K7: 31767.65 | L7: 31767.65 | M7: 31767.65 | N7: 31767.65 | O7: 31767.65 | P7: 31767.65 | Q7: 31767.65 | R7: 31767.65 | S7: =IFERROR(__xludf.DUMMYFUNCTION("IFERROR(if(V7=true, SUM(FILTER(Timesheet!$H:$H,Timesheet!J:J = TRUE,Timesheet!O:O = TRUE,Timesheet!B:B = A7,Timesheet!F:F < DATE(2022,1,1))),0),0)"),0.0) -> 0 | T7: =S7/$T$4 -> 0 | U7: =IF(T7<80%,"Parcial","Exclusivo") -> Parcial | V7: TRUE
A8: Arianna Schreiber | B8: 066.466.799-67 | D8: Gerente Mkt | E8: Pós graduado | G8: 8878.45 | H8: 8878.45 | I8: 8878.45 | J8: 10095 | K8: 10700.7 | L8: 10700.7 | M8: 10700.7 | N8: 10700.7 | O8: 10700.7 | P8: 10700.7 | Q8: 10700.7 | R8: 10700.7 | S8: =IFERROR(__xludf.DUMMYFUNCTION("IFERROR(if(V8=true, SUM(FILTER(Timesheet!$H:$H,Timesheet!J:J = TRUE,Timesheet!O:O = TRUE,Timesheet!B:B = A8,Timesheet!F:F < DATE(2022,1,1))),0),0)"),1.2916666666666667) -> 1.2916667 | T8: =S8/$T$4 -> 0.015196078 | U8: =IF(T8<80%,"Parcial","Exclusivo") -> Parcial | V8: TRUE
A9: Camila Mendes Pereira | B9: 083.832.289-10 | D9: Assistente de P&D | E9: Superior Completo | G9: 2816.69 | H9: 2816.69 | I9: 2816.69 | J9: 3367.8 | K9: 3569.87 | L9: 3569.87 | M9: 3568.87 | N9: 3569.87 | O9: 3569.87 | P9: 3569.87 | Q9: 3569.87 | R9: 3569.87 | S9: =IFERROR(__xludf.DUMMYFUNCTION("IFERROR(if(V9=true, SUM(FILTER(Timesheet!$H:$H,Timesheet!J:J = TRUE,Timesheet!O:O = TRUE,Timesheet!B:B = A9,Timesheet!F:F < DATE(2022,1,1))),0),0)"),27.11111111111111) -> 27.111111 | T9: =S9/$T$4 -> 0.31895425 | U9: =IF(T9<80%,"Parcial","Exclusivo") -> Parcial | V9: TRUE
A10: Gabriela Faria de Oliveira | B10: 087.823.469-17 | D10: Analista Científico | E10: Superior Completo | G10: 3773.89 | H10: 3773.89 | I10: 3773.89 | J10: 3773.89 | K10: 4000.32 | L10: 4000.32 | M10: 4000.32 | N10: 4000.32 | O10: 4000.32 | P10: 4000.32 | Q10: 4000.32 | R10: 4000.32 | S10: =IFERROR(__xludf.DUMMYFUNCTION("IFERROR(if(V10=true, SUM(FILTER(Timesheet!$H:$H,Timesheet!J:J = TRUE,Timesheet!O:O = TRUE,Timesheet!B:B = A10,Timesheet!F:F < DATE(2022,1,1))),0),0)"),27.85416666666664) -> 27.854167 | T10: =S10/$T$4 -> 0.32769608 | U10: =IF(T10<80%,"Parcial","Exclusivo") -> Parcial | V10: TRUE
A11: Hellin dos Santos | B11: 058.544.839-63 | D11: Gerente Cientifico | E11: Mestrado | G11: 12487.72 | H11: 12487.72 | I11: 12487.72 | J11: 12487.72 | K11: 13236.98 | L11: 13236.98 | M11: 13236.98 | N11: 13236.98 | O11: 14358.3 | P11: 14358.3 | Q11: 14358.3 | R11: 14358.3 | S11: =IFERROR(__xludf.DUMMYFUNCTION("IFERROR(if(V11=true, SUM(FILTER(Timesheet!$H:$H,Timesheet!J:J = TRUE,Timesheet!O:O = TRUE,Timesheet!B:B = A11,Timesheet!F:F < DATE(2022,1,1))),0),0)"),0.0) -> 0 | T11: =S11/$T$4 -> 0 | U11: =IF(T11<80%,"Parcial","Exclusivo") -> Parcial | V11: TRUE
A12: Juliana Lamas Roberto | B12: 317.875.738-42 | D12: Especialista em Estudos de Estabilidade | E12: Pós graduado | G12: 8000 | H12: 8000 | I12: 8000 | J12: 8000 | K12: 8480 | L12: 8480 | M12: 8480 | N12: 8480 | O12: 8480 | P12: 8480 | Q12: 8480 | R12: 8480 | S12: =IFERROR(__xludf.DUMMYFUNCTION("IFERROR(if(V12=true, SUM(FILTER(Timesheet!$H:$H,Timesheet!J:J = TRUE,Timesheet!O:O = TRUE,Timesheet!B:B = A12,Timesheet!F:F < DATE(2022,1,1))),0),0)"),64.8902777777778) -> 64.890278 | T12: =S12/$T$4 -> 0.76341503 | U12: =IF(T12<80%,"Parcial","Exclusivo") -> Parcial | V12: TRUE
A13: Kézia Rithássia Piccoli | B13: 077.680.169-47 | D13: Analista de GQ | E13: Pós graduado | G13: 4071.12 | H13: 4071.12 | I13: 4071.12 | J13: 4071.12 | K13: 4315.39 | L13: 4315.39 | M13: 4315.39 | N13: 4315.39 | O13: 4315.39 | P13: 4315.39 | Q13: 4315.39 | R13: 4315.39 | S13: =IFERROR(__xludf.DUMMYFUNCTION("IFERROR(if(V13=true, SUM(FILTER(Timesheet!$H:$H,Timesheet!J:J = TRUE,Timesheet!O:O = TRUE,Timesheet!B:B = A13,Timesheet!F:F < DATE(2022,1,1))),0),0)"),30.357638888888886) -> 30.357639 | T13: =S13/$T$4 -> 0.35714869 | U13: =IF(T13<80%,"Parcial","Exclusivo") -> Parcial | V13: TRUE
A14: Lizianne Shmeil | B14: 052.485.199-93 | D14: Analista P&D | E14: Superior Completo | G14: 4995.55 | H14: 4995.55 | I14: 4995.55 | J14: 4995.55 | K14: 5295.28 | L14: 5295.28 | M14: 5295.28 | N14: 5295.28 | O14: 6038.25 | P14: 6038.25 | Q14: 6038.25 | R14: 6038.25 | S14: =IFERROR(__xludf.DUMMYFUNCTION("IFERROR(if(V14=true, SUM(FILTER(Timesheet!$H:$H,Timesheet!J:J = TRUE,Timesheet!O:O = TRUE,Timesheet!B:B = A14,Timesheet!F:F < DATE(2022,1,1))),0),0)"),60.95833333333327) -> 60.958333 | T14: =S14/$T$4 -> 0.71715686 | U14: =IF(T14<80%,"Parcial","Exclusivo") -> Parcial | V14: TRUE
A15: Luciana Dutra | B15: 186.586.978-35 | D15: Gerente Técnica | E15: Pós graduado | G15: 17611.04 | H15: 17611.04 | I15: 17611.04 | J15: 17611.04 | K15: 17611.04 | L15: 17611.04 | M15: 18667.7 | N15: 18667.7 | O15: 18667.7 | P15: 18668 | Q15: 18668 | R15: 18668 | S15: =IFERROR(__xludf.DUMMYFUNCTION("IFERROR(if(V15=true, SUM(FILTER(Timesheet!$H:$H,Timesheet!J:J = TRUE,Timesheet!O:O = TRUE,Timesheet!B:B = A15,Timesheet!F:F < DATE(2022,1,1))),0),0)"),0.0) -> 0 | T15: =S15/$T$4 -> 0 | U15: =IF(T15<80%,"Parcial","Exclusivo") -> Parcial | V15: TRUE
A16: Márcio Henrique Nogueira | B16: 088.869.216-16 | D16: Analista de P&D | E16: Pós graduado | G16: 5500 | H16: 5500 | I16: 5500 | J16: 5500 | K16: 6000 | L16: 6000 | M16: 6000 | N16: 6000 | O16: 6000 | P16: 6000 | Q16: 6000 | R16: 6000 | S16: =IFERROR(__xludf.DUMMYFUNCTION("IFERROR(if(V16=true, SUM(FILTER(Timesheet!$H:$H,Timesheet!J:J = TRUE,Timesheet!O:O = TRUE,Timesheet!B:B = A16,Timesheet!F:F < DATE(2022,1,1))),0),0)"),42.29861111111107) -> 42.298611 | T16: =S16/$T$4 -> 0.49763072 | U16: =IF(T16<80%,"Parcial","Exclusivo") -> Parcial | V16: TRUE
A17: Marianne Stigar | B17: 066.424.199-95 | D17: Coord. GQ | E17: Pós graduado | G17: 5093.12 | H17: 5093.12 | I17: 5093.12 | J17: 5093.12 | K17: 5398.71 | L17: 5398.71 | M17: 5978 | N17: 5978 | O17: 5978 | P17: 5978 | Q17: 5978 | R17: 5978 | S17: =IFERROR(__xludf.DUMMYFUNCTION("IFERROR(if(V17=true, SUM(FILTER(Timesheet!$H:$H,Timesheet!J:J = TRUE,Timesheet!O:O = TRUE,Timesheet!B:B = A17,Timesheet!F:F < DATE(2022,1,1))),0),0)"),0.0) -> 0 | T17: =S17/$T$4 -> 0 | U17: =IF(T17<80%,"Parcial","Exclusivo") -> Parcial | V17: TRUE
A18: Tahuany Leite | B18: 086.481.459-37 | D18: Analista MKT | E18: Pós graduado | G18: 3963.02 | H18: 3963.02 | I18: 3963.02 | J18: 3963.02 | K18: 3963.02 | L18: 3963.02 | M18: 4200.8 | N18: 4200.8 | O18: 4200.8 | P18: 4454.72 | Q18: 4454.72 | R18: 4454.72 | S18: =IFERROR(__xludf.DUMMYFUNCTION("IFERROR(if(V18=true, SUM(FILTER(Timesheet!$H:$H,Timesheet!J:J = TRUE,Timesheet!O:O = TRUE,Timesheet!B:B = A18,Timesheet!F:F < DATE(2022,1,1))),0),0)"),0.0) -> 0 | T18: =S18/$T$4 -> 0 | U18: =IF(T18<80%,"Parcial","Exclusivo") -> Parcial | V18: TRUE
A21: Cálculo do custo/hora
A23: Encargos sobre folha | H23: INSS | I23: Patronal | J23: 0.2
A24: INSS | B24: FGTS | C24: Férias | D24: 13º | E24: Total | I24: Terceiros | J24: 0.058 | T24: =IFERROR(__xludf.DUMMYFUNCTION("sum(FILTER(T29:T39,match(A29:A39,FILTER(A6:A18,U6:U18 = ""Parcial""))))"),356413.40177364694) -> 356413.4
A25: =sum(J23:J25) -> 0.273 | B25: 0.08 | C25: =((1+(1/3))+A25+B25)/12 -> 0.14052778 | D25: =(1+A25+B25)/12 -> 0.11275 | E25: =sum(A25:D25) -> 0.60627778 | I25: RAT | J25: 0.015 | T25: =IFERROR(__xludf.DUMMYFUNCTION("IFERROR(sum(FILTER(T29:T39,match(A29:A39,FILTER(A6:A18,U6:U18 = ""Exclusivo"")))),0)"),0.0) -> 0
G27: =NETWORKDAYS(DATE(2021,(LEFT(G$28,2)+0),1),DATE(2021,(LEFT(G$28,2)+0)+1,0),$A$45:$A$53) -> 21 | H27: =NETWORKDAYS(DATE(2021,(LEFT(H$28,2)+0),1),DATE(2021,(LEFT(H$28,2)+0)+1,0),$A$45:$A$53) -> 20 | I27: =NETWORKDAYS(DATE(2021,(LEFT(I$28,2)+0),1),DATE(2021,(LEFT(I$28,2)+0)+1,0),$A$45:$A$53) -> 21 | J27: =NETWORKDAYS(DATE(2021,(LEFT(J$28,2)+0),1),DATE(2021,(LEFT(J$28,2)+0)+1,0),$A$45:$A$53) -> 22 | K27: =NETWORKDAYS(DATE(2021,(LEFT(K$28,2)+0),1),DATE(2021,(LEFT(K$28,2)+0)+1,0),$A$45:$A$53) -> 21 | L27: =NETWORKDAYS(DATE(2021,(LEFT(L$28,2)+0),1),DATE(2021,(LEFT(L$28,2)+0)+1,0),$A$45:$A$53) -> 22 | M27: =NETWORKDAYS(DATE(2021,(LEFT(M$28,2)+0),1),DATE(2021,(LEFT(M$28,2)+0)+1,0),$A$45:$A$53) -> 21 | N27: =NETWORKDAYS(DATE(2021,(LEFT(N$28,2)+0),1),DATE(2021,(LEFT(N$28,2)+0)+1,0),$A$45:$A$53) -> 21 | ... R27: =NETWORKDAYS(DATE(2021,(LEFT(R$28,2)+0),1),DATE(2021,(LEFT(R$28,2)+0)+1,0),$A$45:$A$53) -> 21 | S27: =sum(S29:S39) -> 356413.4 | T27: =sum(T29:T39) -> 356413.4 | U27: =T27-S27 -> 0
A28: Nome Completo | D28: {=U5:U18} -> Classificação | E28: {=E5:E18} -> Formação | F28: Custo / Hora | G28: 44227 | H28: 44255 | I28: 44286 | J28: 44316 | K28: 44347 | L28: 44377 | M28: 44408 | N28: 44439 | O28: 44469 | P28: 44500 | Q28: 44530 | R28: 44561 | S28: PD&I R$ | T28: Aprovado R$ | U28: Pesquisador
A29: {=unique(A6:A18)} -> Ana Claudia Zanini | D29: Parcial | E29: Mestrado | G29: =vlookup($A29,$A$6:$R$18,month(G$28)+6)*(1+$E$25)/(G$27*8.8) -> 31.282781 | H29: =vlookup($A29,$A$6:$R$18,month(H$28)+6)*(1+$E$25)/(H$27*8.8) -> 32.84692 | I29: =vlookup($A29,$A$6:$R$18,month(I$28)+6)*(1+$E$25)/(I$27*8.8) -> 31.282781 | J29: =vlookup($A29,$A$6:$R$18,month(J$28)+6)*(1+$E$25)/(J$27*8.8) -> 29.860837 | K29: =vlookup($A29,$A$6:$R$18,month(K$28)+6)*(1+$E$25)/(K$27*8.8) -> 33.159727 | L29: =vlookup($A29,$A$6:$R$18,month(L$28)+6)*(1+$E$25)/(L$27*8.8) -> 31.652467 | M29: =vlookup($A29,$A$6:$R$18,month(M$28)+6)*(1+$E$25)/(M$27*8.8) -> 33.159727 | N29: =vlookup($A29,$A$6:$R$18,month(N$28)+6)*(1+$E$25)/(N$27*8.8) -> 33.159727 | ... R29: =vlookup($A29,$A$6:$R$18,month(R$28)+6)*(1+$E$25)/(R$27*8.8) -> 33.159727 | S29: =SUMIF(Timesheet!B:B,A29,Timesheet!N:N) -> 38249.745 | T29: =SUMIF(U29,TRUE,S29) -> 38249.745 | U29: TRUE
A30: Ana Paula Celes | D30: Parcial | E30: Pós graduado | G30: =G7*(((1/3)*1/12)+1)/(G27*(44/5)) -> 176.67795 | H30: =H7*(((1/3)*1/12)+1)/(H27*(44/5)) -> 185.51184 | I30: =I7*(((1/3)*1/12)+1)/(I27*(44/5)) -> 1761.7248 | J30: =J7*(((1/3)*1/12)+1)/(J27*(44/5)) -> 168.64713 | K30: =K7*(((1/3)*1/12)+1)/(K27*(44/5)) -> 176.67795 | L30: =L7*(((1/3)*1/12)+1)/(L27*(44/5)) -> 168.64713 | M30: =M7*(((1/3)*1/12)+1)/(M27*(44/5)) -> 176.67795 | N30: =N7*(((1/3)*1/12)+1)/(N27*(44/5)) -> 176.67795 | ... R30: =R7*(((1/3)*1/12)+1)/(R27*(44/5)) -> 176.67795 | S30: =SUMIF(Timesheet!B:B,A30,Timesheet!N:N) -> 0 | T30: =SUMIF(U30,TRUE,S30) -> 0 | U30: TRUE
A31: Arianna Schreiber | D31: Parcial | E31: Pós graduado | G31: =vlookup($A31,$A$6:$R$18,month(G$28)+6)*(1+$E$25)/(G$27*8.8) -> 77.171304 | H31: =vlookup($A31,$A$6:$R$18,month(H$28)+6)*(1+$E$25)/(H$27*8.8) -> 81.029869 | I31: =vlookup($A31,$A$6:$R$18,month(I$28)+6)*(1+$E$25)/(I$27*8.8) -> 77.171304 | J31: =vlookup($A31,$A$6:$R$18,month(J$28)+6)*(1+$E$25)/(J$27*8.8) -> 83.757098 | K31: =vlookup($A31,$A$6:$R$18,month(K$28)+6)*(1+$E$25)/(K$27*8.8) -> 93.010263 | L31: =vlookup($A31,$A$6:$R$18,month(L$28)+6)*(1+$E$25)/(L$27*8.8) -> 88.782524 | M31: =vlookup($A31,$A$6:$R$18,month(M$28)+6)*(1+$E$25)/(M$27*8.8) -> 93.010263 | N31: =vlookup($A31,$A$6:$R$18,month(N$28)+6)*(1+$E$25)/(N$27*8.8) -> 93.010263 | ... R31: =vlookup($A31,$A$6:$R$18,month(R$28)+6)*(1+$E$25)/(R$27*8.8) -> 93.010263 | S31: =SUMIF(Timesheet!B:B,A31,Timesheet!N:N) -> 2883.3182 | T31: =SUMIF(U31,TRUE,S31) -> 2883.3182 | U31: TRUE
A32: Camila Mendes Pereira | D32: Parcial | E32: Superior Completo | G32: =vlookup($A32,$A$6:$R$18,month(G$28)+6)*(1+$E$25)/(G$27*8.8) -> 24.482611 | H32: =vlookup($A32,$A$6:$R$18,month(H$28)+6)*(1+$E$25)/(H$27*8.8) -> 25.706742 | I32: =vlookup($A32,$A$6:$R$18,month(I$28)+6)*(1+$E$25)/(I$27*8.8) -> 24.482611 | J32: =vlookup($A32,$A$6:$R$18,month(J$28)+6)*(1+$E$25)/(J$27*8.8) -> 27.942264 | K32: =vlookup($A32,$A$6:$R$18,month(K$28)+6)*(1+$E$25)/(K$27*8.8) -> 31.029236 | L32: =vlookup($A32,$A$6:$R$18,month(L$28)+6)*(1+$E$25)/(L$27*8.8) -> 29.618816 | M32: =vlookup($A32,$A$6:$R$18,month(M$28)+6)*(1+$E$25)/(M$27*8.8) -> 31.020544 | N32: =vlookup($A32,$A$6:$R$18,month(N$28)+6)*(1+$E$25)/(N$27*8.8) -> 31.029236 | ... R32: =vlookup($A32,$A$6:$R$18,month(R$28)+6)*(1+$E$25)/(R$27*8.8) -> 31.029236 | S32: =SUMIF(Timesheet!B:B,A32,Timesheet!N:N) -> 20189.69 | T32: =SUMIF(U32,TRUE,S32) -> 20189.69 | U32: TRUE
A33: Gabriela Faria de Oliveira | D33: Parcial | E33: Superior Completo | G33: =vlookup($A33,$A$6:$R$18,month(G$28)+6)*(1+$E$25)/(G$27*8.8) -> 32.802574 | H33: =vlookup($A33,$A$6:$R$18,month(H$28)+6)*(1+$E$25)/(H$27*8.8) -> 34.442703 | I33: =vlookup($A33,$A$6:$R$18,month(I$28)+6)*(1+$E$25)/(I$27*8.8) -> 32.802574 | J33: =vlookup($A33,$A$6:$R$18,month(J$28)+6)*(1+$E$25)/(J$27*8.8) -> 31.311548 | K33: =vlookup($A33,$A$6:$R$18,month(K$28)+6)*(1+$E$25)/(K$27*8.8) -> 34.770699 | L33: =vlookup($A33,$A$6:$R$18,month(L$28)+6)*(1+$E$25)/(L$27*8.8) -> 33.190212 | M33: =vlookup($A33,$A$6:$R$18,month(M$28)+6)*(1+$E$25)/(M$27*8.8) -> 34.770699 | N33: =vlookup($A33,$A$6:$R$18,month(N$28)+6)*(1+$E$25)/(N$27*8.8) -> 34.770699 | ... R33: =vlookup($A33,$A$6:$R$18,month(R$28)+6)*(1+$E$25)/(R$27*8.8) -> 34.770699 | S33: =SUMIF(Timesheet!B:B,A33,Timesheet!N:N) -> 23244.212 | T33: =SUMIF(U33,TRUE,S33) -> 23244.212 | U33: TRUE
A34: Hellin dos Santos | D34: Parcial | E34: Mestrado | G34: =vlookup($A34,$A$6:$R$18,month(G$28)+6)*(1+$E$25)/(G$27*8.8) -> 108.543 | H34: =vlookup($A34,$A$6:$R$18,month(H$28)+6)*(1+$E$25)/(H$27*8.8) -> 113.97015 | I34: =vlookup($A34,$A$6:$R$18,month(I$28)+6)*(1+$E$25)/(I$27*8.8) -> 108.543 | J34: =vlookup($A34,$A$6:$R$18,month(J$28)+6)*(1+$E$25)/(J$27*8.8) -> 103.60923 | K34: =vlookup($A34,$A$6:$R$18,month(K$28)+6)*(1+$E$25)/(K$27*8.8) -> 115.05556 | L34: =vlookup($A34,$A$6:$R$18,month(L$28)+6)*(1+$E$25)/(L$27*8.8) -> 109.82576 | M34: =vlookup($A34,$A$6:$R$18,month(M$28)+6)*(1+$E$25)/(M$27*8.8) -> 115.05556 | N34: =vlookup($A34,$A$6:$R$18,month(N$28)+6)*(1+$E$25)/(N$27*8.8) -> 115.05556 | ... R34: =vlookup($A34,$A$6:$R$18,month(R$28)+6)*(1+$E$25)/(R$27*8.8) -> 124.80205 | S34: =SUMIF(Timesheet!B:B,A34,Timesheet!N:N) -> 0 | T34: =SUMIF(U34,TRUE,S34) -> 0 | U34: TRUE
A35: Juliana Lamas Roberto | D35: Parcial | E35: Pós graduado | G35: =vlookup($A35,$A$6:$R$18,month(G$28)+6)*(1+$E$25)/(G$27*8.8) -> 69.535835 | H35: =vlookup($A35,$A$6:$R$18,month(H$28)+6)*(1+$E$25)/(H$27*8.8) -> 73.012626 | I35: =vlookup($A35,$A$6:$R$18,month(I$28)+6)*(1+$E$25)/(I$27*8.8) -> 69.535835 | J35: =vlookup($A35,$A$6:$R$18,month(J$28)+6)*(1+$E$25)/(J$27*8.8) -> 66.375115 | K35: =vlookup($A35,$A$6:$R$18,month(K$28)+6)*(1+$E$25)/(K$27*8.8) -> 73.707985 | L35: =vlookup($A35,$A$6:$R$18,month(L$28)+6)*(1+$E$25)/(L$27*8.8) -> 70.357622 | M35: =vlookup($A35,$A$6:$R$18,month(M$28)+6)*(1+$E$25)/(M$27*8.8) -> 73.707985 | N35: =vlookup($A35,$A$6:$R$18,month(N$28)+6)*(1+$E$25)/(N$27*8.8) -> 73.707985 | ... R35: =vlookup($A35,$A$6:$R$18,month(R$28)+6)*(1+$E$25)/(R$27*8.8) -> 73.707985 | S35: =SUMIF(Timesheet!B:B,A35,Timesheet!N:N) -> 114790.36 | T35: =SUMIF(U35,TRUE,S35) -> 114790.36 | U35: TRUE
A36: Kézia Rithássia Piccoli | D36: Parcial | E36: Pós graduado | G36: =vlookup($A36,$A$6:$R$18,month(G$28)+6)*(1+$E$25)/(G$27*8.8) -> 35.386091 | H36: =vlookup($A36,$A$6:$R$18,month(H$28)+6)*(1+$E$25)/(H$27*8.8) -> 37.155395 | I36: =vlookup($A36,$A$6:$R$18,month(I$28)+6)*(1+$E$25)/(I$27*8.8) -> 35.386091 | J36: =vlookup($A36,$A$6:$R$18,month(J$28)+6)*(1+$E$25)/(J$27*8.8) -> 33.777632 | K36: =vlookup($A36,$A$6:$R$18,month(K$28)+6)*(1+$E$25)/(K$27*8.8) -> 37.509281 | L36: =vlookup($A36,$A$6:$R$18,month(L$28)+6)*(1+$E$25)/(L$27*8.8) -> 35.804313 | M36: =vlookup($A36,$A$6:$R$18,month(M$28)+6)*(1+$E$25)/(M$27*8.8) -> 37.509281 | N36: =vlookup($A36,$A$6:$R$18,month(N$28)+6)*(1+$E$25)/(N$27*8.8) -> 37.509281 | ... R36: =vlookup($A36,$A$6:$R$18,month(R$28)+6)*(1+$E$25)/(R$27*8.8) -> 37.509281 | S36: =SUMIF(Timesheet!B:B,A36,Timesheet!N:N) -> 27328.637 | T36: =SUMIF(U36,TRUE,S36) -> 27328.637 | U36: TRUE
