Workbook

Sheet RESUMO
A2: Resumo dos investimentos
A3: BENEFÍCIO FISCAL DE PD&I 2023
G4: 2019-088 PRODIET
A5: PRODIET NUTRIÇÃO CLINICA LTDA | E5: CNPJ 08.183.359/0001-53 | G5: =TODAY() -> 46168
A6: Rua General Potiguara, 1428, Lotes 20 e 21, Novo Mundo - PR - SUL - CURITIBA - CEP 81.050-500 - fone: (41) 3342-2825
A8: Natureza | B8: 1º Trimestre | C8: 2º Trimestre | D8: 3º Trimestre | E8: 4º Trimestre | G8: TOTAL
A9: Material | B9: - | C9: - | D9: - | E9: - | G9: =sum(B9:E9) -> 0
A10: Terceiros | B10: =IFERROR(__xludf.DUMMYFUNCTION("iferror(sum(filter(TERCEIROS!$L12:$L66,month(TERCEIROS!$H12:$H66)>=1,month(TERCEIROS!$H12:$H66)<=3)),0)"),105659.93000000001) -> 105659.93 | C10: =IFERROR(__xludf.DUMMYFUNCTION("iferror(sum(filter(TERCEIROS!$L12:$L66,month(TERCEIROS!$H12:$H66)>=4,month(TERCEIROS!$H12:$H66)<=6)),0)"),89153.48) -> 89153.48 | D10: =IFERROR(__xludf.DUMMYFUNCTION("iferror(sum(filter(TERCEIROS!$L12:$L66,month(TERCEIROS!$H12:$H66)>=7,month(TERCEIROS!$H12:$H66)<=9)),0)"),109284.745) -> 109284.74 | E10: =IFERROR(__xludf.DUMMYFUNCTION("iferror(sum(filter(TERCEIROS!$L12:$L66,month(TERCEIROS!$H12:$H66)>=10,month(TERCEIROS!$H12:$H66)<=12)),0)"),62550.06) -> 62550.06 | G10: =sum(B10:E10) -> 366648.22
A11: RH (Parcial inovação) | B11: =IFERROR(__xludf.DUMMYFUNCTION("iferror(sum(filter(TIMESHEET!$N$12:$N66,TIMESHEET!$Q$12:$Q66=""Parcial"",month(TIMESHEET!$F$12:$F66)>=1,month(TIMESHEET!$F$12:$F66)<=3)),0)"),55379.129999999925) -> 55379.13 | C11: =IFERROR(__xludf.DUMMYFUNCTION("iferror(sum(filter(TIMESHEET!$N$12:$N66,TIMESHEET!$Q$12:$Q66=""Parcial"",month(TIMESHEET!$F$12:$F66)>=4,month(TIMESHEET!$F$12:$F66)<=6)),0)"),62396.73584798719) -> 62396.736 | D11: =IFERROR(__xludf.DUMMYFUNCTION("iferror(sum(filter(TIMESHEET!$N$12:$N66,TIMESHEET!$Q$12:$Q66=""Parcial"",month(TIMESHEET!$F$12:$F66)>=7,month(TIMESHEET!$F$12:$F66)<=9)),0)"),36288.97724144722) -> 36288.977 | E11: =IFERROR(__xludf.DUMMYFUNCTION("iferror(sum(filter(TIMESHEET!$N$12:$N66,TIMESHEET!$Q$12:$Q66=""Parcial"",month(TIMESHEET!$F$12:$F66)>=10,month(TIMESHEET!$F$12:$F66)<=12)),0)"),52844.009887970664) -> 52844.01 | G11: =sum(B11:E11) -> 206908.85
A12: RH (Exclusivo inovação) | B12: =IFERROR(__xludf.DUMMYFUNCTION("iferror(sum(filter(TIMESHEET!$N$12:$N66,TIMESHEET!$Q$12:$Q66=""Exclusivo"",month(TIMESHEET!$F$12:$F66)>=1,month(TIMESHEET!$F$12:$F66)<=3)),0)"),0.0) -> 0 | C12: =IFERROR(__xludf.DUMMYFUNCTION("iferror(sum(filter(TIMESHEET!$N$12:$N66,TIMESHEET!$Q$12:$Q66=""Exclusivo"",month(TIMESHEET!$F$12:$F66)>=4,month(TIMESHEET!$F$12:$F66)<=6)),0)"),0.0) -> 0 | D12: =IFERROR(__xludf.DUMMYFUNCTION("iferror(sum(filter(TIMESHEET!$N$12:$N66,TIMESHEET!$Q$12:$Q66=""Exclusivo"",month(TIMESHEET!$F$12:$F66)>=7,month(TIMESHEET!$F$12:$F66)<=9)),0)"),0.0) -> 0 | E12: =IFERROR(__xludf.DUMMYFUNCTION("iferror(sum(filter(TIMESHEET!$N$12:$N66,TIMESHEET!$Q$12:$Q66=""Exclusivo"",month(TIMESHEET!$F$12:$F66)>=10,month(TIMESHEET!$F$12:$F66)<=12)),0)"),0.0) -> 0 | G12: =sum(B12:E12) -> 0
A13: Total 1 | B13: =sum(B10:B12) -> 161039.06 | C13: =sum(C10:C12) -> 151550.22 | D13: =sum(D10:D12) -> 145573.72 | E13: =sum(E10:E12) -> 115394.07 | G13: =sum(B13:E13) -> 573557.07
A14: Percentual Exclusão | B14: 0.6 | C14: 0.6 | D14: 0.6 | E14: 0.6 | G14: 0.6
A15: Exclusão da Base de cálculo do IRPJ e CSLL | B15: =B13*B14 -> 96623.436 | C15: =C13*C14 -> 90930.13 | D15: =D13*D14 -> 87344.233 | E15: =E13*E14 -> 69236.442 | G15: =sum(B15:E15) -> 344134.24
A17: Economia Estimada [34%] | B17: =B15*34% -> 32851.968 | C17: =C15*34% -> 30916.244 | D17: =D15*34% -> 29697.039 | E17: =E15*34% -> 23540.39 | G17: =sum(B17:E17) -> 117005.64
A18: Comissão McBenner | B18: =B17*0.1 -> 3285.1968 | C18: =C17*0.1 -> 3091.6244 | D18: =D17*0.1 -> 2969.7039 | E18: =E17*0.1 -> 2354.039 | G18: =sum(B18:E18) -> 11700.564
A20: Observações:
A21: 1. Os dispêndios devem ser registrados na contabilidade em conta específica
A22: 2. O benefício deve ser aproveitado na ECF do respectivo ano/competência
A23: 3. O formulário do MCTIC (governo) deve ser enviado até fim de Julho/2024
A24: 4. Os projetos estão descritos em arquivo a parte a ser anexado no FORM PD&I
A25: 5. Alguns benefícios previstos na Lei do Bem não foram utilizados:
A26: --- 5.1. Depreciação acelerada
A27: --- 5.2. Redução de IPI na aquisição de equipamento para PD&I
A28: 5. Alguns benefícios previstos na Lei do Bem não foram utilizados:
A30: Equipe de PD&I
A31: Quadro de resumo | B31: Dedicação Parcial | E31: Dedicação Exclusiva
B32: Qtd | C32: Valor gasto | D32: Horas | E32: Qtd | F32: Valor gasto | G32: Horas
A33: Técnico | B33: =IFERROR(__xludf.DUMMYFUNCTION("COUNTA(IFERROR(FILTER(PESSOAL!$F$13:$F$23,PESSOAL!$F$13:$F$23 = $A33,PESSOAL!$V$13:$V$23 = ""Parcial"",PESSOAL!$W$13:$W$23 = TRUE),))"),0.0) -> 0 | C33: =IFERROR(__xludf.DUMMYFUNCTION("SUM(IFERROR(FILTER(PESSOAL!$U$35:$U$45,PESSOAL!$F$35:$F$45 = $A33,PESSOAL!$E$35:$E$45 = ""Parcial""),0))"),0.0) -> 0 | D33: =IFERROR(__xludf.DUMMYFUNCTION("SUM(IFERROR(FILTER(PESSOAL!$T$13:$T$23,PESSOAL!$F$13:$F$23 = $A33,PESSOAL!$V$13:$V$23 = ""Parcial""),0))*24"),0.0) -> 0 | E33: =IFERROR(__xludf.DUMMYFUNCTION("COUNTA(IFERROR(FILTER(PESSOAL!$E$6:$E$19,PESSOAL!$E$6:$E$19 = $A33,PESSOAL!$U$6:$U$19 = ""Exclusivo"",PESSOAL!$U$28:$U$39 = TRUE),))"),0.0) -> 0 | F33: =IFERROR(__xludf.DUMMYFUNCTION("SUM(IFERROR(FILTER(PESSOAL!$U$35:$U$44,PESSOAL!$F$35:$F$44 = $A33,PESSOAL!$E$35:$E$44 = ""Exclusivo);0))"")))"),0.0) -> 0 | G33: =IFERROR(__xludf.DUMMYFUNCTION("SUM(IFERROR(FILTER(PESSOAL!$T$13:$T$23,PESSOAL!$F$13:$F$23 = $A33,PESSOAL!$V$13:$V$23 = ""Exclusivo""),0))*24"),0.0) -> 0
A34: Tecnologo | B34: =IFERROR(__xludf.DUMMYFUNCTION("COUNTA(IFERROR(FILTER(PESSOAL!$F$13:$F$23,PESSOAL!$F$13:$F$23 = $A34,PESSOAL!$V$13:$V$23 = ""Parcial"",PESSOAL!$W$13:$W$23 = TRUE),))"),0.0) -> 0 | C34: =IFERROR(__xludf.DUMMYFUNCTION("SUM(IFERROR(FILTER(PESSOAL!$U$35:$U$45,PESSOAL!$F$35:$F$45 = $A34,PESSOAL!$E$35:$E$45 = ""Parcial""),0))"),0.0) -> 0 | D34: =IFERROR(__xludf.DUMMYFUNCTION("SUM(IFERROR(FILTER(PESSOAL!$T$13:$T$23,PESSOAL!$F$13:$F$23 = $A34,PESSOAL!$V$13:$V$23 = ""Parcial""),0))*24"),0.0) -> 0 | E34: =IFERROR(__xludf.DUMMYFUNCTION("COUNTA(IFERROR(FILTER(PESSOAL!$E$6:$E$19,PESSOAL!$E$6:$E$19 = $A34,PESSOAL!$U$6:$U$19 = ""Exclusivo"",PESSOAL!$U$28:$U$39 = TRUE),))"),0.0) -> 0 | F34: =IFERROR(__xludf.DUMMYFUNCTION("SUM(IFERROR(FILTER(PESSOAL!$U$35:$U$44,PESSOAL!$F$35:$F$44 = $A34,PESSOAL!$E$35:$E$44 = ""Exclusivo);0))"")))"),0.0) -> 0 | G34: =IFERROR(__xludf.DUMMYFUNCTION("SUM(IFERROR(FILTER(PESSOAL!$T$13:$T$23,PESSOAL!$F$13:$F$23 = $A34,PESSOAL!$V$13:$V$23 = ""Exclusivo""),0))*24"),0.0) -> 0
A35: Superior Completo | B35: =IFERROR(__xludf.DUMMYFUNCTION("COUNTA(IFERROR(FILTER(PESSOAL!$F$13:$F$23,PESSOAL!$F$13:$F$23 = $A35,PESSOAL!$V$13:$V$23 = ""Parcial"",PESSOAL!$W$13:$W$23 = TRUE),))"),4.0) -> 4 | C35: =IFERROR(__xludf.DUMMYFUNCTION("SUM(IFERROR(FILTER(PESSOAL!$U$35:$U$45,PESSOAL!$F$35:$F$45 = $A35,PESSOAL!$E$35:$E$45 = ""Parcial""),0))"),75955.78293522184) -> 75955.783 | D35: =IFERROR(__xludf.DUMMYFUNCTION("SUM(IFERROR(FILTER(PESSOAL!$T$13:$T$23,PESSOAL!$F$13:$F$23 = $A35,PESSOAL!$V$13:$V$23 = ""Parcial""),0))*24"),1302.5666666666668) -> 1302.5667 | E35: =IFERROR(__xludf.DUMMYFUNCTION("COUNTA(IFERROR(FILTER(PESSOAL!$E$6:$E$19,PESSOAL!$E$6:$E$19 = $A35,PESSOAL!$U$6:$U$19 = ""Exclusivo"",PESSOAL!$U$28:$U$39 = TRUE),))"),0.0) -> 0 | F35: =IFERROR(__xludf.DUMMYFUNCTION("SUM(IFERROR(FILTER(PESSOAL!$U$35:$U$44,PESSOAL!$F$35:$F$44 = $A35,PESSOAL!$E$35:$E$44 = ""Exclusivo);0))"")))"),0.0) -> 0 | G35: =IFERROR(__xludf.DUMMYFUNCTION("SUM(IFERROR(FILTER(PESSOAL!$T$13:$T$23,PESSOAL!$F$13:$F$23 = $A35,PESSOAL!$V$13:$V$23 = ""Exclusivo""),0))*24"),0.0) -> 0
A36: Pós graduado | B36: =IFERROR(__xludf.DUMMYFUNCTION("COUNTA(IFERROR(FILTER(PESSOAL!$F$13:$F$23,PESSOAL!$F$13:$F$23 = $A36,PESSOAL!$V$13:$V$23 = ""Parcial"",PESSOAL!$W$13:$W$23 = TRUE),))"),3.0) -> 3 | C36: =IFERROR(__xludf.DUMMYFUNCTION("SUM(IFERROR(FILTER(PESSOAL!$U$35:$U$45,PESSOAL!$F$35:$F$45 = $A36,PESSOAL!$E$35:$E$45 = ""Parcial""),0))"),23118.883308544828) -> 23118.883 | D36: =IFERROR(__xludf.DUMMYFUNCTION("SUM(IFERROR(FILTER(PESSOAL!$T$13:$T$23,PESSOAL!$F$13:$F$23 = $A36,PESSOAL!$V$13:$V$23 = ""Parcial""),0))*24"),271.74999999999994) -> 271.75 | E36: =IFERROR(__xludf.DUMMYFUNCTION("COUNTA(IFERROR(FILTER(PESSOAL!$E$6:$E$19,PESSOAL!$E$6:$E$19 = $A36,PESSOAL!$U$6:$U$19 = ""Exclusivo"",PESSOAL!$U$28:$U$39 = TRUE),))"),0.0) -> 0 | F36: =IFERROR(__xludf.DUMMYFUNCTION("SUM(IFERROR(FILTER(PESSOAL!$U$35:$U$44,PESSOAL!$F$35:$F$44 = $A36,PESSOAL!$E$35:$E$44 = ""Exclusivo);0))"")))"),0.0) -> 0 | G36: =IFERROR(__xludf.DUMMYFUNCTION("SUM(IFERROR(FILTER(PESSOAL!$T$13:$T$23,PESSOAL!$F$13:$F$23 = $A36,PESSOAL!$V$13:$V$23 = ""Exclusivo""),0))*24"),0.0) -> 0
A37: Mestrado | B37: =IFERROR(__xludf.DUMMYFUNCTION("COUNTA(IFERROR(FILTER(PESSOAL!$F$13:$F$23,PESSOAL!$F$13:$F$23 = $A37,PESSOAL!$V$13:$V$23 = ""Parcial"",PESSOAL!$W$13:$W$23 = TRUE),))"),4.0) -> 4 | C37: =IFERROR(__xludf.DUMMYFUNCTION("SUM(IFERROR(FILTER(PESSOAL!$U$35:$U$45,PESSOAL!$F$35:$F$45 = $A37,PESSOAL!$E$35:$E$45 = ""Parcial""),0))"),100109.26978075242) -> 100109.27 | D37: =IFERROR(__xludf.DUMMYFUNCTION("SUM(IFERROR(FILTER(PESSOAL!$T$13:$T$23,PESSOAL!$F$13:$F$23 = $A37,PESSOAL!$V$13:$V$23 = ""Parcial""),0))*24"),1500.050000000001) -> 1500.05 | E37: =IFERROR(__xludf.DUMMYFUNCTION("COUNTA(IFERROR(FILTER(PESSOAL!$E$6:$E$19,PESSOAL!$E$6:$E$19 = $A37,PESSOAL!$U$6:$U$19 = ""Exclusivo"",PESSOAL!$U$28:$U$39 = TRUE),))"),0.0) -> 0 | F37: =IFERROR(__xludf.DUMMYFUNCTION("SUM(IFERROR(FILTER(PESSOAL!$U$35:$U$44,PESSOAL!$F$35:$F$44 = $A37,PESSOAL!$E$35:$E$44 = ""Exclusivo);0))"")))"),0.0) -> 0 | G37: =IFERROR(__xludf.DUMMYFUNCTION("SUM(IFERROR(FILTER(PESSOAL!$T$13:$T$23,PESSOAL!$F$13:$F$23 = $A37,PESSOAL!$V$13:$V$23 = ""Exclusivo""),0))*24"),0.0) -> 0
A38: Doutorado | B38: =IFERROR(__xludf.DUMMYFUNCTION("COUNTA(IFERROR(FILTER(PESSOAL!$F$13:$F$23,PESSOAL!$F$13:$F$23 = $A38,PESSOAL!$V$13:$V$23 = ""Parcial"",PESSOAL!$W$13:$W$23 = TRUE),))"),0.0) -> 0 | C38: =IFERROR(__xludf.DUMMYFUNCTION("SUM(IFERROR(FILTER(PESSOAL!$U$35:$U$45,PESSOAL!$F$35:$F$45 = $A38,PESSOAL!$E$35:$E$45 = ""Parcial""),0))"),0.0) -> 0 | D38: =IFERROR(__xludf.DUMMYFUNCTION("SUM(IFERROR(FILTER(PESSOAL!$T$13:$T$23,PESSOAL!$F$13:$F$23 = $A38,PESSOAL!$V$13:$V$23 = ""Parcial""),0))*24"),0.0) -> 0 | E38: =IFERROR(__xludf.DUMMYFUNCTION("COUNTA(IFERROR(FILTER(PESSOAL!$E$6:$E$19,PESSOAL!$E$6:$E$19 = $A38,PESSOAL!$U$6:$U$19 = ""Exclusivo"",PESSOAL!$U$28:$U$39 = TRUE),))"),0.0) -> 0 | F38: =IFERROR(__xludf.DUMMYFUNCTION("SUM(IFERROR(FILTER(PESSOAL!$U$35:$U$44,PESSOAL!$F$35:$F$44 = $A38,PESSOAL!$E$35:$E$44 = ""Exclusivo);0))"")))"),0.0) -> 0 | G38: =IFERROR(__xludf.DUMMYFUNCTION("SUM(IFERROR(FILTER(PESSOAL!$T$13:$T$23,PESSOAL!$F$13:$F$23 = $A38,PESSOAL!$V$13:$V$23 = ""Exclusivo""),0))*24"),0.0) -> 0
B39: =SUM(B33:B38) -> 11 | C39: =SUM(C33:C38) -> 199183.94 | D39: =SUM(D33:D38) -> 3074.3667 | E39: =SUM(E33:E38) -> 0 | F39: =SUM(F33:F38) -> 0 | G39: =SUM(G33:G38) -> 0
A41: Valores por projeto de PD&I
B42: =sum(D42:G42) -> 573557.07 | D42: =sum(D44:D66) -> 0 | E42: =sum(E44:E66) -> 366648.22 | F42: =sum(F44:F66) -> 206908.85 | G42: =sum(G44:G66) -> 0
A43: Projetos | B43: TOTAL | D43: Vlr materiais | E43: Vlr terceiros | F43: Vlr Rh parcial | G43: Vlr exclusivos
A44: {='BD Projetos'!A2:A24} -> INOV00001 | B44: =sum(D44:G44) -> 285941.65 | D44: - | E44: {=iferror(XLOOKUP(A44:A66,transpose(TERCEIROS!$P$11:$AW$11),transpose(TERCEIROS!$P$10:$AW$10),0,0),"")} -> 196831.42 | F44: =IFERROR(__xludf.DUMMYFUNCTION("ArrayFormula(IFERROR(SUM(filter(TIMESHEET!$N$12:$N66,TIMESHEET!$C$12:$C66=A44,TIMESHEET!$Q$12:$Q66=""Parcial"")),""-""))"),89110.22431248204) -> 89110.224 | G44: =IFERROR(__xludf.DUMMYFUNCTION("iferror(sum(filter(TIMESHEET!$N12:$N66,TIMESHEET!$C12:$C66=A44,TIMESHEET!$Q12:$Q66=""Exclusivo"")),""-"")"),"-") -> -
A45: INOV00004 | B45: =sum(D45:G45) -> 10095.228 | D45: - | E45: 0 | F45: =IFERROR(__xludf.DUMMYFUNCTION("ArrayFormula(IFERROR(SUM(filter(TIMESHEET!$N$12:$N66,TIMESHEET!$C$12:$C66=A45,TIMESHEET!$Q$12:$Q66=""Parcial"")),""-""))"),10095.227904826466) -> 10095.228 | G45: =IFERROR(__xludf.DUMMYFUNCTION("iferror(sum(filter(TIMESHEET!$N13:$N66,TIMESHEET!$C13:$C66=A45,TIMESHEET!$Q13:$Q66=""Exclusivo"")),""-"")"),"-") -> -
A46: INOV00006 | B46: =sum(D46:G46) -> 9719.4221 | D46: - | E46: 0 | F46: =IFERROR(__xludf.DUMMYFUNCTION("ArrayFormula(IFERROR(SUM(filter(TIMESHEET!$N$12:$N66,TIMESHEET!$C$12:$C66=A46,TIMESHEET!$Q$12:$Q66=""Parcial"")),""-""))"),9719.422113103337) -> 9719.4221 | G46: =IFERROR(__xludf.DUMMYFUNCTION("iferror(sum(filter(TIMESHEET!$N14:$N66,TIMESHEET!$C14:$C66=A46,TIMESHEET!$Q14:$Q66=""Exclusivo"")),""-"")"),"-") -> -
...

Sheet INOV0001
B2: PRODIET
B3: Pesquisa, Desenvolvimento & Inovação
B4: Formulário de PD&I - Ano 2023 | J4: Incentivado pela Lei do Bem | M4: TRUE
B5: - preencher somente os campos sombreados (cinza) e - adicionar cronograma no formato de imagem ao fim do formulário - preencher um deste para cada projeto de PD&I | J5: Objetiva tornar-se um Ativo | M5: FALSE
J6: Objetiva gerar patente/registro | M6: FALSE
B8: Dossiê do projeto
B9: Dados gerais para identificação e validação do projeto de PD&I
B11: Nome do projeto | E11: INOV000001 (2018 - RETORT)
J12: Pesquisa básica | M12: 📑
B13: Classificação do projeto | E13: Desenvolvimento experimental | J13: Pesquisa aplicada | M13: 📑
J14: Desenvolvimento experimental | M14: 📑
B15: Objetivos do projeto | E15: A Prodiet tem como objetivo desenvolver e lançar uma nova linha de produtos de Nutrição Enteral, focada em atender a 50% do mercado que atualmente não é contemplado pelos produtos em pó e líquidos UHT da empresa. Esta nova linha utilizará a tecnologia de tratamento térmico em autoclave para criar produtos inovadores que garantam maior qualidade e segurança alimentar. Especificamente, a linha incluirá produtos de nutrição enteral formulados para atender condições clínicas diversas, como fórmulas para pacientes com necessidades calóricas elevadas, fórmulas para intolerâncias alimentares e fórmulas para suporte nutricional de longo prazo. A empresa identificou essa demanda específica através de estudos de mercado detalhados, incluindo análises de concorrência, feedback de profissionais de saúde e dados de vendas regionais. A atual linha de produtos não atende a esta demanda devido à falta de tecnologia adequada para produzir fórmulas mais específicas e de maior estabilidade.
J16: Inovação tecnológica de produto | M16: 📑
B17: Tipo de inovação | E17: Inovação tecnológica de processo | J17: Inovação tecnológica de processo | M17: 📑
J18: Inovação tecnológica de serviços | M18: 📑
B19: Elemento inovador | E19: A introdução da tecnologia de tratamento térmico em autoclave representa uma inovação significativa para a Prodiet, que atualmente utiliza apenas processos UHT. A escolha da tecnologia de autoclave foi motivada pela necessidade de melhorar a qualidade e a segurança dos produtos de nutrição enteral, reduzindo riscos de contaminação e aumentando a vida útil sem a necessidade de aditivos químicos. Comparada aos métodos UHT, a tecnologia de autoclave proporciona um tratamento térmico mais homogêneo e controlado, resultando em produtos de maior qualidade e estabilidade. Além disso, permite a criação de uma variedade maior de produtos, atendendo a necessidades específicas do mercado. A adoção desta tecnologia requer a construção de uma nova área fabril, com mudanças significativas nos fluxos de trabalho e equipamentos. A Prodiet planeja integrar novos processos e treinar funcionários para operar com a tecnologia de autoclave. A empresa também planeja proteger essa inovação através de patentes e outros mecanismos de propriedade intelectual, garantindo que os avanços tecnológicos desenvolvidos sejam devidamente reconhecidos e protegidos. | J19: - Não podem ser consideradas as inovações organizacionais, comerciais e de marketing
J20: Empresa ou segmento regional | M20: 📑
B21: Nível de inovação | E21: Empresa ou segmento regional | J21: Inovador para o Brasil | M21: 📑
J22: Inovador para o Mundo | M22: 📑
B23: Risco tecnológico | E23: O principal desafio do projeto será implantar uma nova área fabril do zero, compreendendo totalmente a tecnologia de autoclave e assegurando a estabilidade e esterilidade comercial dos produtos. Será necessário desenvolver novas embalagens compatíveis com o processo e encontrar um copacker adequado para otimizar o tempo de lançamento dos produtos. A empresa planeja superar esses desafios através de uma abordagem multifásica, que inclui a contratação de consultorias especializadas, desenvolvimento de protótipos em plantas piloto, e estreita colaboração com fornecedores de equipamentos e embalagens.
B25: Metodologias | E25: A Prodiet está realizando diversos estudos e consultorias para adquirir o conhecimento necessário sobre a tecnologia de autoclave. Estes estudos incluem a contratação de consultorias para formulações e desenvolvimento de produtos, a pesquisa de locais para testes em planta piloto, o contato com fornecedores de embalagens e prestadores de serviços, além de estudos detalhados sobre a nova tecnologia, abrangendo produto, processo, equipamentos e embalagens. Estes estudos estão sendo financiados através de fundos próprios e incentivos fiscais da Lei do Bem, geridos por uma equipe dedicada que inclui departamentos de Pesquisa Científica, Assuntos Regulatórios, Qualidade, Manutenção e Produção. As várias áreas da empresa estão colaborando de forma integrada, com reuniões regulares e troca de informações para garantir que todos os aspectos do projeto sejam devidamente considerados e implementados.
B27: Equipe | E27: Nome Completo | F27: Cargo/Função | G27: Qualificação | H27: !
E28: Lizianne Angelica Shmeil | F28: Analista de P&D | G28: Pós-graduação | L28: Técnico | M28: 📑
E29: Ana Paula Celes | F29: Diretora Técnica | G29: Pós-graduação | L29: Graduação
E30: Luciana Dutra | F30: Gerente Técnica | G30: Pós-graduação | L30: Pós-graduação
L31: Mestrado
L32: Doutorado
B35: Cronograma
B36: [anexar imagem - preferencialmente Gantt]

Sheet INOV0004
B2: PRODIET
B3: Pesquisa, Desenvolvimento & Inovação
B4: Formulário de PD&I - Ano 2023 | J4: Incentivado pela Lei do Bem | M4: TRUE
B5: - preencher somente os campos sombreados (cinza) e - adicionar cronograma no formato de imagem ao fim do formulário - preencher um deste para cada projeto de PD&I | J5: Objetiva tornar-se um Ativo | M5: FALSE
J6: Objetiva gerar patente/registro | M6: FALSE
B8: Dossiê do projeto
B9: Dados gerais para identificação e validação do projeto de PD&I
B11: Nome do projeto | E11: INOV000004 (2019 - CICATRIZAÇÃO)
J12: Pesquisa básica | M12: 📑
B13: Classificação do projeto | E13: Desenvolvimento experimental | J13: Pesquisa aplicada | M13: 📑
J14: Desenvolvimento experimental | M14: 📑
B15: Objetivos do projeto | E15: A Prodiet está desenvolvendo um produto voltado para cicatrização, adequado tanto para uso em pós-operatórios quanto para a prevenção e tratamento de lesões por pressão. Para alcançar a eficácia no tratamento de lesões, estão sendo realizados diversos estudos científicos e clínicos. Esses estudos incluem a análise de mecanismos de cicatrização, testes de eficácia em diferentes tipos de lesões e avaliações de segurança. Além disso, foram incorporados novos processos de formulação e testes para assegurar a estabilidade e a eficácia dos ingredientes ativos na cicatrização.
J16: Inovação tecnológica de produto | M16: 📑
B17: Tipo de inovação | E17: Inovação tecnológica de produto | J17: Inovação tecnológica de processo | M17: 📑
J18: Inovação tecnológica de serviços | M18: 📑
B19: Elemento inovador | E19: A fórmula para cicatrização desenvolvida pela Prodiet oferece uma combinação inovadora de nutrientes que não é encontrada em produtos similares no mercado. Enquanto a maioria dos produtos recomendados em ambientes hospitalares são líquidos, a Prodiet desenvolveu uma versão em pó, com o objetivo de oferecer um melhor custo-benefício aos pacientes. Esta fórmula em pó difere significativamente dos produtos líquidos tradicionais ao proporcionar maior flexibilidade na dosagem e uma melhor estabilidade dos nutrientes durante o armazenamento. A principal diferença na cicatrização entre o produto em forma líquida e em pó reside na bioavaliação dos nutrientes, onde a versão em pó tem demonstrado uma liberação mais controlada e eficiente dos componentes ativos. | J19: - Não podem ser consideradas as inovações organizacionais, comerciais e de marketing
J20: Empresa ou segmento regional | M20: 📑
B21: Nível de inovação | E21: Empresa ou segmento regional | J21: Inovador para o Brasil | M21: 📑
J22: Inovador para o Mundo | M22: 📑
B23: Risco tecnológico | E23: O desenvolvimento do produto apresenta desafios tecnológicos significativos, especialmente no que se refere ao sensorial agradável e à combinação de nutrientes de alto residual, como aminoácidos isolados e colágeno hidrolisado. Os principais aminoácidos isolados presentes no produto que causam desafios sensoriais incluem aqueles com sabores intensos e persistentes. Para lidar com esses desafios, a empresa está realizando pesquisas sensoriais e testes de sabor, além de explorar tecnologias de encapsulamento para mascarar sabores indesejados. No que diz respeito ao colágeno hidrolisado, a empresa está garantindo sua estabilidade durante o processamento térmico através de métodos específicos de produção, como a microencapsulação, que protege os nutrientes durante o processo UHT (Ultra High Temperature). Para minimizar os efeitos sensoriais indesejados dos ingredientes com alto residual de sabor ou aroma, estão sendo exploradas diversas estratégias, incluindo a utilização de flavorizantes naturais e a modificação do perfil de liberação dos nutrientes. O processo UHT é adaptado para acomodar ingredientes sensíveis, garantindo a integridade nutricional do produto através de ajustes precisos de temperatura e tempo de processamento. Estão sendo conduzidas pesquisas e testes específicos para avaliar a estabilidade dos ingredientes durante o processamento térmico, utilizando critérios rigorosos para determinar a estabilidade dos componentes, como a retenção de atividade biológica e a ausência de degradação significativa. O desenvolvimento do produto envolveu a colaboração com especialistas externos e consultores, que contribuíram com conhecimentos avançados e técnicas inovadoras para superar os desafios tecnológicos específicos.
B25: Metodologias | E25: A metodologia adotada pela Prodiet para o desenvolvimento da fórmula envolve intensiva pesquisa e contatos com profissionais do setor. A empresa busca compreender o comportamento das matérias-primas selecionadas através de estudos existentes e de novos testes em parceria com fornecedores. Para definir um produto que apresenta sensorial agradável, a Prodiet realiza avaliações sensoriais detalhadas, incluindo testes de sabor, textura e aceitação por parte de grupos de consumidores. Os indicadores utilizados para determinar se o produto é sensorialmente agradável incluem escalas de aceitação sensorial, testes de preferência e análises quantitativas de atributos sensoriais específicos, assegurando que o produto final atenda aos altos padrões de qualidade e aceitação do mercado.
B27: Equipe | E27: Nome Completo | F27: Cargo/Função | G27: Qualificação | H27: !
E28: Gabriela Faria de Oliveira | F28: Analista Científico | G28: Pós-graduação | L28: Técnico | M28: 📑
E29: Rafael Parreira Lorini | F29: Analista de P&D | L29: Graduação
E30: Ana Paula Celes | F30: Diretora Técnica | G30: Pós-graduação | L30: Pós-graduação
E31: Luciana Dutra | F31: Gerente Técnica | G31: Pós-graduação | L31: Mestrado
E32: Hellin dos Santos | F32: Gerente Científico | G32: Mestrado | L32: Doutorado
B35: Cronograma
B36: [anexar imagem - preferencialmente Gantt]

Sheet INOV0006
B2: PRODIET
B3: Pesquisa, Desenvolvimento & Inovação
B4: Formulário de PD&I - Ano 2023 | J4: Incentivado pela Lei do Bem | M4: TRUE
B5: - preencher somente os campos sombreados (cinza) e - adicionar cronograma no formato de imagem ao fim do formulário - preencher um deste para cada projeto de PD&I | J5: Objetiva tornar-se um Ativo | M5: FALSE
J6: Objetiva gerar patente/registro | M6: FALSE
B8: Dossiê do projeto
B9: Dados gerais para identificação e validação do projeto de PD&I
B11: Nome do projeto | E11: INOV000006 (2019 - ARTESANAL)
J12: Pesquisa básica | M12: 📑
B13: Classificação do projeto | E13: Desenvolvimento experimental | J13: Pesquisa aplicada | M13: 📑
J14: Desenvolvimento experimental | M14: 📑
B15: Objetivos do projeto | E15: A Prodiet está desenvolvendo um produto inovador no mercado brasileiro, com o objetivo de complementar a dieta enteral artesanal, oferecendo uma ótima relação custo/benefício. Este produto é único, pois não há similares disponíveis no mercado atualmente. Ele visa preencher uma lacuna significativa no mercado de nutrição enteral, proporcionando uma solução nutritiva e acessível para pacientes que dependem de dietas artesanais.
J16: Inovação tecnológica de produto | M16: 📑
B17: Tipo de inovação | E17: Inovação tecnológica de produto | J17: Inovação tecnológica de processo | M17: 📑
J18: Inovação tecnológica de serviços | M18: 📑
B19: Elemento inovador | E19: A fórmula desenvolvida pela Prodiet é totalmente inovadora, incorporando alimentos que atendem a uma demanda específica ainda não contemplada no mercado brasileiro. Esta formulação oferece propriedades exclusivas que a tornam valiosa para os consumidores, como a utilização de alimentos liofilizados que mantêm o valor nutricional dos ingredientes in natura. A demanda específica foi identificada através de estudos de mercado detalhados, pesquisas com consumidores e análises de tendências de saúde, que indicaram uma necessidade crescente por soluções de nutrição enteral artesanal com melhor qualidade e custo-benefício. | J19: - Não podem ser consideradas as inovações organizacionais, comerciais e de marketing
J20: Empresa ou segmento regional | M20: 📑
B21: Nível de inovação | E21: Inovador para o Brasil | J21: Inovador para o Brasil | M21: 📑
J22: Inovador para o Mundo | M22: 📑
B23: Risco tecnológico | E23: Os desafios tecnológicos associados a este projeto incluem a utilização de novas matérias-primas, como alimentos liofilizados, que apresentam uma composição nutricional variável, dificultando a seleção de ingredientes que atendam ao perfil nutricional desejado. Além disso, desenvolver um produto que seja nutricionalmente adequado para o público que utiliza nutrição enteral artesanal, com um perfil sensorial neutro e solubilidade adequada, representa uma barreira significativa. Para abordar esses desafios, a empresa está adotando estratégias específicas, como a análise rigorosa de lotes de matérias-primas para garantir consistência nutricional e o uso de técnicas avançadas de formulação para melhorar a solubilidade e o perfil sensorial do produto. Medidas estão sendo tomadas para garantir que a fórmula seja segura para consumo em nutrição enteral, incluindo testes rigorosos de segurança e qualidade. A viabilidade técnica da formulação proposta é um foco constante, com esforços contínuos para superar desafios significativos através de inovação e colaboração com especialistas do setor.
B25: Metodologias | E25: A metodologia adotada pela Prodiet inclui um estudo detalhado dos principais nutrientes deficientes na dieta artesanal oferecida a indivíduos que utilizam nutrição enteral artesanal. Análises da composição de produtos com ingredientes in natura e análises sensoriais foram conduzidas para entender melhor os desafios e necessidades. O estudo de novas matérias-primas foi liderado pelos departamentos Científico e de Pesquisa e Desenvolvimento (P&D). Os primeiros testes de bancada não foram satisfatórios devido à presença de grânulos e sabor residual desagradável. No momento, o P&D está realizando novos estudos de matérias-primas em parceria com fornecedores para melhorar a formulação.
B27: Equipe | E27: Nome Completo | F27: Cargo/Função | G27: Qualificação | H27: !
E28: Gabriela Faria de Oliveira | F28: Analista Científico | G28: Pós-graduação | L28: Técnico | M28: 📑
E29: Camila Mendes Pereira | F29: Analista de P&D | G29: Graduação | L29: Graduação
E30: Luciana Dutra | F30: Gerente Técnica | G30: Pós-graduação | L30: Pós-graduação
E31: Hellin dos Santos | F31: Gerente Científico | G31: Mestrado | L31: Mestrado
E32: Ana Paula Celes | F32: Diretora Técnica | G32: Pós-graduação | L32: Doutorado
B35: Cronograma
B36: [anexar imagem - preferencialmente Gantt]

Sheet INOV00010
B2: PRODIET
B3: Pesquisa, Desenvolvimento & Inovação
B4: Formulário de PD&I - Ano 2023 | J4: Incentivado pela Lei do Bem | M4: TRUE
B5: - preencher somente os campos sombreados (cinza) e - adicionar cronograma no formato de imagem ao fim do formulário - preencher um deste para cada projeto de PD&I | J5: Objetiva tornar-se um Ativo | M5: FALSE
J6: Objetiva gerar patente/registro | M6: FALSE
B8: Dossiê do projeto
B9: Dados gerais para identificação e validação do projeto de PD&I
B11: Nome do projeto | E11: INOV000010 (2021 - DIAMAX PÓ)
J12: Pesquisa básica | M12: 📑
B13: Classificação do projeto | E13: Desenvolvimento experimental | J13: Pesquisa aplicada | M13: 📑
J14: Desenvolvimento experimental | M14: 📑
B15: Objetivos do projeto | E15: A Prodiet está desenvolvendo um produto competitivo ao Glucerna* para venda no varejo, categorizado como suplemento para permitir agilidade no lançamento. O produto será focado tanto para diabéticos quanto para a população geral, sendo desenvolvido na forma de pó para facilitar o consumo e a armazenagem. Este produto visa preencher uma lacuna no mercado, oferecendo uma opção acessível e eficaz para o controle glicêmico com alto teor de proteína, alinhado com a linha Diamax já existente no portfólio da empresa.
J16: Inovação tecnológica de produto | M16: 📑
B17: Tipo de inovação | E17: Inovação tecnológica de produto | J17: Inovação tecnológica de processo | M17: 📑
J18: Inovação tecnológica de serviços | M18: 📑
B19: Elemento inovador | E19: O elemento inovador deste produto é a sua formulação específica para controle glicêmico, com aumento do teor proteico, destinado ao mercado varejista. O aumento de proteína no produto contribui para o controle da glicemia ao promover uma liberação mais lenta de glicose no sangue, melhorando a resposta glicêmica pós-prandial. Os benefícios associados a um maior teor de proteína incluem a manutenção da massa muscular, maior saciedade e melhor controle do peso, aspectos essenciais para a gestão da diabetes e saúde geral. | J19: - Não podem ser consideradas as inovações organizacionais, comerciais e de marketing
J20: Empresa ou segmento regional | M20: 📑
B21: Nível de inovação | E21: Empresa ou segmento regional | J21: Inovador para o Brasil | M21: 📑
J22: Inovador para o Mundo | M22: 📑
B23: Risco tecnológico | E23: Os desafios tecnológicos envolvem a construção de um produto com preço de venda competitivo, mantendo a qualidade sensorial que não limite seu consumo. As principais limitações incluem sabor, preço e oferta no mercado. O sensorial final do consumidor será avaliado com foco na efetividade do produto, preço e acessibilidade. Estudos estão sendo realizados para mensurar a aceitação do público-alvo, utilizando pesquisas de mercado e testes de produto. O projeto aborda o desafio de construir um produto com preço de venda competitivo em relação ao Glucerna* e outros concorrentes através de estratégias de otimização de custos na produção e escolha de ingredientes. Para o desenvolvimento de aromas e sabores, a empresa está colaborando com fornecedores especializados para criar perfis sensoriais que sejam agradáveis e aceitos pelo público-alvo.
B25: Metodologias | E25: A metodologia para o desenvolvimento do produto inclui a elaboração de um target de micronutrientes único para suplementos, considerando as necessidades específicas de indivíduos diabéticos, desnutridos e principais deficiências nutricionais encontradas na população. O aumento da proporção de proteína vegetal na formulação visa a redução de custo sem comprometer a qualidade nutricional. As necessidades de diabéticos e desnutridos são priorizadas de forma balanceada, garantindo que o produto atenda ambas as populações de forma eficaz. A parte inovadora de aumentar a proteína vegetal reside na escolha de fontes vegetais de alta qualidade que são mais sustentáveis e economicamente viáveis. Os micronutrientes específicos considerados no target incluem cromo, magnésio, vitaminas do complexo B e antioxidantes, todos críticos para a gestão da diabetes e melhoria do estado nutricional. A empresa planeja aumentar a proporção de proteína vegetal na formulação utilizando fontes como soja, ervilha e arroz, que são conhecidas por seus perfis nutricionais completos. O desenvolvimento de novos aromas em parceria com fornecedores envolve testes rigorosos de palatabilidade e estabilidade, garantindo que os sabores resultantes sejam agradáveis e aceitos pelo consumidor final.
B27: Equipe | E27: Nome Completo | F27: Cargo/Função | G27: Qualificação | H27: !
E28: Ana Claudia Zanini | F28: Analista cientifico | G28: Mestrado | L28: Técnico | M28: 📑
E29: Camila Mendes Pereira | F29: Analista de P&D | G29: Graduação | L29: Graduação
E30: Juliana Lamas Roberto | F30: Especialista de Estudo de Estabilidade | G30: Mestrado | L30: Pós-graduação
E31: Luciana Dutra | F31: Gerente Técnica | G31: Pós-graduação | L31: Mestrado
E32: Hellin dos Santos | F32: Gerente Cientifico | G32: Mestrado | L32: Doutorado
E33: Ana Paula Celes | F33: Diretora Técnica | G33: Pós-graduação
B35: Cronograma
B36: [anexar imagem - preferencialmente Gantt]

Sheet INOV00013
B2: PRODIET
B3: Pesquisa, Desenvolvimento & Inovação
B4: Formulário de PD&I - Ano 2023 | J4: Incentivado pela Lei do Bem | M4: TRUE
B5: - preencher somente os campos sombreados (cinza) e - adicionar cronograma no formato de imagem ao fim do formulário - preencher um deste para cada projeto de PD&I | J5: Objetiva tornar-se um Ativo | M5: FALSE
J6: Objetiva gerar patente/registro | M6: FALSE
B8: Dossiê do projeto
B9: Dados gerais para identificação e validação do projeto de PD&I
B11: Nome do projeto | E11: INOV000013 (2021 - SACHÊ A VÁCUO)
J12: Pesquisa básica | M12: 📑
B13: Classificação do projeto | E13: Desenvolvimento experimental | J13: Pesquisa aplicada | M13: 📑
J14: Desenvolvimento experimental | M14: 📑
B15: Objetivos do projeto | E15: A Prodiet está aplicando o uso do vácuo no envase dos produtos em pó do seu portfólio atual, com o objetivo de estudar se a embalagem mantém o vácuo ao longo do shelf-life, bem como auxiliar a manter as características nutricionais e sensoriais dos produtos, em comparação às embalagens atuais, como potes e latas. Este projeto busca explorar uma abordagem inovadora na conservação de produtos de nutrição enteral, garantindo qualidade superior durante todo o período de validade.
J16: Inovação tecnológica de produto | M16: 📑
B17: Tipo de inovação | E17: Inovação tecnológica de processo | J17: Inovação tecnológica de processo | M17: 📑
J18: Inovação tecnológica de serviços | M18: 📑
B19: Elemento inovador | E19: Atualmente, os produtos em pó são fabricados em embalagens plásticas rígidas (potes), latas de alumínio e embalagens plásticas flexíveis (sachês). A utilização de embalagens a vácuo para nutrição enteral não é uma prática comum no mercado nacional. As principais diferenças ou vantagens esperadas entre as embalagens a vácuo propostas e as embalagens atuais incluem uma melhor preservação das características nutricionais e sensoriais dos produtos, uma maior proteção contra a umidade e oxidação, e uma potencial extensão do shelf-life dos produtos. Existem dados de referência que fundamentam essa comparação, demonstrando os benefícios do vácuo em outras indústrias alimentícias, o que justifica a implementação dessa tecnologia na nutrição enteral. | J19: - Não podem ser consideradas as inovações organizacionais, comerciais e de marketing
J20: Empresa ou segmento regional | M20: 📑
B21: Nível de inovação | E21: Inovador para o Brasil | J21: Inovador para o Brasil | M21: 📑
J22: Inovador para o Mundo | M22: 📑
B23: Risco tecnológico | E23: O principal desafio é entender como o mercado nacional reagirá ao novo tipo de embalagem para nutrição enteral. Além disso, é necessário considerar a limitação fabril, o investimento em novos equipamentos e em uma nova linha de processo, bem como manter um preço de venda competitivo. A reação do mercado será avaliada através de pesquisas de mercado, grupos focais e outros métodos para medir a aceitação do cliente. O investimento em novos equipamentos e linhas de processo inclui a aquisição de máquinas de envase a vácuo e a implementação de uma linha de produção dedicada. O plano de implementação envolve fases de testes e validação para garantir a eficiência e eficácia do processo. A colaboração com fornecedores e parceiros será fundamental para superar os desafios tecnológicos e de produção, garantindo que a cadeia de suprimentos esteja alinhada com os padrões de qualidade e eficiência exigidos. Um estudo de viabilidade econômica foi realizado, levando em consideração os investimentos necessários e o potencial retorno sobre o investimento (ROI), monitorando indicadores financeiros críticos para garantir a sustentabilidade do projeto.
B25: Metodologias | E25: A metodologia envolve a busca de fornecedores de embalagens que suportem o vácuo e de fornecedores de equipamentos com a tecnologia adequada para o envase e selagem dos produtos a vácuo. Um piloto industrial será realizado em parceria com um fornecedor. Os critérios específicos para a seleção dos fornecedores incluem considerações técnicas, qualidade, custo e capacidade de produção. O processo de avaliação de fornecedores garante que eles atendam aos padrões de qualidade necessários, assegurando que a implementação da nova tecnologia seja bem-sucedida e beneficie os consumidores finais.
B27: Equipe | E27: Nome Completo | F27: Cargo/Função | G27: Qualificação | H27: !
E28: Lizianne Shmeil | F28: Analista de P&D | G28: Pós-graduação | L28: Técnico | M28: 📑
L29: Graduação
L30: Pós-graduação
L31: Mestrado
L32: Doutorado
B35: Cronograma
B36: [anexar imagem - preferencialmente Gantt]

Sheet INOV00014
B2: PRODIET
B3: Pesquisa, Desenvolvimento & Inovação
B4: Formulário de PD&I - Ano 2023 | J4: Incentivado pela Lei do Bem | M4: TRUE
B5: - preencher somente os campos sombreados (cinza) e - adicionar cronograma no formato de imagem ao fim do formulário - preencher um deste para cada projeto de PD&I | J5: Objetiva tornar-se um Ativo | M5: FALSE
J6: Objetiva gerar patente/registro | M6: FALSE
B8: Dossiê do projeto
B9: Dados gerais para identificação e validação do projeto de PD&I
B11: Nome do projeto | E11: INOV000014 (2021 - ENERGYZIP 25%)
J12: Pesquisa básica | M12: 📑
B13: Classificação do projeto | E13: Desenvolvimento experimental | J13: Pesquisa aplicada | M13: 📑
J14: Desenvolvimento experimental | M14: 📑
B15: Objetivos do projeto | E15: A Prodiet tem como objetivo desenvolver um suplemento hipercalórico e hiperproteico líquido, visando permitir maior abertura no mercado público e privado. Atualmente, a empresa não possui este tipo de produto em seu portfólio, e existe uma demanda crescente por suplementos hiperproteicos no mercado. Este projeto também acompanhará o lançamento da linha de sistema fechado, oferecendo um mix de vendas para hospitais e sendo competitivo para processos públicos e para o mercado internacional. Para entender melhor o projeto, são necessárias informações específicas, como o público-alvo detalhado e os requisitos técnicos e regulatórios a serem atendidos. No mercado internacional, a demanda por suplementos hipercalóricos e hiperproteicos líquidos é impulsionada por um aumento na conscientização sobre saúde e nutrição, a necessidade de produtos de fácil administração em ambientes clínicos, e o crescimento da população idosa que requer suplementação proteica. Estudos de mercado internacionais indicam uma tendência crescente de consumidores buscando produtos que atendam a essas necessidades nutricionais específicas.
J16: Inovação tecnológica de produto | M16: 📑
B17: Tipo de inovação | E17: Inovação tecnológica de produto | J17: Inovação tecnológica de processo | M17: 📑
J18: Inovação tecnológica de serviços | M18: 📑
B19: Elemento inovador | E19: A inovação desse produto está no aumento do teor de proteína em comparação com os produtos de linha atuais. Isso possibilitará um ganho de mercado, tanto em relação à competição com outros suplementos quanto para fórmulas enterais que necessitam de um aporte proteico mais expressivo. O aumento de proteína será implementado em produtos específicos destinados a pacientes com maiores necessidades proteicas. O aumento no teor de proteína será alcançado através da adição de fontes proteicas de alta qualidade, como proteínas isoladas de soro de leite ou proteína vegetal concentrada, garantindo que o suplemento mantenha sua qualidade nutricional. | J19: - Não podem ser consideradas as inovações organizacionais, comerciais e de marketing
J20: Empresa ou segmento regional | M20: 📑
B21: Nível de inovação | E21: Empresa ou segmento regional | J21: Inovador para o Brasil | M21: 📑
J22: Inovador para o Mundo | M22: 📑
B23: Risco tecnológico | E23: O principal desafio no desenvolvimento dessa fórmula está na estabilização proteica/estrutural, pois o aumento do teor de proteína resulta em maior viscosidade, o que pode dificultar a administração das fórmulas enterais. A alta viscosidade pode afetar a administração, tornando o produto mais difícil de passar através de sondas e equipamentos de alimentação enteral. Na linha de produção, a viscosidade alta pode causar problemas de fluxo e preenchimento, exigindo ajustes nos equipamentos de envase. Para abordar esses desafios, a empresa está utilizando tecnologias de processamento que permitem a redução da viscosidade, como a hidrólise parcial das proteínas, e aditivos que estabilizam a fórmula. Além da viscosidade, estão sendo consideradas outras características sensoriais e de formulação, como sabor, cor e estabilidade ao longo do shelf-life, para garantir uma administração eficaz do produto.
B25: Metodologias | E25: A metodologia para este projeto inclui o desenvolvimento e testes piloto de uma fórmula com maior teor de proteínas. O objetivo é aumentar o teor de proteínas sem comprometer a liquidez do produto, garantindo que ele seja fácil de administrar. A quantidade de aumento de proteína desejada está sendo determinada com base em estudos de necessidades nutricionais dos pacientes alvo. Os indicadores de sucesso do projeto incluem a aceitação sensorial do produto, a estabilidade nutricional ao longo do shelf-life e a viabilidade de produção em larga escala. Os testes piloto estão sendo conduzidos com parâmetros rigorosos, como a solubilidade das proteínas, a viscosidade da fórmula e a estabilidade em diferentes condições de armazenamento.
B27: Equipe | E27: Nome Completo | F27: Cargo/Função | G27: Qualificação | H27: !
E28: Ana Claudia Zanini | F28: Analista Cientifico | G28: Mestrado | L28: Técnico | M28: 📑
E29: Márcio Henrique Nogueira | F29: Analista de P&D | G29: Doutorado | L29: Graduação
E30: Juliana Lamas Roberto | F30: Especialista de Estudo de Estabilidade | G30: Mestrado | L30: Pós-graduação
E31: Hellin dos Santos | F31: Gerente cientifico | G31: Mestrado | L31: Mestrado
E32: Ana Paula Celes | F32: Diretora Técnica | G32: Pós-graduação | L32: Doutorado
E33: Rafael Parreira Lorini | F33: Analista de P&D | G33: Pós-graduação
B35: Cronograma
B36: [anexar imagem - preferencialmente Gantt]

Sheet INOV00016
B2: PRODIET
B3: Pesquisa, Desenvolvimento & Inovação
B4: Formulário de PD&I - Ano 2023 | J4: Incentivado pela Lei do Bem | M4: TRUE
B5: - preencher somente os campos sombreados (cinza) e - adicionar cronograma no formato de imagem ao fim do formulário - preencher um deste para cada projeto de PD&I | J5: Objetiva tornar-se um Ativo | M5: FALSE
J6: Objetiva gerar patente/registro | M6: FALSE
B8: Dossiê do projeto
B9: Dados gerais para identificação e validação do projeto de PD&I
B11: Nome do projeto | E11: INOV000016 (2018 - LINHA TROPHIC SOYA LÍQUIDO)
J12: Pesquisa básica | M12: 📑
B13: Classificação do projeto | E13: Desenvolvimento experimental | J13: Pesquisa aplicada | M13: 📑
J14: Desenvolvimento experimental | M14: 📑
B15: Objetivos do projeto | E15: A Prodiet está expandindo o portfólio da linha 100% Soja com o desenvolvimento de um novo produto de alto perfil proteico e adição de fibras, destinado a consumidores com alergias alimentares às proteínas do leite. O objetivo é oferecer um suplemento nutricional robusto que atenda às necessidades específicas desse público-alvo. Os valores-alvo para o perfil proteico e de fibras são determinados com base em diretrizes nutricionais e necessidades do mercado. Especificamente, o novo produto deve fornecer aproximadamente 1,5 kcal/mL de energia, com um teor de proteína adequado para suportar a saúde muscular e uma quantidade significativa de fibras para promover a saúde digestiva. Esses valores foram estabelecidos após análise de literatura científica, recomendações de especialistas em nutrição e feedback de consumidores.
J16: Inovação tecnológica de produto | M16: 📑
B17: Tipo de inovação | E17: Inovação tecnológica de produto | J17: Inovação tecnológica de processo | M17: 📑
J18: Inovação tecnológica de serviços | M18: 📑
B19: Elemento inovador | E19: O elemento inovador do projeto reside na criação de um produto de alto teor proteico e adição de fibras, sem incluir proteínas de leite. Para alcançar essa formulação, a empresa está considerando o uso de proteínas vegetais, como proteína isolada de soja e ervilha, que oferecem um perfil aminoacídico completo e alta biodisponibilidade. Além disso, estão sendo incorporadas fibras solúveis e insolúveis, como inulina e fibra de chicória, para melhorar a saúde digestiva. Pesquisas e estudos de mercado justificam a escolha desse perfil nutricional, destacando a crescente demanda por produtos livres de alérgenos e ricos em nutrientes. Para abordar o desafio de criar um produto saboroso, a empresa está investindo em testes sensoriais e desenvolvimento de sabores agradáveis, colaborando com especialistas em aromas e palatabilidade. | J19: - Não podem ser consideradas as inovações organizacionais, comerciais e de marketing
J20: Empresa ou segmento regional | M20: 📑
B21: Nível de inovação | E21: Inovador para o Brasil | J21: Inovador para o Brasil | M21: 📑
J22: Inovador para o Mundo | M22: 📑
B23: Risco tecnológico | E23: O principal desafio tecnológico é a estabilização da fórmula, especialmente devido ao aumento do teor de proteína e fibras, que pode resultar em alta viscosidade, dificultando a administração do produto. Para estabilizar a fórmula, estão sendo consideradas abordagens específicas, como a utilização de agentes estabilizantes naturais e a otimização do processo de mistura. Estudos de formulação estão em andamento para encontrar o equilíbrio ideal entre proteína, fibras e viscosidade. Tecnologias de produção avançadas, como homogeneização de alta pressão, estão sendo avaliadas para lidar com a alta viscosidade. A empresa pode precisar investir em equipamentos especiais para garantir a consistência do produto. Para otimizar o processo de fabricação, a Prodiet está implementando protocolos rigorosos de controle de qualidade e consistência de lotes. Além disso, colaborações com pesquisadores acadêmicos e consultores estão sendo exploradas para obter insights adicionais sobre a estabilização do produto e superar os desafios tecnológicos.
B25: Metodologias | E25: A metodologia para este projeto inclui a realização de testes pilotos UHT e a avaliação de estudos de estabilidade da fórmula para garantir que o produto atinja os parâmetros necessários para a comercialização. Os principais objetivos dos testes pilotos UHT são a esterilização e a preservação da estabilidade nutricional e sensorial do produto. A capacidade de produção dos testes pilotos será comparada à escala de produção comercial para assegurar a viabilidade do processo. Estudos de estabilidade serão conduzidos em condições controladas de armazenamento, simulando temperaturas e umidades típicas para avaliar a durabilidade do produto ao longo do tempo. Testes acelerados de estabilidade estão planejados para prever o comportamento do produto em longo prazo, permitindo ajustes na formulação antes da produção em larga escala.
B27: Equipe | E27: Nome Completo | F27: Cargo/Função | G27: Qualificação | H27: !
E28: Rafael Lorini | F28: Analista de P&D | G28: Graduação | L28: Técnico | M28: 📑
E29: Luciana Dutra | F29: Gerente Técnica | G29: Pós-graduação | L29: Graduação
L30: Pós-graduação
L31: Mestrado
L32: Doutorado
B35: Cronograma
B36: [anexar imagem - preferencialmente Gantt]

Sheet INOV00017
B2: PRODIET
B3: Pesquisa, Desenvolvimento & Inovação
B4: Formulário de PD&I - Ano 2023 | J4: Incentivado pela Lei do Bem | M4: TRUE
B5: - preencher somente os campos sombreados (cinza) e - adicionar cronograma no formato de imagem ao fim do formulário - preencher um deste para cada projeto de PD&I | J5: Objetiva tornar-se um Ativo | M5: FALSE
J6: Objetiva gerar patente/registro | M6: FALSE
B8: Dossiê do projeto
B9: Dados gerais para identificação e validação do projeto de PD&I
B11: Nome do projeto | E11: INOV000017 (2020 - LINHA TROPHIC SOYA PÓ)
J12: Pesquisa básica | M12: 📑
B13: Classificação do projeto | E13: Desenvolvimento experimental | J13: Pesquisa aplicada | M13: 📑
J14: Desenvolvimento experimental | M14: 📑
B15: Objetivos do projeto | E15: A Prodiet tem como objetivo expandir a linha guarda-chuva Soya, desenvolvendo produtos em pó para nutrição enteral e oral voltados para o público adulto, com foco em editais de licitação. Este produto será inovador e específico para atender aos requisitos dos editais de licitação. Além de atender aos editais governamentais, o foco também incluirá a venda para o público geral. A demanda específica nos editais de licitação para produtos em pó de nutrição enteral e oral inclui critérios essenciais como composição nutricional adequada, custo competitivo e capacidade de atender grandes volumes. Esses critérios são determinados pelas necessidades de pacientes em ambientes hospitalares e programas de saúde pública.
J16: Inovação tecnológica de produto | M16: 📑
B17: Tipo de inovação | E17: Inovação tecnológica de produto | J17: Inovação tecnológica de processo | M17: 📑
J18: Inovação tecnológica de serviços | M18: 📑
B19: Elemento inovador | E19: O elemento inovador deste projeto é o desenvolvimento de uma linha de produtos em pó com 80% de proteínas de origem vegetal (soja) e apenas 20% de proteína animal, diferindo dos produtos líquidos existentes na linha Soya. Esta composição inovadora oferece vantagens significativas em termos de sustentabilidade e adequação a dietas específicas. A linha Soya existente será expandida para incluir produtos líquidos e em pó, mantendo duas sub-linhas distintas. O aumento da proporção de proteína de soja em relação à proteína animal se alinha à estratégia da Prodiet de oferecer produtos nutricionais mais sustentáveis e acessíveis, respondendo à crescente demanda por produtos vegetais. Os benefícios específicos desta composição incluem uma menor pegada ambiental, melhor aceitação por consumidores com restrições alimentares, e uma fonte de proteína completa e balanceada. | J19: - Não podem ser consideradas as inovações organizacionais, comerciais e de marketing
J20: Empresa ou segmento regional | M20: 📑
B21: Nível de inovação | E21: Empresa ou segmento regional | J21: Inovador para o Brasil | M21: 📑
J22: Inovador para o Mundo | M22: 📑
B23: Risco tecnológico | E23: O principal desafio tecnológico reside na estabilização do sabor e palatabilidade dos produtos, devido ao sabor residual da proteína de soja. A empresa está desenvolvendo estratégias para melhorar o sabor e a palatabilidade, como a aplicação de aromas que mascaram o sabor da proteína de soja e tornam o produto agradável tanto para administração enteral quanto oral. Para manter um custo competitivo, especialmente devido à presença de óleos em pó, estão sendo exploradas alternativas mais econômicas, como a utilização de óleo líquido e tecnologias de spray dryer para misturar proteínas, carboidratos e óleos. Estas estratégias buscam reduzir o custo sem comprometer a qualidade nutricional e sensorial do produto.
B25: Metodologias | E25: As metodologias adotadas incluem a busca por alternativas às gorduras em pó, como óleos líquidos de menor custo e maior solubilidade. A mistura de proteínas, carboidratos e óleo líquido por meio do processo de spray dryer está sendo testada para melhorar a solubilidade, aspecto e sabor do produto. Os testes de adsorção de óleo líquido através da maltodextrina de tapioca visam avaliar a solubilidade e a estabilidade do óleo na formulação. Estes testes estão sendo realizados em bancada, com resultados preliminares indicando uma boa estabilidade e solubilidade. O critério-chave para avaliar essas alternativas inclui o custo, solubilidade, estabilidade e aceitação sensorial do produto final. O prazo estimado para a conclusão dos testes e a determinação da melhor alternativa para as gorduras é de alguns meses, dependendo dos resultados dos testes em andamento. Caso as alternativas testadas não atinjam os resultados desejados, o plano de ação inclui a reavaliação das formulações e o ajuste das proporções dos ingredientes, bem como a busca por novos fornecedores e tecnologias que possam oferecer soluções mais adequadas. Esta abordagem garante que a Prodiet continue a desenvolver produtos que atendam aos altos padrões de qualidade, custo e aceitação no mercado.
B27: Equipe | E27: Nome Completo | F27: Cargo/Função | G27: Qualificação | H27: !
E28: Camila Mendes Pereira | F28: Aanalista de P&D | G28: Graduação | L28: Técnico | M28: 📑
E29: Luciana Dutra | F29: Gerente Técnica | G29: Pós-graduação | L29: Graduação
E30: Ana Paula Celes | F30: Diretora Técnica | G30: Pós-graduação | L30: Pós-graduação
L31: Mestrado
L32: Doutorado
B35: Cronograma
B36: [anexar imagem - preferencialmente Gantt]

Sheet INOV00021
B2: PRODIET
B3: Pesquisa, Desenvolvimento & Inovação
B4: Formulário de PD&I - Ano 2023 | J4: Incentivado pela Lei do Bem | M4: TRUE
B5: - preencher somente os campos sombreados (cinza) e - adicionar cronograma no formato de imagem ao fim do formulário - preencher um deste para cada projeto de PD&I | J5: Objetiva tornar-se um Ativo | M5: FALSE
J6: Objetiva gerar patente/registro | M6: FALSE
B8: Dossiê do projeto
B9: Dados gerais para identificação e validação do projeto de PD&I
B11: Nome do projeto | E11: INOV000021 (2022 - SOBREMESA)
J12: Pesquisa básica | M12: 📑
B13: Classificação do projeto | E13: Desenvolvimento experimental | J13: Pesquisa aplicada | M13: 📑
J14: Desenvolvimento experimental | M14: 📑
B15: Objetivos do projeto | E15: O projeto visa desenvolver uma nova forma de consumir os nutrientes 3+ do Immax, especificamente através de um sorvete nutritivo. A razão para criar essa nova forma de consumo é oferecer uma alternativa agradável e inovadora para a ingestão desses nutrientes, especialmente para pacientes que podem ter dificuldade em consumir suplementos tradicionais. Ao transformar os nutrientes em um sorvete, o objetivo é aumentar a adesão ao tratamento e proporcionar uma experiência de consumo mais agradável.
J16: Inovação tecnológica de produto | M16: 📑
B17: Tipo de inovação | E17: Inovação tecnológica de produto | J17: Inovação tecnológica de processo | M17: 📑
J18: Inovação tecnológica de serviços | M18: 📑
B19: Elemento inovador | E19: A inovação do projeto está na incorporação dos nutrientes do Immax em um sorvete. Esta abordagem não apenas replica os nutrientes existentes no Immax, mas também pode adicionar novos nutrientes, dependendo das necessidades nutricionais identificadas. A conclusão de que o sorvete seria a forma ótima para consumir os nutrientes 3+ do Immax foi baseada em estudos de aceitação sensorial e em pesquisas que indicam uma preferência por formas de consumo mais palatáveis e agradáveis. O sorvete pode incorporar os nutrientes do Immax através de técnicas de microencapsulação e estabilização, garantindo que nutrientes como proteínas, vitaminas, minerais e fibras estejam presentes no produto final. Os benefícios de oferecer esses nutrientes por meio de um sorvete incluem uma maior aceitação pelo público, facilidade de consumo, e potencial para uma melhor absorção dos nutrientes devido à sua forma palatável. | J19: - Não podem ser consideradas as inovações organizacionais, comerciais e de marketing
J20: Empresa ou segmento regional | M20: 📑
B21: Nível de inovação | E21: Inovador para o Brasil | J21: Inovador para o Brasil | M21: 📑
J22: Inovador para o Mundo | M22: 📑
B23: Risco tecnológico | E23: Um dos principais riscos tecnológicos é a não aceitação do mercado. Pesquisas de mercado preliminares indicam que existe um interesse crescente por produtos alimentícios que combinam prazer e saúde, mas ainda há incertezas quanto à aceitação específica de um sorvete nutricional. Para lidar com esse risco, a empresa planeja realizar testes de mercado e estratégias de marketing focadas em demonstrar os benefícios do produto, além de campanhas de educação nutricional. Medidas estão sendo tomadas para garantir que o sorvete mantenha a eficácia nutricional dos nutrientes do Immax durante todo o processo de fabricação e armazenamento, incluindo o uso de tecnologias de preservação e estabilização de nutrientes.
B25: Metodologias | E25: A metodologia envolve o desenvolvimento de uma sobremesa que possa ser acrescida dos nutrientes Pro 3+ do Immax, proporcionando aos pacientes uma forma alternativa e agradável de consumir esses ingredientes. A implementação dos nutrientes no sorvete será feita através de processos como microencapsulação, que protege os nutrientes durante a fabricação e armazenamento, garantindo sua estabilidade e biodisponibilidade. O mercado alvo inclui tanto o público geral quanto pacientes em tratamento nutricional, especialmente aqueles que necessitam de suplementação mas preferem formas de consumo mais agradáveis. O processo de desenvolvimento da sobremesa envolve várias etapas, incluindo pesquisa e desenvolvimento de formulações, testes sensoriais, e avaliações de estabilidade e segurança alimentar. A empresa pretende garantir a dosagem precisa dos nutrientes em cada porção de sorvete através de um rigoroso controle de qualidade durante a produção. Além disso, há planos para avaliar a aceitação do paciente em relação a essa nova forma de consumo através de estudos clínicos e feedback de consumidores. A empresa também está explorando outras formas criativas de oferecer os nutrientes do Immax, como barras nutricionais e bebidas fortificadas, para atender a diferentes preferências e necessidades dos pacientes.
B27: Equipe | E27: Nome Completo | F27: Cargo/Função | G27: Qualificação | H27: !
E28: Luciana Dutra | F28: Gerente P&D e AR | G28: Pós-graduação | L28: Técnico | M28: 📑
E29: Tahuany Caetano | F29: Analista MKT | G29: Pós-graduação | L29: Graduação
E30: Camila Pereira | F30: Anlaista P&D pleno | G30: Graduação | L30: Pós-graduação
E31: Lizianne Shmeil | F31: Anlaista P&D sênior | G31: Pós-graduação | L31: Mestrado
L32: Doutorado
B35: Cronograma
B36: [anexar imagem - preferencialmente Gantt]

Sheet INOV00022
B2: PRODIET
B3: Pesquisa, Desenvolvimento & Inovação
B4: Formulário de PD&I - Ano 2023 | J4: Incentivado pela Lei do Bem | M4: TRUE
B5: - preencher somente os campos sombreados (cinza) e - adicionar cronograma no formato de imagem ao fim do formulário - preencher um deste para cada projeto de PD&I | J5: Objetiva tornar-se um Ativo | M5: FALSE
J6: Objetiva gerar patente/registro | M6: FALSE
B8: Dossiê do projeto
