Workbook

Sheet Resumo
B1: PRODIET NUTRIÇÃO
B2: INOVAÇÃO TECNOLÓGICA 2015
B3: Resumo de investimentos
C6: Natureza | D6: TOTAL
C7: Material | D7: =SUM('Resumo dos Terceiros e MP'!C22:G22) -> 4139.11 | E7: (a)
C8: RH (Parcial inovação) | D8: ='Time Sheet'!K4 -> 694.85409 | E8: (b)
C9: RH (Exclusivo inovação) | D9: =SUMIFS('Salário e Custo Hora'!$Q$21:$Q$28,'Salário e Custo Hora'!$D$21:$D$28,"Exclusiva") -> 51793.855 | E9: (c)
C10: Terceiros | D10: =SUM('Resumo dos Terceiros e MP'!C20:G20) -> 178458.74 | E10: (a)
C11: Total | D11: =SUM(D7:D10) -> 235086.56
C12: Percentual Exclusão | D12: 0.6
C13: Exclusão da Base de cálculo do IRPJ e CSLL | D13: =D11*D12 -> 141051.94
C15: Economia Estimada | D15: =D13*34% -> 47957.659
C17: (a) Resumo dos terceiros e MP - detalhes das faturas em "Investimentos"
C18: (b) Time Sheet - funcionários com dedicação parcial
C19: (c) Salário e Custo Hora - Total com encargos dos funcionários exclusivos

Sheet Resumo dos Terceiros e MP
B1: PRODIET NUTRIÇÃO
B2: =Resumo!B2 -> INOVAÇÃO TECNOLÓGICA 2015
B3: Terceiros envolvidos em inovação | H3: ='Investimentos '!AA3 -> 182597.85
H4: =SUM(C20:G20)+SUM(C22:G22) -> 182597.85
B7: Terceiros | C7: Novos produtos | D7: Novas Mp | E7: Melhoria de processo | F7: Novo Copacker | G7: Melhoria de produto | H7: CNPJ | I7: Descrição dos serviços
B8: Associação Paranaense de Cultura - APC | C8: =SUMIFS('Investimentos '!V$5:V$72,'Investimentos '!$F$5:$F$72,'Resumo dos Terceiros e MP'!$B8) -> 217 | D8: =SUMIFS('Investimentos '!W$5:W$72,'Investimentos '!$F$5:$F$72,'Resumo dos Terceiros e MP'!$B8) -> 0 | E8: =SUMIFS('Investimentos '!X$5:X$72,'Investimentos '!$F$5:$F$72,'Resumo dos Terceiros e MP'!$B8) -> 560 | F8: =SUMIFS('Investimentos '!Y$5:Y$72,'Investimentos '!$F$5:$F$72,'Resumo dos Terceiros e MP'!$B8) -> 0 | G8: =SUMIFS('Investimentos '!Z$5:Z$72,'Investimentos '!$F$5:$F$72,'Resumo dos Terceiros e MP'!$B8) -> 0 | H8: 76.659.820/0003-13 | I8: Locação de espaço em laboratório para testes de bancada
B9: Bioagri Analises de alimentos Ltda | C9: =SUMIFS('Investimentos '!V$5:V$72,'Investimentos '!$F$5:$F$72,'Resumo dos Terceiros e MP'!$B9) -> 488.67 | D9: =SUMIFS('Investimentos '!W$5:W$72,'Investimentos '!$F$5:$F$72,'Resumo dos Terceiros e MP'!$B9) -> 0 | E9: =SUMIFS('Investimentos '!X$5:X$72,'Investimentos '!$F$5:$F$72,'Resumo dos Terceiros e MP'!$B9) -> 562.45 | F9: =SUMIFS('Investimentos '!Y$5:Y$72,'Investimentos '!$F$5:$F$72,'Resumo dos Terceiros e MP'!$B9) -> 0 | G9: =SUMIFS('Investimentos '!Z$5:Z$72,'Investimentos '!$F$5:$F$72,'Resumo dos Terceiros e MP'!$B9) -> 0 | H9: 00.000.410/0001-32 | I9: Serviços de análise laboratorial
B10: Fundação de desenv. Da pesquisa do agronegócio - FUNDEPAG | C10: =SUMIFS('Investimentos '!V$5:V$72,'Investimentos '!$F$5:$F$72,'Resumo dos Terceiros e MP'!$B10) -> 0 | D10: =SUMIFS('Investimentos '!W$5:W$72,'Investimentos '!$F$5:$F$72,'Resumo dos Terceiros e MP'!$B10) -> 0 | E10: =SUMIFS('Investimentos '!X$5:X$72,'Investimentos '!$F$5:$F$72,'Resumo dos Terceiros e MP'!$B10) -> 4301.39 | F10: =SUMIFS('Investimentos '!Y$5:Y$72,'Investimentos '!$F$5:$F$72,'Resumo dos Terceiros e MP'!$B10) -> 0 | G10: =SUMIFS('Investimentos '!Z$5:Z$72,'Investimentos '!$F$5:$F$72,'Resumo dos Terceiros e MP'!$B10) -> 0 | H10: 50.276.237/0001-78 | I10: Inscrição curso de lecitinação
B11: Fundação de estudos e pesquisas aquaticas - FUNDESPA | C11: =SUMIFS('Investimentos '!V$5:V$72,'Investimentos '!$F$5:$F$72,'Resumo dos Terceiros e MP'!$B11) -> 680 | D11: =SUMIFS('Investimentos '!W$5:W$72,'Investimentos '!$F$5:$F$72,'Resumo dos Terceiros e MP'!$B11) -> 0 | E11: =SUMIFS('Investimentos '!X$5:X$72,'Investimentos '!$F$5:$F$72,'Resumo dos Terceiros e MP'!$B11) -> 850 | F11: =SUMIFS('Investimentos '!Y$5:Y$72,'Investimentos '!$F$5:$F$72,'Resumo dos Terceiros e MP'!$B11) -> 0 | G11: =SUMIFS('Investimentos '!Z$5:Z$72,'Investimentos '!$F$5:$F$72,'Resumo dos Terceiros e MP'!$B11) -> 680 | H11: 61.379.657/0001-04 | I11: Pesquisa de materiais - tamanho de partícula
B12: Ilsi Brasil - Internacional Life Sciences Institute do Brasil | C12: =SUMIFS('Investimentos '!V$5:V$72,'Investimentos '!$F$5:$F$72,'Resumo dos Terceiros e MP'!$B12) -> 14975 | D12: =SUMIFS('Investimentos '!W$5:W$72,'Investimentos '!$F$5:$F$72,'Resumo dos Terceiros e MP'!$B12) -> 0 | E12: =SUMIFS('Investimentos '!X$5:X$72,'Investimentos '!$F$5:$F$72,'Resumo dos Terceiros e MP'!$B12) -> 0 | F12: =SUMIFS('Investimentos '!Y$5:Y$72,'Investimentos '!$F$5:$F$72,'Resumo dos Terceiros e MP'!$B12) -> 0 | G12: =SUMIFS('Investimentos '!Z$5:Z$72,'Investimentos '!$F$5:$F$72,'Resumo dos Terceiros e MP'!$B12) -> 0 | H12: 65.086.001/001-46 | I12: Workshop Internacional, cursos, palestras sobre tecnologia e novos produtos.
B13: Labor Tres Laboratorios e Consultoria Tecnica Ltda | C13: =SUMIFS('Investimentos '!V$5:V$72,'Investimentos '!$F$5:$F$72,'Resumo dos Terceiros e MP'!$B13) -> 570 | D13: =SUMIFS('Investimentos '!W$5:W$72,'Investimentos '!$F$5:$F$72,'Resumo dos Terceiros e MP'!$B13) -> 570 | E13: =SUMIFS('Investimentos '!X$5:X$72,'Investimentos '!$F$5:$F$72,'Resumo dos Terceiros e MP'!$B13) -> 1995 | F13: =SUMIFS('Investimentos '!Y$5:Y$72,'Investimentos '!$F$5:$F$72,'Resumo dos Terceiros e MP'!$B13) -> 0 | G13: =SUMIFS('Investimentos '!Z$5:Z$72,'Investimentos '!$F$5:$F$72,'Resumo dos Terceiros e MP'!$B13) -> 0 | H13: 02.021.076/0001-29 | I13: Avaliação fisico-química de alimentos
B14: M Cassab Comercio e Industria Ltda | C14: =SUMIFS('Investimentos '!V$5:V$72,'Investimentos '!$F$5:$F$72,'Resumo dos Terceiros e MP'!$B14) -> 0 | D14: =SUMIFS('Investimentos '!W$5:W$72,'Investimentos '!$F$5:$F$72,'Resumo dos Terceiros e MP'!$B14) -> 0 | E14: =SUMIFS('Investimentos '!X$5:X$72,'Investimentos '!$F$5:$F$72,'Resumo dos Terceiros e MP'!$B14) -> 0 | F14: =SUMIFS('Investimentos '!Y$5:Y$72,'Investimentos '!$F$5:$F$72,'Resumo dos Terceiros e MP'!$B14) -> 2496.2 | G14: =SUMIFS('Investimentos '!Z$5:Z$72,'Investimentos '!$F$5:$F$72,'Resumo dos Terceiros e MP'!$B14) -> 0 | H14: 49.698.723/0001-03 | I14: Análise de laboratório
B15: Tetra Pack Ltda | C15: =SUMIFS('Investimentos '!V$5:V$72,'Investimentos '!$F$5:$F$72,'Resumo dos Terceiros e MP'!$B15) -> 4489.795 | D15: =SUMIFS('Investimentos '!W$5:W$72,'Investimentos '!$F$5:$F$72,'Resumo dos Terceiros e MP'!$B15) -> 0 | E15: =SUMIFS('Investimentos '!X$5:X$72,'Investimentos '!$F$5:$F$72,'Resumo dos Terceiros e MP'!$B15) -> 4489.795 | F15: =SUMIFS('Investimentos '!Y$5:Y$72,'Investimentos '!$F$5:$F$72,'Resumo dos Terceiros e MP'!$B15) -> 0 | G15: =SUMIFS('Investimentos '!Z$5:Z$72,'Investimentos '!$F$5:$F$72,'Resumo dos Terceiros e MP'!$B15) -> 0 | H15: 61.528.030/0001-60 | I15: Teste Piloto UHT - Assessoria / consultoria
B16: TUV SUD SFDK Laboratório de análise de produtos Ltda. | C16: =SUMIFS('Investimentos '!V$5:V$72,'Investimentos '!$F$5:$F$72,'Resumo dos Terceiros e MP'!$B16) -> 0 | D16: =SUMIFS('Investimentos '!W$5:W$72,'Investimentos '!$F$5:$F$72,'Resumo dos Terceiros e MP'!$B16) -> 405.07 | E16: =SUMIFS('Investimentos '!X$5:X$72,'Investimentos '!$F$5:$F$72,'Resumo dos Terceiros e MP'!$B16) -> 0 | F16: =SUMIFS('Investimentos '!Y$5:Y$72,'Investimentos '!$F$5:$F$72,'Resumo dos Terceiros e MP'!$B16) -> 405.07 | G16: =SUMIFS('Investimentos '!Z$5:Z$72,'Investimentos '!$F$5:$F$72,'Resumo dos Terceiros e MP'!$B16) -> 710.15 | H16: 55.953.079/0001-67 | I16: Serviços de análise laboratorial
B17: Nutrimento Gestão de Dados Empresariais Ltda. | C17: =SUMIFS('Investimentos '!V$5:V$72,'Investimentos '!$F$5:$F$72,'Resumo dos Terceiros e MP'!$B17) -> 8125.84 | D17: =SUMIFS('Investimentos '!W$5:W$72,'Investimentos '!$F$5:$F$72,'Resumo dos Terceiros e MP'!$B17) -> 8125.84 | E17: =SUMIFS('Investimentos '!X$5:X$72,'Investimentos '!$F$5:$F$72,'Resumo dos Terceiros e MP'!$B17) -> 8125.84 | F17: =SUMIFS('Investimentos '!Y$5:Y$72,'Investimentos '!$F$5:$F$72,'Resumo dos Terceiros e MP'!$B17) -> 8125.84 | G17: =SUMIFS('Investimentos '!Z$5:Z$72,'Investimentos '!$F$5:$F$72,'Resumo dos Terceiros e MP'!$B17) -> 8125.84 | H17: 03.150.501/0001-42 | I17: Analisa os testes dos produtos e dá assistência na parametrização do produto e dos novos testes a serem feitos. Faz acompanhamento técnico de todos os projetos de pesquisa e desenvolvimento. | J17: Ana Paula Celes
B18: VLL Moura Serviços de Apoio Administrativo | C18: =SUMIFS('Investimentos '!V$5:V$72,'Investimentos '!$F$5:$F$72,'Resumo dos Terceiros e MP'!$B18) -> 21.910878 | D18: =SUMIFS('Investimentos '!W$5:W$72,'Investimentos '!$F$5:$F$72,'Resumo dos Terceiros e MP'!$B18) -> 21.910878 | E18: =SUMIFS('Investimentos '!X$5:X$72,'Investimentos '!$F$5:$F$72,'Resumo dos Terceiros e MP'!$B18) -> 21.910878 | F18: =SUMIFS('Investimentos '!Y$5:Y$72,'Investimentos '!$F$5:$F$72,'Resumo dos Terceiros e MP'!$B18) -> 21.910878 | G18: =SUMIFS('Investimentos '!Z$5:Z$72,'Investimentos '!$F$5:$F$72,'Resumo dos Terceiros e MP'!$B18) -> 21.910878 | H18: 18.390.865/0001-77 | I18: Acompanhamento de resultados das análises realizadas nos produtos em teste. | J18: Vera Lucia Leite Moura
B19: L Dutra Serviços ME | C19: =SUMIFS('Investimentos '!V$5:V$72,'Investimentos '!$F$5:$F$72,'Resumo dos Terceiros e MP'!$B19) -> 19654.88 | D19: =SUMIFS('Investimentos '!W$5:W$72,'Investimentos '!$F$5:$F$72,'Resumo dos Terceiros e MP'!$B19) -> 19654.88 | E19: =SUMIFS('Investimentos '!X$5:X$72,'Investimentos '!$F$5:$F$72,'Resumo dos Terceiros e MP'!$B19) -> 19654.88 | F19: =SUMIFS('Investimentos '!Y$5:Y$72,'Investimentos '!$F$5:$F$72,'Resumo dos Terceiros e MP'!$B19) -> 19654.88 | G19: =SUMIFS('Investimentos '!Z$5:Z$72,'Investimentos '!$F$5:$F$72,'Resumo dos Terceiros e MP'!$B19) -> 19654.88 | H19: 18.337.175/0001-54 | I19: Acompanha e faz teste nos produtos para validação de lote piloto, teste de validade do produto, teste de caracterísca e teste de de administração do produto final.Visto que são produtos de alimentação hospitalar, oral e domiciliar pós-internação. | J19: Luciana Dutra
B20: TOTAL dos terceiros | C20: =SUM(C8:C19) -> 49223.096 | D20: =SUM(D8:D19) -> 28777.701 | E20: =SUM(E8:E19) -> 40561.266 | F20: =SUM(F8:F19) -> 30703.901 | G20: =SUM(G8:G19) -> 29192.781 | H20: =SUM(C20:G20) -> 178458.74
B22: Materiais | C22: =SUMIFS('Investimentos '!V$5:V$72,'Investimentos '!$I$5:$I$72,"Material") -> 1786.6567 | D22: =SUMIFS('Investimentos '!W$5:W$72,'Investimentos '!$I$5:$I$72,"Material") -> 41 | E22: =SUMIFS('Investimentos '!X$5:X$72,'Investimentos '!$I$5:$I$72,"Material") -> 2311.4533 | F22: =SUMIFS('Investimentos '!Y$5:Y$72,'Investimentos '!$I$5:$I$72,"Material") -> 0 | G22: =SUMIFS('Investimentos '!Z$5:Z$72,'Investimentos '!$I$5:$I$72,"Material") -> 0 | H22: =SUM(C22:G22) -> 4139.11
B24: Total | C24: =SUM(C20:C22) -> 51009.753 | D24: =SUM(D20:D22) -> 28818.701 | E24: =SUM(E20:E22) -> 42872.719 | F24: =SUM(F20:F22) -> 30703.901 | G24: =SUM(G20:G22) -> 29192.781 | H24: =SUM(C24:G24) -> 182597.85
B26: Detalhes das faturas em "Investimentos"

Sheet Salário e Custo Hora
B1: PRODIET NUTRIÇÃO LTDA.
B2: =Resumo!B2 -> INOVAÇÃO TECNOLÓGICA 2015
B3: Salário bruto e Custo Hora
J4: INSS
B5: Encargos sobre folha | J5: 0.2 | K5: Patronal
B6: INSS | D6: FGTS | E6: Férias | F6: 13º | G6: Total | J6: 0.058 | K6: Terceiros
B7: =SUM(J5:J7) -> 0.273 | D7: 0.08 | E7: =((1/12)+(1/12/3))*(1+$D$7+$B$7) -> 0.15033333 | F7: =(1/12)*(1+$D$7+$B$7) -> 0.11275 | G7: =SUM(B7:F7) -> 0.61608333 | J7: 0.015 | K7: RAT
B9: Salário Bruto
B10: Nome | C10: Apelido | D10: Dedicação | E10: 42005 | F10: 42036 | G10: 42064 | H10: 42095 | I10: 42125 | J10: 42156 | K10: 42186 | L10: 42217 | M10: 42248 | N10: 42278 | O10: 42309 | P10: 42339 | Q10: Total Ano | R10: Escolaridade | S10: CPF
B11: Aline Francielle Fracasso | C11: Aline | D11: Exclusiva | I11: 3302 | J11: =I11 -> 3302 | K11: 3599 | Q11: =SUM(E11:P11) -> 10203 | T11: Admitida em 04/05/2015 e demitida em 07/2015
B12: Amid Tony Ibrahim | C12: Amid | D12: Exclusiva | L12: 1992 | M12: =L12 -> 1992 | N12: =M12 -> 1992 | O12: =N12 -> 1992 | P12: =O12 -> 1992 | Q12: =SUM(E12:P12) -> 9960 | T12: Admitido em 27/08/2015
B13: Alisson Willian Arruda Montanini | C13: Alisson | D13: Parcial | E13: 1823 | F13: 1823 | G13: 1823 | H13: 1823 | I13: 1823 | J13: 1823 | K13: 1823 | L13: 1987 | M13: 1987 | N13: 1987 | O13: 1987 | P13: 1987 | Q13: =SUM(E13:P13) -> 22696
B14: Felipe Camargo Chavita | C14: Felipe | D14: Parcial | E14: 2025 | F14: 2025 | G14: 2025 | H14: 2329 | I14: 2329 | J14: 2654 | K14: 2654 | L14: 2893 | M14: 2893 | N14: 2893 | O14: 2893 | P14: 2893 | Q14: =SUM(E14:P14) -> 30506 | R14: Graduado
B15: Lucas Leandro Matias do Nascimento | C15: Lucas | D15: Parcial | E15: 1355 | F15: 1355 | G15: 1355 | H15: 1355 | I15: 1355 | J15: 1355 | K15: 1355 | L15: 1477 | Q15: =SUM(E15:P15) -> 10962
B16: Maurício de Sousa Soares | C16: Maurício | D16: Parcial | E16: 1298 | F16: 1298 | G16: 1298 | H16: 1298 | I16: 1298 | J16: 1298 | K16: 1298 | L16: 1415 | M16: 1415 | N16: 1415 | O16: 1415 | Q16: =SUM(E16:P16) -> 14746
B17: Erica Ferreira Serra da Silva | C17: Erica | D17: Exclusiva | E17: 3962 | F17: 3962 | G17: =F17 -> 3962 | Q17: =SUM(E17:P17) -> 11886 | R17: Pós-graduado | T17: Demitida em 03/2015
B20: Salário Bruto com encargos
B21: Nome | C21: Apelido | D21: Dedicação | E21: =E10 -> 42005 | F21: =F10 -> 42036 | G21: =G10 -> 42064 | H21: =H10 -> 42095 | I21: =I10 -> 42125 | J21: =J10 -> 42156 | K21: =K10 -> 42186 | L21: =L10 -> 42217 | ... P21: =P10 -> 42339 | Q21: Total Ano
B22: =B11 -> Aline Francielle Fracasso | C22: =C11 -> Aline | D22: =D11 -> Exclusiva | E22: =E11*(1+$G$7) -> 0 | F22: =F11*(1+$G$7) -> 0 | G22: =G11*(1+$G$7) -> 0 | H22: =H11*(1+$G$7) -> 0 | I22: =I11*(1+$G$7) -> 5336.3072 | J22: =J11*(1+$G$7) -> 5336.3072 | K22: =K11*(1+$G$7) -> 5816.2839 | L22: =L11*(1+$G$7) -> 0 | ... P22: =P11*(1+$G$7) -> 0 | Q22: =SUM(E22:P22) -> 16488.898
B23: =B12 -> Amid Tony Ibrahim | C23: =C12 -> Amid | D23: =D12 -> Exclusiva | E23: =E12*(1+$G$7) -> 0 | F23: =F12*(1+$G$7) -> 0 | G23: =G12*(1+$G$7) -> 0 | H23: =H12*(1+$G$7) -> 0 | I23: =I12*(1+$G$7) -> 0 | J23: =J12*(1+$G$7) -> 0 | K23: =K12*(1+$G$7) -> 0 | L23: =L12*(1+$G$7) -> 3219.238 | ... P23: =P12*(1+$G$7) -> 3219.238 | Q23: =SUM(E23:P23) -> 16096.19
B24: =B13 -> Alisson Willian Arruda Montanini | C24: =C13 -> Alisson | D24: =D13 -> Parcial | E24: =E13*(1+$G$7) -> 2946.1199 | F24: =F13*(1+$G$7) -> 2946.1199 | G24: =G13*(1+$G$7) -> 2946.1199 | H24: =H13*(1+$G$7) -> 2946.1199 | I24: =I13*(1+$G$7) -> 2946.1199 | J24: =J13*(1+$G$7) -> 2946.1199 | K24: =K13*(1+$G$7) -> 2946.1199 | L24: =L13*(1+$G$7) -> 3211.1576 | ... P24: =P13*(1+$G$7) -> 3211.1576 | Q24: =SUM(E24:P24) -> 36678.627
B25: =B14 -> Felipe Camargo Chavita | C25: =C14 -> Felipe | D25: =D14 -> Parcial | E25: =E14*(1+$G$7) -> 3272.5688 | F25: =F14*(1+$G$7) -> 3272.5688 | G25: =G14*(1+$G$7) -> 3272.5688 | H25: =H14*(1+$G$7) -> 3763.8581 | I25: =I14*(1+$G$7) -> 3763.8581 | J25: =J14*(1+$G$7) -> 4289.0852 | K25: =K14*(1+$G$7) -> 4289.0852 | L25: =L14*(1+$G$7) -> 4675.3291 | ... P25: =P14*(1+$G$7) -> 4675.3291 | Q25: =SUM(E25:P25) -> 49300.238
B26: =B15 -> Lucas Leandro Matias do Nascimento | C26: =C15 -> Lucas | D26: =D15 -> Parcial | E26: =E15*(1+$G$7) -> 2189.7929 | F26: =F15*(1+$G$7) -> 2189.7929 | G26: =G15*(1+$G$7) -> 2189.7929 | H26: =H15*(1+$G$7) -> 2189.7929 | I26: =I15*(1+$G$7) -> 2189.7929 | J26: =J15*(1+$G$7) -> 2189.7929 | K26: =K15*(1+$G$7) -> 2189.7929 | L26: =L15*(1+$G$7) -> 2386.9551 | ... P26: =P15*(1+$G$7) -> 0 | Q26: =SUM(E26:P26) -> 17715.506
B27: =B16 -> Maurício de Sousa Soares | C27: =C16 -> Maurício | D27: =D16 -> Parcial | E27: =E16*(1+$G$7) -> 2097.6762 | F27: =F16*(1+$G$7) -> 2097.6762 | G27: =G16*(1+$G$7) -> 2097.6762 | H27: =H16*(1+$G$7) -> 2097.6762 | I27: =I16*(1+$G$7) -> 2097.6762 | J27: =J16*(1+$G$7) -> 2097.6762 | K27: =K16*(1+$G$7) -> 2097.6762 | L27: =L16*(1+$G$7) -> 2286.7579 | ... P27: =P16*(1+$G$7) -> 0 | Q27: =SUM(E27:P27) -> 23830.765
B28: =B17 -> Erica Ferreira Serra da Silva | C28: =C17 -> Erica | D28: =D17 -> Exclusiva | E28: =E17*(1+$G$7) -> 6402.9222 | F28: =F17*(1+$G$7) -> 6402.9222 | G28: =G17*(1+$G$7) -> 6402.9222 | H28: =H17*(1+$G$7) -> 0 | I28: =I17*(1+$G$7) -> 0 | J28: =J17*(1+$G$7) -> 0 | K28: =K17*(1+$G$7) -> 0 | L28: =L17*(1+$G$7) -> 0 | ... P28: =P17*(1+$G$7) -> 0 | Q28: =SUM(E28:P28) -> 19208.767
B30: Custo Hora com encargos
B31: Nome | C31: Apelido | D31: Dedicação | E31: =E21 -> 42005 | F31: =F21 -> 42036 | G31: =G21 -> 42064 | H31: =H21 -> 42095 | I31: =I21 -> 42125 | J31: =J21 -> 42156 | K31: =K21 -> 42186 | L31: =L21 -> 42217 | ... P31: =P21 -> 42339
B32: =B22 -> Aline Francielle Fracasso | C32: =C22 -> Aline | D32: =D22 -> Exclusiva | E32: =E22/E$42 -> 0 | F32: =F22/F$42 -> 0 | G32: =G22/G$42 -> 0 | H32: =H22/H$42 -> 0 | I32: =I22/I$42 -> 31.464075 | J32: =J22/J$42 -> 29.965786 | K32: =K22/K$42 -> 29.82098 | L32: =L22/L$42 -> 0 | ... P32: =P22/P$42 -> 0
B33: =B23 -> Amid Tony Ibrahim | C33: =C23 -> Amid | D33: =D23 -> Exclusiva | E33: =E23/E$42 -> 0 | F33: =F23/F$42 -> 0 | G33: =G23/G$42 -> 0 | H33: =H23/H$42 -> 0 | I33: =I23/I$42 -> 0 | J33: =J23/J$42 -> 0 | K33: =K23/K$42 -> 0 | L33: =L23/L$42 -> 18.077482 | ... P33: =P23/P$42 -> 18.981356
B34: =B24 -> Alisson Willian Arruda Montanini | C34: =C24 -> Alisson | D34: =D24 -> Parcial | E34: =E24/E$42 -> 15.791809 | F34: =F24/F$42 -> 17.37099 | G34: =G24/G$42 -> 15.791809 | H34: =H24/H$42 -> 16.5438 | I34: =I24/I$42 -> 17.37099 | J34: =J24/J$42 -> 16.5438 | K34: =K24/K$42 -> 15.105209 | L34: =L24/L$42 -> 18.032107 | ... P34: =P24/P$42 -> 18.933712
B35: =B25 -> Felipe Camargo Chavita | C35: =C25 -> Felipe | D35: =D25 -> Parcial | E35: =E25/E$42 -> 17.541642 | F35: =F25/F$42 -> 19.295806 | G35: =G25/G$42 -> 17.541642 | H35: =H25/H$42 -> 21.135771 | I35: =I25/I$42 -> 22.192559 | J35: =J25/J$42 -> 24.085159 | K35: =K25/K$42 -> 21.990798 | L35: =L25/L$42 -> 26.254094 | ... P35: =P25/P$42 -> 27.566799
B36: =B26 -> Lucas Leandro Matias do Nascimento | C36: =C26 -> Lucas | D36: =D26 -> Parcial | E36: =E26/E$42 -> 11.737741 | F36: =F26/F$42 -> 12.911515 | G36: =G26/G$42 -> 11.737741 | H36: =H26/H$42 -> 12.296681 | I36: =I26/I$42 -> 12.911515 | J36: =J26/J$42 -> 12.296681 | K36: =K26/K$42 -> 11.227404 | L36: =L26/L$42 -> 13.403836 | ... P36: =P26/P$42 -> 0
B37: =B27 -> Maurício de Sousa Soares | C37: =C27 -> Maurício | D37: =D27 -> Parcial | E37: =E27/E$42 -> 11.243976 | F37: =F27/F$42 -> 12.368374 | G37: =G27/G$42 -> 11.243976 | H37: =H27/H$42 -> 11.779403 | I37: =I27/I$42 -> 12.368374 | J37: =J27/J$42 -> 11.779403 | K37: =K27/K$42 -> 10.755107 | L37: =L27/L$42 -> 12.841183 | ... P37: =P27/P$42 -> 0
B38: =B28 -> Erica Ferreira Serra da Silva | C38: =C28 -> Erica | D38: =D28 -> Exclusiva | E38: =E28/E$42 -> 34.320981 | F38: =F28/F$42 -> 37.753079 | G38: =G28/G$42 -> 34.320981 | H38: =H28/H$42 -> 0 | I38: =I28/I$42 -> 0 | J38: =J28/J$42 -> 0 | K38: =K28/K$42 -> 0 | L38: =L28/L$42 -> 0 | ... P38: =P28/P$42 -> 0
B40: Horas Úteis - CWB | E40: =E31 -> 42005 | F40: =F31 -> 42036 | G40: =G31 -> 42064 | H40: =H31 -> 42095 | I40: =I31 -> 42125 | J40: =J31 -> 42156 | K40: =K31 -> 42186 | L40: =L31 -> 42217 | ... P40: =P31 -> 42339
B41: Dias Úteis | E41: =VLOOKUP(E40,'Dias Úteis'!$E$7:$G$18,3,FALSE) -> 22 | F41: =VLOOKUP(F40,'Dias Úteis'!$E$7:$G$18,3,FALSE) -> 20 | G41: =VLOOKUP(G40,'Dias Úteis'!$E$7:$G$18,3,FALSE) -> 22 | H41: =VLOOKUP(H40,'Dias Úteis'!$E$7:$G$18,3,FALSE) -> 21 | I41: =VLOOKUP(I40,'Dias Úteis'!$E$7:$G$18,3,FALSE) -> 20 | J41: =VLOOKUP(J40,'Dias Úteis'!$E$7:$G$18,3,FALSE) -> 21 | K41: =VLOOKUP(K40,'Dias Úteis'!$E$7:$G$18,3,FALSE) -> 23 | L41: =VLOOKUP(L40,'Dias Úteis'!$E$7:$G$18,3,FALSE) -> 21 | ... P41: =VLOOKUP(P40,'Dias Úteis'!$E$7:$G$18,3,FALSE) -> 20
A42: (a) | B42: Horas Úteis | E42: =8.48*E41 -> 186.56 | F42: =8.48*F41 -> 169.6 | G42: =8.48*G41 -> 186.56 | H42: =8.48*H41 -> 178.08 | I42: =8.48*I41 -> 169.6 | J42: =8.48*J41 -> 178.08 | K42: =8.48*K41 -> 195.04 | L42: =8.48*L41 -> 178.08 | ... P42: =8.48*P41 -> 169.6
A46: (a) | B46: Confimado com Alexandre Velozo, via fone, que os funcionários trabalham 44 horas semanais.

Sheet Time Sheet
B1: PRODIET NUTRIÇÃO
B2: Time Sheet - equipe parcial
B3: Funcionários que auxiliam/executam tarefas nos projetos de P&D.
H4: =SUM(H6:H30) -> 1.6597222 | K4: =SUM(K6:K30) -> 694.85409
B5: Funcionário | C5: Projeto | D5: Data | E5: Mês | F5: Horário Início | G5: Horário Fim | H5: Horas totais | I5: Apelido | J5: Custo por hora | K5: Custo total
B6: Alisson Montanini | C6: Segurança alimentar | D6: 42038 | E6: =MONTH(D6) -> 2 | F6: 0.41666667 | G6: 0.4375 | H6: 0.020833333 | I6: Alisson | J6: =VLOOKUP(I6,'Salário e Custo Hora'!$C$31:$P$38,'Time Sheet'!E6+2,FALSE) -> 17.37099 | K6: =H6*24*J6 -> 8.685495
B7: Alisson Montanini | C7: Novo Copacker Produtos Líquidos | D7: 42089 | E7: =MONTH(D7) -> 3 | F7: 0.60416667 | G7: 0.70833333 | H7: 0.10416667 | I7: Alisson | J7: =VLOOKUP(I7,'Salário e Custo Hora'!$C$31:$P$38,'Time Sheet'!E7+2,FALSE) -> 15.791809 | K7: =H7*24*J7 -> 39.479523
B8: Alisson Montanini | C8: Energyzip Master pó | D8: 42142 | E8: =MONTH(D8) -> 5 | F8: 0.58333333 | G8: 0.70833333 | H8: 0.125 | I8: Alisson | J8: =VLOOKUP(I8,'Salário e Custo Hora'!$C$31:$P$38,'Time Sheet'!E8+2,FALSE) -> 17.37099 | K8: =H8*24*J8 -> 52.11297
B9: Alisson Montanini | C9: Controle em Shelf Life | D9: 42145 | E9: =MONTH(D9) -> 5 | F9: 0.625 | G9: 0.70833333 | H9: 0.083333333 | I9: Alisson | J9: =VLOOKUP(I9,'Salário e Custo Hora'!$C$31:$P$38,'Time Sheet'!E9+2,FALSE) -> 17.37099 | K9: =H9*24*J9 -> 34.74198
B10: Alisson Montanini | C10: Controle em Shelf Life | D10: 42180 | E10: =MONTH(D10) -> 6 | F10: 0.58333333 | G10: 0.64583333 | H10: 0.0625 | I10: Alisson | J10: =VLOOKUP(I10,'Salário e Custo Hora'!$C$31:$P$38,'Time Sheet'!E10+2,FALSE) -> 16.5438 | K10: =H10*24*J10 -> 24.8157
B11: Alisson Montanini | C11: Controle em Shelf Life | D11: 42236 | E11: =MONTH(D11) -> 8 | F11: 0.41666667 | G11: 0.45833333 | H11: 0.041666667 | I11: Alisson | J11: =VLOOKUP(I11,'Salário e Custo Hora'!$C$31:$P$38,'Time Sheet'!E11+2,FALSE) -> 18.032107 | K11: =H11*24*J11 -> 18.032107
B12: Alisson Montanini | C12: Controle em Shelf Life | D12: 42271 | E12: =MONTH(D12) -> 9 | F12: 0.625 | G12: 0.72916667 | H12: 0.10416667 | I12: Alisson | J12: =VLOOKUP(I12,'Salário e Custo Hora'!$C$31:$P$38,'Time Sheet'!E12+2,FALSE) -> 18.933712 | K12: =H12*24*J12 -> 47.33428
B13: Alisson Montanini | C13: Trophic Infant liq | D13: 42282 | E13: =MONTH(D13) -> 10 | F13: 0.60416667 | G13: 0.70833333 | H13: 0.10416667 | I13: Alisson | J13: =VLOOKUP(I13,'Salário e Custo Hora'!$C$31:$P$38,'Time Sheet'!E13+2,FALSE) -> 18.032107 | K13: =H13*24*J13 -> 45.080267
B14: Alisson Montanini | C14: Macronutrientes | D14: 42282 | E14: =MONTH(D14) -> 10 | F14: 0.64583333 | G14: 0.6875 | H14: 0.041666667 | I14: Alisson | J14: =VLOOKUP(I14,'Salário e Custo Hora'!$C$31:$P$38,'Time Sheet'!E14+2,FALSE) -> 18.032107 | K14: =H14*24*J14 -> 18.032107
B15: Alisson Montanini | C15: Trophic Infant liq | D15: 42655 | E15: =MONTH(D15) -> 10 | F15: 0.375 | G15: 0.47222222 | H15: 0.097222222 | I15: Alisson | J15: =VLOOKUP(I15,'Salário e Custo Hora'!$C$31:$P$38,'Time Sheet'!E15+2,FALSE) -> 18.032107 | K15: =H15*24*J15 -> 42.074916
B16: Alisson Montanini | C16: Micronutrientes | D16: 42664 | E16: =MONTH(D16) -> 10 | F16: 0.60416667 | G16: 0.64583333 | H16: 0.041666667 | I16: Alisson | J16: =VLOOKUP(I16,'Salário e Custo Hora'!$C$31:$P$38,'Time Sheet'!E16+2,FALSE) -> 18.032107 | K16: =H16*24*J16 -> 18.032107
B17: Alisson Montanini | C17: Novo Copacker Produtos Líquidos | D17: 42664 | E17: =MONTH(D17) -> 10 | F17: 0.64583333 | G17: 0.66666667 | H17: 0.020833333 | I17: Alisson | J17: =VLOOKUP(I17,'Salário e Custo Hora'!$C$31:$P$38,'Time Sheet'!E17+2,FALSE) -> 18.032107 | K17: =H17*24*J17 -> 9.0160534
... B30: Maurício Soares | C30: Trophic Infant liq | D30: 42282 | E30: =MONTH(D30) -> 10 | F30: 0.6875 | G30: 0.75 | H30: 0.0625 | I30: Maurício | J30: =VLOOKUP(I30,'Salário e Custo Hora'!$C$31:$P$38,'Time Sheet'!E30+2,FALSE) -> 12.841183 | K30: =H30*24*J30 -> 19.261775

Sheet Relatório PJ
A1: LOTE/SUB/DOC/LINHA | B1: HISTORICO | C1: DEBITO | D1: CREDITO
A2: CONTA | B2: DESCRICAO
A3: 3.4.2.1 | B3: - DESPESAS ADMINISTRATIVAS
A4: CONTA - 3.4.2.10.3 - PRESTADORES DE SERVICOS
A5: 008810001000009001 | B5: N.F. DE ENTRADA N.20-VLL MOURA SERV APOI | C5: 11708 | D5: 0 | E5: N.F. DE ENTRADA | F5: N. | G5: 20 | H5: - | I5: VLL MOURA SERV APOI
A6: 008810001000011001 | B6: N.F. DE ENTRADA N.24-NUTRIMENTO CONS E T | C6: 33875 | D6: 0 | E6: N.F. DE ENTRADA | F6: N. | G6: 24 | H6: - | I6: NUTRIMENTO CONS E T
B7: REIN EM NUTRICAO LTDA | E7: REIN EM NUTRICA | F7: O L | G7: TD | H7: A
A8: 008810001000015001 | B8: N.F. DE ENTRADA N.20-L DUTRA SERVICOS ME | C8: 11708 | D8: 0 | E8: N.F. DE ENTRADA | F8: N. | G8: 20 | H8: - | I8: L DUTRA SERVICOS ME
A9: 008810001000006001 | B9: N.F. DE ENTRADA N.21-L DUTRA SERVICOS ME | C9: 11708 | D9: 0 | E9: N.F. DE ENTRADA | F9: N. | G9: 21 | H9: - | I9: L DUTRA SERVICOS ME
A10: 008810001000022001 | B10: N.F. DE ENTRADA N.26-NUTRIMENTO CONS E T | C10: 33875 | D10: 0 | E10: N.F. DE ENTRADA | F10: N. | G10: 26 | H10: - | I10: NUTRIMENTO CONS E T
A11: 008810001000038001 | B11: N.F. DE ENTRADA N.21-VLL MOURA SERV APOI | C11: 11708 | D11: 0 | E11: N.F. DE ENTRADA | F11: N. | G11: 21 | H11: - | I11: VLL MOURA SERV APOI
A12: 008810001000013001 | B12: N.F. DE ENTRADA N.22-L DUTRA SERVICOS ME | C12: 11708 | D12: 0 | E12: N.F. DE ENTRADA | F12: N. | G12: 22 | H12: - | I12: L DUTRA SERVICOS ME
A13: 008810001000007001 | B13: N.F. DE ENTRADA N.22-VLL MOURA SERV APOI | C13: 11708 | D13: 0 | E13: N.F. DE ENTRADA | F13: N. | G13: 22 | H13: - | I13: VLL MOURA SERV APOI
A14: 008810001000011001 | B14: N.F. DE ENTRADA N.28-NUTRIMENTO CONS E T | C14: 33875 | D14: 0 | E14: N.F. DE ENTRADA | F14: N. | G14: 28 | H14: - | I14: NUTRIMENTO CONS E T
A15: 008810001000003001 | B15: N.F. DE ENTRADA N.30-NUTRIMENTO CONS E T | C15: 33875 | D15: 0 | E15: N.F. DE ENTRADA | F15: N. | G15: 30 | H15: - | I15: NUTRIMENTO CONS E T
A16: 008810001000004001 | B16: N.F. DE ENTRADA N.23-L DUTRA SERVICOS ME | C16: 11708 | D16: 0 | E16: N.F. DE ENTRADA | F16: N. | G16: 23 | H16: - | I16: L DUTRA SERVICOS ME
A17: 008810001000008001 | B17: N.F. DE ENTRADA N.23-VLL MOURA SERV APOI | C17: 11708 | D17: 0 | E17: N.F. DE ENTRADA | F17: N. | G17: 23 | H17: - | I17: VLL MOURA SERV APOI
A18: 008810001000039001 | B18: N.F. DE ENTRADA N.24-L DUTRA SERVICOS ME | C18: 11708 | D18: 0 | E18: N.F. DE ENTRADA | F18: N. | G18: 24 | H18: - | I18: L DUTRA SERVICOS ME
A19: 008810001000012001 | B19: N.F. DE ENTRADA N.24-VLL MOURA SERV APOI | C19: 11708 | D19: 0 | E19: N.F. DE ENTRADA | F19: N. | G19: 24 | H19: - | I19: VLL MOURA SERV APOI
... A31: 008810001000016001 | B31: N.F. DE ENTRADA N.28-VLL MOURA SERV APOI | C31: 11708 | D31: 0 | E31: N.F. DE ENTRADA | F31: N. | G31: 28 | H31: - | I31: VLL MOURA SERV APOI
A32: 008810001000009001 | B32: N.F. DE ENTRADA N.201500001-NUTRIMENTO G | C32: 33771 | D32: 0 | E32: N.F. DE ENTRADA | F32: N. | G32: 201500001 | H32: 1 | I32: 500001-NUTRIMENTO G
A33: 008810001000011001 | B33: N.F. DE ENTRADA N.29-VLL MOURA SERV APOI | C33: 11708 | D33: 0 | E33: N.F. DE ENTRADA | F33: N. | G33: 29 | H33: - | I33: VLL MOURA SERV APOI
A34: 008810001000014001 | B34: N.F. DE ENTRADA N.29-L DUTRA SERVICOS ME | C34: 11604 | D34: 0 | E34: N.F. DE ENTRADA | F34: N. | G34: 29 | H34: - | I34: L DUTRA SERVICOS ME
A35: 008810001000008001 | B35: N.F. DE ENTRADA N.5-NUTRIMENTO GESTAO DE | C35: 33771 | D35: 0 | E35: N.F. DE ENTRADA | F35: N. | G35: -5 | H35: N | I35: UTRIMENTO GESTAO DE
A36: 008810001000006001 | B36: N.F. DE ENTRADA N.7-NUTRIMENTO GESTAO DE | C36: 33875 | D36: 0 | E36: N.F. DE ENTRADA | F36: N. | G36: -7 | H36: N | I36: UTRIMENTO GESTAO DE
B37: DADOS EMPRESARIAIS | E37: DADOS EMPRESAR | F37: IAI | G37: S
A38: 008810001000008001 | B38: N.F. DE ENTRADA N.30-L DUTRA SERVICOS ME | C38: 11708 | D38: 0 | E38: N.F. DE ENTRADA | F38: N. | G38: 30 | H38: - | I38: L DUTRA SERVICOS ME
A39: 008810001000010001 | B39: N.F. DE ENTRADA N.30-VLL MOURA SERV APOI | C39: 11708 | D39: 0 | E39: N.F. DE ENTRADA | F39: N. | G39: 30 | H39: - | I39: VLL MOURA SERV APOI
A40: 008810001000009001 | B40: N.F. DE ENTRADA N.31-L DUTRA SERVICOS ME | C40: 11708 | D40: 0 | E40: N.F. DE ENTRADA | F40: N. | G40: 31 | H40: - | I40: L DUTRA SERVICOS ME
A41: 008810001000010001 | B41: N.F. DE ENTRADA N.31-VLL MOURA SERV APOI | C41: 11708 | D41: 0 | E41: N.F. DE ENTRADA | F41: N. | G41: 31 | H41: - | I41: VLL MOURA SERV APOI
B42: O ADMINISTRATIVO ME | E42: O ADMINISTRATIV | F42: O M | G42: E
A43: 008810001000014001 | B43: N.F. DE ENTRADA N.201510-NUTRIMENTO GEST | C43: 33875 | D43: 0 | E43: N.F. DE ENTRADA | F43: N. | G43: 201510 | H43: 1 | I43: 510-NUTRIMENTO GEST

Sheet Investimentos 
A1: PRODIET NUTRIÇÃO
A2: =Resumo!B2 -> INOVAÇÃO TECNOLÓGICA 2015
A3: Investimentos | V3: =SUM(V6:V72) -> 51009.753 | W3: =SUM(W6:W72) -> 28818.701 | X3: =SUM(X6:X72) -> 42872.719 | Y3: =SUM(Y6:Y72) -> 30703.901 | Z3: =SUM(Z6:Z72) -> 29192.781 | AA3: =SUM(V3:Z3) -> 182597.85
I4: Verificar natureza dos testes em labs | N4: =SUBTOTAL(9,N6:N1048576) -> 182597.85 | O4: S | P4: Participação nos projetos | V4: Dispêndio (R$) por projeto
A5: Coments | B5: Documento | C5: Controle DOCS | D5: Total NF | E5: PRODUTOS | F5: RECURSO | G5: CPF / CNPJ | H5: ATIVIDADE | I5: NATUREZA | J5: DATA | K5: Mês | L5: QTD | M5: UNITÁRIO | N5: TOTAL | P5: Novos Produtos | Q5: Novas matérias-primas | R5: Melhoria de Produto | S5: Melhoria de Processo | T5: Novo Copacker | V5: Novos Produtos | W5: Novas matérias-primas | X5: Melhoria de Produto | Y5: Melhoria de Processo | Z5: Novo Copacker
A6: NF | B6: 12822 | C6: 1 | D6: 510 | E6: Energyzip 1.0, Peptimax 400g, Diamax | F6: Fundação de estudos e pesquisas aquaticas - FUNDESPA | G6: 61.379.657/0001-04 | H6: Pesquisa de materiais - tamanho de partícula | I6: Serviço de terceiros | J6: 42142 | K6: =MONTH(J6) -> 5 | L6: 1 | M6: 510 | N6: =M6*L6 -> 510 | O6: =SUM(P6:T6) -> 1 | P6: =2/3 -> 0.66666667 | Q6: 0 | R6: 0 | S6: 0 | T6: =1/3 -> 0.33333333 | V6: =P6*$N6 -> 340 | W6: =Q6*$N6 -> 0 | X6: =R6*$N6 -> 0 | Y6: =S6*$N6 -> 0 | Z6: =T6*$N6 -> 170
A7: Recibo | B7: 1946 | C7: 2 | D7: 217 | E7: E-Master | F7: Associação Paranaense de Cultura - APC | G7: 76.659.820/0003-13 | H7: Uso do laboratório (14h35 às 17h45) | I7: Serviço de terceiros | J7: 42199 | K7: =MONTH(J7) -> 7 | L7: 1 | M7: 217 | N7: =M7*L7 -> 217 | O7: =SUM(P7:T7) -> 1 | P7: 1 | Q7: 0 | R7: 0 | S7: 0 | T7: 0 | V7: =P7*$N7 -> 217 | W7: =Q7*$N7 -> 0 | X7: =R7*$N7 -> 0 | Y7: =S7*$N7 -> 0 | Z7: =T7*$N7 -> 0
A8: Cupom fiscal | B8: 377135 | C8: 3 | D8: 68.39 | E8: Suplemento | F8: Sonda Supermercados | G8: 01.937.635/0030-17 | H8: Aquisição de material para análise (Sustagen e Nutren) | I8: Material | J8: 42360 | K8: =MONTH(J8) -> 12 | L8: 1 | M8: 68.39 | N8: =M8*L8 -> 68.39 | O8: =SUM(P8:T8) -> 1 | P8: 1 | Q8: 0 | R8: 0 | S8: 0 | T8: 0 | V8: =P8*$N8 -> 68.39 | W8: =Q8*$N8 -> 0 | X8: =R8*$N8 -> 0 | Y8: =S8*$N8 -> 0 | Z8: =T8*$N8 -> 0
A9: Recibo | C9: 4 | D9: 275 | E9: ALZ | F9: Ilsi Brasil - Internacional Life Sciences Institute do Brasil | G9: 65.086.001/001-46 | H9: Workshop Internacional sobre alimentos com alegações de propriedades funcionais - Neurociência, Cérebro e Nutrição. | I9: Serviço de terceiros | J9: 42325 | K9: =MONTH(J9) -> 11 | L9: 1 | M9: 275 | N9: =M9*L9 -> 275 | O9: =SUM(P9:T9) -> 1 | P9: 1 | Q9: 0 | R9: 0 | S9: 0 | T9: 0 | V9: =P9*$N9 -> 275 | W9: =Q9*$N9 -> 0 | X9: =R9*$N9 -> 0 | Y9: =S9*$N9 -> 0 | Z9: =T9*$N9 -> 0
A10: Valor por e-mail | C10: 5 | D10: 704.29 | E10: Trophic infant líquido | F10: Azul linhas aéreas | H10: Passagens Amir IDA e Volta São Paulo - Campinas - Teste ITAL | I10: Material | J10: 42284 | K10: =MONTH(J10) -> 10 | L10: 1 | M10: 704.29 | N10: =M10*L10 -> 704.29 | O10: =SUM(P10:T10) -> 1 | P10: =1/3 -> 0.33333333 | Q10: 0 | R10: =2/3 -> 0.66666667 | S10: 0 | T10: 0 | V10: =P10*$N10 -> 234.76333 | W10: =Q10*$N10 -> 0 | X10: =R10*$N10 -> 469.52667 | Y10: =S10*$N10 -> 0 | Z10: =T10*$N10 -> 0
A11: Confirmação de reserva | C11: 6 | D11: 268 | E11: Trophic infant líquido | F11: Turrance White Campinas hotel | H11: Hospedagem Amir - Teste ITAL | I11: Material | J11: 42284 | K11: =MONTH(J11) -> 10 | L11: 1 | M11: 268 | N11: =M11*L11 -> 268 | O11: =SUM(P11:T11) -> 1 | P11: =1/3 -> 0.33333333 | Q11: 0 | R11: =2/3 -> 0.66666667 | S11: 0 | T11: 0 | V11: =P11*$N11 -> 89.333333 | W11: =Q11*$N11 -> 0 | X11: =R11*$N11 -> 178.66667 | Y11: =S11*$N11 -> 0 | Z11: =T11*$N11 -> 0
A12: Cupons fiscais | C12: 7 | D12: =32.78+29 -> 61.78 | E12: Trophic infant líquido | F12: Diversos | H12: Alimentação Amir - Teste ITAL | I12: Material | J12: 42284 | K12: =MONTH(J12) -> 10 | L12: 1 | M12: =32.78+29 -> 61.78 | N12: =M12*L12 -> 61.78 | O12: =SUM(P12:T12) -> 1 | P12: =1/3 -> 0.33333333 | Q12: 0 | R12: =2/3 -> 0.66666667 | S12: 0 | T12: 0 | V12: =P12*$N12 -> 20.593333 | W12: =Q12*$N12 -> 0 | X12: =R12*$N12 -> 41.186667 | Y12: =S12*$N12 -> 0 | Z12: =T12*$N12 -> 0
A13: Recibo | B13: 863 | C13: 8 | D13: 21.65 | E13: Trophic infant líquido | F13: Diversos | H13: Taxi Amir - Teste ITAL | I13: Material | J13: 42284 | K13: =MONTH(J13) -> 10 | L13: 1 | M13: 21.65 | N13: =M13*L13 -> 21.65 | O13: =SUM(P13:T13) -> 1 | P13: =1/3 -> 0.33333333 | Q13: 0 | R13: =2/3 -> 0.66666667 | S13: 0 | T13: 0 | V13: =P13*$N13 -> 7.2166667 | W13: =Q13*$N13 -> 0 | X13: =R13*$N13 -> 14.433333 | Y13: =S13*$N13 -> 0 | Z13: =T13*$N13 -> 0
A14: NF | B14: 4924 | C14: 9 | D14: 8979.59 | E14: ? | F14: Tetra Pack Ltda | G14: 61.528.030/0001-60 | H14: Teste Piloto UHT - Assessoria / consultoria | I14: Serviço de terceiros | J14: 42318 | K14: =MONTH(J14) -> 11 | L14: 1 | M14: 8979.59 | N14: =M14*L14 -> 8979.59 | O14: =SUM(P14:T14) -> 1 | P14: =1/2 -> 0.5 | Q14: 0 | R14: =1/2 -> 0.5 | S14: 0 | T14: 0 | V14: =P14*$N14 -> 4489.795 | W14: =Q14*$N14 -> 0 | X14: =R14*$N14 -> 4489.795 | Y14: =S14*$N14 -> 0 | Z14: =T14*$N14 -> 0
A15: NF | B15: 24964 | C15: 10 | D15: 1995 | E15: EP, Trophic infant | F15: Labor Tres Laboratorios e Consultoria Tecnica Ltda | G15: 02.021.076/0001-29 | H15: Avaliação fisico-química de alimentos | I15: Serviço de terceiros | J15: 42292 | K15: =MONTH(J15) -> 10 | L15: 1 | M15: 1995 | N15: =M15*L15 -> 1995 | O15: =SUM(P15:T15) -> 1 | P15: =2/7 -> 0.28571429 | Q15: 0 | R15: =5/7 -> 0.71428571 | S15: 0 | T15: 0 | V15: =P15*$N15 -> 570 | W15: =Q15*$N15 -> 0 | X15: =R15*$N15 -> 1425 | Y15: =S15*$N15 -> 0 | Z15: =T15*$N15 -> 0
A16: NF | B16: 23253 | C16: 11 | D16: 570 | E16: ? | F16: Labor Tres Laboratorios e Consultoria Tecnica Ltda | G16: 02.021.076/0001-29 | H16: Avaliação fisico-química de alimentos | I16: Serviço de terceiros | J16: 42088 | K16: =MONTH(J16) -> 3 | L16: 2 | M16: 285 | N16: =M16*L16 -> 570 | O16: =SUM(P16:T16) -> 1 | P16: 0 | Q16: 1 | R16: 0 | S16: 0 | T16: 0 | V16: =P16*$N16 -> 0 | W16: =Q16*$N16 -> 570 | X16: =R16*$N16 -> 0 | Y16: =S16*$N16 -> 0 | Z16: =T16*$N16 -> 0
A17: NF | B17: 64339 | C17: 12 | D17: 405.07 | E17: ? | F17: TUV SUD SFDK Laboratório de análise de produtos Ltda. | G17: 55.953.079/0001-67 | H17: Serviços de análise laboratorial | I17: Serviço de terceiros | J17: 42219 | K17: =MONTH(J17) -> 8 | L17: 1 | M17: 405.07 | N17: =M17*L17 -> 405.07 | O17: =SUM(P17:T17) -> 1 | P17: 0 | Q17: 1 | R17: 0 | S17: 0 | T17: 0 | V17: =P17*$N17 -> 0 | W17: =Q17*$N17 -> 405.07 | X17: =R17*$N17 -> 0 | Y17: =S17*$N17 -> 0 | Z17: =T17*$N17 -> 0
A18: Voucher | B18: 1430513 e 14 | C18: 13 | D18: 41 | E18: ? | F18: Radio Taxi Curitiba | H18: Transporte até a PUC para testes laboratoriais | I18: Material | J18: 42033 | K18: =MONTH(J18) -> 1 | L18: 1 | M18: 41 | N18: =M18*L18 -> 41 | O18: =SUM(P18:T18) -> 1 | P18: 0 | Q18: 1 | R18: 0 | S18: 0 | T18: 0 | V18: =P18*$N18 -> 0 | W18: =Q18*$N18 -> 41 | X18: =R18*$N18 -> 0 | Y18: =S18*$N18 -> 0 | Z18: =T18*$N18 -> 0
A19: NF | B19: 25280 | C19: 14 | D19: 570 | E19: ? | F19: Labor Tres Laboratorios e Consultoria Tecnica Ltda | G19: 02.021.076/0001-29 | H19: Avaliação fisico-química de alimentos | I19: Serviço de terceiros | J19: 42332 | K19: =MONTH(J19) -> 11 | L19: 1 | M19: 570 | N19: =M19*L19 -> 570 | O19: =SUM(P19:T19) -> 1 | P19: 0 | Q19: 0 | R19: 1 | S19: 0 | T19: 0 | V19: =P19*$N19 -> 0 | W19: =Q19*$N19 -> 0 | X19: =R19*$N19 -> 570 | Y19: =S19*$N19 -> 0 | Z19: =T19*$N19 -> 0
A20: NF | B20: 61954 | C20: 15 | D20: 710.15 | E20: ? | F20: TUV SUD SFDK Laboratório de análise de produtos Ltda. | G20: 55.953.079/0001-67 | H20: Serviços de análise laboratorial | I20: Serviço de terceiros | J20: 42111 | K20: =MONTH(J20) -> 4 | L20: 1 | M20: 710.15 | N20: =M20*L20 -> 710.15 | O20: =SUM(P20:T20) -> 1 | P20: 0 | Q20: 0 | R20: 0 | S20: 0 | T20: 1 | V20: =P20*$N20 -> 0 | W20: =Q20*$N20 -> 0 | X20: =R20*$N20 -> 0 | Y20: =S20*$N20 -> 0 | Z20: =T20*$N20 -> 710.15
A21: NF | B21: 28874 | C21: 16 | D21: 488.67 | E21: ? | F21: Bioagri Analises de alimentos Ltda | G21: 00.000.410/0001-32 | H21: Serviços de análise laboratorial | I21: Serviço de terceiros | J21: 42125 | K21: =MONTH(J21) -> 5 | L21: 1 | M21: 488.67 | N21: =M21*L21 -> 488.67 | O21: =SUM(P21:T21) -> 1 | P21: 1 | Q21: 0 | R21: 0 | S21: 0 | T21: 0 | V21: =P21*$N21 -> 488.67 | W21: =Q21*$N21 -> 0 | X21: =R21*$N21 -> 0 | Y21: =S21*$N21 -> 0 | Z21: =T21*$N21 -> 0
A22: NF | B22: 66894 | C22: 17 | D22: 405.07 | E22: ? | F22: TUV SUD SFDK Laboratório de análise de produtos Ltda. | G22: 55.953.079/0001-67 | H22: Serviços de análise laboratorial | I22: Serviço de terceiros | J22: 42319 | K22: =MONTH(J22) -> 11 | L22: 1 | M22: 405.07 | N22: =M22*L22 -> 405.07 | O22: =SUM(P22:T22) -> 1 | P22: 0 | Q22: 0 | R22: 0 | S22: 1 | T22: 0 | V22: =P22*$N22 -> 0 | W22: =Q22*$N22 -> 0 | X22: =R22*$N22 -> 0 | Y22: =S22*$N22 -> 405.07 | Z22: =T22*$N22 -> 0
A23: NF | B23: 12529 | C23: 18 | D23: 340 | E23: ? | F23: Fundação de estudos e pesquisas aquaticas - FUNDESPA | G23: 61.379.657/0001-04 | H23: Pesquisa de materiais - tamanho de partícula | I23: serviço de terceiros | J23: 42104 | K23: =MONTH(J23) -> 4 | L23: 1 | M23: 340 | N23: =M23*L23 -> 340 | O23: =SUM(P23:T23) -> 1 | P23: 0 | Q23: 0 | R23: 0 | S23: 0 | T23: 1 | V23: =P23*$N23 -> 0 | W23: =Q23*$N23 -> 0 | X23: =R23*$N23 -> 0 | Y23: =S23*$N23 -> 0 | Z23: =T23*$N23 -> 340
A24: Recibo | B24: 197 | C24: 19 | D24: 560 | E24: ? | F24: Associação Paranaense de Cultura - APC | G24: 76.659.820/0003-13 | H24: Uso do laboratório (8h50 às 12h00 - 14h00 às 18h40) | I24: Serviço de terceiros | J24: 42199 | K24: =MONTH(J24) -> 7 | L24: 1 | M24: 560 | N24: =M24*L24 -> 560 | O24: =SUM(P24:T24) -> 1 | P24: 0 | Q24: 0 | R24: 1 | S24: 0 | T24: 0 | V24: =P24*$N24 -> 0 | W24: =Q24*$N24 -> 0 | X24: =R24*$N24 -> 560 | Y24: =S24*$N24 -> 0 | Z24: =T24*$N24 -> 0
A25: Cupons fiscais | B25: 1466 e 52819 | C25: 20 | D25: =37.4+39.95 -> 77.35 | E25: ? | F25: Diversos | H25: Alimentação Amir- Curso Lecitinação | I25: Material | J25: 42302 | K25: =MONTH(J25) -> 10 | L25: 1 | M25: =37.4+39.95 -> 77.35 | N25: =M25*L25 -> 77.35 | O25: =SUM(P25:T25) -> 1 | P25: 0 | Q25: 0 | R25: 1 | S25: 0 | T25: 0 | V25: =P25*$N25 -> 0 | W25: =Q25*$N25 -> 0 | X25: =R25*$N25 -> 77.35 | Y25: =S25*$N25 -> 0 | Z25: =T25*$N25 -> 0
A26: Confirmação de reserva | C26: 21 | D26: 450 | E26: ? | F26: Turrance White Campinas hotel | H26: Hospedagem Amir - Curso Lecitinação | I26: Material | J26: 42302 | K26: =MONTH(J26) -> 10 | L26: 3 | M26: 150 | N26: =M26*L26 -> 450 | O26: =SUM(P26:T26) -> 1 | P26: 0 | Q26: 0 | R26: 1 | S26: 0 | T26: 0 | V26: =P26*$N26 -> 0 | W26: =Q26*$N26 -> 0 | X26: =R26*$N26 -> 450 | Y26: =S26*$N26 -> 0 | Z26: =T26*$N26 -> 0
A27: NF | B27: 74361 | C27: 22 | D27: 1100 | E27: ? | F27: Fundação de desenv. Da pesquisa do agronegócio - FUNDEPAG | G27: 50.276.237/0001-78 | H27: Inscrição curso de lecitinação | I27: Serviço de terceiros | J27: 42297 | K27: =MONTH(J27) -> 10 | L27: 1 | M27: 1100 | N27: =M27*L27 -> 1100 | O27: =SUM(P27:T27) -> 1 | P27: 0 | Q27: 0 | R27: 1 | S27: 0 | T27: 0 | V27: =P27*$N27 -> 0 | W27: =Q27*$N27 -> 0 | X27: =R27*$N27 -> 1100 | Y27: =S27*$N27 -> 0 | Z27: =T27*$N27 -> 0
A28: Bilhete e-ticket | B28: 577 0005698435 | C28: 23 | D28: 1080.29 | E28: ? | F28: Azul linhas aéreas | H28: Passagem Amir - Curso Lecitinação | I28: Material | J28: 42302 | K28: =MONTH(J28) -> 10 | L28: 1 | M28: 1080.29 | N28: =M28*L28 -> 1080.29 | O28: =SUM(P28:T28) -> 1 | P28: 0 | Q28: 0 | R28: 1 | S28: 0 | T28: 0 | V28: =P28*$N28 -> 0 | W28: =Q28*$N28 -> 0 | X28: =R28*$N28 -> 1080.29 | Y28: =S28*$N28 -> 0 | Z28: =T28*$N28 -> 0
A29: NF | B29: 31865 | C29: 24 | D29: 562.45 | E29: ? | F29: Bioagri Analises de alimentos Ltda | G29: 00.000.410/0001-32 | H29: Serviços de análise laboratorial | I29: Serviço de terceiros | J29: 42317 | K29: =MONTH(J29) -> 11 | L29: 1 | M29: 562.45 | N29: =M29*L29 -> 562.45 | O29: =SUM(P29:T29) -> 1 | P29: 0 | Q29: 0 | R29: 1 | S29: 0 | T29: 0 | V29: =P29*$N29 -> 0 | W29: =Q29*$N29 -> 0 | X29: =R29*$N29 -> 562.45 | Y29: =S29*$N29 -> 0 | Z29: =T29*$N29 -> 0
A30: NF | B30: 74098 | C30: 25 | D30: 3201.39 | E30: ? | F30: Fundação de desenv. Da pesquisa do agronegócio - FUNDEPAG | G30: 50.276.237/0001-78 | H30: Teste em planta de lecitinação e aglomeração com vapor | I30: Serviço de terceiros | J30: 42290 | K30: =MONTH(J30) -> 10 | L30: 1 | M30: 3201.39 | N30: =M30*L30 -> 3201.39 | O30: =SUM(P30:T30) -> 1 | P30: 0 | Q30: 0 | R30: 1 | S30: 0 | T30: 0 | V30: =P30*$N30 -> 0 | W30: =Q30*$N30 -> 0 | X30: =R30*$N30 -> 3201.39 | Y30: =S30*$N30 -> 0 | Z30: =T30*$N30 -> 0
A31: NF | B31: 14080 | C31: 26 | D31: 1190 | E31: ? | F31: Fundação de estudos e pesquisas aquaticas - FUNDESPA | G31: 61.379.657/0001-04 | H31: Pesquisa de materiais - tamanho de partícula | I31: serviço de terceiros | J31: 42311 | K31: =MONTH(J31) -> 11 | L31: 1 | M31: 1190 | N31: =M31*L31 -> 1190 | O31: =SUM(P31:T31) -> 1 | P31: =2/7 -> 0.28571429 | Q31: 0 | R31: =5/7 -> 0.71428571 | S31: 0 | T31: 0 | V31: =P31*$N31 -> 340 | W31: =Q31*$N31 -> 0 | X31: =R31*$N31 -> 850 | Y31: =S31*$N31 -> 0 | Z31: =T31*$N31 -> 0
A32: NF | B32: 6791 | C32: 27 | D32: 2496.2 | E32: ? | F32: M Cassab Comercio e Industria Ltda | G32: 49.698.723/0001-03 | H32: Análise de laboratório | I32: Serviço de terceiros | J32: 42062 | K32: =MONTH(J32) -> 2 | L32: 1 | M32: 2496.2 | N32: =M32*L32 -> 2496.2 | O32: =SUM(P32:T32) -> 1 | P32: 0 | Q32: 0 | R32: 0 | S32: 1 | T32: 0 | V32: =P32*$N32 -> 0 | W32: =Q32*$N32 -> 0 | X32: =R32*$N32 -> 0 | Y32: =S32*$N32 -> 2496.2 | Z32: =T32*$N32 -> 0
A33: Ficha de adesão | C33: 28 | D33: 16800 | E33: ? | F33: Ilsi Brasil - Internacional Life Sciences Institute do Brasil | G33: 65.086.001/001-46 | H33: Anuidade de treinamento e workshops em pesquisa e desenvolvimento | I33: Serviço de terceiros | J33: 42132 | K33: =MONTH(J33) -> 5 | L33: 7 | M33: =25200/12 -> 2100 | N33: =M33*L33 -> 14700 | O33: =SUM(P33:T33) -> 1 | P33: 1 | Q33: 0 | R33: 0 | S33: 0 | T33: 0 | V33: =P33*$N33 -> 14700 | W33: =Q33*$N33 -> 0 | X33: =R33*$N33 -> 0 | Y33: =S33*$N33 -> 0 | Z33: =T33*$N33 -> 0
A34: NF | B34: 12549 | C34: 29 | D34: 170 | E34: ? | F34: Fundação de estudos e pesquisas aquaticas - FUNDESPA | G34: 61.379.657/0001-04 | H34: Pesquisa de materiais - tamanho de partícula | I34: Serviço de terceiros | J34: 42104 | K34: =MONTH(J34) -> 4 | L34: 1 | M34: 170 | N34: =M34*L34 -> 170 | O34: =SUM(P34:T34) -> 1 | P34: 0 | Q34: 0 | R34: 0 | S34: 0 | T34: 1 | V34: =P34*$N34 -> 0 | W34: =Q34*$N34 -> 0 | X34: =R34*$N34 -> 0 | Y34: =S34*$N34 -> 0 | Z34: =T34*$N34 -> 170
A35: Bilhete e-ticket | B35: 247-2417281373 | C35: 30 | D35: 821.28 | E35: TNCGAN | F35: Avianca | H35: Viagem para testes | I35: Material | J35: 42206 | K35: =MONTH(J35) -> 7 | L35: 1 | M35: =D35 -> 821.28 | N35: =M35*L35 -> 821.28 | O35: =SUM(P35:T35) -> 1 | P35: 1 | Q35: 0 | R35: 0 | S35: 0 | T35: 0 | V35: =P35*$N35 -> 821.28 | W35: =Q35*$N35 -> 0 | X35: =R35*$N35 -> 0 | Y35: =S35*$N35 -> 0 | Z35: =T35*$N35 -> 0
A36: Relatório Agência de viagens | B36: 2144 | C36: 31 | D36: 545.08 | F36: APA Agência de viagens e turismo corporativo Ltda | H36: Viagem da Aline Fracasso para curso Ilsi | I36: Material | J36: 42130 | K36: =MONTH(J36) -> 5 | L36: 1 | M36: =D36 -> 545.08 | N36: =M36*L36 -> 545.08 | O36: =SUM(P36:T36) -> 1 | P36: 1 | Q36: 0 | R36: 0 | S36: 0 | T36: 0 | V36: =P36*$N36 -> 545.08 | W36: =Q36*$N36 -> 0 | X36: =R36*$N36 -> 0 | Y36: =S36*$N36 -> 0 | Z36: =T36*$N36 -> 0
A37: NF (Relatório contábil) | B37: 20 | C37: 32 | D37: 11708 | E37: Vera Lucia Leite Moura | F37: VLL Moura Serviços de Apoio Administrativo | G37: 18.390.865/0001-77 | H37: Acompanhamento de resultados das análises realizadas nos produtos em teste. | I37: Serviço de terceiros | J37: 42029 | K37: =MONTH(J37) -> 1 | L37: ='Time Sheet'!H4/SUM('Salário e Custo Hora'!E42:P42) -> 0.00077976877 | M37: 11708 | N37: =L37*M37 -> 9.1295327 | O37: =SUM(P37:T37) -> 1 | P37: 0.2 | Q37: 0.2 | R37: 0.2 | S37: 0.2 | T37: 0.2 | V37: =P37*$N37 -> 1.8259065 | W37: =Q37*$N37 -> 1.8259065 | X37: =R37*$N37 -> 1.8259065 | Y37: =S37*$N37 -> 1.8259065 | Z37: =T37*$N37 -> 1.8259065
A38: NF (Relatório contábil) | B38: 24 | C38: 33 | D38: 33875 | E38: Ana Paula Celes | F38: Nutrimento Gestão de Dados Empresariais Ltda. | G38: 03.150.501/0001-42 | H38: Analisa os testes dos produtos e dá assistência na parametrização do produto e dos novos testes a serem feitos. Faz acompanhamento técnico de todos os projetos de pesquisa e desenvolvimento. | I38: Serviço de terceiros | J38: 42029 | K38: =MONTH(J38) -> 1 | L38: 0.1 | M38: 33875 | N38: =L38*M38 -> 3387.5 | O38: =SUM(P38:T38) -> 1 | P38: 0.2 | Q38: 0.2 | R38: 0.2 | S38: 0.2 | T38: 0.2 | V38: =P38*$N38 -> 677.5 | W38: =Q38*$N38 -> 677.5 | X38: =R38*$N38 -> 677.5 | Y38: =S38*$N38 -> 677.5 | Z38: =T38*$N38 -> 677.5
A39: NF (Relatório contábil) | B39: 20 | C39: 34 | D39: 11708 | E39: Luciana Dutra | F39: L Dutra Serviços ME | G39: 18.337.175/0001-54 | H39: Acompanha e faz teste nos produtos para validação de lote piloto, teste de validade do produto, teste de caracterísca e teste de de administração do produto final.Visto que são produtos de alimentação hospitalar, oral e domiciliar pós-internação. | I39: Serviço de terceiros | J39: 42029 | K39: =MONTH(J39) -> 1 | L39: 0.7 | M39: 11708 | N39: =L39*M39 -> 8195.6 | O39: =SUM(P39:T39) -> 1 | P39: 0.2 | Q39: 0.2 | R39: 0.2 | S39: 0.2 | T39: 0.2 | V39: =P39*$N39 -> 1639.12 | W39: =Q39*$N39 -> 1639.12 | X39: =R39*$N39 -> 1639.12 | Y39: =S39*$N39 -> 1639.12 | Z39: =T39*$N39 -> 1639.12
A40: NF (Relatório contábil) | B40: 21 | C40: 35 | D40: 11708 | E40: Luciana Dutra | F40: L Dutra Serviços ME | G40: 18.337.175/0001-54 | H40: Acompanha e faz teste nos produtos para validação de lote piloto, teste de validade do produto, teste de caracterísca e teste de de administração do produto final.Visto que são produtos de alimentação hospitalar, oral e domiciliar pós-internação. | I40: Serviço de terceiros | J40: 42060 | K40: =MONTH(J40) -> 2 | L40: 0.7 | M40: 11708 | N40: =L40*M40 -> 8195.6 | O40: =SUM(P40:T40) -> 1 | P40: 0.2 | Q40: 0.2 | R40: 0.2 | S40: 0.2 | T40: 0.2 | V40: =P40*$N40 -> 1639.12 | W40: =Q40*$N40 -> 1639.12 | X40: =R40*$N40 -> 1639.12 | Y40: =S40*$N40 -> 1639.12 | Z40: =T40*$N40 -> 1639.12
...

Sheet Projetos
A1: PRODIET NUTRIÇÃO
A2: =Resumo!B2 -> INOVAÇÃO TECNOLÓGICA 2015
A3: Projetos
C4: (a)
B5: Projeto | C5: RH (parcial inovação) | D5: RH (exclusivo) | E5: Total RH | F5: Material | G5: Terceiros | H5: Total
B6: Novos produtos | E6: =SUM(D6,C6) -> 0 | H6: =SUM(E6:G6) -> 0
B7: Novas Mp | E7: =SUM(D7,C7) -> 0 | H7: =SUM(E7:G7) -> 0
B8: Melhoria de processo | E8: =SUM(D8,C8) -> 0 | H8: =SUM(E8:G8) -> 0
B9: Novo Copacker | E9: =SUM(D9,C9) -> 0 | H9: =SUM(E9:G9) -> 0
B10: Melhoria de produto | E10: =SUM(D10,C10) -> 0 | H10: =SUM(E10:G10) -> 0
C11: =SUM(C6:C10) -> 0 | D11: =SUM(D6:D10) -> 0 | E11: =SUM(E6:E10) -> 0 | F11: =SUM(F6:F10) -> 0 | G11: =SUM(G6:G10) -> 0 | H11: =SUM(H6:H10) -> 0
C14: Soma de "RH (Parcial inovação)" da coluna "Natureza" da planilha Investimentos e Soma do Total da Érica multiplicado por uma proporção
C15: Soma de "Material" da coluna "Natureza" da planilha Investimentos
C16: Soma de "Terceiros" da coluna "Natureza" da planilha Investimentos + Soma dos valores da planilha de Terceiros

Sheet Dias Úteis
B5: FERIADOS EM CURITIBA | E5: Total de Dias úteis por mês
B6: Data | C6: Feriado | E6: Dt. Inicial | F6: Dt. Final | G6: Dias úteis
B7: 42005 | C7: Ano Novo | E7: 42005 | F7: 42035 | G7: =NETWORKDAYS(E7,F7,$B$9:$B$18) -> 22
B8: 42097 | C8: Páscoa | E8: 42036 | F8: 42063 | G8: =NETWORKDAYS(E8,F8,$B$9:$B$18) -> 20
B9: 42115 | C9: Tiradentes | E9: 42064 | F9: 42094 | G9: =NETWORKDAYS(E9,F9,$B$9:$B$18) -> 22
B10: 42125 | C10: Dia do Trabalho | E10: 42095 | F10: 42124 | G10: =NETWORKDAYS(E10,F10,$B$9:$B$18) -> 21
B11: 42159 | C11: Corpus Christi | E11: 42125 | F11: 42155 | G11: =NETWORKDAYS(E11,F11,$B$9:$B$18) -> 20
B12: 42254 | C12: Independência | E12: 42156 | F12: 42185 | G12: =NETWORKDAYS(E12,F12,$B$9:$B$18) -> 21
B13: 42255 | C13: Padroeira de Curitiba | E13: 42186 | F13: 42216 | G13: =NETWORKDAYS(E13,F13,$B$9:$B$18) -> 23
B14: 42289 | C14: N.S.Aparecida | E14: 42217 | F14: 42247 | G14: =NETWORKDAYS(E14,F14,$B$9:$B$18) -> 21
B15: 42310 | C15: Finados | E15: 42248 | F15: 42277 | G15: =NETWORKDAYS(E15,F15,$B$9:$B$18) -> 20
B16: 42362 | C16: Natal | E16: 42278 | F16: 42308 | G16: =NETWORKDAYS(E16,F16,$B$9:$B$18) -> 21
B17: 42363 | C17: Natal | E17: 42309 | F17: 42338 | G17: =NETWORKDAYS(E17,F17,$B$9:$B$18) -> 20
B18: 42369 | C18: Ano novo | E18: 42339 | F18: 42369 | G18: =NETWORKDAYS(E18,F18,$B$9:$B$18) -> 20
B37: Detalhamento da Apuração sem exclusão de inovação

Sheet Quadro de pessoal
A1: PRODIET NUTRIÇÃO
A2: =Resumo!B2 -> INOVAÇÃO TECNOLÓGICA 2015
A3: Quadro de pessoal
D6: Recursos Humanos
C7: Título | D7: Nº de Pessoas com Dedicação Parcial | E7: Valor Gasto | F7: Nº de Pessoas com Dedicação Exclusiva | G7: Valor Gasto | H7: Total Valor Gasto
C8: Doutores | H8: =SUM(E8,G8) -> 0
C9: Mestres | H9: =SUM(E9,G9) -> 0
C10: Pós-Graduados | D10: 1 | F10: 1 | H10: =SUM(E10,G10) -> 0
C11: Graduados | D11: 2 | H11: =SUM(E11,G11) -> 0
C12: Tecnólogo | H12: =SUM(E12,G12) -> 0
C13: Técnico de nível médio | H13: =SUM(E13,G13) -> 0
C14: Total | D14: =SUM(D8:D13) -> 3 | E14: =SUM(E8:E13) -> 0 | F14: =SUM(F8:F13) -> 1 | G14: =SUM(G8:G13) -> 0 | H14: =SUM(E14,G14) -> 0
C15: Valor despendido com funcionários de apoio técnico
C16: VALOR TOTAL DESPENDIDO EM RH | H16: =SUM(H14:H15) -> 0
