Workbook

Sheet Base Projetos
B1: Incentivado pela Lei do Bem | C1: Objetiva tornar-se um Ativo | D1: Objetiva gerar patente/registro
A2: INOV00001 | B2: TRUE | C2: FALSE | D2: FALSE
A3: INOV00004 | B3: TRUE | C3: FALSE | D3: FALSE
A4: INOV00006 | B4: TRUE | C4: FALSE | D4: FALSE
A5: INOV00010 | B5: TRUE | C5: FALSE | D5: FALSE
A6: INOV00013 | B6: TRUE | C6: FALSE | D6: FALSE
A7: INOV00014 | B7: TRUE | C7: FALSE | D7: FALSE
A8: INOV00016 | B8: TRUE | C8: FALSE | D8: FALSE
A9: INOV00017 | B9: TRUE | C9: FALSE | D9: FALSE
A10: INOV00020 | B10: FALSE | C10: FALSE | D10: FALSE
A11: INOV00022 | B11: TRUE | C11: FALSE | D11: FALSE
A12: INOV00023 | B12: TRUE | C12: FALSE | D12: FALSE
A13: INOV00024 | B13: TRUE | C13: FALSE | D13: FALSE
A14: INOV00025 | B14: TRUE | C14: FALSE | D14: FALSE | E14: New | F14: Tampa
A15: INOV00027 | B15: FALSE | C15: FALSE | D15: FALSE
A16: INOV00029 | B16: TRUE | C16: FALSE | D16: FALSE | E16: New | F16: (Pesquisa)
A17: INOV00032 | B17: TRUE | C17: FALSE | D17: FALSE | E17: New | F17: (Spray)
A18: INOV00035 | B18: TRUE | C18: FALSE | D18: FALSE
A19: INOV00036 | B19: TRUE | C19: FALSE | D19: FALSE
A20: INOV00037 | B20: TRUE | C20: FALSE | D20: FALSE
A21: INOV00038 | B21: TRUE | C21: FALSE | D21: FALSE
A22: INOV00039 | B22: TRUE | C22: FALSE | D22: FALSE
A23: INOV00041 | B23: TRUE | C23: FALSE | D23: FALSE
A24: INOV00046 | B24: FALSE | C24: FALSE | D24: FALSE | E24: Perguntar | F24: aguardando resposta
A25: INOV00047 | B25: FALSE | C25: FALSE | D25: FALSE | E25: iguais | F25: aguardando resposta
A26: INOV00048 | B26: FALSE | C26: FALSE | D26: FALSE | E26: iguais | F26: aguardando resposta
A27: INOV00049 | B27: FALSE | C27: FALSE | D27: FALSE | E27: Perguntar | F27: aguardando resposta
A28: INOV00050 | B28: FALSE | C28: FALSE | D28: FALSE | E28: Perguntar | F28: aguardando resposta
A29: INOV00051 | B29: FALSE | C29: FALSE | D29: FALSE | E29: Perguntar | F29: aguardando resposta
A30: INOV00052 | B30: FALSE | C30: FALSE | D30: FALSE | E30: Solicitar | F30: aguardando resposta

Sheet RESUMO
B2: Resumo dos investimentos
B3: BENEFÍCIO FISCAL DE PD&I 2024
B5: PRODIET NUTRIÇÃO CLINICA LTDA | F5: CNPJ 08.183.359/0001-53 | H5: 2019-088 PRODIET
B6: Rua General Potiguara, 1428, Lotes 20 e 21, Novo Mundo - PR - SUL - CURITIBA - CEP 81.050-500 - fone: (41) 3342-2825 | H6: =TODAY() -> 46168
B8: Natureza | C8: 1º Trimestre | D8: 2º Trimestre | E8: 3º Trimestre | F8: 4º Trimestre | H8: TOTAL
B9: Material | C9: - | D9: - | E9: - | F9: - | H9: =sum(C9:F9) -> 0
B10: Terceiros | C10: =IFERROR(__xludf.DUMMYFUNCTION("iferror(sum(filter(TERCEIROS!$M12:$M71,month(TERCEIROS!$I12:$I71)>=1,month(TERCEIROS!$I12:$I71)<=3)),0)"),36035.1) -> 36035.1 | D10: =IFERROR(__xludf.DUMMYFUNCTION("iferror(sum(filter(TERCEIROS!$M12:$M71,month(TERCEIROS!$I12:$I71)>=4,month(TERCEIROS!$I12:$I71)<=6)),0)"),162191.78) -> 162191.78 | E10: =IFERROR(__xludf.DUMMYFUNCTION("iferror(sum(filter(TERCEIROS!$M12:$M71,month(TERCEIROS!$I12:$I71)>=7,month(TERCEIROS!$I12:$I71)<=9)),0)"),132155.385) -> 132155.39 | F10: =IFERROR(__xludf.DUMMYFUNCTION("iferror(sum(filter(TERCEIROS!$M12:$M71,month(TERCEIROS!$I12:$I71)>=10,month(TERCEIROS!$I12:$I71)<=12)),0)"),32886.7) -> 32886.7 | H10: =sum(C10:F10) -> 363268.97
B11: RH (Parcial inovação) | C11: =IFERROR(__xludf.DUMMYFUNCTION("iferror(sum(filter(TIMESHEET!$N$12:$N71,TIMESHEET!$Q$12:$Q71=""Parcial"",month(TIMESHEET!$F$12:$F71)>=1,month(TIMESHEET!$F$12:$F71)<=3)),0)-0.06"),15366.9) -> 15366.9 | D11: =IFERROR(__xludf.DUMMYFUNCTION("iferror(sum(filter(TIMESHEET!$N$12:$N71,TIMESHEET!$Q$12:$Q71=""Parcial"",month(TIMESHEET!$F$12:$F71)>=4,month(TIMESHEET!$F$12:$F71)<=6)),0)"),37022.72820846256) -> 37022.728 | E11: =IFERROR(__xludf.DUMMYFUNCTION("iferror(sum(filter(TIMESHEET!$N$12:$N71,TIMESHEET!$Q$12:$Q71=""Parcial"",month(TIMESHEET!$F$12:$F71)>=7,month(TIMESHEET!$F$12:$F71)<=9)),0)"),34877.28698090117) -> 34877.287 | F11: =IFERROR(__xludf.DUMMYFUNCTION("iferror(sum(filter(TIMESHEET!$N$12:$N71,TIMESHEET!$Q$12:$Q71=""Parcial"",month(TIMESHEET!$F$12:$F71)>=10,month(TIMESHEET!$F$12:$F71)<=12)),0)"),12531.24418370417) -> 12531.244 | H11: =sum(C11:F11) -> 99798.159
B12: RH (Exclusivo inovação) | C12: =IFERROR(__xludf.DUMMYFUNCTION("iferror(sum(filter(TIMESHEET!$N$12:$N71,TIMESHEET!$Q$12:$Q71=""Exclusivo"",month(TIMESHEET!$F$12:$F71)>=1,month(TIMESHEET!$F$12:$F71)<=3)),0)"),0.0) -> 0 | D12: =IFERROR(__xludf.DUMMYFUNCTION("iferror(sum(filter(TIMESHEET!$N$12:$N71,TIMESHEET!$Q$12:$Q71=""Exclusivo"",month(TIMESHEET!$F$12:$F71)>=4,month(TIMESHEET!$F$12:$F71)<=6)),0)"),0.0) -> 0 | E12: =IFERROR(__xludf.DUMMYFUNCTION("iferror(sum(filter(TIMESHEET!$N$12:$N71,TIMESHEET!$Q$12:$Q71=""Exclusivo"",month(TIMESHEET!$F$12:$F71)>=7,month(TIMESHEET!$F$12:$F71)<=9)),0)"),0.0) -> 0 | F12: =IFERROR(__xludf.DUMMYFUNCTION("iferror(sum(filter(TIMESHEET!$N$12:$N71,TIMESHEET!$Q$12:$Q71=""Exclusivo"",month(TIMESHEET!$F$12:$F71)>=10,month(TIMESHEET!$F$12:$F71)<=12)),0)"),0.0) -> 0 | H12: =sum(C12:F12) -> 0
B13: Total 1 | C13: =sum(C10:C12) -> 51402 | D13: =sum(D10:D12) -> 199214.51 | E13: =sum(E10:E12) -> 167032.67 | F13: =sum(F10:F12) -> 45417.944 | H13: =sum(C13:F13) -> 463067.12
B14: Percentual Exclusão | C14: 0.6 | D14: 0.6 | E14: 0.6 | F14: 0.6 | H14: 0.6
B15: Exclusão da Base de cálculo do IRPJ e CSLL | C15: =C13*C14 -> 30841.2 | D15: =D13*D14 -> 119528.7 | E15: =E13*E14 -> 100219.6 | F15: =F13*F14 -> 27250.767 | H15: =sum(C15:F15) -> 277840.27
B17: Economia Estimada [34%] | C17: =C15*34% -> 10486.008 | D17: =D15*34% -> 40639.76 | E17: =E15*34% -> 34074.665 | F17: =F15*34% -> 9265.2606 | H17: =sum(C17:F17) -> 94465.693
B18: Comissão McBenner | C18: =C17*0.1 -> 1048.6008 | D18: =D17*0.1 -> 4063.976 | E18: =E17*0.1 -> 3407.4665 | F18: =F17*0.1 -> 926.52606 | H18: =sum(C18:F18) -> 9446.5693
B20: Observações:
B21: 1. Os dispêndios devem ser registrados na contabilidade em conta específica
B22: 2. O benefício deve ser aproveitado na ECF do respectivo ano/competência
B23: 3. O formulário do MCTIC (governo) deve ser enviado até fim de Julho/2025
B24: 4. Os projetos estão descritos em arquivo a parte a ser anexado no FORM PD&I
B25: 5. Alguns benefícios previstos na Lei do Bem não foram utilizados:
B26: --- 5.1. Depreciação acelerada
B27: --- 5.2. Redução de IPI na aquisição de equipamento para PD&I
B29: Equipe de PD&I
B30: Quadro de resumo | C30: Dedicação Parcial | F30: Dedicação Exclusiva
C31: Qtd | D31: Valor gasto | E31: Horas | F31: Qtd | G31: Valor gasto | H31: Horas
B32: Técnico | C32: =IFERROR(__xludf.DUMMYFUNCTION("COUNTA(IFERROR(FILTER(PESSOAL!$F$13:$F$23,PESSOAL!$F$13:$F$23 = $B32,PESSOAL!$V$13:$V$23 = ""Parcial"",PESSOAL!$W$13:$W$23 = TRUE),))"),0.0) -> 0 | D32: =IFERROR(__xludf.DUMMYFUNCTION("SUM(IFERROR(FILTER(PESSOAL!$U$35:$U$45,PESSOAL!$F$35:$F$45 = $B32,PESSOAL!$E$35:$E$45 = ""Parcial""),0))"),0.0) -> 0 | E32: =IFERROR(__xludf.DUMMYFUNCTION("SUM(IFERROR(FILTER(PESSOAL!$T$13:$T$23,PESSOAL!$F$13:$F$23 = $B32,PESSOAL!$V$13:$V$23 = ""Parcial""),0))*24"),0.0) -> 0 | F32: =IFERROR(__xludf.DUMMYFUNCTION("COUNTA(IFERROR(FILTER(PESSOAL!$E$6:$E$19,PESSOAL!$E$6:$E$19 = $B32,PESSOAL!$U$6:$U$19 = ""Exclusivo"",PESSOAL!$U$28:$U$39 = TRUE),))"),0.0) -> 0 | G32: =IFERROR(__xludf.DUMMYFUNCTION("SUM(IFERROR(FILTER(PESSOAL!$U$35:$U$44,PESSOAL!$F$35:$F$44 = $B32,PESSOAL!$E$35:$E$44 = ""Exclusivo);0))"")))"),0.0) -> 0 | H32: =IFERROR(__xludf.DUMMYFUNCTION("SUM(IFERROR(FILTER(PESSOAL!$T$13:$T$23,PESSOAL!$F$13:$F$23 = $B32,PESSOAL!$V$13:$V$23 = ""Exclusivo""),0))*24"),0.0) -> 0
B33: Tecnologo | C33: =IFERROR(__xludf.DUMMYFUNCTION("COUNTA(IFERROR(FILTER(PESSOAL!$F$13:$F$23,PESSOAL!$F$13:$F$23 = $B33,PESSOAL!$V$13:$V$23 = ""Parcial"",PESSOAL!$W$13:$W$23 = TRUE),))"),0.0) -> 0 | D33: =IFERROR(__xludf.DUMMYFUNCTION("SUM(IFERROR(FILTER(PESSOAL!$U$35:$U$45,PESSOAL!$F$35:$F$45 = $B33,PESSOAL!$E$35:$E$45 = ""Parcial""),0))"),0.0) -> 0 | E33: =IFERROR(__xludf.DUMMYFUNCTION("SUM(IFERROR(FILTER(PESSOAL!$T$13:$T$23,PESSOAL!$F$13:$F$23 = $B33,PESSOAL!$V$13:$V$23 = ""Parcial""),0))*24"),0.0) -> 0 | F33: =IFERROR(__xludf.DUMMYFUNCTION("COUNTA(IFERROR(FILTER(PESSOAL!$E$6:$E$19,PESSOAL!$E$6:$E$19 = $B33,PESSOAL!$U$6:$U$19 = ""Exclusivo"",PESSOAL!$U$28:$U$39 = TRUE),))"),0.0) -> 0 | G33: =IFERROR(__xludf.DUMMYFUNCTION("SUM(IFERROR(FILTER(PESSOAL!$U$35:$U$44,PESSOAL!$F$35:$F$44 = $B33,PESSOAL!$E$35:$E$44 = ""Exclusivo);0))"")))"),0.0) -> 0 | H33: =IFERROR(__xludf.DUMMYFUNCTION("SUM(IFERROR(FILTER(PESSOAL!$T$13:$T$23,PESSOAL!$F$13:$F$23 = $B33,PESSOAL!$V$13:$V$23 = ""Exclusivo""),0))*24"),0.0) -> 0
B34: Graduação | C34: =IFERROR(__xludf.DUMMYFUNCTION("COUNTA(IFERROR(FILTER(PESSOAL!$F$13:$F$23,PESSOAL!$F$13:$F$23 = $B34,PESSOAL!$V$13:$V$23 = ""Parcial"",PESSOAL!$W$13:$W$23 = TRUE),))"),2.0) -> 2 | D34: =IFERROR(__xludf.DUMMYFUNCTION("SUM(IFERROR(FILTER(PESSOAL!$U$35:$U$45,PESSOAL!$F$35:$F$45 = $B34,PESSOAL!$E$35:$E$45 = ""Parcial""),0))"),16980.383291514452) -> 16980.383 | E34: =IFERROR(__xludf.DUMMYFUNCTION("SUM(IFERROR(FILTER(PESSOAL!$T$13:$T$23,PESSOAL!$F$13:$F$23 = $B34,PESSOAL!$V$13:$V$23 = ""Parcial""),0))*24"),311.2500000000001) -> 311.25 | F34: =IFERROR(__xludf.DUMMYFUNCTION("COUNTA(IFERROR(FILTER(PESSOAL!$E$6:$E$19,PESSOAL!$E$6:$E$19 = $B34,PESSOAL!$U$6:$U$19 = ""Exclusivo"",PESSOAL!$U$28:$U$39 = TRUE),))"),0.0) -> 0 | G34: =IFERROR(__xludf.DUMMYFUNCTION("SUM(IFERROR(FILTER(PESSOAL!$U$35:$U$44,PESSOAL!$F$35:$F$44 = $B34,PESSOAL!$E$35:$E$44 = ""Exclusivo);0))"")))"),0.0) -> 0 | H34: =IFERROR(__xludf.DUMMYFUNCTION("SUM(IFERROR(FILTER(PESSOAL!$T$13:$T$23,PESSOAL!$F$13:$F$23 = $B34,PESSOAL!$V$13:$V$23 = ""Exclusivo""),0))*24"),0.0) -> 0
B35: Pós graduado | C35: =IFERROR(__xludf.DUMMYFUNCTION("COUNTA(IFERROR(FILTER(PESSOAL!$F$13:$F$23,PESSOAL!$F$13:$F$23 = $B35,PESSOAL!$V$13:$V$23 = ""Parcial"",PESSOAL!$W$13:$W$23 = TRUE),))"),3.0) -> 3 | D35: =IFERROR(__xludf.DUMMYFUNCTION("SUM(IFERROR(FILTER(PESSOAL!$U$35:$U$45,PESSOAL!$F$35:$F$45 = $B35,PESSOAL!$E$35:$E$45 = ""Parcial""),0))"),28795.85934765911) -> 28795.859 | E35: =IFERROR(__xludf.DUMMYFUNCTION("SUM(IFERROR(FILTER(PESSOAL!$T$13:$T$23,PESSOAL!$F$13:$F$23 = $B35,PESSOAL!$V$13:$V$23 = ""Parcial""),0))*24"),542.0) -> 542 | F35: =IFERROR(__xludf.DUMMYFUNCTION("COUNTA(IFERROR(FILTER(PESSOAL!$E$6:$E$19,PESSOAL!$E$6:$E$19 = $B35,PESSOAL!$U$6:$U$19 = ""Exclusivo"",PESSOAL!$U$28:$U$39 = TRUE),))"),0.0) -> 0 | G35: =IFERROR(__xludf.DUMMYFUNCTION("SUM(IFERROR(FILTER(PESSOAL!$U$35:$U$44,PESSOAL!$F$35:$F$44 = $B35,PESSOAL!$E$35:$E$44 = ""Exclusivo);0))"")))"),0.0) -> 0 | H35: =IFERROR(__xludf.DUMMYFUNCTION("SUM(IFERROR(FILTER(PESSOAL!$T$13:$T$23,PESSOAL!$F$13:$F$23 = $B35,PESSOAL!$V$13:$V$23 = ""Exclusivo""),0))*24"),0.0) -> 0
B36: Mestrado | C36: =IFERROR(__xludf.DUMMYFUNCTION("COUNTA(IFERROR(FILTER(PESSOAL!$F$13:$F$23,PESSOAL!$F$13:$F$23 = $B36,PESSOAL!$V$13:$V$23 = ""Parcial"",PESSOAL!$W$13:$W$23 = TRUE),))"),1.0) -> 1 | D36: =IFERROR(__xludf.DUMMYFUNCTION("SUM(IFERROR(FILTER(PESSOAL!$U$35:$U$45,PESSOAL!$F$35:$F$45 = $B36,PESSOAL!$E$35:$E$45 = ""Parcial""),0))"),23918.220024484064) -> 23918.22 | E36: =IFERROR(__xludf.DUMMYFUNCTION("SUM(IFERROR(FILTER(PESSOAL!$T$13:$T$23,PESSOAL!$F$13:$F$23 = $B36,PESSOAL!$V$13:$V$23 = ""Parcial""),0))*24"),258.84999999999997) -> 258.85 | F36: =IFERROR(__xludf.DUMMYFUNCTION("COUNTA(IFERROR(FILTER(PESSOAL!$E$6:$E$19,PESSOAL!$E$6:$E$19 = $B36,PESSOAL!$U$6:$U$19 = ""Exclusivo"",PESSOAL!$U$28:$U$39 = TRUE),))"),0.0) -> 0 | G36: =IFERROR(__xludf.DUMMYFUNCTION("SUM(IFERROR(FILTER(PESSOAL!$U$35:$U$44,PESSOAL!$F$35:$F$44 = $B36,PESSOAL!$E$35:$E$44 = ""Exclusivo);0))"")))"),0.0) -> 0 | H36: =IFERROR(__xludf.DUMMYFUNCTION("SUM(IFERROR(FILTER(PESSOAL!$T$13:$T$23,PESSOAL!$F$13:$F$23 = $B36,PESSOAL!$V$13:$V$23 = ""Exclusivo""),0))*24"),0.0) -> 0
B37: Doutorado | C37: =IFERROR(__xludf.DUMMYFUNCTION("COUNTA(IFERROR(FILTER(PESSOAL!$F$13:$F$23,PESSOAL!$F$13:$F$23 = $B37,PESSOAL!$V$13:$V$23 = ""Parcial"",PESSOAL!$W$13:$W$23 = TRUE),))"),2.0) -> 2 | D37: =IFERROR(__xludf.DUMMYFUNCTION("SUM(IFERROR(FILTER(PESSOAL!$U$35:$U$45,PESSOAL!$F$35:$F$45 = $B37,PESSOAL!$E$35:$E$45 = ""Parcial""),0))"),30103.75670941025) -> 30103.757 | E37: =IFERROR(__xludf.DUMMYFUNCTION("SUM(IFERROR(FILTER(PESSOAL!$T$13:$T$23,PESSOAL!$F$13:$F$23 = $B37,PESSOAL!$V$13:$V$23 = ""Parcial""),0))*24"),559.1) -> 559.1 | F37: =IFERROR(__xludf.DUMMYFUNCTION("COUNTA(IFERROR(FILTER(PESSOAL!$E$6:$E$19,PESSOAL!$E$6:$E$19 = $B37,PESSOAL!$U$6:$U$19 = ""Exclusivo"",PESSOAL!$U$28:$U$39 = TRUE),))"),0.0) -> 0 | G37: =IFERROR(__xludf.DUMMYFUNCTION("SUM(IFERROR(FILTER(PESSOAL!$U$35:$U$44,PESSOAL!$F$35:$F$44 = $B37,PESSOAL!$E$35:$E$44 = ""Exclusivo);0))"")))"),0.0) -> 0 | H37: =IFERROR(__xludf.DUMMYFUNCTION("SUM(IFERROR(FILTER(PESSOAL!$T$13:$T$23,PESSOAL!$F$13:$F$23 = $B37,PESSOAL!$V$13:$V$23 = ""Exclusivo""),0))*24"),0.0) -> 0
C38: =SUM(C32:C37) -> 8 | D38: =SUM(D32:D37) -> 99798.219 | E38: =SUM(E32:E37) -> 1671.2 | F38: =SUM(F32:F37) -> 0 | G38: =SUM(G32:G37) -> 0 | H38: =SUM(H32:H37) -> 0
B40: Valores por projeto de PD&I
B41: Projetos | C41: TOTAL | E41: Vlr materiais | F41: Vlr terceiros | G41: Vlr Rh parcial | H41: Vlr exclusivos
A42: 1 | B42: {='Base Projetos'!A2:A71} -> INOV00001 | C42: =sum(E42:H42) -> 162088.55 | E42: - | F42: {=IFERROR(XLOOKUP(B42:B70,TRANSPOSE(TERCEIROS!$Q$11:$AX$11),TRANSPOSE(TERCEIROS!$Q$10:$AX$10),0,0),"")} -> 112121.99 | G42: =IFERROR(__xludf.DUMMYFUNCTION("ArrayFormula(IFERROR(SUM(filter(TIMESHEET!$N$12:$N71,TIMESHEET!$C$12:$C71=B42,TIMESHEET!$Q$12:$Q71=""Parcial"")),""-""))"),49966.559431866524) -> 49966.559 | H42: =IFERROR(__xludf.DUMMYFUNCTION("iferror(sum(filter(TIMESHEET!$N12:$N71,TIMESHEET!$C12:$C71=B42,TIMESHEET!$Q12:$Q71=""Exclusivo"")),""-"")"),"-") -> -
A43: 2 | B43: INOV00004 | C43: =sum(E43:H43) -> 17072.115 | E43: - | F43: 5388.575 | G43: =IFERROR(__xludf.DUMMYFUNCTION("ArrayFormula(IFERROR(SUM(filter(TIMESHEET!$N$12:$N71,TIMESHEET!$C$12:$C71=B43,TIMESHEET!$Q$12:$Q71=""Parcial"")),""-""))"),11683.539797642836) -> 11683.54 | H43: =IFERROR(__xludf.DUMMYFUNCTION("iferror(sum(filter(TIMESHEET!$N13:$N71,TIMESHEET!$C13:$C71=B43,TIMESHEET!$Q13:$Q71=""Exclusivo"")),""-"")"),"-") -> -
A44: 3 | B44: INOV00006 | C44: =sum(E44:H44) -> 14246.671 | E44: - | F44: 5322.08 | G44: =IFERROR(__xludf.DUMMYFUNCTION("ArrayFormula(IFERROR(SUM(filter(TIMESHEET!$N$12:$N71,TIMESHEET!$C$12:$C71=B44,TIMESHEET!$Q$12:$Q71=""Parcial"")),""-""))"),8924.590649799264) -> 8924.5907 | H44: =IFERROR(__xludf.DUMMYFUNCTION("iferror(sum(filter(TIMESHEET!$N14:$N71,TIMESHEET!$C14:$C71=B44,TIMESHEET!$Q14:$Q71=""Exclusivo"")),""-"")"),"-") -> -
A45: 4 | B45: INOV00010 | C45: =sum(E45:H45) -> 12156.39 | E45: - | F45: 12156.39 | G45: =IFERROR(__xludf.DUMMYFUNCTION("ArrayFormula(IFERROR(SUM(filter(TIMESHEET!$N$12:$N71,TIMESHEET!$C$12:$C71=B45,TIMESHEET!$Q$12:$Q71=""Parcial"")),""-""))"),"-") -> - | H45: =IFERROR(__xludf.DUMMYFUNCTION("iferror(sum(filter(TIMESHEET!$N15:$N71,TIMESHEET!$C15:$C71=B45,TIMESHEET!$Q15:$Q71=""Exclusivo"")),""-"")"),"-") -> -
A46: 5 | B46: INOV00013 | C46: =sum(E46:H46) -> 32723.672 | E46: - | F46: 32488.45 | G46: =IFERROR(__xludf.DUMMYFUNCTION("ArrayFormula(IFERROR(SUM(filter(TIMESHEET!$N$12:$N71,TIMESHEET!$C$12:$C71=B46,TIMESHEET!$Q$12:$Q71=""Parcial"")),""-""))"),235.22225388463443) -> 235.22225 | H46: =IFERROR(__xludf.DUMMYFUNCTION("iferror(sum(filter(TIMESHEET!$N16:$N71,TIMESHEET!$C16:$C71=B46,TIMESHEET!$Q16:$Q71=""Exclusivo"")),""-"")"),"-") -> -
A47: 6 | B47: INOV00014 | C47: =sum(E47:H47) -> 53892.415 | E47: - | F47: 49956.91 | G47: =IFERROR(__xludf.DUMMYFUNCTION("ArrayFormula(IFERROR(SUM(filter(TIMESHEET!$N$12:$N71,TIMESHEET!$C$12:$C71=B47,TIMESHEET!$Q$12:$Q71=""Parcial"")),""-""))"),3935.5051161177626) -> 3935.5051 | H47: =IFERROR(__xludf.DUMMYFUNCTION("iferror(sum(filter(TIMESHEET!$N17:$N71,TIMESHEET!$C17:$C71=B47,TIMESHEET!$Q17:$Q71=""Exclusivo"")),""-"")"),"-") -> -
...

Sheet PROJETO
B2: PRODIET
B3: Pesquisa, Desenvolvimento & Inovação
B4: Formulário de PD&I - Ano 2024 | J4: Incentivado pela Lei do Bem | M4: FALSE
B5: - preencher somente os campos sombreados (cinza) e - adicionar cronograma no formato de imagem ao fim do formulário - preencher um deste para cada projeto de PD&I | J5: Objetiva tornar-se um Ativo | M5: FALSE
J6: Objetiva gerar patente/registro | M6: FALSE
B8: Dossiêdoprojeto
B9: DadosgeraisparaidentificaçãoevalidaçãodoprojetodePD&I
B11: Nome do projeto
J12: Pesquisa básica | M12: 📑
B13: Classificação do projeto | J13: Pesquisa aplicada | M13: 📑
J14: Desenvolvimento experimental | M14: 📑
B15: Objetivos do projeto
J16: Inovação tecnológica de produto | M16: 📑
B17: Tipo de inovação | J17: Inovação tecnológica de processo | M17: 📑
J18: Inovação tecnológica de serviços | M18: 📑
B19: Elemento inovador | J19: - Não podem ser consideradas as inovações organizacionais, comerciais e de marketing
J20: Empresa ou segmento regional | M20: 📑
B21: Nível de inovação | J21: Inovador para o Brasil | M21: 📑
J22: Inovador para o Mundo | M22: 📑
B23: Risco tecnológico
B25: Metodologias
B27: Equipe | E27: NomeCompleto | F27: Cargo|Função | G27: Qualificação | H27: !
E28: Lizianne Angelica Shmeil | F28: Analista de P&D | G28: Pós-graduação | H28: FALSE | L28: Técnico | M28: 📑
E29: Ana Paula Celes | F29: Diretora Técnica | G29: Pós-graduação | H29: FALSE | L29: Graduação
E30: Luciana Dutra | F30: Gerente Técnica | G30: Pós-graduação | H30: FALSE | L30: Pós-graduação
E31: Gabriela Faria de Oliveira | F31: Analista Científico | G31: Pós-graduação | H31: FALSE | L31: Mestrado
E32: Rafael Parreira Lorini | F32: Analista de P&D | G32: Graduação | H32: FALSE | L32: Doutorado
E33: Hellin dos Santos | F33: Gerente Científico | G33: Mestrado | H33: FALSE
E34: Camila Mendes Pereira | F34: Analista de P&D | G34: Graduação | H34: FALSE
E35: Ana Claudia Zanini | F35: Analista cientifico | G35: Mestrado | H35: FALSE
E36: Juliana Lamas Roberto | F36: Especialista de Estudo de Estabilidade | G36: Mestrado | H36: FALSE
E37: Márcio Henrique Nogueira | F37: Analista de P&D | G37: Doutorado | H37: FALSE
E38: Tahuany Caetano | F38: Analista MKT | G38: Pós-graduação | H38: FALSE
E39: Arianna Schreiber | F39: MARKETING
E40: Mihaela Theer Moura | F40: MARKETING
E41: Tahuany Leite | F41: MARKETING
E42: Vaneisse Cristina Lima Monteiro
E43: Ana Paula Biz
E44: Raissa Bellotti
E45: Alyne Alves Nunes Oliveira
...

Sheet CHECKLIST
B2: PRODIET
B3: Pesquisa ,Desenvolvimento & Inovação
B4: Formulário de PD&I - Ano2024
B5: -preencher somente os campos sombreados (cinza)
B8: Dossiê do projeto
B9: Checklist - outras informações
B11: Área | C11: Item | D11: Descrição | E11: Status | F11: Comentáriocliente | G11: ComentárioMcBenner

Sheet PESSOAL
B2: PRODIET
B3: Pesquisa ,Desenvolvimento & Inovação
B4: Formulário de PD&I - Ano2024
B5: -preencher somente os campos sombreados (cinza)
B8: Dossiê do projeto
B9: Cálculo de custo - Pessoal
B11: Salário bruto | T11: =(U11/12)*24 -> 186.26667 | U11: =(SUM(H33:S33)*8.8)/24 -> 93.133333
B12: Nome Completo | C12: CPF | D12: notas | E12: Cargo/função | F12: Formação | G12: Attachments | H12: Salário 01 | I12: Salário 02 | J12: Salário 03 | K12: Salário 04 | L12: Salário 05 | M12: Salário 06 | N12: Salário 07 | O12: Salário 08 | P12: Salário 09 | Q12: Salário 10 | R12: Salário 11 | S12: Salário 12 | T12: PD&I time | U12: PD&I (%) | V12: Classificação | W12: Pesquisador
B13: {=SORT(UNIQUE(TIMESHEET!E12:E67))} -> Alyne Alves Nunes Oliveira | C13: 129.307.117-01 | E13: Especialista de P&D | F13: Doutorado | G13: CLT | H13: 7234.78 | I13: 7234.78 | J13: 7234.78 | K13: 7234.78 | L13: 7234.78 | M13: 7234.78 | N13: 7234.78 | O13: 7596.52 | P13: 7596.52 | Q13: 7596.52 | T13: =IFERROR(__xludf.DUMMYFUNCTION("IFERROR(IF(W13=TRUE, SUM(FILTER(TIMESHEET!$G:$G,TIMESHEET!O:O = TRUE,TIMESHEET!P:P = TRUE,TIMESHEET!E:E = B13,TIMESHEET!F:F < DATE(2025,1,1))),0),0)"),13.659722222222223) -> 13.659722 | U13: =T13/$U$11 -> 0.14666846 | V13: =IF(U13<80%,"Parcial","Exclusivo") -> Parcial | W13: TRUE
B14: Ana Claudia Zanini | C14: 076.046.519-33 | E14: Analista Científico SR | F14: Graduação | G14: CLT | H14: 6143.46 | I14: 6143.46 | J14: 6143.46 | K14: 6143.46 | L14: 6143.46 | M14: 6143.46 | N14: 6143.46 | O14: 7613.79 | P14: 7613.79 | Q14: 7613.79 | R14: 7613.79 | S14: 7613.79 | T14: =IFERROR(__xludf.DUMMYFUNCTION("IFERROR(IF(W14=TRUE, SUM(FILTER(TIMESHEET!$G:$G,TIMESHEET!O:O = TRUE,TIMESHEET!P:P = TRUE,TIMESHEET!E:E = B14,TIMESHEET!F:F < DATE(2025,1,1))),0),0)"),10.187500000000004) -> 10.1875 | U14: =T14/$U$11 -> 0.10938618 | V14: =IF(U14<80%,"Parcial","Exclusivo") -> Parcial | W14: TRUE
B15: Ana Paula Biz | C15: 071.847.899-11 | E15: Analista de P&D Pleno | F15: Doutorado | G15: CLT | H15: 4594.31 | I15: 4594.31 | J15: 4594.31 | K15: 4594.31 | L15: 4594.31 | M15: 4594.31 | N15: 4594.31 | O15: 4824.03 | P15: 4824.03 | Q15: 5481.24 | R15: 5481.24 | S15: 5481.24 | T15: =IFERROR(__xludf.DUMMYFUNCTION("IFERROR(IF(W15=TRUE, SUM(FILTER(TIMESHEET!$G:$G,TIMESHEET!O:O = TRUE,TIMESHEET!P:P = TRUE,TIMESHEET!E:E = B15,TIMESHEET!F:F < DATE(2025,1,1))),0),0)"),9.636111111111111) -> 9.6361111 | U15: =T15/$U$11 -> 0.10346576 | V15: =IF(U15<80%,"Parcial","Exclusivo") -> Parcial | W15: TRUE
B16: Ana Paula Celes | C16: 759.837.297-72 | E16: Diretora Técnica | F16: Pós Graduado | G16: PJ | H16: 37755.67 | I16: 37755.67 | J16: 37755.67 | K16: 37755.67 | L16: 37755.67 | M16: 37755.67 | N16: 37755.67 | O16: 37243.45 | P16: 37243.45 | Q16: 37243.45 | R16: 37243.45 | S16: 37243.45 | T16: =IFERROR(__xludf.DUMMYFUNCTION("IFERROR(IF(W16=TRUE, SUM(FILTER(TIMESHEET!$G:$G,TIMESHEET!O:O = TRUE,TIMESHEET!P:P = TRUE,TIMESHEET!E:E = B16,TIMESHEET!F:F < DATE(2025,1,1))),0),0)"),0.2604166666666667) -> 0.26041667 | U16: =T16/$U$11 -> 0.0027961704 | V16: =IF(U16<80%,"Parcial","Exclusivo") -> Parcial | W16: TRUE
B17: Camila Mendes Pereira | C17: 083.832.289-10 | E17: Analista de P&D Pleno | F17: Graduação | G17: CLT | H17: 5469.76 | I17: 5469.76 | J17: 5469.76 | K17: 5469.76 | L17: 5469.76 | M17: 5469.76 | N17: 5850.91 | O17: 6143.46 | P17: 6143.46 | Q17: 6143.46 | R17: 6143.46 | S17: 6143.46 | T17: =IFERROR(__xludf.DUMMYFUNCTION("IFERROR(IF(W17=TRUE, SUM(FILTER(TIMESHEET!$G:$G,TIMESHEET!O:O = TRUE,TIMESHEET!P:P = TRUE,TIMESHEET!E:E = B17,TIMESHEET!F:F < DATE(2025,1,1))),0),0)"),2.7812500000000004) -> 2.78125 | U17: =T17/$U$11 -> 0.0298631 | V17: =IF(U17<80%,"Parcial","Exclusivo") -> Parcial | W17: TRUE
B18: Gabriela Faria de Oliveira | C18: 087.823.469-17 | E18: Analista Científico SR | F18: Pós Graduado | G18: CLT | H18: 5743.25 | I18: 5743.25 | J18: 5743.25 | K18: 5743.25 | L18: 5743.25 | M18: 5743.25 | N18: 6143.46 | O18: 7234.78 | P18: 7234.78 | Q18: 7234.78 | R18: 7234.78 | S18: 7234.78 | T18: =IFERROR(__xludf.DUMMYFUNCTION("IFERROR(IF(W18=TRUE, SUM(FILTER(TIMESHEET!$G:$G,TIMESHEET!O:O = TRUE,TIMESHEET!P:P = TRUE,TIMESHEET!E:E = B18,TIMESHEET!F:F < DATE(2025,1,1))),0),0)"),17.208333333333336) -> 17.208333 | U18: =T18/$U$11 -> 0.18477094 | V18: =IF(U18<80%,"Parcial","Exclusivo") -> Parcial | W18: TRUE
B19: Juliana Lamas Roberto | C19: 317.875.738-42 | E19: Coordenadora de P&D | F19: Mestrado | G19: CLT | H19: 11225.48 | I19: 11225.48 | J19: 11225.48 | K19: 11225.48 | L19: 11225.48 | M19: 11225.48 | N19: 11225.48 | O19: 11786.75 | P19: 11786.75 | Q19: 11786.75 | R19: 11786.75 | S19: 11786.75 | T19: =IFERROR(__xludf.DUMMYFUNCTION("IFERROR(IF(W19=TRUE, SUM(FILTER(TIMESHEET!$G:$G,TIMESHEET!O:O = TRUE,TIMESHEET!P:P = TRUE,TIMESHEET!E:E = B19,TIMESHEET!F:F < DATE(2025,1,1))),0),0)"),10.785416666666665) -> 10.785417 | U19: =T19/$U$11 -> 0.11580619 | V19: =IF(U19<80%,"Parcial","Exclusivo") -> Parcial | W19: TRUE
B20: Raissa Bellotti | C20: 430.604.838-17 | E20: Analista Científico Jr | F20: Pós Graduado | G20: CLT | H20: 4780.42 | I20: 4780.42 | J20: 4780.42 | K20: 4780.42 | L20: 4780.42 | M20: 4780.42 | N20: 4780.42 | O20: 5481.24 | P20: 5481.24 | Q20: 5481.24 | R20: 5481.24 | S20: 5481.24 | T20: =IFERROR(__xludf.DUMMYFUNCTION("IFERROR(IF(W20=TRUE, SUM(FILTER(TIMESHEET!$G:$G,TIMESHEET!O:O = TRUE,TIMESHEET!P:P = TRUE,TIMESHEET!E:E = B20,TIMESHEET!F:F < DATE(2025,1,1))),0),0)"),5.114583333333334) -> 5.1145833 | U20: =T20/$U$11 -> 0.054916786 | V20: =IF(U20<80%,"Parcial","Exclusivo") -> Parcial | W20: TRUE
T21: =IFERROR(__xludf.DUMMYFUNCTION("IFERROR(IF(W21=TRUE, SUM(FILTER(TIMESHEET!$G:$G,TIMESHEET!O:O = TRUE,TIMESHEET!P:P = TRUE,TIMESHEET!E:E = B21,TIMESHEET!F:F < DATE(2025,1,1))),0),0)"),0.0) -> 0 | U21: =T21/$U$11 -> 0 | V21: =IF(U21<80%,"Parcial","Exclusivo") -> Parcial | W21: TRUE
T22: =IFERROR(__xludf.DUMMYFUNCTION("IFERROR(IF(W22=TRUE, SUM(FILTER(TIMESHEET!$G:$G,TIMESHEET!O:O = TRUE,TIMESHEET!P:P = TRUE,TIMESHEET!E:E = B22,TIMESHEET!F:F < DATE(2025,1,1))),0),0)"),0.0) -> 0 | U22: =T22/$U$11 -> 0 | V22: =IF(U22<80%,"Parcial","Exclusivo") -> Parcial | W22: TRUE
T23: =IFERROR(__xludf.DUMMYFUNCTION("IFERROR(IF(W23=TRUE, SUM(FILTER(TIMESHEET!$G:$G,TIMESHEET!O:O = TRUE,TIMESHEET!P:P = TRUE,TIMESHEET!E:E = B23,TIMESHEET!F:F < DATE(2025,1,1))),0),0)"),0.0) -> 0 | U23: =T23/$U$11 -> 0 | V23: =IF(U23<80%,"Parcial","Exclusivo") -> Parcial | W23: TRUE
T24: =IFERROR(__xludf.DUMMYFUNCTION("IFERROR(IF(W24=TRUE, SUM(FILTER(TIMESHEET!$G:$G,TIMESHEET!O:O = TRUE,TIMESHEET!P:P = TRUE,TIMESHEET!E:E = B24,TIMESHEET!F:F < DATE(2025,1,1))),0),0)"),0.0) -> 0 | U24: =T24/$U$11 -> 0 | V24: =IF(U24<80%,"Parcial","Exclusivo") -> Parcial | W24: TRUE
T25: =IFERROR(__xludf.DUMMYFUNCTION("IFERROR(IF(W25=TRUE, SUM(FILTER(TIMESHEET!$G:$G,TIMESHEET!O:O = TRUE,TIMESHEET!P:P = TRUE,TIMESHEET!E:E = B25,TIMESHEET!F:F < DATE(2025,1,1))),0),0)"),0.0) -> 0 | U25: =T25/$U$11 -> 0 | V25: =IF(U25<80%,"Parcial","Exclusivo") -> Parcial | W25: TRUE
B27: Cálculo do custo/hora
B29: Encargos sobre folha | I29: INSS | J29: Patronal | K29: 0.2
B30: INSS | C30: FGTS | D30: Férias | E30: 13º | F30: Total | J30: Terceiros | K30: 0.058
B31: =SUM(K29:K31) -> 0.273 | C31: 0.08 | D31: =((1+(1/3))*(1+B31+C31)/12) -> 0.15033333 | E31: =(1+B31+C31)/12 -> 0.11275 | F31: =SUM(B31:E31) -> 0.61608333 | J31: RAT | K31: 0.015
H33: =NETWORKDAYS(DATE(right(H34,4),mid(H34,4,2),1),DATE(right(H34,4),mid(H34,4,2)+1,0),$B$50:$B$61) -> 22 | I33: =NETWORKDAYS(DATE(right(I34,4),mid(I34,4,2),1),DATE(right(I34,4),mid(I34,4,2)+1,0),$B$50:$B$61) -> 19 | J33: =NETWORKDAYS(DATE(right(J34,4),mid(J34,4,2),1),DATE(right(J34,4),mid(J34,4,2)+1,0),$B$50:$B$61) -> 20 | K33: =NETWORKDAYS(DATE(right(K34,4),mid(K34,4,2),1),DATE(right(K34,4),mid(K34,4,2)+1,0),$B$50:$B$61) -> 22 | L33: =NETWORKDAYS(DATE(right(L34,4),mid(L34,4,2),1),DATE(right(L34,4),mid(L34,4,2)+1,0),$B$50:$B$61) -> 22 | M33: =NETWORKDAYS(DATE(right(M34,4),mid(M34,4,2),1),DATE(right(M34,4),mid(M34,4,2)+1,0),$B$50:$B$61) -> 20 | N33: =NETWORKDAYS(DATE(right(N34,4),mid(N34,4,2),1),DATE(right(N34,4),mid(N34,4,2)+1,0),$B$50:$B$61) -> 23 | O33: =NETWORKDAYS(DATE(right(O34,4),mid(O34,4,2),1),DATE(right(O34,4),mid(O34,4,2)+1,0),$B$50:$B$61) -> 22 | ... S33: =NETWORKDAYS(DATE(right(S34,4),mid(S34,4,2),1),DATE(right(S34,4),mid(S34,4,2)+1,0),$B$50:$B$61) -> 21 | T33: =SUM(T35:T49) -> 99798.219 | U33: =SUM(U35:U49) -> 99798.219 | V33: =U33-T33 -> 0
B34: Nome Completo | E34: Classificação | F34: Formação | H34: 45322 | I34: 45350 | J34: 45382 | K34: 45412 | L34: 45443 | M34: 45473 | N34: 45504 | O34: 45535 | P34: 45565 | Q34: 45596 | R34: 45626 | S34: 45657 | T34: PD&I R$ | U34: Aprovado R$ | V34: Pesquisador
B35: {=unique(B13:B25)} -> Alyne Alves Nunes Oliveira | E35: {=V13:V25} -> Parcial | F35: {=F13:F25} -> Doutorado | H35: =vlookup($B35,$B$13:$S$23,month(H$34)+6,0)*(1+$F$31)/(H$33*8.8) -> 60.3926 | I35: =vlookup($B35,$B$13:$S$23,month(I$34)+6,0)*(1+$F$31)/(I$33*8.8) -> 69.928274 | J35: =vlookup($B35,$B$13:$S$23,month(J$34)+6,0)*(1+$F$31)/(J$33*8.8) -> 66.43186 | K35: =vlookup($B35,$B$13:$S$23,month(K$34)+6,0)*(1+$F$31)/(K$33*8.8) -> 60.3926 | L35: =vlookup($B35,$B$13:$S$23,month(L$34)+6,0)*(1+$F$31)/(L$33*8.8) -> 60.3926 | M35: =vlookup($B35,$B$13:$S$23,month(M$34)+6,0)*(1+$F$31)/(M$33*8.8) -> 66.43186 | N35: =vlookup($B35,$B$13:$S$23,month(N$34)+6,0)*(1+$F$31)/(N$33*8.8) -> 57.766835 | O35: =vlookup($B35,$B$13:$S$23,month(O$34)+6,0)*(1+$F$31)/(O$33*8.8) -> 63.412238 | ... S35: =vlookup($B35,$B$13:$S$23,month(S$34)+6,0)*(1+$F$31)/(S$33*8.8) -> 0 | T35: =SUMIF(TIMESHEET!E:E,B35,TIMESHEET!N:N) -> 20331.727 | U35: =SUMIF(V35,TRUE,T35) -> 20331.727 | V35: TRUE
B36: Ana Claudia Zanini | E36: Parcial | F36: Graduação | H36: =vlookup($B36,$B$13:$S$23,month(H$34)+6,0)*(1+$F$31)/(H$33*8.8) -> 51.282765 | I36: =vlookup($B36,$B$13:$S$23,month(I$34)+6,0)*(1+$F$31)/(I$33*8.8) -> 59.380044 | J36: =vlookup($B36,$B$13:$S$23,month(J$34)+6,0)*(1+$F$31)/(J$33*8.8) -> 56.411042 | K36: =vlookup($B36,$B$13:$S$23,month(K$34)+6,0)*(1+$F$31)/(K$33*8.8) -> 51.282765 | L36: =vlookup($B36,$B$13:$S$23,month(L$34)+6,0)*(1+$F$31)/(L$33*8.8) -> 51.282765 | M36: =vlookup($B36,$B$13:$S$23,month(M$34)+6,0)*(1+$F$31)/(M$33*8.8) -> 56.411042 | N36: =vlookup($B36,$B$13:$S$23,month(N$34)+6,0)*(1+$F$31)/(N$33*8.8) -> 49.05308 | O36: =vlookup($B36,$B$13:$S$23,month(O$34)+6,0)*(1+$F$31)/(O$33*8.8) -> 63.5564 | ... S36: =vlookup($B36,$B$13:$S$23,month(S$34)+6,0)*(1+$F$31)/(S$33*8.8) -> 66.582896 | T36: =SUMIF(TIMESHEET!E:E,B36,TIMESHEET!N:N) -> 13740.744 | U36: =SUMIF(V36,TRUE,T36) -> 13740.744 | V36: TRUE
B37: Ana Paula Biz | E37: Parcial | F37: Doutorado | H37: =vlookup($B37,$B$13:$S$23,month(H$34)+6,0)*(1+$F$31)/(H$33*8.8) -> 38.351177 | I37: =vlookup($B37,$B$13:$S$23,month(I$34)+6,0)*(1+$F$31)/(I$33*8.8) -> 44.406626 | J37: =vlookup($B37,$B$13:$S$23,month(J$34)+6,0)*(1+$F$31)/(J$33*8.8) -> 42.186294 | K37: =vlookup($B37,$B$13:$S$23,month(K$34)+6,0)*(1+$F$31)/(K$33*8.8) -> 38.351177 | L37: =vlookup($B37,$B$13:$S$23,month(L$34)+6,0)*(1+$F$31)/(L$33*8.8) -> 38.351177 | M37: =vlookup($B37,$B$13:$S$23,month(M$34)+6,0)*(1+$F$31)/(M$33*8.8) -> 42.186294 | N37: =vlookup($B37,$B$13:$S$23,month(N$34)+6,0)*(1+$F$31)/(N$33*8.8) -> 36.683734 | O37: =vlookup($B37,$B$13:$S$23,month(O$34)+6,0)*(1+$F$31)/(O$33*8.8) -> 40.268773 | ... S37: =vlookup($B37,$B$13:$S$23,month(S$34)+6,0)*(1+$F$31)/(S$33*8.8) -> 47.933661 | T37: =SUMIF(TIMESHEET!E:E,B37,TIMESHEET!N:N) -> 9772.0299 | U37: =SUMIF(V37,TRUE,T37) -> 9772.0299 | V37: TRUE
B38: Ana Paula Celes | E38: Parcial | F38: Pós Graduado | G38: PJ | H38: =vlookup($B38,$B$13:$S$23,month(H$34)+6,0)/(H$33*8.8) -> 195.01896 | I38: =vlookup($B38,$B$13:$S$23,month(I$34)+6,0)/(I$33*8.8) -> 225.81142 | J38: =vlookup($B38,$B$13:$S$23,month(J$34)+6,0)/(J$33*8.8) -> 214.52085 | K38: =vlookup($B38,$B$13:$S$23,month(K$34)+6,0)/(K$33*8.8) -> 195.01896 | L38: =vlookup($B38,$B$13:$S$23,month(L$34)+6,0)/(L$33*8.8) -> 195.01896 | M38: =vlookup($B38,$B$13:$S$23,month(M$34)+6,0)/(M$33*8.8) -> 214.52085 | N38: =vlookup($B38,$B$13:$S$23,month(N$34)+6,0)/(N$33*8.8) -> 186.53987 | O38: =vlookup($B38,$B$13:$S$23,month(O$34)+6,0)/(O$33*8.8) -> 192.37319 | ... S38: =vlookup($B38,$B$13:$S$23,month(S$34)+6,0)/(S$33*8.8) -> 201.53382 | T38: =SUMIF(TIMESHEET!E:E,B38,TIMESHEET!N:N) -> 1843.959 | U38: =SUMIF(V38,TRUE,T38) -> 1843.959 | V38: TRUE
B39: Camila Mendes Pereira | E39: Parcial | F39: Graduação | H39: =vlookup($B39,$B$13:$S$23,month(H$34)+6,0)*(1+$F$31)/(H$33*8.8) -> 45.659029 | I39: =vlookup($B39,$B$13:$S$23,month(I$34)+6,0)*(1+$F$31)/(I$33*8.8) -> 52.868349 | J39: =vlookup($B39,$B$13:$S$23,month(J$34)+6,0)*(1+$F$31)/(J$33*8.8) -> 50.224932 | K39: =vlookup($B39,$B$13:$S$23,month(K$34)+6,0)*(1+$F$31)/(K$33*8.8) -> 45.659029 | L39: =vlookup($B39,$B$13:$S$23,month(L$34)+6,0)*(1+$F$31)/(L$33*8.8) -> 45.659029 | M39: =vlookup($B39,$B$13:$S$23,month(M$34)+6,0)*(1+$F$31)/(M$33*8.8) -> 50.224932 | N39: =vlookup($B39,$B$13:$S$23,month(N$34)+6,0)*(1+$F$31)/(N$33*8.8) -> 46.717184 | O39: =vlookup($B39,$B$13:$S$23,month(O$34)+6,0)*(1+$F$31)/(O$33*8.8) -> 51.282765 | ... S39: =vlookup($B39,$B$13:$S$23,month(S$34)+6,0)*(1+$F$31)/(S$33*8.8) -> 53.724801 | T39: =SUMIF(TIMESHEET!E:E,B39,TIMESHEET!N:N) -> 3239.6395 | U39: =SUMIF(V39,TRUE,T39) -> 3239.6395 | V39: TRUE
B40: Gabriela Faria de Oliveira | E40: Parcial | F40: Pós Graduado | H40: =vlookup($B40,$B$13:$S$23,month(H$34)+6,0)*(1+$F$31)/(H$33*8.8) -> 47.941997 | I40: =vlookup($B40,$B$13:$S$23,month(I$34)+6,0)*(1+$F$31)/(I$33*8.8) -> 55.511786 | J40: =vlookup($B40,$B$13:$S$23,month(J$34)+6,0)*(1+$F$31)/(J$33*8.8) -> 52.736197 | K40: =vlookup($B40,$B$13:$S$23,month(K$34)+6,0)*(1+$F$31)/(K$33*8.8) -> 47.941997 | L40: =vlookup($B40,$B$13:$S$23,month(L$34)+6,0)*(1+$F$31)/(L$33*8.8) -> 47.941997 | M40: =vlookup($B40,$B$13:$S$23,month(M$34)+6,0)*(1+$F$31)/(M$33*8.8) -> 52.736197 | N40: =vlookup($B40,$B$13:$S$23,month(N$34)+6,0)*(1+$F$31)/(N$33*8.8) -> 49.05308 | O40: =vlookup($B40,$B$13:$S$23,month(O$34)+6,0)*(1+$F$31)/(O$33*8.8) -> 60.3926 | ... S40: =vlookup($B40,$B$13:$S$23,month(S$34)+6,0)*(1+$F$31)/(S$33*8.8) -> 63.268438 | T40: =SUMIF(TIMESHEET!E:E,B40,TIMESHEET!N:N) -> 21526.287 | U40: =SUMIF(V40,TRUE,T40) -> 21526.287 | V40: TRUE
B41: Juliana Lamas Roberto | E41: Parcial | F41: Mestrado | H41: =vlookup($B41,$B$13:$S$23,month(H$34)+6,0)*(1+$F$31)/(H$33*8.8) -> 93.70512 | I41: =vlookup($B41,$B$13:$S$23,month(I$34)+6,0)*(1+$F$31)/(I$33*8.8) -> 108.50066 | J41: =vlookup($B41,$B$13:$S$23,month(J$34)+6,0)*(1+$F$31)/(J$33*8.8) -> 103.07563 | K41: =vlookup($B41,$B$13:$S$23,month(K$34)+6,0)*(1+$F$31)/(K$33*8.8) -> 93.70512 | L41: =vlookup($B41,$B$13:$S$23,month(L$34)+6,0)*(1+$F$31)/(L$33*8.8) -> 93.70512 | M41: =vlookup($B41,$B$13:$S$23,month(M$34)+6,0)*(1+$F$31)/(M$33*8.8) -> 103.07563 | N41: =vlookup($B41,$B$13:$S$23,month(N$34)+6,0)*(1+$F$31)/(N$33*8.8) -> 89.630984 | O41: =vlookup($B41,$B$13:$S$23,month(O$34)+6,0)*(1+$F$31)/(O$33*8.8) -> 98.390342 | ... S41: =vlookup($B41,$B$13:$S$23,month(S$34)+6,0)*(1+$F$31)/(S$33*8.8) -> 103.0756 | T41: =SUMIF(TIMESHEET!E:E,B41,TIMESHEET!N:N) -> 23918.22 | U41: =SUMIF(V41,TRUE,T41) -> 23918.22 | V41: TRUE
B42: Raissa Bellotti | E42: Parcial | F42: Pós Graduado | H42: =vlookup($B42,$B$13:$S$23,month(H$34)+6,0)*(1+$F$31)/(H$33*8.8) -> 39.904737 | I42: =vlookup($B42,$B$13:$S$23,month(I$34)+6,0)*(1+$F$31)/(I$33*8.8) -> 46.205485 | J42: =vlookup($B42,$B$13:$S$23,month(J$34)+6,0)*(1+$F$31)/(J$33*8.8) -> 43.895211 | K42: =vlookup($B42,$B$13:$S$23,month(K$34)+6,0)*(1+$F$31)/(K$33*8.8) -> 39.904737 | L42: =vlookup($B42,$B$13:$S$23,month(L$34)+6,0)*(1+$F$31)/(L$33*8.8) -> 39.904737 | M42: =vlookup($B42,$B$13:$S$23,month(M$34)+6,0)*(1+$F$31)/(M$33*8.8) -> 43.895211 | N42: =vlookup($B42,$B$13:$S$23,month(N$34)+6,0)*(1+$F$31)/(N$33*8.8) -> 38.169748 | O42: =vlookup($B42,$B$13:$S$23,month(O$34)+6,0)*(1+$F$31)/(O$33*8.8) -> 45.754859 | ... S42: =vlookup($B42,$B$13:$S$23,month(S$34)+6,0)*(1+$F$31)/(S$33*8.8) -> 47.933661 | T42: =SUMIF(TIMESHEET!E:E,B42,TIMESHEET!N:N) -> 5425.6135 | U42: =SUMIF(V42,TRUE,T42) -> 5425.6135 | V42: TRUE
E43: Parcial | H43: =vlookup($B43,$B$13:$S$23,month(H$34)+6,0)*(1+$F$31)/(H$33*8.8) -> #N/A | I43: =vlookup($B43,$B$13:$S$23,month(I$34)+6,0)*(1+$F$31)/(I$33*8.8) -> #N/A | J43: =vlookup($B43,$B$13:$S$23,month(J$34)+6,0)*(1+$F$31)/(J$33*8.8) -> #N/A | K43: =vlookup($B43,$B$13:$S$23,month(K$34)+6,0)*(1+$F$31)/(K$33*8.8) -> #N/A | L43: =vlookup($B43,$B$13:$S$23,month(L$34)+6,0)*(1+$F$31)/(L$33*8.8) -> #N/A | M43: =vlookup($B43,$B$13:$S$23,month(M$34)+6,0)*(1+$F$31)/(M$33*8.8) -> #N/A | N43: =vlookup($B43,$B$13:$S$23,month(N$34)+6,0)*(1+$F$31)/(N$33*8.8) -> #N/A | O43: =vlookup($B43,$B$13:$S$23,month(O$34)+6,0)*(1+$F$31)/(O$33*8.8) -> #N/A | ... S43: =vlookup($B43,$B$13:$S$23,month(S$34)+6,0)*(1+$F$31)/(S$33*8.8) -> #N/A | T43: =SUMIF(TIMESHEET!E:E,B43,TIMESHEET!N:N) -> 0 | U43: =SUMIF(V43,TRUE,T43) -> 0 | V43: TRUE
E44: Parcial | H44: =vlookup($B44,$B$13:$S$25,month(H$34)+6,0)*(1+$F$31)/(H$33*8.8) -> #N/A | I44: =vlookup($B44,$B$13:$S$23,month(I$34)+6,0)*(1+$F$31)/(I$33*8.8) -> #N/A | J44: =vlookup($B44,$B$13:$S$23,month(J$34)+6,0)*(1+$F$31)/(J$33*8.8) -> #N/A | K44: =vlookup($B44,$B$13:$S$23,month(K$34)+6,0)*(1+$F$31)/(K$33*8.8) -> #N/A | L44: =vlookup($B44,$B$13:$S$23,month(L$34)+6,0)*(1+$F$31)/(L$33*8.8) -> #N/A | M44: =vlookup($B44,$B$13:$S$23,month(M$34)+6,0)*(1+$F$31)/(M$33*8.8) -> #N/A | N44: =vlookup($B44,$B$13:$S$23,month(N$34)+6,0)*(1+$F$31)/(N$33*8.8) -> #N/A | O44: =vlookup($B44,$B$13:$S$23,month(O$34)+6,0)*(1+$F$31)/(O$33*8.8) -> #N/A | P44: =vlookup($B44,$B$13:$S$23,month(P$34)+6,0)*(1+$F$31)/(P$33*8.8) -> #N/A | ... S44: =vlookup($B44,$B$13:$S$23,month(S$34)+6,0)*(1+$F$31)/(S$33*8.8) -> #N/A | T44: =SUMIF(TIMESHEET!E:E,B44,TIMESHEET!N:N) -> 0 | U44: =SUMIF(V44,TRUE,T44) -> 0 | V44: TRUE
E45: Parcial | H45: =vlookup($B45,$B$13:$S$23,month(H$34)+6,0)*(1+$F$31)/(H$33*8.8) -> #N/A | I45: =vlookup($B45,$B$13:$S$23,month(I$34)+6,0)*(1+$F$31)/(I$33*8.8) -> #N/A | J45: =vlookup($B45,$B$13:$S$23,month(J$34)+6,0)*(1+$F$31)/(J$33*8.8) -> #N/A | K45: =vlookup($B45,$B$13:$S$23,month(K$34)+6,0)*(1+$F$31)/(K$33*8.8) -> #N/A | L45: =vlookup($B45,$B$13:$S$23,month(L$34)+6,0)*(1+$F$31)/(L$33*8.8) -> #N/A | M45: =vlookup($B45,$B$13:$S$23,month(M$34)+6,0)*(1+$F$31)/(M$33*8.8) -> #N/A | N45: =vlookup($B45,$B$13:$S$23,month(N$34)+6,0)*(1+$F$31)/(N$33*8.8) -> #N/A | O45: =vlookup($B45,$B$13:$S$23,month(O$34)+6,0)*(1+$F$31)/(O$33*8.8) -> #N/A | ... S45: =vlookup($B45,$B$13:$S$23,month(S$34)+6,0)*(1+$F$31)/(S$33*8.8) -> #N/A | T45: =SUMIF(TIMESHEET!E:E,B45,TIMESHEET!N:N) -> 0 | U45: =SUMIF(V45,TRUE,T45) -> 0 | V45: TRUE
E46: Parcial | H46: =vlookup($B46,$B$13:$S$25,month(H$34)+6,0)*(1+$F$31)/(H$33*8.8) -> #N/A | I46: =vlookup($B46,$B$13:$S$25,month(I$34)+6,0)*(1+$F$31)/(I$33*8.8) -> #N/A | J46: =vlookup($B46,$B$13:$S$25,month(J$34)+6,0)*(1+$F$31)/(J$33*8.8) -> #N/A | K46: =vlookup($B46,$B$13:$S$25,month(K$34)+6,0)*(1+$F$31)/(K$33*8.8) -> #N/A | L46: =vlookup($B46,$B$13:$S$25,month(L$34)+6,0)*(1+$F$31)/(L$33*8.8) -> #N/A | M46: =vlookup($B46,$B$13:$S$25,month(M$34)+6,0)*(1+$F$31)/(M$33*8.8) -> #N/A | N46: =vlookup($B46,$B$13:$S$25,month(N$34)+6,0)*(1+$F$31)/(N$33*8.8) -> #N/A | O46: =vlookup($B46,$B$13:$S$25,month(O$34)+6,0)*(1+$F$31)/(O$33*8.8) -> #N/A | ... S46: =vlookup($B46,$B$13:$S$25,month(S$34)+6,0)*(1+$F$31)/(S$33*8.8) -> #N/A | T46: =SUMIF(TIMESHEET!E:E,B46,TIMESHEET!N:N) -> 0 | U46: =SUMIF(V46,TRUE,T46) -> 0 | V46: TRUE
E47: Parcial | H47: =vlookup($B47,$B$13:$S$25,month(H$34)+6,0)*(1+$F$31)/(H$33*8.8) -> #N/A | I47: =vlookup($B47,$B$13:$S$25,month(I$34)+6,0)*(1+$F$31)/(I$33*8.8) -> #N/A | J47: =vlookup($B47,$B$13:$S$25,month(J$34)+6,0)*(1+$F$31)/(J$33*8.8) -> #N/A | K47: =vlookup($B47,$B$13:$S$25,month(K$34)+6,0)*(1+$F$31)/(K$33*8.8) -> #N/A | L47: =vlookup($B47,$B$13:$S$25,month(L$34)+6,0)*(1+$F$31)/(L$33*8.8) -> #N/A | M47: =vlookup($B47,$B$13:$S$25,month(M$34)+6,0)*(1+$F$31)/(M$33*8.8) -> #N/A | N47: =vlookup($B47,$B$13:$S$25,month(N$34)+6,0)*(1+$F$31)/(N$33*8.8) -> #N/A | O47: =vlookup($B47,$B$13:$S$25,month(O$34)+6,0)*(1+$F$31)/(O$33*8.8) -> #N/A | ... S47: =vlookup($B47,$B$13:$S$25,month(S$34)+6,0)*(1+$F$31)/(S$33*8.8) -> #N/A | T47: =SUMIF(TIMESHEET!E:E,B47,TIMESHEET!N:N) -> 0 | U47: =SUMIF(V47,TRUE,T47) -> 0 | V47: TRUE
...

Sheet TERCEIROS
B2: PRODIET
B3: Pesquisa ,Desenvolvimento & Inovação
B4: Formulário de PD&I - Ano2024
B5: -preencher somente os campos sombreados (cinza)
O7: Rateio
B8: Dossiê do projeto
B9: Investimentos com terceiros | H9: =SUBTOTAL(9,H24:H97) -> 459074.9 | K9: Diferença | Q9: {=XLOOKUP(Q11,'Base Projetos'!$A:$A,'Base Projetos'!$B:$B,FALSE)} -> TRUE | R9: {=XLOOKUP(R11,'Base Projetos'!$A:$A,'Base Projetos'!$B:$B,FALSE)} -> FALSE | S9: {=XLOOKUP(S11,'Base Projetos'!$A:$A,'Base Projetos'!$B:$B,FALSE)} -> TRUE | T9: {=XLOOKUP(T11,'Base Projetos'!$A:$A,'Base Projetos'!$B:$B,FALSE)} -> TRUE | U9: {=XLOOKUP(U11,'Base Projetos'!$A:$A,'Base Projetos'!$B:$B,FALSE)} -> TRUE | V9: {=XLOOKUP(V11,'Base Projetos'!$A:$A,'Base Projetos'!$B:$B,FALSE)} -> FALSE | W9: {=XLOOKUP(W11,'Base Projetos'!$A:$A,'Base Projetos'!$B:$B,FALSE)} -> TRUE | X9: {=XLOOKUP(X11,'Base Projetos'!$A:$A,'Base Projetos'!$B:$B,FALSE)} -> TRUE | ... BE9: {=XLOOKUP(BE11,'Base Projetos'!$A:$A,'Base Projetos'!$B:$B,FALSE)} -> FALSE
H10: =SUM(H12:H1135) -> 527033.36 | M10: =sum(M12:M1135) -> 363268.97 | O10: =sum(Q10:BE10) -> 363268.97 | Q10: =SUM(Q12:Q1135) -> 112121.99 | R10: =SUM(R12:R1135) -> 0 | S10: =SUM(S12:S1135) -> 5388.575 | T10: =SUM(T12:T1135) -> 5322.08 | U10: =SUM(U12:U1135) -> 12156.39 | V10: =SUM(V12:V1135) -> 0 | W10: =SUM(W12:W1135) -> 32488.45 | X10: =SUM(X12:X1135) -> 49956.91 | ... BE10: =SUM(BE12:BE1135) -> 0
B11: Projeto | C11: Etapa | D11: Fornecedor | F11: CNPJ | G11: Notafiscal | H11: Valor | I11: Data | J11: Descrição da Atividade | K11: Objetivo do gasto e eventual info de rateio | L11: Incentivado? | M11: Valor incentivado | O11: Conf. val. rateio | P11: Count | Q11: INOV00001 | R11: INOV00003 | S11: INOV00004 | T11: INOV00006 | U11: INOV00010 | V11: INOV00012 | W11: INOV00013 | X11: INOV00014 | Y11: INOV00015 | Z11: INOV00016 | AA11: INOV00017 | AB11: INOV00018 | AC11: INOV00019 | AD11: INOV00020 | AE11: INOV00021 | AF11: INOV00022 | AG11: INOV00023 | AH11: INOV00024 | AI11: INOV00025 | AJ11: INOV00026 | AK11: INOV00027 | AL11: INOV00028 | AM11: INOV00029 | AN11: INOV00030 | AO11: INOV00031 | AP11: INOV00032 | AQ11: INOV00034 | AR11: INOV00035 | AS11: INOV00036 | AT11: INOV00037 | AU11: INOV00038 | AV11: INOV00039 | AW11: INOV00040 | AX11: INOV00041 | AY11: INOV00046 | AZ11: INOV00047 | BA11: INOV00048 | BB11: INOV00049 | BC11: INOV00050 | BD11: INOV00051 | BE11: INOV00052
B12: INOV00013 | D12: Eurofins do Brasil Análise de Alimentos Ltda. | F12: 04.329.668/0001-38 | G12: 234790 | H12: 15029.59 | I12: 45302 | J12: Análise de vitaminas, minerais e macronutrientes. | L12: TRUE | M12: =SUM(Q12:BE12) -> 15029.59 | O12: =SUM(Q12:AP12)=H12 -> TRUE | P12: =IF(L12=FALSE,0,IF(LEN(B12)=0,0,IF(LEN(B12)=9,1,(LEN(B12)+1)/10))) -> 1 | Q12: =iferror(if(Q$9=FALSE,, if(if(search(Q$11,$B12,1)>0,1,0)=1,$H12/$P12,)),"") | R12: =iferror(if(R$9=FALSE,, if(if(search(R$11,$B12,1)>0,1,0)=1,$H12/$P12,)),"") | S12: =iferror(if(S$9=FALSE,, if(if(search(S$11,$B12,1)>0,1,0)=1,$H12/$P12,)),"") | T12: =iferror(if(T$9=FALSE,, if(if(search(T$11,$B12,1)>0,1,0)=1,$H12/$P12,)),"") | U12: =iferror(if(U$9=FALSE,, if(if(search(U$11,$B12,1)>0,1,0)=1,$H12/$P12,)),"") | V12: =iferror(if(V$9=FALSE,, if(if(search(V$11,$B12,1)>0,1,0)=1,$H12/$P12,)),"") | W12: =iferror(if(W$9=FALSE,, if(if(search(W$11,$B12,1)>0,1,0)=1,$H12/$P12,)),"") -> 15029.59 | X12: =iferror(if(X$9=FALSE,, if(if(search(X$11,$B12,1)>0,1,0)=1,$H12/$P12,)),"") | ... BE12: =iferror(if(BE$9=FALSE,, if(if(search(BE$11,$B12,1)>0,1,0)=1,$H12/$P12,)),"")
B13: INOV00006 | D13: Eurofins do Brasil Análise de Alimentos Ltda. | F13: 04.329.668/0001-38 | G13: 235095 | H13: 5322.08 | I13: 45307 | J13: Análise de vitaminas, minerais e macronutrientes. | L13: TRUE | M13: =SUM(Q13:BE13) -> 5322.08 | O13: =SUM(Q13:AP13)=H13 -> TRUE | P13: =IF(L13=FALSE,0,IF(LEN(B13)=0,0,IF(LEN(B13)=9,1,(LEN(B13)+1)/10))) -> 1 | Q13: =iferror(if(Q$9=FALSE,, if(if(search(Q$11,$B13,1)>0,1,0)=1,$H13/$P13,)),"") | R13: =iferror(if(R$9=FALSE,, if(if(search(R$11,$B13,1)>0,1,0)=1,$H13/$P13,)),"") | S13: =iferror(if(S$9=FALSE,, if(if(search(S$11,$B13,1)>0,1,0)=1,$H13/$P13,)),"") | T13: =iferror(if(T$9=FALSE,, if(if(search(T$11,$B13,1)>0,1,0)=1,$H13/$P13,)),"") -> 5322.08 | U13: =iferror(if(U$9=FALSE,, if(if(search(U$11,$B13,1)>0,1,0)=1,$H13/$P13,)),"") | V13: =iferror(if(V$9=FALSE,, if(if(search(V$11,$B13,1)>0,1,0)=1,$H13/$P13,)),"") | W13: =iferror(if(W$9=FALSE,, if(if(search(W$11,$B13,1)>0,1,0)=1,$H13/$P13,)),"") | X13: =iferror(if(X$9=FALSE,, if(if(search(X$11,$B13,1)>0,1,0)=1,$H13/$P13,)),"") | ... BE13: =iferror(if(BE$9=FALSE,, if(if(search(BE$11,$B13,1)>0,1,0)=1,$H13/$P13,)),"")
B14: INOV00013 | D14: Fundação de apoio à Pesquisa | F14: 50.276.237/0001-78 | G14: 149770 | H14: 2556 | I14: 45309 | J14: Análise de PL. | L14: TRUE | M14: =SUM(Q14:BE14) -> 2556 | O14: =SUM(Q14:AP14)=H14 -> TRUE | P14: =IF(L14=FALSE,0,IF(LEN(B14)=0,0,IF(LEN(B14)=9,1,(LEN(B14)+1)/10))) -> 1 | Q14: =iferror(if(Q$9=FALSE,, if(if(search(Q$11,$B14,1)>0,1,0)=1,$H14/$P14,)),"") | R14: =iferror(if(R$9=FALSE,, if(if(search(R$11,$B14,1)>0,1,0)=1,$H14/$P14,)),"") | S14: =iferror(if(S$9=FALSE,, if(if(search(S$11,$B14,1)>0,1,0)=1,$H14/$P14,)),"") | T14: =iferror(if(T$9=FALSE,, if(if(search(T$11,$B14,1)>0,1,0)=1,$H14/$P14,)),"") | U14: =iferror(if(U$9=FALSE,, if(if(search(U$11,$B14,1)>0,1,0)=1,$H14/$P14,)),"") | V14: =iferror(if(V$9=FALSE,, if(if(search(V$11,$B14,1)>0,1,0)=1,$H14/$P14,)),"") | W14: =iferror(if(W$9=FALSE,, if(if(search(W$11,$B14,1)>0,1,0)=1,$H14/$P14,)),"") -> 2556 | X14: =iferror(if(X$9=FALSE,, if(if(search(X$11,$B14,1)>0,1,0)=1,$H14/$P14,)),"") | ... BE14: =iferror(if(BE$9=FALSE,, if(if(search(BE$11,$B14,1)>0,1,0)=1,$H14/$P14,)),"")
B15: INOV00037 | D15: PRODIET NUTRICAO CLINICA LTDA | F15: 08.183.359/0003-15 | G15: 82609 | H15: 4821.12 | I15: 45322 | J15: Doação de Produto Immax para Pesquisa Clinica | L15: FALSE | M15: =SUM(Q15:BE15) -> 0 | O15: =SUM(Q15:AP15)=H15 -> FALSE | P15: =IF(L15=FALSE,0,IF(LEN(B15)=0,0,IF(LEN(B15)=9,1,(LEN(B15)+1)/10))) -> 0 | Q15: =iferror(if(Q$9=FALSE,, if(if(search(Q$11,$B15,1)>0,1,0)=1,$H15/$P15,)),"") | R15: =iferror(if(R$9=FALSE,, if(if(search(R$11,$B15,1)>0,1,0)=1,$H15/$P15,)),"") | S15: =iferror(if(S$9=FALSE,, if(if(search(S$11,$B15,1)>0,1,0)=1,$H15/$P15,)),"") | T15: =iferror(if(T$9=FALSE,, if(if(search(T$11,$B15,1)>0,1,0)=1,$H15/$P15,)),"") | U15: =iferror(if(U$9=FALSE,, if(if(search(U$11,$B15,1)>0,1,0)=1,$H15/$P15,)),"") | V15: =iferror(if(V$9=FALSE,, if(if(search(V$11,$B15,1)>0,1,0)=1,$H15/$P15,)),"") | W15: =iferror(if(W$9=FALSE,, if(if(search(W$11,$B15,1)>0,1,0)=1,$H15/$P15,)),"") | X15: =iferror(if(X$9=FALSE,, if(if(search(X$11,$B15,1)>0,1,0)=1,$H15/$P15,)),"") | ... BE15: =iferror(if(BE$9=FALSE,, if(if(search(BE$11,$B15,1)>0,1,0)=1,$H15/$P15,)),"")
B16: INOV00016 | D16: Eurofins do Brasil Análise de Alimentos Ltda. | F16: 04.329.668/0001-38 | G16: 235962 | H16: 971.04 | I16: 45323 | J16: Análise de Vitamina C. | L16: TRUE | M16: =SUM(Q16:BE16) -> 971.04 | O16: =SUM(Q16:AP16)=H16 -> TRUE | P16: =IF(L16=FALSE,0,IF(LEN(B16)=0,0,IF(LEN(B16)=9,1,(LEN(B16)+1)/10))) -> 1 | Q16: =iferror(if(Q$9=FALSE,, if(if(search(Q$11,$B16,1)>0,1,0)=1,$H16/$P16,)),"") | R16: =iferror(if(R$9=FALSE,, if(if(search(R$11,$B16,1)>0,1,0)=1,$H16/$P16,)),"") | S16: =iferror(if(S$9=FALSE,, if(if(search(S$11,$B16,1)>0,1,0)=1,$H16/$P16,)),"") | T16: =iferror(if(T$9=FALSE,, if(if(search(T$11,$B16,1)>0,1,0)=1,$H16/$P16,)),"") | U16: =iferror(if(U$9=FALSE,, if(if(search(U$11,$B16,1)>0,1,0)=1,$H16/$P16,)),"") | V16: =iferror(if(V$9=FALSE,, if(if(search(V$11,$B16,1)>0,1,0)=1,$H16/$P16,)),"") | W16: =iferror(if(W$9=FALSE,, if(if(search(W$11,$B16,1)>0,1,0)=1,$H16/$P16,)),"") | X16: =iferror(if(X$9=FALSE,, if(if(search(X$11,$B16,1)>0,1,0)=1,$H16/$P16,)),"") | ... BE16: =iferror(if(BE$9=FALSE,, if(if(search(BE$11,$B16,1)>0,1,0)=1,$H16/$P16,)),"")
B17: INOV00010 | D17: J&J Serviços de Entregas Ltda - ME | F17: 20.618.029/0001-49 | G17: 75457 | H17: 250.4 | I17: 45324 | J17: Envio para análise. | L17: TRUE | M17: =SUM(Q17:BE17) -> 250.4 | O17: =SUM(Q17:AP17)=H17 -> TRUE | P17: =IF(L17=FALSE,0,IF(LEN(B17)=0,0,IF(LEN(B17)=9,1,(LEN(B17)+1)/10))) -> 1 | Q17: =iferror(if(Q$9=FALSE,, if(if(search(Q$11,$B17,1)>0,1,0)=1,$H17/$P17,)),"") | R17: =iferror(if(R$9=FALSE,, if(if(search(R$11,$B17,1)>0,1,0)=1,$H17/$P17,)),"") | S17: =iferror(if(S$9=FALSE,, if(if(search(S$11,$B17,1)>0,1,0)=1,$H17/$P17,)),"") | T17: =iferror(if(T$9=FALSE,, if(if(search(T$11,$B17,1)>0,1,0)=1,$H17/$P17,)),"") | U17: =iferror(if(U$9=FALSE,, if(if(search(U$11,$B17,1)>0,1,0)=1,$H17/$P17,)),"") -> 250.4 | V17: =iferror(if(V$9=FALSE,, if(if(search(V$11,$B17,1)>0,1,0)=1,$H17/$P17,)),"") | W17: =iferror(if(W$9=FALSE,, if(if(search(W$11,$B17,1)>0,1,0)=1,$H17/$P17,)),"") | X17: =iferror(if(X$9=FALSE,, if(if(search(X$11,$B17,1)>0,1,0)=1,$H17/$P17,)),"") | ... BE17: =iferror(if(BE$9=FALSE,, if(if(search(BE$11,$B17,1)>0,1,0)=1,$H17/$P17,)),"")
B18: INOV00010 | D18: Eurofins do Brasil Análise de Alimentos Ltda. | F18: 04.329.668/0001-38 | G18: 237669 | H18: 10113.99 | I18: 45344 | J18: Análise de vitaminas, minerais e macronutrientes. | L18: TRUE | M18: =SUM(Q18:BE18) -> 10113.99 | O18: =SUM(Q18:AP18)=H18 -> TRUE | P18: =IF(L18=FALSE,0,IF(LEN(B18)=0,0,IF(LEN(B18)=9,1,(LEN(B18)+1)/10))) -> 1 | Q18: =iferror(if(Q$9=FALSE,, if(if(search(Q$11,$B18,1)>0,1,0)=1,$H18/$P18,)),"") | R18: =iferror(if(R$9=FALSE,, if(if(search(R$11,$B18,1)>0,1,0)=1,$H18/$P18,)),"") | S18: =iferror(if(S$9=FALSE,, if(if(search(S$11,$B18,1)>0,1,0)=1,$H18/$P18,)),"") | T18: =iferror(if(T$9=FALSE,, if(if(search(T$11,$B18,1)>0,1,0)=1,$H18/$P18,)),"") | U18: =iferror(if(U$9=FALSE,, if(if(search(U$11,$B18,1)>0,1,0)=1,$H18/$P18,)),"") -> 10113.99 | V18: =iferror(if(V$9=FALSE,, if(if(search(V$11,$B18,1)>0,1,0)=1,$H18/$P18,)),"") | W18: =iferror(if(W$9=FALSE,, if(if(search(W$11,$B18,1)>0,1,0)=1,$H18/$P18,)),"") | X18: =iferror(if(X$9=FALSE,, if(if(search(X$11,$B18,1)>0,1,0)=1,$H18/$P18,)),"") | ... BE18: =iferror(if(BE$9=FALSE,, if(if(search(BE$11,$B18,1)>0,1,0)=1,$H18/$P18,)),"")
B19: INOV00010 | D19: Fundação de Desenvolvimento da Pesquisa do Agronegocio | F19: 50.276.237/0001-78 | G19: 150563 | H19: 1792 | I19: 45352 | J19: Análise de PL. | L19: TRUE | M19: =SUM(Q19:BE19) -> 1792 | O19: =SUM(Q19:AP19)=H19 -> TRUE | P19: =IF(L19=FALSE,0,IF(LEN(B19)=0,0,IF(LEN(B19)=9,1,(LEN(B19)+1)/10))) -> 1 | Q19: =iferror(if(Q$9=FALSE,, if(if(search(Q$11,$B19,1)>0,1,0)=1,$H19/$P19,)),"") | R19: =iferror(if(R$9=FALSE,, if(if(search(R$11,$B19,1)>0,1,0)=1,$H19/$P19,)),"") | S19: =iferror(if(S$9=FALSE,, if(if(search(S$11,$B19,1)>0,1,0)=1,$H19/$P19,)),"") | T19: =iferror(if(T$9=FALSE,, if(if(search(T$11,$B19,1)>0,1,0)=1,$H19/$P19,)),"") | U19: =iferror(if(U$9=FALSE,, if(if(search(U$11,$B19,1)>0,1,0)=1,$H19/$P19,)),"") -> 1792 | V19: =iferror(if(V$9=FALSE,, if(if(search(V$11,$B19,1)>0,1,0)=1,$H19/$P19,)),"") | W19: =iferror(if(W$9=FALSE,, if(if(search(W$11,$B19,1)>0,1,0)=1,$H19/$P19,)),"") | X19: =iferror(if(X$9=FALSE,, if(if(search(X$11,$B19,1)>0,1,0)=1,$H19/$P19,)),"") | ... BE19: =iferror(if(BE$9=FALSE,, if(if(search(BE$11,$B19,1)>0,1,0)=1,$H19/$P19,)),"")
B20: INOV00023 | D20: RaiaDrogasil S/A | F20: 61.585.865/3103-47 | G20: 13955 | H20: 1205.5 | I20: 45352 | J20: Doação de sensores para Pesquisa Clínica | L20: FALSE | M20: =SUM(Q20:BE20) -> 0 | O20: =SUM(Q20:AP20)=H20 -> FALSE | P20: =IF(L20=FALSE,0,IF(LEN(B20)=0,0,IF(LEN(B20)=9,1,(LEN(B20)+1)/10))) -> 0 | Q20: =iferror(if(Q$9=FALSE,, if(if(search(Q$11,$B20,1)>0,1,0)=1,$H20/$P20,)),"") | R20: =iferror(if(R$9=FALSE,, if(if(search(R$11,$B20,1)>0,1,0)=1,$H20/$P20,)),"") | S20: =iferror(if(S$9=FALSE,, if(if(search(S$11,$B20,1)>0,1,0)=1,$H20/$P20,)),"") | T20: =iferror(if(T$9=FALSE,, if(if(search(T$11,$B20,1)>0,1,0)=1,$H20/$P20,)),"") | U20: =iferror(if(U$9=FALSE,, if(if(search(U$11,$B20,1)>0,1,0)=1,$H20/$P20,)),"") | V20: =iferror(if(V$9=FALSE,, if(if(search(V$11,$B20,1)>0,1,0)=1,$H20/$P20,)),"") | W20: =iferror(if(W$9=FALSE,, if(if(search(W$11,$B20,1)>0,1,0)=1,$H20/$P20,)),"") | X20: =iferror(if(X$9=FALSE,, if(if(search(X$11,$B20,1)>0,1,0)=1,$H20/$P20,)),"") | ... BE20: =iferror(if(BE$9=FALSE,, if(if(search(BE$11,$B20,1)>0,1,0)=1,$H20/$P20,)),"")
B21: INOV00023 | D21: RaiaDrogasil S/A | F21: 61.585.865/3103-47 | G21: 14277 | H21: 905.6 | I21: 45358 | J21: Doação de sensores para Pesquisa Clínica | L21: FALSE | M21: =SUM(Q21:BE21) -> 0 | O21: =SUM(Q21:AP21)=H21 -> FALSE | P21: =IF(L21=FALSE,0,IF(LEN(B21)=0,0,IF(LEN(B21)=9,1,(LEN(B21)+1)/10))) -> 0 | Q21: =iferror(if(Q$9=FALSE,, if(if(search(Q$11,$B21,1)>0,1,0)=1,$H21/$P21,)),"") | R21: =iferror(if(R$9=FALSE,, if(if(search(R$11,$B21,1)>0,1,0)=1,$H21/$P21,)),"") | S21: =iferror(if(S$9=FALSE,, if(if(search(S$11,$B21,1)>0,1,0)=1,$H21/$P21,)),"") | T21: =iferror(if(T$9=FALSE,, if(if(search(T$11,$B21,1)>0,1,0)=1,$H21/$P21,)),"") | U21: =iferror(if(U$9=FALSE,, if(if(search(U$11,$B21,1)>0,1,0)=1,$H21/$P21,)),"") | V21: =iferror(if(V$9=FALSE,, if(if(search(V$11,$B21,1)>0,1,0)=1,$H21/$P21,)),"") | W21: =iferror(if(W$9=FALSE,, if(if(search(W$11,$B21,1)>0,1,0)=1,$H21/$P21,)),"") | X21: =iferror(if(X$9=FALSE,, if(if(search(X$11,$B21,1)>0,1,0)=1,$H21/$P21,)),"") | ... BE21: =iferror(if(BE$9=FALSE,, if(if(search(BE$11,$B21,1)>0,1,0)=1,$H21/$P21,)),"")
B22: INOV00023 | D22: RaiaDrogasil S/A | F22: 61.585.865/3103-47 | G22: 14639 | H22: 305.8 | I22: 45364 | J22: Doação de sensores para Pesquisa Clínica | L22: FALSE | M22: =SUM(Q22:BE22) -> 0 | O22: =SUM(Q22:AP22)=H22 -> FALSE | P22: =IF(L22=FALSE,0,IF(LEN(B22)=0,0,IF(LEN(B22)=9,1,(LEN(B22)+1)/10))) -> 0 | Q22: =iferror(if(Q$9=FALSE,, if(if(search(Q$11,$B22,1)>0,1,0)=1,$H22/$P22,)),"") | R22: =iferror(if(R$9=FALSE,, if(if(search(R$11,$B22,1)>0,1,0)=1,$H22/$P22,)),"") | S22: =iferror(if(S$9=FALSE,, if(if(search(S$11,$B22,1)>0,1,0)=1,$H22/$P22,)),"") | T22: =iferror(if(T$9=FALSE,, if(if(search(T$11,$B22,1)>0,1,0)=1,$H22/$P22,)),"") | U22: =iferror(if(U$9=FALSE,, if(if(search(U$11,$B22,1)>0,1,0)=1,$H22/$P22,)),"") | V22: =iferror(if(V$9=FALSE,, if(if(search(V$11,$B22,1)>0,1,0)=1,$H22/$P22,)),"") | W22: =iferror(if(W$9=FALSE,, if(if(search(W$11,$B22,1)>0,1,0)=1,$H22/$P22,)),"") | X22: =iferror(if(X$9=FALSE,, if(if(search(X$11,$B22,1)>0,1,0)=1,$H22/$P22,)),"") | ... BE22: =iferror(if(BE$9=FALSE,, if(if(search(BE$11,$B22,1)>0,1,0)=1,$H22/$P22,)),"")
B23: INOV00001 | D23: J&J Serviços de Entregas Ltda - ME | F23: 20.618.029/0001-49 | G23: 76271 | H23: 541.28 | I23: 45371 | J23: Envio para análise. | L23: FALSE | M23: =SUM(Q23:BE23) -> 0 | O23: =SUM(Q23:AP23)=H23 -> FALSE | P23: =IF(L23=FALSE,0,IF(LEN(B23)=0,0,IF(LEN(B23)=9,1,(LEN(B23)+1)/10))) -> 0 | Q23: =iferror(if(Q$9=FALSE,, if(if(search(Q$11,$B23,1)>0,1,0)=1,$H23/$P23,)),"") | R23: =iferror(if(R$9=FALSE,, if(if(search(R$11,$B23,1)>0,1,0)=1,$H23/$P23,)),"") | S23: =iferror(if(S$9=FALSE,, if(if(search(S$11,$B23,1)>0,1,0)=1,$H23/$P23,)),"") | T23: =iferror(if(T$9=FALSE,, if(if(search(T$11,$B23,1)>0,1,0)=1,$H23/$P23,)),"") | U23: =iferror(if(U$9=FALSE,, if(if(search(U$11,$B23,1)>0,1,0)=1,$H23/$P23,)),"") | V23: =iferror(if(V$9=FALSE,, if(if(search(V$11,$B23,1)>0,1,0)=1,$H23/$P23,)),"") | W23: =iferror(if(W$9=FALSE,, if(if(search(W$11,$B23,1)>0,1,0)=1,$H23/$P23,)),"") | X23: =iferror(if(X$9=FALSE,, if(if(search(X$11,$B23,1)>0,1,0)=1,$H23/$P23,)),"") | ... BE23: =iferror(if(BE$9=FALSE,, if(if(search(BE$11,$B23,1)>0,1,0)=1,$H23/$P23,)),"")
... B36: INOV00016 | D36: J&J Serviços de Entregas Ltda - ME | F36: 20.618.029/0001-49 | G36: 77414 | H36: 67.6 | I36: 45429 | J36: Envio para análise. | L36: TRUE | M36: =SUM(Q36:BE36) -> 67.6 | O36: =SUM(Q36:AP36)=H36 -> TRUE | P36: =IF(L36=FALSE,0,IF(LEN(B36)=0,0,IF(LEN(B36)=9,1,(LEN(B36)+1)/10))) -> 1 | Q36: =iferror(if(Q$9=FALSE,, if(if(search(Q$11,$B36,1)>0,1,0)=1,$H36/$P36,)),"") | R36: =iferror(if(R$9=FALSE,, if(if(search(R$11,$B36,1)>0,1,0)=1,$H36/$P36,)),"") | S36: =iferror(if(S$9=FALSE,, if(if(search(S$11,$B36,1)>0,1,0)=1,$H36/$P36,)),"") | T36: =iferror(if(T$9=FALSE,, if(if(search(T$11,$B36,1)>0,1,0)=1,$H36/$P36,)),"") | U36: =iferror(if(U$9=FALSE,, if(if(search(U$11,$B36,1)>0,1,0)=1,$H36/$P36,)),"") | V36: =iferror(if(V$9=FALSE,, if(if(search(V$11,$B36,1)>0,1,0)=1,$H36/$P36,)),"") | W36: =iferror(if(W$9=FALSE,, if(if(search(W$11,$B36,1)>0,1,0)=1,$H36/$P36,)),"") | X36: =iferror(if(X$9=FALSE,, if(if(search(X$11,$B36,1)>0,1,0)=1,$H36/$P36,)),"") | ... BE36: =iferror(if(BE$9=FALSE,, if(if(search(BE$11,$B36,1)>0,1,0)=1,$H36/$P36,)),"")
B37: INOV00001 | D37: LATCO BEVERAGES IND. E COM. DE BEB. E ALIM. IMP. E EXP. LTDA. | F37: 01.046.213/0002-06 | G37: 003/2024 | H37: 2438.04 | I37: 45421 | J37: Aquisição de hidróxido de potássio | L37: TRUE | M37: =SUM(Q37:BE37) -> 2438.04 | O37: =SUM(Q37:AP37)=H37 -> TRUE | P37: =IF(L37=FALSE,0,IF(LEN(B37)=0,0,IF(LEN(B37)=9,1,(LEN(B37)+1)/10))) -> 1 | Q37: =iferror(if(Q$9=FALSE,, if(if(search(Q$11,$B37,1)>0,1,0)=1,$H37/$P37,)),"") -> 2438.04 | R37: =iferror(if(R$9=FALSE,, if(if(search(R$11,$B37,1)>0,1,0)=1,$H37/$P37,)),"") | S37: =iferror(if(S$9=FALSE,, if(if(search(S$11,$B37,1)>0,1,0)=1,$H37/$P37,)),"") | T37: =iferror(if(T$9=FALSE,, if(if(search(T$11,$B37,1)>0,1,0)=1,$H37/$P37,)),"") | U37: =iferror(if(U$9=FALSE,, if(if(search(U$11,$B37,1)>0,1,0)=1,$H37/$P37,)),"") | V37: =iferror(if(V$9=FALSE,, if(if(search(V$11,$B37,1)>0,1,0)=1,$H37/$P37,)),"") | W37: =iferror(if(W$9=FALSE,, if(if(search(W$11,$B37,1)>0,1,0)=1,$H37/$P37,)),"") | X37: =iferror(if(X$9=FALSE,, if(if(search(X$11,$B37,1)>0,1,0)=1,$H37/$P37,)),"") | ... BE37: =iferror(if(BE$9=FALSE,, if(if(search(BE$11,$B37,1)>0,1,0)=1,$H37/$P37,)),"")
B38: INOV00016 | D38: Eurofins do Brasil Análise de Alimentos Ltda. | F38: 04.329.668/0001-38 | G38: 244682 | H38: 26698.5 | I38: 45441 | J38: Análise de vitaminas, minerais. | L38: TRUE | M38: =SUM(Q38:BE38) -> 26698.5 | O38: =SUM(Q38:AP38)=H38 -> TRUE | P38: =IF(L38=FALSE,0,IF(LEN(B38)=0,0,IF(LEN(B38)=9,1,(LEN(B38)+1)/10))) -> 1 | Q38: =iferror(if(Q$9=FALSE,, if(if(search(Q$11,$B38,1)>0,1,0)=1,$H38/$P38,)),"") | R38: =iferror(if(R$9=FALSE,, if(if(search(R$11,$B38,1)>0,1,0)=1,$H38/$P38,)),"") | S38: =iferror(if(S$9=FALSE,, if(if(search(S$11,$B38,1)>0,1,0)=1,$H38/$P38,)),"") | T38: =iferror(if(T$9=FALSE,, if(if(search(T$11,$B38,1)>0,1,0)=1,$H38/$P38,)),"") | U38: =iferror(if(U$9=FALSE,, if(if(search(U$11,$B38,1)>0,1,0)=1,$H38/$P38,)),"") | V38: =iferror(if(V$9=FALSE,, if(if(search(V$11,$B38,1)>0,1,0)=1,$H38/$P38,)),"") | W38: =iferror(if(W$9=FALSE,, if(if(search(W$11,$B38,1)>0,1,0)=1,$H38/$P38,)),"") | X38: =iferror(if(X$9=FALSE,, if(if(search(X$11,$B38,1)>0,1,0)=1,$H38/$P38,)),"") | ... BE38: =iferror(if(BE$9=FALSE,, if(if(search(BE$11,$B38,1)>0,1,0)=1,$H38/$P38,)),"")
B39: INOV00023 | D39: RaiaDrogasil S/A | F39: 61.585.865/0300-69 | G39: 35068 | H39: 305.8 | I39: 45446 | J39: Doação de sensores para Pesquisa Clínica | L39: FALSE | M39: =SUM(Q39:BE39) -> 0 | O39: =SUM(Q39:AP39)=H39 -> FALSE | P39: =IF(L39=FALSE,0,IF(LEN(B39)=0,0,IF(LEN(B39)=9,1,(LEN(B39)+1)/10))) -> 0 | Q39: =iferror(if(Q$9=FALSE,, if(if(search(Q$11,$B39,1)>0,1,0)=1,$H39/$P39,)),"") | R39: =iferror(if(R$9=FALSE,, if(if(search(R$11,$B39,1)>0,1,0)=1,$H39/$P39,)),"") | S39: =iferror(if(S$9=FALSE,, if(if(search(S$11,$B39,1)>0,1,0)=1,$H39/$P39,)),"") | T39: =iferror(if(T$9=FALSE,, if(if(search(T$11,$B39,1)>0,1,0)=1,$H39/$P39,)),"") | U39: =iferror(if(U$9=FALSE,, if(if(search(U$11,$B39,1)>0,1,0)=1,$H39/$P39,)),"") | V39: =iferror(if(V$9=FALSE,, if(if(search(V$11,$B39,1)>0,1,0)=1,$H39/$P39,)),"") | W39: =iferror(if(W$9=FALSE,, if(if(search(W$11,$B39,1)>0,1,0)=1,$H39/$P39,)),"") | X39: =iferror(if(X$9=FALSE,, if(if(search(X$11,$B39,1)>0,1,0)=1,$H39/$P39,)),"") | ... BE39: =iferror(if(BE$9=FALSE,, if(if(search(BE$11,$B39,1)>0,1,0)=1,$H39/$P39,)),"")
B40: INOV00016 | D40: Laboratório ALAC | F40: 94.088.952/0001-52 | G40: 112105 | H40: 2386.43 | I40: 45448 | J40: Perfil de aminoácidos e proteína | L40: TRUE | M40: =SUM(Q40:BE40) -> 2386.43 | O40: =SUM(Q40:AP40)=H40 -> TRUE | P40: =IF(L40=FALSE,0,IF(LEN(B40)=0,0,IF(LEN(B40)=9,1,(LEN(B40)+1)/10))) -> 1 | Q40: =iferror(if(Q$9=FALSE,, if(if(search(Q$11,$B40,1)>0,1,0)=1,$H40/$P40,)),"") | R40: =iferror(if(R$9=FALSE,, if(if(search(R$11,$B40,1)>0,1,0)=1,$H40/$P40,)),"") | S40: =iferror(if(S$9=FALSE,, if(if(search(S$11,$B40,1)>0,1,0)=1,$H40/$P40,)),"") | T40: =iferror(if(T$9=FALSE,, if(if(search(T$11,$B40,1)>0,1,0)=1,$H40/$P40,)),"") | U40: =iferror(if(U$9=FALSE,, if(if(search(U$11,$B40,1)>0,1,0)=1,$H40/$P40,)),"") | V40: =iferror(if(V$9=FALSE,, if(if(search(V$11,$B40,1)>0,1,0)=1,$H40/$P40,)),"") | W40: =iferror(if(W$9=FALSE,, if(if(search(W$11,$B40,1)>0,1,0)=1,$H40/$P40,)),"") | X40: =iferror(if(X$9=FALSE,, if(if(search(X$11,$B40,1)>0,1,0)=1,$H40/$P40,)),"") | ... BE40: =iferror(if(BE$9=FALSE,, if(if(search(BE$11,$B40,1)>0,1,0)=1,$H40/$P40,)),"")
