Workbook
Name Complemento: #REF!
Name Dias_íteis: 'Dias úteis e Feriados'!$E$1:$I$14
Name Pessoal: Pessoal!$D:$V
Name Feriados: 'Dias úteis e Feriados'!$A:$B
Name Dias_úteis: 'Dias úteis e Feriados'!$E:$I

Sheet <>
A1: Nome da ABA | B1: Descrição | C1: Como interpretar
A2: RESUMO | B2: O que é: uma aba “relatório” (bem formatada no Excel) que consolida investimentos de PD&I 2025 e calcula benefício fiscal. Estrutura geral: vários blocos (não é uma tabela única “limpa”). Tem cabeçalhos, textos e subtabelas. Blocos que aparecem dentro do CSV: Cabeçalho institucional: “Resumo dos investimentos”, “BENEFÍCIO FISCAL DE PD&I 2025”, dados da empresa (PRODIET…), CNPJ, e uma data no rodapé (“27, janeiro de 2026”). Quadro trimestral por natureza de dispêndio: Linhas: Material, Terceiros, RH (Parcial inovação), RH (Exclusivo inovação), Total. Colunas: Trimestres 1–4 e TOTAL. Ex.: “Terceiros” soma 755.697,10 no total (incentivado), e RH parcial soma 44.537,05. Cálculo do benefício fiscal: “Percentual Exclusão”: 60% (por trimestre e total). “Exclusão da Base de cálculo do IRPJ e CSLL”: total 480.140,49 (60% de 800.234,15). “Economia Estimada [34%]”: total 163.247,77 (34% da exclusão). “Comissão Taticca”: total 16.324,78 (aparenta ser 10% da economia estimada). Observações (texto): lista de recomendações/condições, por exemplo: dispêndios em conta contábil específica; aproveitar benefício na ECF do ano; envio do formulário MCTIC até agosto/2026; anexar evidências; benefícios não usados (depreciação acelerada; redução de IPI…). Equipe de PD&I (quadro de resumo): separa Dedicação Parcial vs Dedicação Exclusiva (exclusiva está zerada). Mostra Qtd, Valor gasto e Horas por escolaridade (Superior completo, Mestrado etc.). Total dedicação parcial: R$ 44.537,05 e 792:25:00 (horas). Valores por projeto de PD&I (consolidação por INOVxxxxx): Uma tabela com colunas: Projetos (INOV00001, INOV00004, …), TOTAL, Vlr materiais, Vlr terceiros, Vlr RH parcial, Vlr exclusivos. Ex.: INOV00001 total 253.097,59 = terceiros 238.620,42 + RH parcial 14.477,17. Tipos de dado: Moeda em pt-BR (“755.697,10”), percentuais (“60%”, “34%”), horas em formato texto (“792:25:00”), e blocos textuais. | C2: Leia como relatório consolidado (não como tabela única). Ele junta blocos: Investimentos por trimestre (Material / Terceiros / RH parcial / RH exclusivo). Cálculo do benefício fiscal: “Percentual Exclusão” (ex.: 60%) → aplica sobre o total incentivado. “Exclusão da base IRPJ/CSLL” → 60% do total incentivado. “Economia estimada [34%]” → 34% da exclusão. “Comissão” → percentagem da economia (no seu caso aparenta 10%). Resumo RH por escolaridade (horas e valores). Resumo por projeto (INOVxxxxx) com valores de materiais/terceiros/RH. Use esta aba para responder: “quanto foi investido (incentivado) e qual o benefício estimado”. Checagem-chave: totais desta aba devem bater com a soma das abas Investimentos (Terceiros incentivado) + Pessoal (RH PD&I) e com as horas vindas de Trabalho.
A3: Projetos | B3: O que é: cadastro “mestre” dos projetos de PD&I (códigos INOV…), com descrição técnica e colunas de consolidação financeira. Tamanho: precisa contar a quantidade de linhas sempre, 12 colunas. Colunas principais (como aparecem no CSV): Projeto (ex.: INOV00001, INOV00046, etc. Alguns vêm com título entre parênteses). Natureza (ex.: “Pesquisa aplicada”, “Desenvolvimento experimental”; algumas linhas têm Natureza vazia). Campos textuais longos (narrativa técnica): Descrição Elemento tecnologicamente novo ou inovador Barreira ou desafio tecnológico a superar Metodologia Campos de controle: Data início Data de término (estimada) Attach (parece ser o identificador/âncora do projeto) Incentivado? (True/False) Consolidação de valores: Total investido (bate com Terceiros/Investimentos rateados por projeto) Total Help Desk (bate com RH parcial do Pessoal) Pontos bem claros lendo os dados: O arquivo traz tanto projetos incentivados quanto não incentivados (contagem: 21 True / 7 False). Vários projetos “mais novos” estão cadastrados com datas e/ou natureza vazias, mas com flag incentivado e totais (muitas vezes zerados). | C3: Cada linha representa um projeto de PD&I. Os campos textuais (descrição, novidade, barreira, metodologia) são a base para justificar tecnicamente o projeto. Campos de data mostram período do projeto (início/fim estimado). “Incentivado?” indica se o projeto é elegível para o benefício. “Total investido” e “Total Help Desk” são consolidações que devem bater com: Investimentos.csv (rateio por projeto) → “Total investido” Pessoal (2).csv (custo RH PD&I por projeto) → “Total Help Desk” Use esta aba como “dicionário”: quando você vê INOV000xx em outra aba, é aqui que você encontra o contexto técnico.
A4: Trabalho | B4: O que é: a aba de diário de trabalho / timesheet de PD&I. É a base “mais evidencial”: registra o que cada pessoa fez, em qual projeto, em qual dia, por quantas horas, com descrição textual da atividade. Tamanho e estrutura: sempre contar a quantiade de linhas e colunas | 610 linhas × 13 colunas. Aqui sim é uma tabela contínua (1 linha = 1 apontamento). Granularidade (o que é 1 linha) 1 colaborador em 1 projeto em 1 data, com descrição e horas trabalhadas. Colunas (e o que significam na prática) Projeto: código INOVxxxxx (ex.: INOV00001, INOV00016 etc.) Funcionário Mês: 1–12 (e bate 100% com o mês da coluna Data) Etapa: está 100% vazio (coluna existe, mas sem preenchimento) Atividade realizada: classificação macro (ex.: Desenvolvimento, Pesquisa, Gestão e outros, Treinamento) Descrição da atividade: texto livre (bem importante para evidência técnica) Data: DD/MM/AAAA Horas: HH:MM:SS Horas decimais: número em pt-BR (ex.: “1,83”) Projeto incentivado?: True/False (se o projeto é elegível/incentivado) Atividade incentivada?: True/False (se aquela atividade específica entra como elegível) Alterações\nDescrição da atividade: está 100% vazio (campo “reserva” para ajustes) Dedicação: no arquivo inteiro está como Parcial O que tem “dentro” (conteúdo real) Mistura de apontamentos de pesquisa, desenvolvimento, treinamento e gestão. As descrições incluem coisas como análise de resultados, testes piloto, acompanhamento de testes produtivos, reuniões técnicas, protocolos de pesquisa, deslocamentos etc. Regras implícitas (e conexão direta com as outras abas) Essa aba é a fonte das horas de PD&I que aparecem nas demais: Se você somar as horas decimais apenas quando: Projeto incentivado? = True E Atividade incentivada? = True O total dá 792,42 horas, que bate com: # Salários → “PD&I time” por funcionário (os totais por pessoa ficam idênticos) Pessoal (2) → “Horas efetivas (PD&I)” (total anual ~792,41 por arredondamento) RESUMO → total de horas da equipe (792:25:00) E um detalhe bem relevante: dentro do que é elegível (projeto+atividade True), praticamente só aparece Pesquisa/Desenvolvimento/Treinamento — “Gestão e outros” não entra como elegível (fica fora por flag). Nota de qualidade de dado (importante pra prompt/auditoria) Existem 3 lançamentos com Data em 2024 (o resto é 2025). 1 deles (4h) está marcado como projeto+atividade incentivados, então ele entra na soma de horas elegíveis. Isso pode ser só ano digitado errado e vale revisar. Como essa aba “Trabalho” se encaixa no mapa geral Trabalho = evidência e base das horas (o “por quê” e “o que foi feito”). # Salários = agrega essas horas por funcionário (PD&I time / %). Pessoal (2) = usa essas horas como “Horas efetivas (PD&I)” para transformar em custo (salário+encargos → custo-hora → Total PD&I). RESUMO = consolida custo e calcula benefício fiscal. | C4: Cada linha é um apontamento: Projeto + Funcionário + Data + Horas + Descrição. Campos importantes: “Projeto incentivado?” (se o projeto entra no incentivo) “Atividade incentivada?” (se aquele tipo de atividade entra) “Horas decimais” é a forma mais fácil de somar. Interpretação correta: Para horas elegíveis de incentivo, some apenas quando: Projeto incentivado? = True e Atividade incentivada? = True Essa soma alimenta: “PD&I time” da aba # Salários “Horas efetivas (PD&I)” da aba Pessoal (2) Alerta de qualidade: você tem poucos registros com data em 2024; isso pode indicar digitação/ano incorreto e merece revisão.
A5: Pessoal | B5: O que é: detalhamento do custo de RH alocado a PD&I, por projeto + funcionário + mês (timesheet/custeio por hora). Tamanho: precisa contar a quantidade de linhas sempre × 22 colunas. Granularidade (o que é 1 linha): 1 funcionário trabalhando em 1 projeto, em 1 mês de 2025. Colunas (estrutura): Chaves: Projeto (INOV…) Funcionário Mês (1–12) Ano (2025) Perfil do colaborador: Cargo Formação Base mensal de custo: (A) Salário (valor cheio do mês) (B) Encargos (calculado a partir do % de encargos) (C) = (A) + (B) Quebra de encargos em %: INSS Patronal, INSS Terceiros, INSS RAT/FAP, FGTS, 13º, Férias, e % total de encargos Capacidade/horas: Dias úteis Horas nominais (ex.: 193,6; 184,8 etc.) Horas trabalhadas Horas efetivas (PD&I) (o que realmente vira custo de PD&I) Custeio: Custo hora (PD&I) (= (C)/(Horas nominais)) Total PD&I (= Custo hora × Horas efetivas) Checagens implícitas (regras do próprio dado): (B) Encargos ≈ (A) Salário × % total de encargos Total PD&I ≈ Horas efetivas (PD&I) × Custo hora (PD&I) O total anual de RH PD&I soma ~44.537,05, que é exatamente o que aparece no RESUMO. Tipos de dado: Salários/encargos em pt-BR, percentuais em texto (“63,40%”), horas com decimal e vírgula. | C5: Cada linha é: Funcionário + Projeto + Mês (2025), com: salário do mês, encargos, custo total, horas nominais / trabalhadas / efetivas (PD&I), custo-hora e total de PD&I daquele mês. O valor importante para PD&I é “Total PD&I” (custo alocado a PD&I). “Horas efetivas (PD&I)” é o elo com a aba Trabalho (timesheet). Checagens principais: Total PD&I ≈ Horas efetivas × Custo hora Encargos ≈ Salário × % encargos Somatório anual de Total PD&I deve bater com: #verificação RH RESUMO (RH parcial) Interpretação correta: essa aba responde “quanto custou RH de PD&I (e por qual projeto/mês)”.
A6: Investimentos | B6: O que é: lista de dispêndios de terceiros (serviços, fornecedores) com rateio por projeto e identificação do que é “inovação/incentivado”. Tamanho bruto do CSV: precisa contar as linhas e colunas sempre, mas ele tem linhas de metadados (não é só tabela). Como esse CSV está organizado (muito importante) Ele tem 3 linhas “especiais” antes dos lançamentos: Linha de flags TRUE/FALSE (aparece em colunas de projetos): indica status por projeto (parece ser “incentivado?” por código). Linha de totais gerais e totais por projeto: Valor total ≈ 920.786,07 Valor Incentivado total ≈ 755.697,10 Totais por projeto (ex.: INOV00001 = 238.620,42, INOV00014 = 79.988,12, etc.) Linha que contém os nomes das colunas (“Fornecedor”, “CNPJ”, … “INOV00001”, “INOV00003”, etc.) Depois disso, vêm os 84 lançamentos (cada linha = 1 nota/dispêndio). Colunas relevantes dos lançamentos Dados do fornecedor/documento: Fornecedor CNPJ Descrição NF/ND Valor (total do lançamento) Data (DD/MM/AAAA) Natureza (no seu arquivo, praticamente tudo aparece como “Serviços”) Objetivo do gasto Classificação de incentivo: Inovação? (TRUE/FALSE) Valor Incentivado (quando Inovação?=FALSE, aqui zera; no seu arquivo, FALSE soma 7.920,83 e incentiva 0,00) Rateio: Projeto e eventual info de rateio (às vezes “INOV00001|INOV00014”) Count (quantidade de projetos no rateio; ex.: 2) Colunas uma por projeto (INOV00001, INOV00003, …): já trazem o valor rateado por projeto (em geral, rateio igualitário: valor/Count). Conf. val. rateio (parece ser um boolean de conferência da soma do rateio) Uso típico: é a base para o Terceiros no RESUMO e para Total investido no cadastro de Projetos. | C6: Aqui estão os gastos com fornecedores/serviços (notas/dispêndios), com: fornecedor, CNPJ, NF, data, valor, descrição e objetivo do gasto. Existem duas leituras: Valor total do lançamento (sempre preenche “Valor”). Valor incentivado (só quando “Inovação? = TRUE”). A parte mais importante é o rateio por projeto: há uma coluna por projeto (INOVxxxxx) com o valor rateado, “Count” indica em quantos projetos aquele gasto foi dividido, “Conf. val. rateio” serve para conferir se a soma do rateio bate com o valor esperado. Checagens principais: Se Inovação? = FALSE → Valor Incentivado deve ser 0,00. Soma de todos os valores rateados (colunas INOV…) deve bater com o Valor Incentivado (quando elegível). Interpretação correta: essa aba responde “quais gastos de terceiros entram no incentivo e como foram distribuídos por projeto”.
A7: Dias úteis e Feriados | B7: O que é: aba de apoio/calendário: lista de feriados + tentativa de trazer dias úteis por mês (usado para horas nominais). Tamanho: precisa contar sempre a quantiadade de linhas × 10 colunas. O que aparece: Colunas: Data (data do feriado) Descrição (Ano Novo, Carnaval, Tiradentes, etc.) Unnamed: 2 (tipo: “Nacional” / “Facultativo”) Mês, Ano, Início, Fim, Dias úteis, Tempo utíl Mistura de conteúdos: Há uma lista de feriados (todas as linhas têm Data e Descrição) E há um bloco com “jan–jun/2025” preenchido em Mês/Ano/Início/Fim/Dias úteis (só 6 linhas têm esse trecho preenchido no CSV). Tempo utíl aparece preenchido só em 1 linha (ex.: “2182:24:00”), com cara de campo vindo de Excel e possivelmente não diretamente interpretável como horas reais sem regra do Excel. Observação prática: este CSV parece ter sido exportado de uma aba com células mescladas/estrutura visual; então ele é mais “base auxiliar” do que tabela transacional. | C7: Essa aba mistura lista de feriados com um bloco parcial de dias úteis por mês (pelo jeito, a exportação do Excel trouxe os blocos meio “quebrados”). Use como fonte de apoio, não como base transacional: Feriados: Data + Descrição + tipo (nacional/facultativo). Dias úteis: mês, início/fim do mês, dias úteis (só alguns meses preenchidos no CSV). Interpretação típica: alimentar “Horas nominais” (capacidade do mês) na aba Pessoal (2). Se você for automatizar, trate esta aba como: tabela de feriados separada OU tabela de dias úteis separada (porque hoje estão misturadas).
A8: # Encargos folha | B8: O que é: tabela de alíquotas/percentuais de encargos por mês (INSS patronal, terceiros, RAT/FAP, FGTS etc.) usada para calcular encargos do RH. Tamanho: 12 linhas × 8 colunas (1 por mês de 2025). Colunas: Período (01/2025 … 12/2025) Aderência ao CPRB (A) (no seu arquivo: 0,00% em todos) Aderência ao INSS (B) (20,00% em todos) INSS adicional (C) (0,00% com CPRB zerado) INSS Patronal (D) (= B + C) INSS Terceiros (5,80%) INSS RAT/FAP (varia: 3,00% no começo, 1,50% em vários meses, 3,87% no fim) FGTS (8,00%) Conexão: esses percentuais aparecem refletidos em INSS…/FGTS/13º/Férias/% total de encargos na aba Pessoal. | C8: É uma tabela de parâmetros: para cada mês, define as alíquotas: INSS Patronal/terceiros/RAT-FAP, FGTS etc. Serve para calcular o % total de encargos aplicado na aba Pessoal (2). Interpretação correta: não é “dado de gasto”, é regra de cálculo. Checagem: se o RAT/FAP muda no mês, o % total de encargos no Pessoal (2) deve refletir isso.
A9: # Salários | B9: O que é: base de salários por colaborador e métricas agregadas de dedicação a PD&I (tempo e %). Tamanho: sempre analisar a quantidade de linhas e colunas | 22 linhas × 20 colunas, mas nesse caso só ~9 linhas têm dados (o resto está vazio por causa do layout do Excel ou pelo fato de não ter informação mesmo). Colunas: Identificação: ID, CPF, Funcionário Perfil: Formação Função / Cargo Salário por mês (jan–dez): janeiro ... dezembro (valores em pt-BR; alguns meses em branco ou “-” quando não há salário) Métricas de PD&I: PD&I time (ex.: “215:30:00” = horas totais no ano dedicadas a PD&I) PD&I (%) (ex.: “9,87%”) Dedicação (no arquivo, aparece como “Parcial”) Conexão: alimenta o custo mensal e perfil que aparece na aba Pessoal. | C9: Para cada funcionário, você tem: salários por mês (jan–dez), “PD&I time” (total anual de horas em PD&I), “PD&I (%)” (proporção do tempo), “Dedicação” (no seu caso: Parcial). Essa aba funciona como ponte: Horas PD&I por pessoa vêm do Trabalho Salário mensal alimenta o custo mensal do Pessoal (2) Checagens: soma de “PD&I time” por funcionário deve bater com a soma das horas (Trabalho) filtradas para elegível. salários devem bater com a base salarial usada no Pessoal (2).
A10: #verificação RH | B10: "O que é: uma aba de conferência (tipo pivot) para validar RH. Tamanho: sempre analisar a quantiadede de linhas e colunas | 9 linhas × 6 colunas (e aqui também tem “linhas de cabeçalho” dentro do corpo). Conteúdo: Traz por funcionário: valores de 1º trimestre, 2º trimestre, 3º trimestre, 4º trimestre e Total. A primeira linha mostra o Total geral por trimestre e o total anual: Q1 6.559,97, Q2 9.124,11, Q3 10.836,30, Q4 18.016,68, Total 44.537,05. Bate com: RESUMO → linha “RH (Parcial inovação)” Pessoal → soma anual do “Total PD&I” (com variação só de arredondamento)." | C10: É um quadro de validação: soma o RH PD&I por pessoa e por trimestre. A linha “Total” mostra o RH PD&I trimestral e anual. Serve para confirmar que: Pessoal (2) está somando correto por trimestre, RESUMO está refletindo os mesmos totais. Interpretação correta: “se essa aba não bate, tem erro de horas/custeio/encargos lá atrás”.

Sheet RESUMO
A2: Resumo dos investimentos
A3: BENEFÍCIO FISCAL DE PD&I 2025
A5: PRODIET NUTRIÇÃO CLINICA LTDA | E5: CNPJ 08.183.359/0001-53 | G5: 2019-088 PRODIET
A6: Rua General Potiguara, 1428, Lotes 20 e 21, Novo Mundo - PR - SUL - CURITIBA - CEP 81.050-500 - fone: (41) 3342-2825 | G6: =TODAY() -> 46168
A8: Natureza | B8: 1 | C8: 2 | D8: 3 | E8: 4 | G8: TOTAL
A9: Material | B9: =IFERROR(__xludf.DUMMYFUNCTION("IFERROR(SUM(filter(Investimentos!$E:$E,#REF!=TRUE,Investimentos!$G:$G=""Material"",MONTH(Investimentos!$F:$F)>=1,MONTH(Investimentos!$F:$F)<=3)),0)"),0.0) -> 0 | C9: =IFERROR(__xludf.DUMMYFUNCTION("IFERROR(SUM(filter(Investimentos!$E:$E,#REF!=TRUE,Investimentos!$G:$G=""Material"",MONTH(Investimentos!$F:$F)>=4,MONTH(Investimentos!$F:$F)<=6)),0)"),0.0) -> 0 | D9: =IFERROR(__xludf.DUMMYFUNCTION("IFERROR(SUM(filter(Investimentos!$E:$E,#REF!=TRUE,Investimentos!$G:$G=""Material"",MONTH(Investimentos!$F:$F)>=7,MONTH(Investimentos!$F:$F)<=9)),0)"),0.0) -> 0 | E9: =IFERROR(__xludf.DUMMYFUNCTION("IFERROR(SUM(filter(Investimentos!$E:$E,#REF!=TRUE,Investimentos!$G:$G=""Material"",MONTH(Investimentos!$F:$F)>=10,MONTH(Investimentos!$F:$F)<=12)),0)"),0.0) -> 0 | G9: =SUM(B9:E9) -> 0
A10: Terceiros | B10: =IFERROR(__xludf.DUMMYFUNCTION("IFERROR(SUM(filter(Investimentos!$K:$K,Investimentos!$G:$G=""Serviços"",MONTH(Investimentos!$F:$F)>=1,MONTH(Investimentos!$F:$F)<=3)),0)"),135485.53) -> 135485.53 | C10: =IFERROR(__xludf.DUMMYFUNCTION("IFERROR(SUM(filter(Investimentos!$K:$K,Investimentos!$G:$G=""Serviços"",MONTH(Investimentos!$F:$F)>=4,MONTH(Investimentos!$F:$F)<=6)),0)"),242461.48166666663) -> 242461.48 | D10: =IFERROR(__xludf.DUMMYFUNCTION("IFERROR(SUM(filter(Investimentos!$K:$K,Investimentos!$G:$G=""Serviços"",MONTH(Investimentos!$F:$F)>=7,MONTH(Investimentos!$F:$F)<=9)),0)"),177276.80000000002) -> 177276.8 | E10: =IFERROR(__xludf.DUMMYFUNCTION("IFERROR(SUM(filter(Investimentos!$K:$K,Investimentos!$G:$G=""Serviços"",MONTH(Investimentos!$F:$F)>=10,MONTH(Investimentos!$F:$F)<=12)),0)"),200473.29000000004) -> 200473.29 | G10: =SUM(B10:E10) -> 755697.1
A11: RH (Parcial inovação) | B11: =IFERROR(__xludf.DUMMYFUNCTION("IFERROR(SUM(filter(Pessoal!$V:$V,(Pessoal!$C:$C)>=1,(Pessoal!$C:$C)<=3)),0)"),6559.965145979168) -> 6559.9651 | C11: =IFERROR(__xludf.DUMMYFUNCTION("IFERROR(SUM(filter(Pessoal!$V:$V,(Pessoal!$C:$C)>=4,(Pessoal!$C:$C)<=6)),0)"),9124.10550873039) -> 9124.1055 | D11: =IFERROR(__xludf.DUMMYFUNCTION("IFERROR(SUM(filter(Pessoal!$V:$V,(Pessoal!$C:$C)>=7,(Pessoal!$C:$C)<=9)),0)"),10836.297825499109) -> 10836.298 | E11: =IFERROR(__xludf.DUMMYFUNCTION("IFERROR(SUM(filter(Pessoal!$V:$V,(Pessoal!$C:$C)>=10,(Pessoal!$C:$C)<=12)),0)"),18016.677142233166) -> 18016.677 | G11: =SUM(B11:E11) -> 44537.046
A12: RH (Exclusivo inovação) | B12: =IFERROR(__xludf.DUMMYFUNCTION("IFERROR(SUM(filter(#REF!,Trabalho!$M:$M=""Exclusivo"",MONTH(Trabalho!$G:$G)>=1,MONTH(Trabalho!$G:$G)<=3)),0)"),0.0) -> 0 | C12: =IFERROR(__xludf.DUMMYFUNCTION("IFERROR(SUM(filter(#REF!,Trabalho!$M:$M=""Exclusivo"",MONTH(Trabalho!$G:$G)>=4,MONTH(Trabalho!$G:$G)<=6)),0)"),0.0) -> 0 | D12: =IFERROR(__xludf.DUMMYFUNCTION("IFERROR(SUM(filter(#REF!,Trabalho!$M:$M=""Exclusivo"",MONTH(Trabalho!$G:$G)>=7,MONTH(Trabalho!$G:$G)<=9)),0)"),0.0) -> 0 | E12: =IFERROR(__xludf.DUMMYFUNCTION("IFERROR(SUM(filter(#REF!,Trabalho!$M:$M=""Exclusivo"",MONTH(Trabalho!$G:$G)>=10,MONTH(Trabalho!$G:$G)<=12)),0)"),0.0) -> 0 | G12: =SUM(B12:E12) -> 0
A13: Total | B13: =SUM(B9:B12) -> 142045.5 | C13: =SUM(C9:C12) -> 251585.59 | D13: =SUM(D9:D12) -> 188113.1 | E13: =SUM(E9:E12) -> 218489.97 | G13: =SUM(G9:G12) -> 800234.15
A14: Percentual Exclusão | B14: 0.6 | C14: 0.6 | D14: 0.6 | E14: 0.6 | G14: 0.6
A15: Exclusão da Base de cálculo do IRPJ e CSLL | B15: =B13*B14 -> 85227.297 | C15: =C13*C14 -> 150951.35 | D15: =D13*D14 -> 112867.86 | E15: =E13*E14 -> 131093.98 | G15: =G13*G14 -> 480140.49
A17: Economia Estimada [34%] | B17: =B15*34% -> 28977.281 | C17: =C15*34% -> 51323.46 | D17: =D15*34% -> 38375.072 | E17: =E15*34% -> 44571.953 | G17: =G15*34% -> 163247.77
A18: Comissão Taticca | B18: =B17*0.1 -> 2897.7281 | C18: =C17*0.1 -> 5132.346 | D18: =D17*0.1 -> 3837.5072 | E18: =E17*0.1 -> 4457.1953 | G18: =G17*0.1 -> 16324.777
A20: Observações:
A21: 1. Os dispêndios devem ser registrados na contabilidade em conta específica
A22: 2. O benefício deve ser aproveitado na ECF do respectivo ano/competência
A23: 3. O formulário do MCTIC (governo) deve ser enviado até fim de AGOSTO/2026
A24: 4. Evidências de PD&I devem ser anexadas no FORM MCTIC
A25: 5. Alguns benefícios previstos na Lei do Bem não foram utilizados:
A26: --- 5.1. Depreciação acelerada
A27: --- 5.2. Redução de IPI na aquisição de equipamento para PD&I
A30: Equipe de PD&I
A31: Quadro de resumo | B31: Dedicação Parcial | E31: Dedicação Exclusiva
B32: Qtd | C32: Valor gasto | D32: Horas | E32: Qtd | F32: Valor gasto | G32: Horas
A33: Técnico | B33: =COUNTIFS('# Salários'!$D$2:$D65,A33,'# Salários'!$T$2:$T65,"Parcial") -> 0 | C33: =IFERROR(__xludf.DUMMYFUNCTION("IFERROR(SUM(FILTER(Pessoal!$V:$V,Pessoal!$F:$F=A33)),0)"),0.0) -> 0 | D33: =IFERROR(__xludf.DUMMYFUNCTION("IFERROR(SUM(FILTER('# Salários'!$R$2:$R$17,'# Salários'!$T$2:$T$17 = ""Parcial"",'# Salários'!$D$2:$D$17= $A33)),0)"),0.0) -> 0 | E33: =COUNTIFS(Pessoal1!$F$7:$F$31,"Técnico",Pessoal1!$V$7:$V$31,"Exclusiva") -> 0 | F33: - | G33: -
A34: Não determinado | B34: =COUNTIFS('# Salários'!$D$2:$D$17,A34,'# Salários'!$T$2:$T$17,"Parcial") -> 0 | C34: =IFERROR(__xludf.DUMMYFUNCTION("IFERROR(SUM(FILTER(Pessoal!$V:$V,Pessoal!$F:$F=A34)),0)"),0.0) -> 0 | D34: =IFERROR(__xludf.DUMMYFUNCTION("IFERROR(SUM(FILTER(Pessoal1!$T$7:$T$31,Pessoal1!$V$7:$V$31 = ""Parcial"",Pessoal1!$F$7:$F$31 = $A34)),0)"),0.0) -> 0 | E34: =COUNTIFS(Pessoal1!$F$7:$F$31,"Graduado",Pessoal1!$V$7:$V$31,"Exclusiva") -> 0 | F34: =SUMIF(Pessoal1!$O$90:$O$92,$A34,Pessoal1!$K$90:$K$92) -> #N/A | G34: =IFERROR(__xludf.DUMMYFUNCTION("IFERROR(SUM(FILTER(Pessoal1!$T$7:$T$21,Pessoal1!$V$7:$V$21 = ""Exclusivo"",Pessoal1!$F$7:$F$26 = $A34)),0)"),0.0) -> 0
A35: Superior Incompleto | B35: =COUNTIFS('# Salários'!$D$2:$D65,A35) -> 1 | C35: =IFERROR(__xludf.DUMMYFUNCTION("IFERROR(SUM(FILTER(Pessoal!$V:$V,Pessoal!$F:$F=A35)),0)"),418.435992827032) -> 418.43599 | D35: =IFERROR(__xludf.DUMMYFUNCTION("IFERROR(SUM(FILTER('# Salários'!$R$2:$R$17,'# Salários'!$D$2:$D$17= $A35)),0)"),0.4236111111111111) -> 0.42361111 | E35: =COUNTIFS(Pessoal1!$F$7:$F$31,"Graduado",Pessoal1!$V$7:$V$31,"Exclusiva") -> 0 | F35: - | G35: -
A36: Superior Completo | B36: =COUNTIFS('# Salários'!$D$2:$D65,A36) -> 3 | C36: =IFERROR(__xludf.DUMMYFUNCTION("IFERROR(SUM(FILTER(Pessoal!$V:$V,Pessoal!$F:$F=A36)),0)"),9829.277184387589) -> 9829.2772 | D36: =IFERROR(__xludf.DUMMYFUNCTION("IFERROR(SUM(FILTER('# Salários'!$R$2:$R$17,'# Salários'!$D$2:$D$17= $A36)),0)"),7.75) -> 7.75 | E36: =COUNTIFS(Pessoal1!$F$7:$F$31,"Graduado",Pessoal1!$V$7:$V$31,"Exclusiva") -> 0 | F36: - | G36: -
A37: Pós graduado | B37: =COUNTIFS('# Salários'!$D$2:$D65,A37) -> 2 | C37: =IFERROR(__xludf.DUMMYFUNCTION("IFERROR(SUM(FILTER(Pessoal!$V:$V,Pessoal!$F:$F=A37)),0)"),14192.518687423788) -> 14192.519 | D37: =IFERROR(__xludf.DUMMYFUNCTION("IFERROR(SUM(FILTER('# Salários'!$R$2:$R$17,'# Salários'!$D$2:$D$17= $A37)),0)"),9.208333333333332) -> 9.2083333 | E37: =COUNTIFS(Pessoal1!$F$7:$F$31,"Pós graduado",Pessoal1!$V$7:$V$31,"Exclusiva") -> 0 | F37: - | G37: -
A38: Mestrado | B38: =COUNTIFS('# Salários'!$D$2:$D$17,A38,'# Salários'!$T$2:$T$17,"Parcial") -> 3 | C38: =IFERROR(__xludf.DUMMYFUNCTION("IFERROR(SUM(FILTER(Pessoal!$V:$V,Pessoal!$F:$F=A38)),0)"),20096.813757803422) -> 20096.814 | D38: =IFERROR(__xludf.DUMMYFUNCTION("IFERROR(SUM(FILTER('# Salários'!$R$2:$R$17,'# Salários'!$D$2:$D$17= $A38)),0)"),15.63541666666667) -> 15.635417 | E38: 0 | F38: - | G38: -
A39: Doutorado | B39: =COUNTIFS('# Salários'!$D$2:$D$17,A39,'# Salários'!$T$2:$T$17,"Parcial") -> 0 | C39: =IFERROR(__xludf.DUMMYFUNCTION("IFERROR(SUM(FILTER(Pessoal!$V:$V,Pessoal!$F:$F=A39)),0)"),0.0) -> 0 | D39: =IFERROR(__xludf.DUMMYFUNCTION("IFERROR(SUM(FILTER(Pessoal1!$T$7:$T$31,Pessoal1!$V$7:$V$31 = ""Parcial"",Pessoal1!$F$7:$F$31 = $A39)),0)"),0.0) -> 0 | E39: =COUNTIFS(Pessoal1!$F$7:$F$31,"Doutorado",Pessoal1!$V$7:$V$31,"Exclusiva") -> 0 | F39: =SUMIF(Pessoal1!$O$90:$O$92,$A39,Pessoal1!$K$90:$K$92) -> #N/A | G39: =IFERROR(__xludf.DUMMYFUNCTION("IFERROR(SUM(FILTER(Pessoal1!$T$7:$T$21,Pessoal1!$V$7:$V$21 = ""Exclusivo"",Pessoal1!$F$7:$F$26 = $A39)),0)"),0.0) -> 0
B40: =SUBTOTAL(9,B36:B38) -> 8 | C40: =SUM(C33:C39) -> 44537.046 | D40: =SUM(D33:D39) -> 33.017361 | E40: =SUM(E33:E39) -> 0 | F40: - | G40: =SUM(G33:G39) -> 0
A42: Valores por projeto de PD&I
A43: Projetos | C43: TOTAL | D43: Vlr materiais | E43: Vlr terceiros | F43: Vlr Rh parcial | G43: Vlr exclusivos
A44: =IFERROR(__xludf.DUMMYFUNCTION("filter(Projetos!J2:J65,Projetos!K2:K65=TRUE)"),"INOV00001") -> INOV00001 | C44: =SUM(E44:F44) -> 253097.59 | E44: {=IFERROR(XLOOKUP(A44:A64,TRANSPOSE(Investimentos!$N$3:$BB$3),TRANSPOSE(Investimentos!$N$2:$BB$3),0,0),"")} -> 238620.42 | F44: =IFERROR(__xludf.DUMMYFUNCTION("IFERROR(SUM(FILTER(Pessoal!$V$2:$V65,Pessoal!$A$2:$A65=A44)))"),14477.174411206699) -> 14477.174 | G44: 0
A45: =IFERROR(__xludf.DUMMYFUNCTION("""COMPUTED_VALUE"""),"INOV00004") -> INOV00004 | C45: =SUM(E45:F45) -> 31072.13 | E45: 30440.287 | F45: =IFERROR(__xludf.DUMMYFUNCTION("IFERROR(SUM(FILTER(Pessoal!$V$2:$V65,Pessoal!$A$2:$A65=A45)))"),631.84228426613) -> 631.84228 | G45: 0
A46: =IFERROR(__xludf.DUMMYFUNCTION("""COMPUTED_VALUE"""),"INOV00006") -> INOV00006 | C46: =SUM(E46:F46) -> 25012.03 | E46: 20462.53 | F46: =IFERROR(__xludf.DUMMYFUNCTION("IFERROR(SUM(FILTER(Pessoal!$V$2:$V65,Pessoal!$A$2:$A65=A46)))"),4549.499901871496) -> 4549.4999 | G46: 0
A47: =IFERROR(__xludf.DUMMYFUNCTION("""COMPUTED_VALUE"""),"INOV00010") -> INOV00010 | C47: =SUM(E47:F47) -> 36218.156 | E47: 35743.177 | F47: =IFERROR(__xludf.DUMMYFUNCTION("IFERROR(SUM(FILTER(Pessoal!$V$2:$V65,Pessoal!$A$2:$A65=A47)))"),474.97858090602745) -> 474.97858 | G47: 0
A48: =IFERROR(__xludf.DUMMYFUNCTION("""COMPUTED_VALUE"""),"INOV00013") -> INOV00013 | C48: =SUM(E48:F48) -> 0 | E48: 0 | F48: =IFERROR(__xludf.DUMMYFUNCTION("IFERROR(SUM(FILTER(Pessoal!$V$2:$V65,Pessoal!$A$2:$A65=A48)))"),"") | G48: 0
...

Sheet Projetos
A1: Projeto | C1: Natureza | D1: Descrição | E1: Elemento tecnologicamente novo ou inovador | F1: Barreira ou desafio tecnológico a superar | G1: Metodologia empregada | H1: Data início | I1: Data de término (estimada) | J1: Attach | K1: Incentivado? | L1: Total investido | M1: Total Help Desk
A2: INOV000001 (2018 - RETORT) | C2: Desenvolvimento experimental | D2: O objetivo é atuar num mercado que demanda 50% da Nutrição Enteral, mercado este que a Prodiet não atende com sua linha atual. | E2: Atualmente a Prodiet somente comercializa produtos em pó ou líquidos UHT, portanto, a tecnologia de processo de tratamento térmico em autoclave se mostra como um elemento inovador. | F2: O principal desafio do projeto Retort é entender uma tecnologia diferenciada e implantar uma área fabril do zero, garantindo a estabilidade e esterilidade comercial do produto durante toda sua vida de prateleira, após aplicação de temperaturas mais brandas (em comparação ao processo UHT), conciliada com maiores tempos de permanência durante o tratamento térmico e correlacionando com a tecnologia de embalagens (também sendo inovação para a Prodiet). Concomitante a isso, buscar e desenvolver um possível copacker para otimizar o tempo de lançamento dos produtos. | G2: Por meio de consultorias e estudos, a Prodiet for e continua em busca do conhecimento para implantar uma nova estrutura para Sistema Fechado. O objetivo da consultoria para as formulações foi trazer as pesquisas sobre possibilidades de locais para realização dos teste em planta piloto, expôr seu conhecimento e prática a este processo e contatar fornecedores de embalagens/prestadores de serviços relacionados ao projeto. Simultaneamente, foram e estão sendo realizados estudos aprofundados sobre a nova tecnologia (tanto no quesito produto, quanto processo, equipamentos e embalagem), em conjunto com as diversas áreas da empresa, como Científico, Assuntos Regulatórios, Qualidade, Manutenção e Produção. Além disso, a partir de 2020 foi contratada uma consultoria para a parte de Engenharia, que está auxiliando com os estudos na implantação da nova fábrica (estrutural e de equipamentos/processos). | H2: 43853 | I2: 44926 | J2: INOV00001 | K2: TRUE | L2: {=SUM(INDEX(Investimentos!$N$3:$BB30,,MATCH(J2,Investimentos!$N$3:$BB$3,0)))} -> 238620.42 | M2: =IF(K2=TRUE,SUMIF(Pessoal!A:A,J2,Pessoal!$V:$V),0) -> 14477.174
A3: INOV000004 (2019 - CICATRIZAÇÃO) | C3: Desenvolvimento experimental | D3: Produto voltado para cicatrização, desde pós-operatórios, como prevenção ou tratamento de lesões por pressão. | E3: A fórmula para cicatrização tem como objetivo oferecer uma combinação de nutrientes inovadora para cicatrização. Os produtos usualmente indicados no ambiente hospitalar são produtos líquidos, e nós desenvolvemos um produto na versão pó com o intuito de melhor o custo-benefício aos pacientes. | F3: O desafio neste caso é desenvolver um produto que apresente sensorial agradável considerando a combinação de nutrientes com alto residual como aminoácidos isolados presentes no produto bem como o colágeno hidrolisado. Dentre os vários nutrientes avaliados a preocupação era encontrar um ingrediente que apresentasse estabilidade no processamento térmico, e que pudesse ser submetido ao processo UHT. | G3: Por meio de pesquisa e de contatos com profissionais, a Prodiet tem buscado realizar o desenvolvimento de uma fórmula viável e que atenda aos requisitos nutricionais e sensoriais desejados. O contato com fornecedores a fim de compreender o comportamento das matérias primas selecionadas, o conhecimento de estudos já realizados com estas matérias primas. | H3: 43500 | I3: 44561 | J3: INOV00004 | K3: TRUE | L3: {=SUM(INDEX(Investimentos!$N$3:$BB30,,MATCH(J3,Investimentos!$N$3:$BB$3,0)))} -> 30440.287 | M3: =IF(K3=TRUE,SUMIF(Pessoal!A:A,J3,Pessoal!$V:$V),0) -> 631.84228
A4: INOV000006 (2019 - ARTESANAL) | C4: Desenvolvimento experimental | D4: Desenvolver um produto inovador no mercado brasileiro, visto que não há produto semelhante, com o objetivo de complementar a dieta enteral artesanal, com ótima relação custo/benefício. | E4: O desenvolvimento de uma fórmula com alimentos e que atendam uma demanda específica que ainda não é atendida no mercado brasileiro. O elemento inovador é uma proposta (formulação) totalmente inovadora. | F4: Os desafios são as novas matérias primas, que são alimentos liofilizados, até então não trabalhados previamente, que apresentam uma composição nutricional muito variável, dificultanto assim a seleção de MPs que correspondam ao desenho nutricional desejado. Além disso, o desenvolvimento de um produto que atenda a demanda nutricional do público em uso de nutrição enteral artesanal, com sensorial final neutro, com solubilidade adequada para nutrição enteral, também são barreiras para este desenvolvimento. | G4: Foi realizado estudo com os principais nutrientes deficientes na dieta artesanal ofertada aos indivíduos em uso de nutrição enteral artesanal. Além disso, foi realizada análise da composição de produtos com ingredientes in natura, bem como análise sensorial. O estudo de novas MP’s foi conduzidos por Científico e P&D, mas os primeiros testes de bancada não foram satisfatórios com relação à presença de grânulos e à neutralidade de sabor, apresentando sabor residual desagradável. No momento, P&D está realizando novos estudos de MP’s em parceria com os fornecedores. | H4: 43553 | I4: 44742 | J4: INOV00006 | K4: TRUE | L4: {=SUM(INDEX(Investimentos!$N$3:$BB30,,MATCH(J4,Investimentos!$N$3:$BB$3,0)))} -> 20462.53 | M4: =IF(K4=TRUE,SUMIF(Pessoal!A:A,J4,Pessoal!$V:$V),0) -> 4549.4999
A5: INOV000010 | C5: Desenvolvimento experimental | J5: INOV00010 | K5: TRUE | L5: {=SUM(INDEX(Investimentos!$N$3:$BB30,,MATCH(J5,Investimentos!$N$3:$BB$3,0)))} -> 35743.177 | M5: =IF(K5=TRUE,SUMIF(Pessoal!A:A,J5,Pessoal!$V:$V),0) -> 474.97858
A6: INOV000013 (2021 - SACHÊ A VÁCUO) | C6: Desenvolvimento experimental | D6: Aplicar o uso do vácuo no envase dos produtos em pó do portfólio atual Prodiet, com o intuito de estudar se a embalagem mantém o vácuo ao longo do shelf-life, bem como auxiliar a manter as suas características nutricionais e sensoriais, em comparação às embalagens atuais (potes e latas). | E6: Nos dias atuais, os produtos em pó são fabricados em embalagens plásticas rígidas (potes), latas de alumínio e embalagens plásticas flexíveis (sachês). A embalagem a vácuo não é utilizada para o envase de nutrição enteral no mercado nacional. | F6: O principal desafio é entender como o mercado nacional irá reagir ao novo tipo de embalagem para Nutrição Enteral. Além disso, atender à limitação fabril, considerando o investimento em novos equipamentos e em uma nova linha de processo, bem como atender ao preço de venda competitivo. | G6: Busca de fornecedores de embalagens que suportem o vácuo, e de fornecedores de equipamentos com a tecnologia adequada para o envase e selagem dos produtos a vácuo. Realização de um piloto industrial em fornecedor parceiro. | H6: 43853 | I6: 44926 | J6: INOV00013 | K6: TRUE | L6: {=SUM(INDEX(Investimentos!$N$3:$BB30,,MATCH(J6,Investimentos!$N$3:$BB$3,0)))} -> 0 | M6: =IF(K6=TRUE,SUMIF(Pessoal!A:A,J6,Pessoal!$V:$V),0) -> 0
A7: INOV000014 (2021 - ENERGYZIP 25%) | C7: Desenvolvimento experimental | D7: O projeto visa permitir maior abertura para Prodiet no mercado público e privado. Desenvolver suplemento hipercalórico e hiperproteico líquido, uma vez que hoje não há este produto em portfolio e existe demanda cada vez maior por suplementos hiperproteicos no mercado. Acompanhar o lançamento da linha de sistema fechado, tendo um produto que acompanha um mix de vendas para hospitais. Produto que seja competitivo também para processos públicos, bem como para o mercado internacional | E7: A inovação desse produto é, justamente, o aumento no teor de proteína em relação ao produto de linha. A produção desse produto possibilitará um ganho de mercado, tanto em relação a competição com alguns suplementos, quanto para fórmulas enterais que necessitem de um aporte mais expressivo de proteínas. | F7: O principal desafio no desenvolvimento dessa fórmula está na estabilização proteica/estrutural da fórmula. O aumento do teor de proteína acarreta um aumento expressivo da viscosidade. A viscosidade alta em fórmulas enterais é responsável por dificuldades de administração. | G7: Testar desenvolvimento de fórmula com maior teor de proteínas em teste piloto. | H7: 43853 | I7: 44926 | J7: INOV00014 | K7: TRUE | L7: {=SUM(INDEX(Investimentos!$N$3:$BB30,,MATCH(J7,Investimentos!$N$3:$BB$3,0)))} -> 79988.117 | M7: =IF(K7=TRUE,SUMIF(Pessoal!A:A,J7,Pessoal!$V:$V),0) -> 268.47273
A8: INOV000016 (2018 - LINHA TROPHIC SOYA LÍQUIDO) | C8: Desenvolvimento experimental | D8: Este projeto tem como objetivo aumentar o portfólio da linha 100% Soja, com produto de maior perfil proteico e fibras, atendendo a consumidores com alergias alimentares às protéinas do leite. | E8: Produto de alto teo proteico e adição de fibras sem proteínas de leite. | F8: O desafio principal deste desenvolvimento é a estabilização da fórmula, devido ao aumento no teor de proteína para 1.5 kcal/mL e acréscimo de Fibras, o que acarretam em uma alta viscosidade do produto, responsável por dificuldades de administração do mesmo. | G8: Realização de Testes Pilotos UHT e Avaliação de Estudos de Estabilidade da fórmula para que o produto atinja os parâmetros necessários para a comercialização. | J8: INOV00016 | K8: TRUE | L8: {=SUM(INDEX(Investimentos!$N$3:$BB30,,MATCH(J8,Investimentos!$N$3:$BB$3,0)))} -> 181490.81 | M8: =IF(K8=TRUE,SUMIF(Pessoal!A:A,J8,Pessoal!$V:$V),0) -> 6719.7125
A9: INOV000017 (2020 - LINHA TROPHIC SOYA PÓ) | C9: Desenvolvimento experimental | D9: O objetivo é expandir a linha guarda-chuva Soya, desenvolvendo produtos em pó para nutrição enteral e oral para público adulto, com foco em editais de licitação. | E9: Até o momento, a linha Soya foi desenvolvida somente para produtos líquidos. Diferente dos demais produtos pó do portfólio Prodiet, a Linha Soya pó possuirá 80% das proteínas de origem vegetal (soja) e somente 20% proteína animal. | F9: Devido a composição dos produtos Linha Soya conterem 80% de proteína de soja, MP com sabor residual bastante presente, o maior desafio é desenvolver um produto de administração enteral mas também oral, com sabor agradável, palatável, aplicando aromas com função satisfatória de mascarar a proteína e economicamente viável. Por ser um produto para licitação, o maior desafio é o custo competitivo do produto, que por possui óleos em pó apresenta custo elevado. | G9: Atualmente as gorduras tem maior impacto no custo do produto, desta forma estão sendo buscadas alternativas para alteração de gorduras em pó, como óleo líquido que possui menor valor. Para melhor solubilidade, aspecto e sabor do produto, a possibilidade junto a fornecedor parceiro, é de realizar uma mistura de proteínas+carboidrato+óleo liquido obtidas por spray dryer. Também estão sendo realizados testes de bancada de adsorção do óleo líquido através da maltodextrina de tapioca, ainda a terceira opção é revisão da fórmula e substituição da proteína láctea por fonte mais barata. | J9: INOV00017 | K9: TRUE | L9: {=SUM(INDEX(Investimentos!$N$3:$BB30,,MATCH(J9,Investimentos!$N$3:$BB$3,0)))} -> 168637.05 | M9: =IF(K9=TRUE,SUMIF(Pessoal!A:A,J9,Pessoal!$V:$V),0) -> 4186.8604
A10: INOV000022 (2021 - PESQUISA CLÍNICA - INSTANTH NEO) | C10: Pesquisa aplicada | D10: Determinar se o uso de Instanth Neo por 6 meses em pacientes acima dos 60 anos, com diagnóstico de CCL por DA é capaz de interferir no desempenho cognitivo, medido por testes neuropsicológicos. | E10: Suplemento alimentar com combinação patenteada de nutrientes: ácido cáprico, caprílico, fosfatidilserina, DHA e vitaminas e minerais. A patente foi concedida para esta combinação visando a suplementação na doença de Alzheimer, o qual é objetivo das pesquisas em andamento. | F10: - Com relação ao produto Instanth Neo: Instanth Neo por sua especificidade da composição (90% lipídios) necessita o envase com nitrogênio, a fim de evitar a oxidação da formulação. Desta forma, será envasado em um terceiro. Este é um dos desafios tecnológicos na produção do Instanth Neo (seja para pesquisa, seja para produção comercial). - Com relação as pesquisas: O principal desafio é o cenário atual, da pandemia, que está atrasando consideravelmente o andamento da pesquisa clínica, que estava prevista para iniciar em 2021. Ainda, o protocolo do estudo é robusto e requer parcerias dentro da universidade para que o desenho do estudo aconteça de forma satisfatória. | G10: Parceria UNIFESP: Eficácia do produto AZ2021 no desfecho cognitivo de pacientes com Comprometimento Cognitivo Leve por provável Doença de Alzheimer: estudo randomizado duplo cego controlado por placebo. | J10: INOV00022 | K10: TRUE | L10: {=SUM(INDEX(Investimentos!$N$3:$BB30,,MATCH(J10,Investimentos!$N$3:$BB$3,0)))} -> 0 | M10: =IF(K10=TRUE,SUMIF(Pessoal!A:A,J10,Pessoal!$V:$V),0) -> 0
A11: INOV000023 (2021 - PESQUISA CLÍNICA - DIAMAX IG) | C11: Pesquisa aplicada | D11: Comprovar os benefícios e segurança de uso do produto DiamaxIG em amostra com Diabetes Mellitus tipo 2 e apresentar os resultados encontrados em forma de abstracts em congressos e artigos científicos. | E11: O uso de fórmula especializada para controle glicêmico pode reduzir a variabilidade glicêmica, principal objetivo das pesquisas atualmente pelo grande impacto na saúde de pessoas com diabetes. | F11: Risco da pesquisa não apresentar resultados satisfatórios no quesito redução da variabilidade glicêmica em indivíduos com diabetes mellitus tipo 2. | G11: Controlar possíveis vieses de pesquisa por meio de protocolo bem estabelecido. A variabilidade glicemica será avaliada por meio de sensor de monitoramento continuo de glicose, o mais atual método de quantificação. | J11: INOV00023 | K11: TRUE | L11: {=SUM(INDEX(Investimentos!$N$3:$BB30,,MATCH(J11,Investimentos!$N$3:$BB$3,0)))} -> 0 | M11: =IF(K11=TRUE,SUMIF(Pessoal!A:A,J11,Pessoal!$V:$V),0) -> 0
A12: INOV000024 (2021 - ESTUDO DE CASO) | C12: Pesquisa básica | D12: A realização de estudos de caso (EC) permite à empresa comprovar os benefícios e segurança de uso dos produtos, agregar maior participação na comunidade cientifica pela parceria com os profissionais, além apresentar os resultados encontrados em forma de abstracts em congressos e/ou artigos científicos. | E12: Os estudos de caso permitem que tenhamos resultados clínicos divulgados de maneira cientifica (divulgação em congressos de peso na área de nutrição enteral) com um menor investimento financeiro e maior agilidade | F12: O principal risco dos estudos de caso prospectivos, quando o estudo ainda irá ocorrer, se dá pela possibilidade de não obter o resultado esperado na conduta clínica, por não haver tantos controles de vieses e o risco de não ser aceito para publicação e/ou apresentação pelo menor peso cientifico, sendo este também aplicável para os estudos retrospectivos. | G12: A publicação de um relato de caso é a escrita de um caso clínico e evolução sobre o uso de determinado produto do portifolio conforme interesse manisfastado pelo profissional que o acompanha e a empresa. Os estudos de caso podem ser realizados de forma prospectiva, por meio da doação de produtos à profissionais ou de maneira retrospectiva, por levantamento de dados de um caso já finalizado. | J12: INOV00024 | K12: FALSE | L12: {=SUM(INDEX(Investimentos!$N$3:$BB30,,MATCH(J12,Investimentos!$N$3:$BB$3,0)))} -> 0 | M12: =IF(K12=TRUE,SUMIF(Pessoal!A:A,J12,Pessoal!$V:$V),0) -> 0
A13: INOV000025 (2022 - TETRA PAK SF) | C13: Desenvolvimento experimental | D13: Comercializar a atual embalagem cartonada no uso de Sistema Fechado, sem haver a necessidade de transferência para o frasco de administração | E13: Tampa da embalagem cartonada deve ser adaptada para que o equipo possa ser conectado. | F13: Aceitação do mercado, tendo em vista que a embalagem cartonada não possui uma janela para controle da administração. | G13: Desenvolver junto ao marketing uma tampa específica para a embalagem cartonada que permita que o equipo seja fixado conforme no frasco. | J13: INOV00025 | K13: TRUE | L13: {=SUM(INDEX(Investimentos!$N$3:$BB30,,MATCH(J13,Investimentos!$N$3:$BB$3,0)))} -> 0 | M13: =IF(K13=TRUE,SUMIF(Pessoal!A:A,J13,Pessoal!$V:$V),0) -> 0
A14: INOV000026 | J14: INOV00026 | K14: FALSE | L14: {=SUM(INDEX(Investimentos!$N$3:$BB30,,MATCH(J14,Investimentos!$N$3:$BB$3,0)))} -> 0 | M14: =IF(K14=TRUE,SUMIF(Pessoal!A:A,J14,Pessoal!$V:$V),0) -> 0
A15: INOV000027 (2022 - PROJETO PESQUISA BÁSICA) | C15: Pesquisa básica | D15: A realização de pesquisas clínicas permite à empresa comprovar os benefícios e segurança de uso dos produtos, agregar maior participação na comunidade cientifica pela parceria com as universidades, além apresentar os resultados encontrados em forma de abstracts em congressos e/ou artigos científicos. | E15: A participação em congressos com estudos científicos bem como o entendimento dos conteúdos e pesquisas recentes sobre possibilidades de intervenções nutricionais nos permitem a avaliação de possibilidades de desenvolvimento de novos produtos, embasando a inovação. | F15: Há congressos nacionais internacionais com diversos temas, sendo uma das barreiras o entendimento e alinhamento dos conteúdos que possam embasar as inovações que desejamos. Além disso, a participação com pesquisas em congressos é um dos objeivos da Prodiet, contribuindo sempre para a inovação e possibilidades de melhoria de produtos. | G15: O planejamento e entendimento das palestras/estudos e conteúdos compartilhados é uma das estratégias para se obter o acesso às pesquisas com maior assertividade. Além disso, a programação prévia das nossas pesquisas para os congressos nacionais e internacionais, tendo em vista as datas limites para submissão à congresso são estratégias. | J15: INOV00027 | K15: FALSE | L15: {=SUM(INDEX(Investimentos!$N$3:$BB30,,MATCH(J15,Investimentos!$N$3:$BB$3,0)))} -> 0 | M15: =IF(K15=TRUE,SUMIF(Pessoal!A:A,J15,Pessoal!$V:$V),0) -> 0
A16: INOV000028 (2021 - PESQUISA APLICADA - RESULTADOS P&D) | C16: Desenvolvimento experimental | D16: Obter dados para construção de uma base de dados sólidas e possuir literatura reconhecida cientificamente, a ser utilizada como referência para análise estatística de dados analíticos obtidos, para alimentos para nutrição enteral e suplementos alimentares. | E16: Literatura científica que poderá ser utilizada como base para avaliação de dados analíticos em alimentos e suplementos alimentares, que atualmente não existe equivalente. | F16: Não aceitação do artigo por periódico científico | G16: Captação de dados: realização de testes pilotos para obtenção de valores de concentração de nutrientes nos produtos em tempo inicial e após armazenamento por tempo determinado para construção de banco de dados. Análise dos resultados armazenados no banco de dados. Elaboração do esboço do documento que será publicado, seguido de levantamento de referências bibliográficas. Após elaboração do esboço será elaborado um artigo. Após aprovação interna, o mesmo será submetido a publicação em periódico científico | J16: INOV00028 | K16: FALSE | L16: {=SUM(INDEX(Investimentos!$N$3:$BB30,,MATCH(J16,Investimentos!$N$3:$BB$3,0)))} -> 0 | M16: =IF(K16=TRUE,SUMIF(Pessoal!A:A,J16,Pessoal!$V:$V),0) -> 0
A17: INOV000029 (2021 - PESQUISA CLÍNICA - HDMAX) | C17: Pesquisa básica | D17: Agregar à comunidade científica conhecimento sobre os efeitos da suplementação especializada em pacientes dialíticos | E17: Esta pesquisa clínica tem como inovação a avaliação de parâmetros de composição corporal, funcionalidade e qualidade de vida entre pacientes idosos em hemodiálise suplementados durante a diálise. A inovação está nos parâmetros a serem avaliados e no público de avaliação. | F17: A impossibilidade de conduzir uma pesquisa que envolvesse este público, considerando todos os processos requeridos para uma pesquisa. | G17: O contato com profissionais que atuam na área de pesquisa com pacientes em hemodiálise é a principal metodologia para lidar com a barreira da pesquisa. | J17: INOV00029 | K17: TRUE | L17: {=SUM(INDEX(Investimentos!$N$3:$BB30,,MATCH(J17,Investimentos!$N$3:$BB$3,0)))} -> 0 | M17: =IF(K17=TRUE,SUMIF(Pessoal!A:A,J17,Pessoal!$V:$V),0) -> 455.53274
A18: INOV00032 | J18: INOV00032 | K18: TRUE | L18: {=SUM(INDEX(Investimentos!$N$3:$BB30,,MATCH(J18,Investimentos!$N$3:$BB$3,0)))} -> 0 | M18: =IF(K18=TRUE,SUMIF(Pessoal!A:A,J18,Pessoal!$V:$V),0) -> 0
A19: INOV000035 (2023 - PESQUISA CLÍNICA - CICATRIZAÇÃO) | C19: Pesquisa aplicada | D19: Avaliar o impacto do uso do suplemento em pó para cicatrização no tempo de cicatrização e evolução da ferida. | E19: Combinação de peptidios de colageno, arginina, a micronutrientes chave para cicatrização, e isomaltulose para controle glicêmico. | F19: Possibilidade de não obter o resultado esperado na conduta clínica. | G19: Doação de produto investigacional, consultoria ténica, análise de biomarcadores e escalas clínicas. | J19: INOV00035 | K19: TRUE | L19: {=SUM(INDEX(Investimentos!$N$3:$BB30,,MATCH(J19,Investimentos!$N$3:$BB$3,0)))} -> 0 | M19: =IF(K19=TRUE,SUMIF(Pessoal!A:A,J19,Pessoal!$V:$V),0) -> 1437.5729
A20: INOV000036 (2023 - PESQUISA APLICADA - ARTESANAL) | C20: Pesquisa aplicada | D20: Avaliar composição físico-químicas de dietas enterais artesanais com e sem uso de suplementação específica, por meio de análises laboratoriais | E20: Utilização de elementos presentes em dietas artesanais com oferta de micronutrietes e segurança | F20: Não observar diferenças significativas na composição físico-química de dietas enterais artesanais com e sem uso de suplementação específica. | G20: Análise química de calorias, proteínas, carboidratos, gorduras, fibras, ferro, cobre, cromo, ácido fólico, ácido pantotênico e colina | J20: INOV00036 | K20: TRUE | L20: {=SUM(INDEX(Investimentos!$N$3:$BB30,,MATCH(J20,Investimentos!$N$3:$BB$3,0)))} -> 172.5 | M20: =IF(K20=TRUE,SUMIF(Pessoal!A:A,J20,Pessoal!$V:$V),0) -> 4120.5641
A21: INOV000037 (2023 - PESQUISA CLÍNICA - IMMAX) | C21: Pesquisa aplicada | D21: Comprovar os benefícios e segurança de uso do produto Immax em amostra de indivíduos com câncer colorretal e apresentar os resultados encontrados em forma de abstracts em congressos e artigos científicos. | E21: O uso de fórmula especializada para pacientes oncológicos pode reduzir a perda e/ou estimular o aumento de massa muscular , principal objetivo das pesquisas atualmente pelo grande impacto na saúde e qualidade de vida de pessoas com câncer. | F21: Risco da pesquisa não apresentar resultados satisfatórios no quesito redução da perda e/ou aumento de massa muscular em indivíduos com cancer colorretal. | G21: Controlar possíveis vieses de pesquisa por meio de protocolo bem estabelecido. A massa muscular será avaliada por meio de densitometria óssea, um dos mlhores métodos de quantificação sem exposição à radiação. | J21: INOV00037 | K21: TRUE | L21: {=SUM(INDEX(Investimentos!$N$3:$BB30,,MATCH(J21,Investimentos!$N$3:$BB$3,0)))} -> 0 | M21: =IF(K21=TRUE,SUMIF(Pessoal!A:A,J21,Pessoal!$V:$V),0) -> 0
A22: INOV00038 | J22: INOV00038 | K22: TRUE | L22: {=SUM(INDEX(Investimentos!$N$3:$BB30,,MATCH(J22,Investimentos!$N$3:$BB$3,0)))} -> 0 | M22: =IF(K22=TRUE,SUMIF(Pessoal!A:A,J22,Pessoal!$V:$V),0) -> 502.97602
A23: INOV000039 (2023 - PESQUISA ÍNDICE GLICÊMICO - DIAMAX IN / SF UTI) | C23: Pesquisa aplicada | D23: Determinar o Indice glicemico de 2 fórmulas especializadas | E23: Fórmulas especializadas com baixo indice glicemico apresentam beneficios para pacientes com diabetes melittus e hiperglicemia por estresse. A comprovação do baixo indice glicemico destas formulas embasaria a prescrição para estes grupos populacionais. | F23: Risco das fórmulas não apresentarem resultados satisfatórios de baixo indice glicemico | G23: Controlar possíveis vieses de pesquisa por meio de protocolo bem estabelecido. Adeterminação do indice glicemico será relizada no centro de referência no Brasil para este tipo de pesquisa e seguirá os protocolos recomendados na literatura. | J23: INOV00039 | K23: TRUE | L23: {=SUM(INDEX(Investimentos!$N$3:$BB30,,MATCH(J23,Investimentos!$N$3:$BB$3,0)))} -> 0 | M23: =IF(K23=TRUE,SUMIF(Pessoal!A:A,J23,Pessoal!$V:$V),0) -> 0
A24: INOV000041 (2023 - PROTEÍNA LÍQUIDA) | C24: Desenvolvimento experimental | D24: Desenvolver módulo de proteína líquido para produção própria, em processo retort, que forneça o mínimo de aminoácidos segundo a RDC 21/2015, com menor volume, para uso em hospitais. | E24: Módulo líquido próprio, inovador para o mercado brasileiro, na categoria de Nutrição Enteral. | F24: Não atingimento da estabilidade da formulação, devido ao tratamento térmico agressivo em autoclave. Se atingida a estabilidade: desestabilização da formulação ao longo do shelf-life, devido à alta concentração proteica em baixo volume. | G24: Estudo da estabilidade de emulsões de proteínas, para fazer a combinação que atenda ao perfil de aminoácidos conforme o direcinal do Briefing do Científico. Aplicação das formulações com tratamento térmico em autoclave. | J24: INOV00041 | K24: TRUE | L24: {=SUM(INDEX(Investimentos!$N$3:$BB30,,MATCH(J24,Investimentos!$N$3:$BB$3,0)))} -> 0 | M24: =IF(K24=TRUE,SUMIF(Pessoal!A:A,J24,Pessoal!$V:$V),0) -> 2540.3101
A25: INOV00046 (2023 - PEPTIMAX IBD) | C25: Desenvolvimento experimental | D25: Desenvolver um novo produto voltado para nutrição em estados de inflamação intestinal. Crescente demanda de mercado deste tipo de produto com fator bioativo TGF beta 2 | E25: A inovação deste produto está na presença do fator TGF beta-2 na composição além da combinação de aminoácido livre e proteína hidrolisada, fatores que desafiam o desenvolvimento sensorial. | F25: Desenvolver um produto que apresente sensorial agradável considerando a combinação de nutrientes com alto residual, além de identificar por meio de análises laboratoriais a presença e teor de TGF beta 2 nas matérias primas do produto e selecionar processo industrial que permita a presença deste ativo. | G25: Por meio de pesquisas sobre o fator TGF beta 2 tem se buscado entender os métodos de análise laboratorias e de processos industriais para este desenvolvimento, além de possibilidades de contatar pesquisadores da área para possível consultoria em relação à este tema. Em relação ao desafio sensorial, a Prodiet busca continuamente parceria com empresas de aromas a fim de desenvolver alternativas que garatam melhor palatabilidade. | J25: INOV00046 | K25: TRUE | L25: {=SUM(INDEX(Investimentos!$N$3:$BB30,,MATCH(J25,Investimentos!$N$3:$BB$3,0)))} -> 142.22 | M25: =IF(K25=TRUE,SUMIF(Pessoal!A:A,J25,Pessoal!$V:$V),0) -> 4171.5489
A26: INOV00047 (2024 - PEPTÍDICA JUNIOR LÍQUIDA) | C26: Desenvolvimento experimental | D26: Desenvolver uma fórmula oligomérica para pediatria (1 a 10 anos), líquida. Competitivo com mercado nacional e internacional. | E26: A inovação desse produto é construir uma linha para o mercado de 1-10 anos com diversidade de apresentação e fórmula. | F26: Desenvolver produto pediátrico com proteína hidrolisada com sensorial ideal para aceitação do publico e/ou que apresente boa resistência térmica, garantindo estabilização proteica e estrutura da fórmula | G26: Testar desenvolvimento de fórmula com estabilidade proteica. | J26: INOV00047 | K26: TRUE | L26: {=SUM(INDEX(Investimentos!$N$3:$BB30,,MATCH(J26,Investimentos!$N$3:$BB$3,0)))} -> 0 | M26: =IF(K26=TRUE,SUMIF(Pessoal!A:A,J26,Pessoal!$V:$V),0) -> 0
A27: INOV00049 (2024 - PESQUISA CLÍNICA PROTEIN PT WHEY) | C27: Pesquisa aplicada | D27: Avaliar a melhoria da massa muscular de mulheres obesas com câncer de mama em tratamento quimioterápico que receberam suplementação nutricional com whey protein isolado (WPI - ProteinPT Whey). | E27: Avaliar efeitos de suplementação e benefícios do protein pt whey em público vulnerável. | F27: Não atender aos objetivos esperados da pesquisa. | G27: Trata-se de um estudo epidemiológico prospectivo experimental aberto que visa investigar se existe diferença entre a utilização do suplemento nutricional WPI associado ao aconselhamento nutricional quando comparado apenas ao aconselhamento nutricional no que diz respeito à mudança da composição corporal e controle dos efeitos colaterais do tratamento quimioterápico em mulheres obesas portadoras de câncer de mama. | J27: INOV00049 | K27: FALSE | L27: {=SUM(INDEX(Investimentos!$N$3:$BB30,,MATCH(J27,Investimentos!$N$3:$BB$3,0)))} -> 0 | M27: =IF(K27=TRUE,SUMIF(Pessoal!A:A,J27,Pessoal!$V:$V),0) -> 0
A28: INOV00050 (2024 - PESQUISA APLICAÇÃO MICROBIOLOGIA) | C28: Pesquisa aplicada | D28: Avaliar o comportamento microbiológico dos produtos da Prodiet Medical Nutrition, durante a administração em sistema aberto e sistema com adaptador de conexão direta ao equipo | E28: Avaliar segurança microbiológica em produto com sistema de admnistração inovador. | F28: Aceitação do mercado, tendo em vista que a embalagem cartonada não possui uma janela para controle da administração e não conformidade microbiológica. | G28: Estudo em laboratório de qualidade. | J28: INOV00050 | K28: FALSE | L28: {=SUM(INDEX(Investimentos!$N$3:$BB30,,MATCH(J28,Investimentos!$N$3:$BB$3,0)))} -> 0 | M28: =IF(K28=TRUE,SUMIF(Pessoal!A:A,J28,Pessoal!$V:$V),0) -> 0
A29: INOV00052 (2024 - DIAMAX 1.5) | C29: Desenvolvimento experimental | D29: Desenvolver dieta enteral líquida para controle glicêmico hipercalórico e hiperproteico | E29: Desenvolver um produto específico para controle glicêmico para a venda no mercado hospitalar, com aumento do teor calórico e proteico, seguindo a linha Diamax já existente em portifólio. | F29: "O principal desafio no desenvolvimento dessa fórmula está na estabilização proteica/estrutural da fórmula. O aumento do teor de proteína acarreta um aumento expressivo da viscosidade. A viscosidade alta em fórmulas enterais é responsável por dificuldades de administração." | G29: Entendimento dos ultimos guidelines e evidencias de alimentação para publico com diabetes e hiperglicemia por estresse. Testar desenvolvimento de fórmula com maior teor de proteínas em teste piloto. | J29: INOV00051 | K29: FALSE | L29: {=SUM(INDEX(Investimentos!$N$3:$BB30,,MATCH(J29,Investimentos!$N$3:$BB$3,0)))} -> 0 | M29: =IF(K29=TRUE,SUMIF(Pessoal!A:A,J29,Pessoal!$V:$V),0) -> 0

Sheet Trabalho
A1: Projeto | B1: Funcionário | C1: Mês | D1: Etapa | E1: Atividade realizada | F1: Descrição da atividade | G1: Data | H1: Horas | I1: Horas decimais | J1: Projeto incentivado? | K1: Atividade incentivada? | L1: Alterações Descrição da atividade | M1: Dedicação
A2: INOV00001 | B2: Ana Paula Biz | C2: {=MONTH(G2:G611)} -> 1 | E2: Pesquisa | F2: Análise do resultados de vitaminas e minerais. | G2: 45666 | H2: 0.03125 | I2: =H2*24 -> 0.75 | J2: {=IFERROR(VLOOKUP(A2:A611,Projetos!J2:K611,2,false),FALSE)} -> TRUE | K2: =IF(OR(E2="Treinamento",E2="Pesquisa",E2="Desenvolvimento"),TRUE,FALSE) -> TRUE | M2: {=XLOOKUP($B$2:$B611,'# Salários'!$C$2:$C611,'# Salários'!$T$2:$T611,,0)} -> Parcial
A3: INOV00028 | B3: Ana Paula Biz | C3: 1 | E3: Pesquisa | F3: Análise de dados, pesquisa científica e escrita de artigo. | G3: 45670 | H3: 0.125 | I3: =H3*24 -> 3 | J3: FALSE | K3: =IF(OR(E3="Treinamento",E3="Pesquisa",E3="Desenvolvimento"),TRUE,FALSE) -> TRUE | M3: Parcial
A4: INOV00028 | B4: Ana Paula Biz | C4: 1 | E4: Pesquisa | F4: Análise de dados, pesquisa científica e escrita de artigo. | G4: 45671 | H4: 0.076388889 | I4: =H4*24 -> 1.8333333 | J4: FALSE | K4: =IF(OR(E4="Treinamento",E4="Pesquisa",E4="Desenvolvimento"),TRUE,FALSE) -> TRUE | M4: Parcial
A5: INOV00028 | B5: Ana Paula Biz | C5: 1 | E5: Pesquisa | F5: Análise de dados, pesquisa científica e escrita de artigo. | G5: 45671 | H5: 0.048611111 | I5: =H5*24 -> 1.1666667 | J5: FALSE | K5: =IF(OR(E5="Treinamento",E5="Pesquisa",E5="Desenvolvimento"),TRUE,FALSE) -> TRUE | M5: Parcial
A6: INOV00046 | B6: Ana Paula Biz | C6: 1 | E6: Desenvolvimento | F6: Alinhamento do projeto Peptimax IBD com foco na quantificação do TGF-beta2 | G6: 45663 | H6: 0.027777778 | I6: =H6*24 -> 0.66666667 | J6: TRUE | K6: =IF(OR(E6="Treinamento",E6="Pesquisa",E6="Desenvolvimento"),TRUE,FALSE) -> TRUE | M6: Parcial
