Workbook

Sheet Resumo
A1: Resumo de investimentos
A2: INOVAÇÃO TECNOLÓGICA 2016
A5: Natureza | B5: Total
A6: Material | B6: ='(a) Investimentos'!J4 -> 16180.07 | C6: (a1)
A7: Terceiros | B7: ='(a) Investimentos'!J5 -> 257166.12 | C7: (a2)
A8: RH (Parcial inovação) | B8: ='(b) Timesheet consolidado'!K7 -> 6980.2545 | C8: (b)
A9: RH (Exclusivo inovação) | B9: ='(c) Dedicação exclusiva'!Q13 -> 154995.32 | C9: (c)
A10: Total | B10: =SUM(B6:B9) -> 435321.76
A11: Percentual Exclusão | B11: 0.6
A12: Exclusão da Base de cálculo do IRPJ e CSLL | B12: =B10*B11 -> 261193.06
A14: Economia Estimada [34%] | B14: =B12*34% -> 88805.64
A16: (a1) Material consumido - detalhes na planilha Investimentos
A17: (a2) Serviços contratados + Ana Paula Celes e Luciana Dutra [dedicação parcial sem apontamento de horas] - detalhes na planilha Investimentos
A18: (b) Time Sheet [funcionários com dedicação parcial] - planilhas Timesheet consolidado
A19: (c) Custo total dos funcionários com dedicação exclusiva - planilha Dedicação Exclusiva

Sheet Distribuição
A1: Distribuição
A2: INOVAÇÃO TECNOLÓGICA 2016
A3: Distribuição entre os projetos dos gastos [para formulário do MCTI]
A6: R$ | B6: Novos produtos | C6: Novas matérias-primas | D6: Melhoria de produto | E6: Melhoria de produto | F6: Total
A7: RH Ded. | B7: =SUM('(c) Dedicação exclusiva'!$E$10:$P$12)*B15 -> 58223.604 | C7: =SUM('(c) Dedicação exclusiva'!$E$10:$P$12)*C15 -> 28806.105 | D7: =SUM('(c) Dedicação exclusiva'!$E$10:$P$12)*D15 -> 40236.433 | E7: =SUM('(c) Dedicação exclusiva'!$E$10:$P$12)*E15 -> 27729.178 | F7: =SUM(B7:E7) -> 154995.32
A8: RH Par. | B8: =SUM('(b) Timesheet consolidado'!$K$9:$K$71)*B15 -> 2622.1151 | C8: =SUM('(b) Timesheet consolidado'!$K$9:$K$71)*C15 -> 1297.2904 | D8: =SUM('(b) Timesheet consolidado'!$K$9:$K$71)*D15 -> 1812.0582 | E8: =SUM('(b) Timesheet consolidado'!$K$9:$K$71)*E15 -> 1248.7907 | F8: =SUM(B8:E8) -> 6980.2545
A9: Material | B9: =SUMIF('(a) Investimentos'!$I$8:$I$114,$A9,'(a) Investimentos'!W$8:W$114) -> 7378.48 | C9: =SUMIF('(a) Investimentos'!$I$8:$I$114,$A9,'(a) Investimentos'!X$8:X$114) -> 895.15 | D9: =SUMIF('(a) Investimentos'!$I$8:$I$114,$A9,'(a) Investimentos'!Y$8:Y$114) -> 2798.98 | E9: =SUMIF('(a) Investimentos'!$I$8:$I$114,$A9,'(a) Investimentos'!Z$8:Z$114) -> 0 | F9: =SUM(B9:E9) -> 11072.61
A10: PJ (terceiros) | B10: =SUMIFS('(a) Investimentos'!W8:W114,'(a) Investimentos'!$I$8:$I$114,"Terceiros") -> 83866.465 | C10: =SUMIFS('(a) Investimentos'!X8:X114,'(a) Investimentos'!$I$8:$I$114,"Terceiros") -> 43737.234 | D10: =SUMIFS('(a) Investimentos'!Y8:Y114,'(a) Investimentos'!$I$8:$I$114,"Terceiros") -> 59543.635 | E10: =SUMIFS('(a) Investimentos'!Z8:Z114,'(a) Investimentos'!$I$8:$I$114,"Terceiros") -> 42963.785 | F10: =SUM(B10:E10) -> 230111.12
A11: Distribuição ILSI (PJ) | B11: =SUMIFS('(a) Investimentos'!$N$8:$N$114,'(a) Investimentos'!$E$8:$E$114,"ILSI",'(a) Investimentos'!$I$8:$I$114,"Terceiros")*B15 -> 10163.143 | C11: =SUMIFS('(a) Investimentos'!$N$8:$N$114,'(a) Investimentos'!$E$8:$E$114,"ILSI",'(a) Investimentos'!$I$8:$I$114,"Terceiros")*C15 -> 5028.211 | D11: =SUMIFS('(a) Investimentos'!$N$8:$N$114,'(a) Investimentos'!$E$8:$E$114,"ILSI",'(a) Investimentos'!$I$8:$I$114,"Terceiros")*D15 -> 7023.4166 | E11: =SUMIFS('(a) Investimentos'!$N$8:$N$114,'(a) Investimentos'!$E$8:$E$114,"ILSI",'(a) Investimentos'!$I$8:$I$114,"Terceiros")*E15 -> 4840.2294 | F11: =SUM(B11:E11) -> 27055
A12: Distribuição ILSI (material) | B12: =SUMIFS('(a) Investimentos'!$N$8:$N$114,'(a) Investimentos'!$E$8:$E$114,"ILSI",'(a) Investimentos'!$I$8:$I$114,"Material")*B15 -> 1918.6045 | C12: =SUMIFS('(a) Investimentos'!$N$8:$N$114,'(a) Investimentos'!$E$8:$E$114,"ILSI",'(a) Investimentos'!$I$8:$I$114,"Material")*C15 -> 949.22886 | D12: =SUMIFS('(a) Investimentos'!$N$8:$N$114,'(a) Investimentos'!$E$8:$E$114,"ILSI",'(a) Investimentos'!$I$8:$I$114,"Material")*D15 -> 1325.885 | E12: =SUMIFS('(a) Investimentos'!$N$8:$N$114,'(a) Investimentos'!$E$8:$E$114,"ILSI",'(a) Investimentos'!$I$8:$I$114,"Material")*E15 -> 913.74157 | F12: =SUM(B12:E12) -> 5107.46
A13: Material (total) | B13: =B12+B9 -> 9297.0845 | C13: =C12+C9 -> 1844.3789 | D13: =D12+D9 -> 4124.865 | E13: =E12+E9 -> 913.74157 | F13: =SUM(B13:E13) -> 16180.07
A14: Total | B14: =SUM(B7:B12) -> 164172.41 | C14: =SUM(C7:C12) -> 80713.22 | D14: =SUM(D7:D12) -> 112740.41 | E14: =SUM(E7:E12) -> 77695.725 | F14: =SUM(B14:E14) -> 435321.76
A15: % (proporção) | B15: 0.37564749 | C15: 0.18585145 | D15: 0.25959773 | E15: 0.17890332 | F15: =SUM(B15:E15) -> 1
A16: Observação: a proporção foi calculada considerando o percentual de cada projeto nos gastos com PJ (terceiros).
B19: Novos produtos | C19: Novas matérias-primas | D19: Melhoria de produto | E19: Melhoria de produto | F19: Total (R$) | G19: Dedicação | H19: CPF | I19: Escolaridade | J19: Novos produtos | K19: Novas matérias-primas | L19: Melhoria de produto | M19: Melhoria de produto | N19: Total (Horas)
A20: Amid Tony Ibrahim | B20: =B$15*Salários!$Q$23 -> 17092.271 | C20: =C$15*Salários!$Q$23 -> 8456.3947 | D20: =D$15*Salários!$Q$23 -> 11811.911 | E20: =E$15*Salários!$Q$23 -> 8140.2491 | F20: =SUM(B20:E20) -> 45500.826 | G20: Exclusivo | H20: =VLOOKUP($A20,'Informações RH'!$A$2:$D$9,2,FALSE) -> 075.215.579-21 | I20: =VLOOKUP($A20,'Informações RH'!$A$2:$D$9,4,FALSE) -> Superior Completo | J20: ='Dias úteis'!$H$20*B$15 -> 839.64728 | K20: ='Dias úteis'!$H$20*C$15 -> 415.41517 | L20: ='Dias úteis'!$H$20*D$15 -> 580.25285 | M20: ='Dias úteis'!$H$20*E$15 -> 399.88471 | N20: =SUM(J20:M20) -> 2235.2
A21: Franciele Guedes | B21: =SUMIF('(b) Timesheet consolidado'!$A$9:$A$71,$A21,'(b) Timesheet consolidado'!$K$9:$K$71)*B$15 -> 520.81936 | C21: =SUMIF('(b) Timesheet consolidado'!$A$9:$A$71,$A21,'(b) Timesheet consolidado'!$K$9:$K$71)*C$15 -> 257.67518 | D21: =SUMIF('(b) Timesheet consolidado'!$A$9:$A$71,$A21,'(b) Timesheet consolidado'!$K$9:$K$71)*D$15 -> 359.92127 | E21: =SUMIF('(b) Timesheet consolidado'!$A$9:$A$71,$A21,'(b) Timesheet consolidado'!$K$9:$K$71)*E$15 -> 248.04189 | F21: =SUM(B21:E21) -> 1386.4577 | G21: Parcial | H21: =VLOOKUP($A21,'Informações RH'!$A$2:$D$9,2,FALSE) -> 065.423.719-07 | I21: =VLOOKUP($A21,'Informações RH'!$A$2:$D$9,4,FALSE) -> Superior Completo | J21: =SUMIF('(b) Timesheet consolidado'!$A$9:$A$71,$A21,'(b) Timesheet consolidado'!$G$9:$G$71)*B$15 -> 17.586563 | K21: =SUMIF('(b) Timesheet consolidado'!$A$9:$A$71,$A21,'(b) Timesheet consolidado'!$G$9:$G$71)*C$15 -> 8.7009455 | L21: =SUMIF('(b) Timesheet consolidado'!$A$9:$A$71,$A21,'(b) Timesheet consolidado'!$G$9:$G$71)*D$15 -> 12.1535 | M21: =SUMIF('(b) Timesheet consolidado'!$A$9:$A$71,$A21,'(b) Timesheet consolidado'!$G$9:$G$71)*E$15 -> 8.3756573 | N21: =SUM(J21:M21) -> 46.816667
A22: Hellin dos Santos | B22: =Salários!$Q$25*B$15 -> 33144.619 | C22: =Salários!$Q$25*C$15 -> 16398.287 | D22: =Salários!$Q$25*D$15 -> 22905.165 | E22: =Salários!$Q$25*E$15 -> 15785.231 | F22: =SUM(B22:E22) -> 88233.302 | G22: Exclusivo | H22: =VLOOKUP($A22,'Informações RH'!$A$2:$D$9,2,FALSE) -> 058.544.839-63 | I22: =VLOOKUP($A22,'Informações RH'!$A$2:$D$9,4,FALSE) -> Superior Completo | J22: ='Dias úteis'!$H$20*B$15 -> 839.64728 | K22: ='Dias úteis'!$H$20*C$15 -> 415.41517 | L22: ='Dias úteis'!$H$20*D$15 -> 580.25285 | M22: ='Dias úteis'!$H$20*E$15 -> 399.88471 | N22: =SUM(J22:M22) -> 2235.2
A23: Hozana Bueno | B23: =SUMIF('(b) Timesheet consolidado'!$A$9:$A$71,$A23,'(b) Timesheet consolidado'!$K$9:$K$71)*B$15 -> 170.9379 | C23: =SUMIF('(b) Timesheet consolidado'!$A$9:$A$71,$A23,'(b) Timesheet consolidado'!$K$9:$K$71)*C$15 -> 84.571461 | D23: =SUMIF('(b) Timesheet consolidado'!$A$9:$A$71,$A23,'(b) Timesheet consolidado'!$K$9:$K$71)*D$15 -> 118.12961 | E23: =SUMIF('(b) Timesheet consolidado'!$A$9:$A$71,$A23,'(b) Timesheet consolidado'!$K$9:$K$71)*E$15 -> 81.409725 | F23: =SUM(B23:E23) -> 455.0487 | G23: Parcial | H23: =VLOOKUP($A23,'Informações RH'!$A$2:$D$9,2,FALSE) -> 039.677.159-90 | I23: =VLOOKUP($A23,'Informações RH'!$A$2:$D$9,4,FALSE) -> Técnico | J23: =SUMIF('(b) Timesheet consolidado'!$A$9:$A$71,$A23,'(b) Timesheet consolidado'!$G$9:$G$71)*B$15 -> 9.0155398 | K23: =SUMIF('(b) Timesheet consolidado'!$A$9:$A$71,$A23,'(b) Timesheet consolidado'!$G$9:$G$71)*C$15 -> 4.4604349 | L23: =SUMIF('(b) Timesheet consolidado'!$A$9:$A$71,$A23,'(b) Timesheet consolidado'!$G$9:$G$71)*D$15 -> 6.2303455 | M23: =SUMIF('(b) Timesheet consolidado'!$A$9:$A$71,$A23,'(b) Timesheet consolidado'!$G$9:$G$71)*E$15 -> 4.2936798 | N23: =SUM(J23:M23) -> 24
A24: Jana Grenteski | B24: =B$15*Salários!$Q$27 -> 7986.7136 | C24: =C$15*Salários!$Q$27 -> 3951.4235 | D24: =D$15*Salários!$Q$27 -> 5519.3573 | E24: =E$15*Salários!$Q$27 -> 3803.698 | F24: =SUM(B24:E24) -> 21261.192 | G24: Exclusivo | H24: =VLOOKUP($A24,'Informações RH'!$A$2:$D$9,2,FALSE) -> 040.201.929-60 | I24: =VLOOKUP($A24,'Informações RH'!$A$2:$D$9,4,FALSE) -> Superior Completo / Doutorado em Andamento | J24: ='Dias úteis'!$H$20*B$15 -> 839.64728 | K24: ='Dias úteis'!$H$20*C$15 -> 415.41517 | L24: ='Dias úteis'!$H$20*D$15 -> 580.25285 | M24: ='Dias úteis'!$H$20*E$15 -> 399.88471 | N24: =SUM(J24:M24) -> 2235.2
A25: Lizianne Shmeil | B25: =SUMIF('(b) Timesheet consolidado'!$A$9:$A$71,$A25,'(b) Timesheet consolidado'!$K$9:$K$71)*B$15 -> 354.06264 | C25: =SUMIF('(b) Timesheet consolidado'!$A$9:$A$71,$A25,'(b) Timesheet consolidado'!$K$9:$K$71)*C$15 -> 175.17236 | D25: =SUMIF('(b) Timesheet consolidado'!$A$9:$A$71,$A25,'(b) Timesheet consolidado'!$K$9:$K$71)*D$15 -> 244.68114 | E25: =SUMIF('(b) Timesheet consolidado'!$A$9:$A$71,$A25,'(b) Timesheet consolidado'!$K$9:$K$71)*E$15 -> 168.62347 | F25: =SUM(B25:E25) -> 942.53961 | G25: Parcial | H25: =VLOOKUP($A25,'Informações RH'!$A$2:$D$9,2,FALSE) -> 052.485.199-93 | I25: =VLOOKUP($A25,'Informações RH'!$A$2:$D$9,4,FALSE) -> Pós graduada | J25: =SUMIF('(b) Timesheet consolidado'!$A$9:$A$71,$A25,'(b) Timesheet consolidado'!$G$9:$G$71)*B$15 -> 11.926808 | K25: =SUMIF('(b) Timesheet consolidado'!$A$9:$A$71,$A25,'(b) Timesheet consolidado'!$G$9:$G$71)*C$15 -> 5.9007836 | L25: =SUMIF('(b) Timesheet consolidado'!$A$9:$A$71,$A25,'(b) Timesheet consolidado'!$G$9:$G$71)*D$15 -> 8.2422279 | M25: =SUMIF('(b) Timesheet consolidado'!$A$9:$A$71,$A25,'(b) Timesheet consolidado'!$G$9:$G$71)*E$15 -> 5.6801806 | N25: =SUM(J25:M25) -> 31.75
A26: Marianne Stigar | B26: =SUMIF('(b) Timesheet consolidado'!$A$9:$A$71,$A26,'(b) Timesheet consolidado'!$K$9:$K$71)*B$15 -> 703.88126 | C26: =SUMIF('(b) Timesheet consolidado'!$A$9:$A$71,$A26,'(b) Timesheet consolidado'!$K$9:$K$71)*C$15 -> 348.24498 | D26: =SUMIF('(b) Timesheet consolidado'!$A$9:$A$71,$A26,'(b) Timesheet consolidado'!$K$9:$K$71)*D$15 -> 486.42938 | E26: =SUMIF('(b) Timesheet consolidado'!$A$9:$A$71,$A26,'(b) Timesheet consolidado'!$K$9:$K$71)*E$15 -> 335.22571 | F26: =SUM(B26:E26) -> 1873.7813 | G26: Parcial | H26: =VLOOKUP($A26,'Informações RH'!$A$2:$D$9,2,FALSE) -> 066.424.199-95 | I26: =VLOOKUP($A26,'Informações RH'!$A$2:$D$9,4,FALSE) -> Pós graduada | J26: =SUMIF('(b) Timesheet consolidado'!$A$9:$A$71,$A26,'(b) Timesheet consolidado'!$G$9:$G$71)*B$15 -> 21.004956 | K26: =SUMIF('(b) Timesheet consolidado'!$A$9:$A$71,$A26,'(b) Timesheet consolidado'!$G$9:$G$71)*C$15 -> 10.392194 | L26: =SUMIF('(b) Timesheet consolidado'!$A$9:$A$71,$A26,'(b) Timesheet consolidado'!$G$9:$G$71)*D$15 -> 14.51584 | M26: =SUMIF('(b) Timesheet consolidado'!$A$9:$A$71,$A26,'(b) Timesheet consolidado'!$G$9:$G$71)*E$15 -> 10.003678 | N26: =SUM(J26:M26) -> 55.916667
A27: Mauricio Ragadalli | B27: =SUMIF('(b) Timesheet consolidado'!$A$9:$A$71,$A27,'(b) Timesheet consolidado'!$K$9:$K$71)*B$15 -> 872.41395 | C27: =SUMIF('(b) Timesheet consolidado'!$A$9:$A$71,$A27,'(b) Timesheet consolidado'!$K$9:$K$71)*C$15 -> 431.62647 | D27: =SUMIF('(b) Timesheet consolidado'!$A$9:$A$71,$A27,'(b) Timesheet consolidado'!$K$9:$K$71)*D$15 -> 602.89682 | E27: =SUMIF('(b) Timesheet consolidado'!$A$9:$A$71,$A27,'(b) Timesheet consolidado'!$K$9:$K$71)*E$15 -> 415.48994 | F27: =SUM(B27:E27) -> 2322.4272 | G27: Parcial | H27: =VLOOKUP($A27,'Informações RH'!$A$2:$D$9,2,FALSE) -> 060.236.389-61 | I27: =VLOOKUP($A27,'Informações RH'!$A$2:$D$9,4,FALSE) -> Superior Completo | J27: =SUMIF('(b) Timesheet consolidado'!$A$9:$A$71,$A27,'(b) Timesheet consolidado'!$G$9:$G$71)*B$15 -> 19.314542 | K27: =SUMIF('(b) Timesheet consolidado'!$A$9:$A$71,$A27,'(b) Timesheet consolidado'!$G$9:$G$71)*C$15 -> 9.5558622 | L27: =SUMIF('(b) Timesheet consolidado'!$A$9:$A$71,$A27,'(b) Timesheet consolidado'!$G$9:$G$71)*D$15 -> 13.34765 | M27: =SUMIF('(b) Timesheet consolidado'!$A$9:$A$71,$A27,'(b) Timesheet consolidado'!$G$9:$G$71)*E$15 -> 9.1986126 | N27: =SUM(J27:M27) -> 51.416667
A28: Total | B28: =SUM(B20:B27) -> 60845.719 | C28: =SUM(C20:C27) -> 30103.396 | D28: =SUM(D20:D27) -> 42048.492 | E28: =SUM(E20:E27) -> 28977.969 | F28: =SUM(F20:F27) -> 161975.57 | J28: =SUM(J20:J27) -> 2597.7902 | K28: =SUM(K20:K27) -> 1285.2557 | L28: =SUM(L20:L27) -> 1795.2481 | M28: =SUM(M20:M27) -> 1237.2059 | N28: =SUM(N20:N27) -> 6915.5
D31: =SUBTOTAL(9,D33:D54) -> 83866.465 | E31: =SUBTOTAL(9,E33:E54) -> 43737.234 | F31: =SUBTOTAL(9,F33:F54) -> 59543.635 | G31: =SUBTOTAL(9,G33:G54) -> 42963.785 | H31: =SUBTOTAL(9,H33:H54) -> 27055 | I31: =SUM(D31:H31) -> 257166.12
A32: RECURSO | B32: CPF / CNPJ | C32: NATUREZA | D32: Novos Produtos | E32: Novas matérias-primas | F32: Melhoria de Produto | G32: Melhoria de Processo | H32: ILSI
A33: Bioagri Analises de alimentos Ltda | B33: 00.000.410/0001-32 | C33: Terceiros | D33: =SUMIFS('(a) Investimentos'!W$8:W$114,'(a) Investimentos'!$F$8:$F$114,$A33,'(a) Investimentos'!$G$8:$G$114,$B33,'(a) Investimentos'!$I$8:$I$114,$C33) -> 651.7 | E33: =SUMIFS('(a) Investimentos'!X$8:X$114,'(a) Investimentos'!$F$8:$F$114,$A33,'(a) Investimentos'!$G$8:$G$114,$B33,'(a) Investimentos'!$I$8:$I$114,$C33) -> 0 | F33: =SUMIFS('(a) Investimentos'!Y$8:Y$114,'(a) Investimentos'!$F$8:$F$114,$A33,'(a) Investimentos'!$G$8:$G$114,$B33,'(a) Investimentos'!$I$8:$I$114,$C33) -> 651.7 | G33: =SUMIFS('(a) Investimentos'!Z$8:Z$114,'(a) Investimentos'!$F$8:$F$114,$A33,'(a) Investimentos'!$G$8:$G$114,$B33,'(a) Investimentos'!$I$8:$I$114,$C33) -> 1303.4 | H33: =SUMIFS('(a) Investimentos'!AA$8:AA$114,'(a) Investimentos'!$F$8:$F$114,$A33,'(a) Investimentos'!$G$8:$G$114,$B33,'(a) Investimentos'!$I$8:$I$114,$C33) -> 0
A34: Oraculum Inteligência em Nutrição e Saúde Ltda - ME | B34: 21.213.714/0001-58 | C34: Terceiros | D34: =SUMIFS('(a) Investimentos'!W$8:W$114,'(a) Investimentos'!$F$8:$F$114,$A34,'(a) Investimentos'!$G$8:$G$114,$B34,'(a) Investimentos'!$I$8:$I$114,$C34) -> 12042 | E34: =SUMIFS('(a) Investimentos'!X$8:X$114,'(a) Investimentos'!$F$8:$F$114,$A34,'(a) Investimentos'!$G$8:$G$114,$B34,'(a) Investimentos'!$I$8:$I$114,$C34) -> 0 | F34: =SUMIFS('(a) Investimentos'!Y$8:Y$114,'(a) Investimentos'!$F$8:$F$114,$A34,'(a) Investimentos'!$G$8:$G$114,$B34,'(a) Investimentos'!$I$8:$I$114,$C34) -> 0 | G34: =SUMIFS('(a) Investimentos'!Z$8:Z$114,'(a) Investimentos'!$F$8:$F$114,$A34,'(a) Investimentos'!$G$8:$G$114,$B34,'(a) Investimentos'!$I$8:$I$114,$C34) -> 0 | H34: =SUMIFS('(a) Investimentos'!AA$8:AA$114,'(a) Investimentos'!$F$8:$F$114,$A34,'(a) Investimentos'!$G$8:$G$114,$B34,'(a) Investimentos'!$I$8:$I$114,$C34) -> 0
A35: Impressione Impressão Digital Ltda - ME | B35: 12.457.568/0001-15 | C35: Terceiros | D35: =SUMIFS('(a) Investimentos'!W$8:W$114,'(a) Investimentos'!$F$8:$F$114,$A35,'(a) Investimentos'!$G$8:$G$114,$B35,'(a) Investimentos'!$I$8:$I$114,$C35) -> 0 | E35: =SUMIFS('(a) Investimentos'!X$8:X$114,'(a) Investimentos'!$F$8:$F$114,$A35,'(a) Investimentos'!$G$8:$G$114,$B35,'(a) Investimentos'!$I$8:$I$114,$C35) -> 0 | F35: =SUMIFS('(a) Investimentos'!Y$8:Y$114,'(a) Investimentos'!$F$8:$F$114,$A35,'(a) Investimentos'!$G$8:$G$114,$B35,'(a) Investimentos'!$I$8:$I$114,$C35) -> 0 | G35: =SUMIFS('(a) Investimentos'!Z$8:Z$114,'(a) Investimentos'!$F$8:$F$114,$A35,'(a) Investimentos'!$G$8:$G$114,$B35,'(a) Investimentos'!$I$8:$I$114,$C35) -> 0 | H35: =SUMIFS('(a) Investimentos'!AA$8:AA$114,'(a) Investimentos'!$F$8:$F$114,$A35,'(a) Investimentos'!$G$8:$G$114,$B35,'(a) Investimentos'!$I$8:$I$114,$C35) -> 0
A36: Laboratório Alac Ltda | B36: 94.088.952/0001-52 | C36: Terceiros | D36: =SUMIFS('(a) Investimentos'!W$8:W$114,'(a) Investimentos'!$F$8:$F$114,$A36,'(a) Investimentos'!$G$8:$G$114,$B36,'(a) Investimentos'!$I$8:$I$114,$C36) -> 2425.256 | E36: =SUMIFS('(a) Investimentos'!X$8:X$114,'(a) Investimentos'!$F$8:$F$114,$A36,'(a) Investimentos'!$G$8:$G$114,$B36,'(a) Investimentos'!$I$8:$I$114,$C36) -> 3919.2255 | F36: =SUMIFS('(a) Investimentos'!Y$8:Y$114,'(a) Investimentos'!$F$8:$F$114,$A36,'(a) Investimentos'!$G$8:$G$114,$B36,'(a) Investimentos'!$I$8:$I$114,$C36) -> 8020.159 | G36: =SUMIFS('(a) Investimentos'!Z$8:Z$114,'(a) Investimentos'!$F$8:$F$114,$A36,'(a) Investimentos'!$G$8:$G$114,$B36,'(a) Investimentos'!$I$8:$I$114,$C36) -> 290 | H36: =SUMIFS('(a) Investimentos'!AA$8:AA$114,'(a) Investimentos'!$F$8:$F$114,$A36,'(a) Investimentos'!$G$8:$G$114,$B36,'(a) Investimentos'!$I$8:$I$114,$C36) -> 0
A37: Fundação de desenv. Da pesquisa do agronegócio - FUNDEPAG | B37: 50.276.237/0001-78 | C37: Terceiros | D37: =SUMIFS('(a) Investimentos'!W$8:W$114,'(a) Investimentos'!$F$8:$F$114,$A37,'(a) Investimentos'!$G$8:$G$114,$B37,'(a) Investimentos'!$I$8:$I$114,$C37) -> 5804.2 | E37: =SUMIFS('(a) Investimentos'!X$8:X$114,'(a) Investimentos'!$F$8:$F$114,$A37,'(a) Investimentos'!$G$8:$G$114,$B37,'(a) Investimentos'!$I$8:$I$114,$C37) -> 2364.7 | F37: =SUMIFS('(a) Investimentos'!Y$8:Y$114,'(a) Investimentos'!$F$8:$F$114,$A37,'(a) Investimentos'!$G$8:$G$114,$B37,'(a) Investimentos'!$I$8:$I$114,$C37) -> 12665.9 | G37: =SUMIFS('(a) Investimentos'!Z$8:Z$114,'(a) Investimentos'!$F$8:$F$114,$A37,'(a) Investimentos'!$G$8:$G$114,$B37,'(a) Investimentos'!$I$8:$I$114,$C37) -> 0 | H37: =SUMIFS('(a) Investimentos'!AA$8:AA$114,'(a) Investimentos'!$F$8:$F$114,$A37,'(a) Investimentos'!$G$8:$G$114,$B37,'(a) Investimentos'!$I$8:$I$114,$C37) -> 0
A38: Sandra Marcia da Silva de Souza - ME | B38: 13.807.270/0001-50 | C38: Terceiros | D38: =SUMIFS('(a) Investimentos'!W$8:W$114,'(a) Investimentos'!$F$8:$F$114,$A38,'(a) Investimentos'!$G$8:$G$114,$B38,'(a) Investimentos'!$I$8:$I$114,$C38) -> 0 | E38: =SUMIFS('(a) Investimentos'!X$8:X$114,'(a) Investimentos'!$F$8:$F$114,$A38,'(a) Investimentos'!$G$8:$G$114,$B38,'(a) Investimentos'!$I$8:$I$114,$C38) -> 0 | F38: =SUMIFS('(a) Investimentos'!Y$8:Y$114,'(a) Investimentos'!$F$8:$F$114,$A38,'(a) Investimentos'!$G$8:$G$114,$B38,'(a) Investimentos'!$I$8:$I$114,$C38) -> 0 | G38: =SUMIFS('(a) Investimentos'!Z$8:Z$114,'(a) Investimentos'!$F$8:$F$114,$A38,'(a) Investimentos'!$G$8:$G$114,$B38,'(a) Investimentos'!$I$8:$I$114,$C38) -> 0 | H38: =SUMIFS('(a) Investimentos'!AA$8:AA$114,'(a) Investimentos'!$F$8:$F$114,$A38,'(a) Investimentos'!$G$8:$G$114,$B38,'(a) Investimentos'!$I$8:$I$114,$C38) -> 0
A39: Clínica Médica Mourão Faccio S/S | B39: 04.404.467/0001-58 | C39: Terceiros | D39: =SUMIFS('(a) Investimentos'!W$8:W$114,'(a) Investimentos'!$F$8:$F$114,$A39,'(a) Investimentos'!$G$8:$G$114,$B39,'(a) Investimentos'!$I$8:$I$114,$C39) -> 24000 | E39: =SUMIFS('(a) Investimentos'!X$8:X$114,'(a) Investimentos'!$F$8:$F$114,$A39,'(a) Investimentos'!$G$8:$G$114,$B39,'(a) Investimentos'!$I$8:$I$114,$C39) -> 0 | F39: =SUMIFS('(a) Investimentos'!Y$8:Y$114,'(a) Investimentos'!$F$8:$F$114,$A39,'(a) Investimentos'!$G$8:$G$114,$B39,'(a) Investimentos'!$I$8:$I$114,$C39) -> 0 | G39: =SUMIFS('(a) Investimentos'!Z$8:Z$114,'(a) Investimentos'!$F$8:$F$114,$A39,'(a) Investimentos'!$G$8:$G$114,$B39,'(a) Investimentos'!$I$8:$I$114,$C39) -> 0 | H39: =SUMIFS('(a) Investimentos'!AA$8:AA$114,'(a) Investimentos'!$F$8:$F$114,$A39,'(a) Investimentos'!$G$8:$G$114,$B39,'(a) Investimentos'!$I$8:$I$114,$C39) -> 0
A40: Contabilista Papelaria e informática | B40: 77.765.840/0001-70 | C40: Terceiros | D40: =SUMIFS('(a) Investimentos'!W$8:W$114,'(a) Investimentos'!$F$8:$F$114,$A40,'(a) Investimentos'!$G$8:$G$114,$B40,'(a) Investimentos'!$I$8:$I$114,$C40) -> 0 | E40: =SUMIFS('(a) Investimentos'!X$8:X$114,'(a) Investimentos'!$F$8:$F$114,$A40,'(a) Investimentos'!$G$8:$G$114,$B40,'(a) Investimentos'!$I$8:$I$114,$C40) -> 0 | F40: =SUMIFS('(a) Investimentos'!Y$8:Y$114,'(a) Investimentos'!$F$8:$F$114,$A40,'(a) Investimentos'!$G$8:$G$114,$B40,'(a) Investimentos'!$I$8:$I$114,$C40) -> 0 | G40: =SUMIFS('(a) Investimentos'!Z$8:Z$114,'(a) Investimentos'!$F$8:$F$114,$A40,'(a) Investimentos'!$G$8:$G$114,$B40,'(a) Investimentos'!$I$8:$I$114,$C40) -> 0 | H40: =SUMIFS('(a) Investimentos'!AA$8:AA$114,'(a) Investimentos'!$F$8:$F$114,$A40,'(a) Investimentos'!$G$8:$G$114,$B40,'(a) Investimentos'!$I$8:$I$114,$C40) -> 0
A41: Medicalcom Hospitalares Eireli - ME | B41: 21.059.832/0001-53 | C41: Terceiros | D41: =SUMIFS('(a) Investimentos'!W$8:W$114,'(a) Investimentos'!$F$8:$F$114,$A41,'(a) Investimentos'!$G$8:$G$114,$B41,'(a) Investimentos'!$I$8:$I$114,$C41) -> 0 | E41: =SUMIFS('(a) Investimentos'!X$8:X$114,'(a) Investimentos'!$F$8:$F$114,$A41,'(a) Investimentos'!$G$8:$G$114,$B41,'(a) Investimentos'!$I$8:$I$114,$C41) -> 0 | F41: =SUMIFS('(a) Investimentos'!Y$8:Y$114,'(a) Investimentos'!$F$8:$F$114,$A41,'(a) Investimentos'!$G$8:$G$114,$B41,'(a) Investimentos'!$I$8:$I$114,$C41) -> 0 | G41: =SUMIFS('(a) Investimentos'!Z$8:Z$114,'(a) Investimentos'!$F$8:$F$114,$A41,'(a) Investimentos'!$G$8:$G$114,$B41,'(a) Investimentos'!$I$8:$I$114,$C41) -> 0 | H41: =SUMIFS('(a) Investimentos'!AA$8:AA$114,'(a) Investimentos'!$F$8:$F$114,$A41,'(a) Investimentos'!$G$8:$G$114,$B41,'(a) Investimentos'!$I$8:$I$114,$C41) -> 0
A42: Comercial Brey Ltda | B42: 02.608.645/0001-37 | C42: Terceiros | D42: =SUMIFS('(a) Investimentos'!W$8:W$114,'(a) Investimentos'!$F$8:$F$114,$A42,'(a) Investimentos'!$G$8:$G$114,$B42,'(a) Investimentos'!$I$8:$I$114,$C42) -> 0 | E42: =SUMIFS('(a) Investimentos'!X$8:X$114,'(a) Investimentos'!$F$8:$F$114,$A42,'(a) Investimentos'!$G$8:$G$114,$B42,'(a) Investimentos'!$I$8:$I$114,$C42) -> 0 | F42: =SUMIFS('(a) Investimentos'!Y$8:Y$114,'(a) Investimentos'!$F$8:$F$114,$A42,'(a) Investimentos'!$G$8:$G$114,$B42,'(a) Investimentos'!$I$8:$I$114,$C42) -> 0 | G42: =SUMIFS('(a) Investimentos'!Z$8:Z$114,'(a) Investimentos'!$F$8:$F$114,$A42,'(a) Investimentos'!$G$8:$G$114,$B42,'(a) Investimentos'!$I$8:$I$114,$C42) -> 0 | H42: =SUMIFS('(a) Investimentos'!AA$8:AA$114,'(a) Investimentos'!$F$8:$F$114,$A42,'(a) Investimentos'!$G$8:$G$114,$B42,'(a) Investimentos'!$I$8:$I$114,$C42) -> 0
A43: Valéria Paschoal Editora Produtos e Serviços Ltda EPP | B43: 06.635.677/0001-82 | C43: Terceiros | D43: =SUMIFS('(a) Investimentos'!W$8:W$114,'(a) Investimentos'!$F$8:$F$114,$A43,'(a) Investimentos'!$G$8:$G$114,$B43,'(a) Investimentos'!$I$8:$I$114,$C43) -> 0 | E43: =SUMIFS('(a) Investimentos'!X$8:X$114,'(a) Investimentos'!$F$8:$F$114,$A43,'(a) Investimentos'!$G$8:$G$114,$B43,'(a) Investimentos'!$I$8:$I$114,$C43) -> 0 | F43: =SUMIFS('(a) Investimentos'!Y$8:Y$114,'(a) Investimentos'!$F$8:$F$114,$A43,'(a) Investimentos'!$G$8:$G$114,$B43,'(a) Investimentos'!$I$8:$I$114,$C43) -> 0 | G43: =SUMIFS('(a) Investimentos'!Z$8:Z$114,'(a) Investimentos'!$F$8:$F$114,$A43,'(a) Investimentos'!$G$8:$G$114,$B43,'(a) Investimentos'!$I$8:$I$114,$C43) -> 0 | H43: =SUMIFS('(a) Investimentos'!AA$8:AA$114,'(a) Investimentos'!$F$8:$F$114,$A43,'(a) Investimentos'!$G$8:$G$114,$B43,'(a) Investimentos'!$I$8:$I$114,$C43) -> 0
A44: Nutrihealth Comercio de Produtos Alimentícios Eireli ME | B44: 14.492.128/0001-89 | C44: Terceiros | D44: =SUMIFS('(a) Investimentos'!W$8:W$114,'(a) Investimentos'!$F$8:$F$114,$A44,'(a) Investimentos'!$G$8:$G$114,$B44,'(a) Investimentos'!$I$8:$I$114,$C44) -> 0 | E44: =SUMIFS('(a) Investimentos'!X$8:X$114,'(a) Investimentos'!$F$8:$F$114,$A44,'(a) Investimentos'!$G$8:$G$114,$B44,'(a) Investimentos'!$I$8:$I$114,$C44) -> 0 | F44: =SUMIFS('(a) Investimentos'!Y$8:Y$114,'(a) Investimentos'!$F$8:$F$114,$A44,'(a) Investimentos'!$G$8:$G$114,$B44,'(a) Investimentos'!$I$8:$I$114,$C44) -> 0 | G44: =SUMIFS('(a) Investimentos'!Z$8:Z$114,'(a) Investimentos'!$F$8:$F$114,$A44,'(a) Investimentos'!$G$8:$G$114,$B44,'(a) Investimentos'!$I$8:$I$114,$C44) -> 0 | H44: =SUMIFS('(a) Investimentos'!AA$8:AA$114,'(a) Investimentos'!$F$8:$F$114,$A44,'(a) Investimentos'!$G$8:$G$114,$B44,'(a) Investimentos'!$I$8:$I$114,$C44) -> 0
... A54: L Dutra Serviços ME | B54: 18.337.175/0001-54 | C54: Terceiros | D54: =SUMIFS('(a) Investimentos'!W$8:W$114,'(a) Investimentos'!$F$8:$F$114,$A54,'(a) Investimentos'!$G$8:$G$114,$B54,'(a) Investimentos'!$I$8:$I$114,$C54) -> 27893.984 | E54: =SUMIFS('(a) Investimentos'!X$8:X$114,'(a) Investimentos'!$F$8:$F$114,$A54,'(a) Investimentos'!$G$8:$G$114,$B54,'(a) Investimentos'!$I$8:$I$114,$C54) -> 27893.984 | F54: =SUMIFS('(a) Investimentos'!Y$8:Y$114,'(a) Investimentos'!$F$8:$F$114,$A54,'(a) Investimentos'!$G$8:$G$114,$B54,'(a) Investimentos'!$I$8:$I$114,$C54) -> 27893.984 | G54: =SUMIFS('(a) Investimentos'!Z$8:Z$114,'(a) Investimentos'!$F$8:$F$114,$A54,'(a) Investimentos'!$G$8:$G$114,$B54,'(a) Investimentos'!$I$8:$I$114,$C54) -> 27893.984 | H54: =SUMIFS('(a) Investimentos'!AA$8:AA$114,'(a) Investimentos'!$F$8:$F$114,$A54,'(a) Investimentos'!$G$8:$G$114,$B54,'(a) Investimentos'!$I$8:$I$114,$C54) -> 0

Sheet (a) Investimentos
A1: PRODIET
A2: Anexo I - Investimentos - Materiais
A3: INOVAÇÃO TECNOLÓGICA 2016
I4: Material | J4: =SUMIF($I$8:$I$115,I4,$N$8:$N$115) -> 16180.07
I5: Terceiros | J5: =SUMIF($I$8:$I$115,I5,$N$8:$N$115) -> 257166.12
D6: =SUBTOTAL(9,D8:D114) -> 16180.07 | N6: =SUBTOTAL(9,N8:N114) -> 16180.07 | P6: Participação nos projetos | U6: =SUM(U8:U90)/COUNT(U8:U90) -> 1 | W6: Dispêndio (R$) por projeto
A7: Tipo de documento | B7: Documento | C7: DOCS | D7: Total NF | E7: PRODUTOS | F7: RECURSO | G7: CPF / CNPJ | H7: ATIVIDADE | I7: NATUREZA | J7: DATA | K7: Mês | L7: QTD | M7: UNITÁRIO | N7: TOTAL | P7: Novos Produtos | Q7: Novas matérias-primas | R7: Melhoria de Produto | S7: Melhoria de Processo | T7: ILSI | U7: Total | W7: Novos Produtos | X7: Novas matérias-primas | Y7: Melhoria de Produto | Z7: Melhoria de Processo | AA7: ILSI
A8: NF | B8: 34840 | C8: 1 | D8: 1303.4 | E8: Bemmax, Peptimax | F8: Bioagri Analises de alimentos Ltda | G8: 00.000.410/0001-32 | H8: Análise de ácidos graxos | I8: Terceiros | J8: 42500 | K8: 5 | L8: 1 | M8: 1303.4 | N8: =M8*L8 -> 1303.4 | P8: 0.5 | Q8: 0 | R8: 0 | S8: 0.5 | T8: 0 | U8: =SUM(P8:T8) -> 1 | W8: =$N8*P8 -> 651.7 | X8: =$N8*Q8 -> 0 | Y8: =$N8*R8 -> 0 | Z8: =$N8*S8 -> 651.7 | AA8: =$N8*T8 -> 0
A9: Bilhete e-ticket | B9: 577 0005868279 | C9: 2 | D9: 579.24 | E9: Immax | F9: Azul linhas aéreas | H9: Passagens Hellin IDA e VOLTA Ribeirão Preto | I9: Material | J9: 42641 | K9: 9 | L9: 1 | M9: 579.24 | N9: =M9*L9 -> 579.24 | P9: 1 | Q9: 0 | R9: 0 | S9: 0 | T9: 0 | U9: =SUM(P9:T9) -> 1 | W9: =$N9*P9 -> 579.24 | X9: =$N9*Q9 -> 0 | Y9: =$N9*R9 -> 0 | Z9: =$N9*S9 -> 0 | AA9: =$N9*T9 -> 0
A10: Cupons fiscais | C10: 2 | D10: 138.01 | E10: Immax | F10: Diversos | H10: Alimentação e táxi Hellin Ribeirão Preto | I10: Material | J10: 42641 | K10: 9 | L10: 1 | M10: 138.01 | N10: =M10*L10 -> 138.01 | P10: 1 | Q10: 0 | R10: 0 | S10: 0 | T10: 0 | U10: =SUM(P10:T10) -> 1 | W10: =$N10*P10 -> 138.01 | X10: =$N10*Q10 -> 0 | Y10: =$N10*R10 -> 0 | Z10: =$N10*S10 -> 0 | AA10: =$N10*T10 -> 0
A11: NF | B11: 98 | C11: 4 | D11: 12042 | E11: Immax | F11: Oraculum Inteligência em Nutrição e Saúde Ltda - ME | G11: 21.213.714/0001-58 | H11: Desenvolvimento de receitas Immax | I11: Terceiros | J11: 42628 | K11: 9 | L11: 1 | M11: 12042 | N11: =M11*L11 -> 12042 | P11: 1 | Q11: 0 | R11: 0 | S11: 0 | T11: 0 | U11: =SUM(P11:T11) -> 1 | W11: =$N11*P11 -> 12042 | X11: =$N11*Q11 -> 0 | Y11: =$N11*R11 -> 0 | Z11: =$N11*S11 -> 0 | AA11: =$N11*T11 -> 0
A12: NF | B12: 11849 | C12: 5 | D12: 877.5 | E12: Immax | F12: Impressione Impressão Digital Ltda - ME | G12: 12.457.568/0001-15 | H12: Immax | I12: Material | J12: 42529 | K12: 6 | L12: 1 | M12: 877.5 | N12: =M12*L12 -> 877.5 | P12: 1 | Q12: 0 | R12: 0 | S12: 0 | T12: 0 | U12: =SUM(P12:T12) -> 1 | W12: =$N12*P12 -> 877.5 | X12: =$N12*Q12 -> 0 | Y12: =$N12*R12 -> 0 | Z12: =$N12*S12 -> 0 | AA12: =$N12*T12 -> 0
A13: NF | B13: 9354 | C13: 6 | D13: 1230 | E13: Immax | F13: Laboratório Alac Ltda | G13: 94.088.952/0001-52 | H13: Análise de micronutrientes Immax | I13: Terceiros | J13: 42587 | K13: 8 | L13: 1 | M13: 1230 | N13: =M13*L13 -> 1230 | P13: 1 | Q13: 0 | R13: 0 | S13: 0 | T13: 0 | U13: =SUM(P13:T13) -> 1 | W13: =$N13*P13 -> 1230 | X13: =$N13*Q13 -> 0 | Y13: =$N13*R13 -> 0 | Z13: =$N13*S13 -> 0 | AA13: =$N13*T13 -> 0
A14: NF | B14: 81028 | C14: 7 | D14: 2401 | E14: Immax | F14: Fundação de desenv. Da pesquisa do agronegócio - FUNDEPAG | G14: 50.276.237/0001-78 | H14: Análises físico-químicas Immax | I14: Terceiros | J14: 42565 | K14: 7 | L14: 1 | M14: 2401 | N14: =M14*L14 -> 2401 | P14: 1 | Q14: 0 | R14: 0 | S14: 0 | T14: 0 | U14: =SUM(P14:T14) -> 1 | W14: =$N14*P14 -> 2401 | X14: =$N14*Q14 -> 0 | Y14: =$N14*R14 -> 0 | Z14: =$N14*S14 -> 0 | AA14: =$N14*T14 -> 0
A15: NF | B15: 81357 | C15: 8 | D15: 2401 | E15: Immax | F15: Fundação de desenv. Da pesquisa do agronegócio - FUNDEPAG | G15: 50.276.237/0001-78 | H15: Análises físico-químicas Immax | I15: Terceiros | J15: 42585 | K15: 8 | L15: 1 | M15: 2401 | N15: =M15*L15 -> 2401 | P15: 1 | Q15: 0 | R15: 0 | S15: 0 | T15: 0 | U15: =SUM(P15:T15) -> 1 | W15: =$N15*P15 -> 2401 | X15: =$N15*Q15 -> 0 | Y15: =$N15*R15 -> 0 | Z15: =$N15*S15 -> 0 | AA15: =$N15*T15 -> 0
A16: NF | B16: 38 | C16: 9 | D16: 1000 | E16: Immax | F16: Sandra Marcia da Silva de Souza - ME | G16: 13.807.270/0001-50 | H16: Immax | I16: Material | J16: 42611 | K16: 8 | L16: 1 | M16: 1000 | N16: =M16*L16 -> 1000 | P16: 1 | Q16: 0 | R16: 0 | S16: 0 | T16: 0 | U16: =SUM(P16:T16) -> 1 | W16: =$N16*P16 -> 1000 | X16: =$N16*Q16 -> 0 | Y16: =$N16*R16 -> 0 | Z16: =$N16*S16 -> 0 | AA16: =$N16*T16 -> 0
A17: NF | B17: 48 | C17: 10 | D17: 89 | E17: Immax | F17: Sandra Marcia da Silva de Souza - ME | G17: 13.807.270/0001-50 | H17: Immax | I17: Material | J17: 42654 | K17: 10 | L17: 1 | M17: 89 | N17: =M17*L17 -> 89 | P17: 1 | Q17: 0 | R17: 0 | S17: 0 | T17: 0 | U17: =SUM(P17:T17) -> 1 | W17: =$N17*P17 -> 89 | X17: =$N17*Q17 -> 0 | Y17: =$N17*R17 -> 0 | Z17: =$N17*S17 -> 0 | AA17: =$N17*T17 -> 0
A18: NF | B18: 80303 | C18: 11 | D18: 524 | E18: Immax | F18: Fundação de desenv. Da pesquisa do agronegócio - FUNDEPAG | G18: 50.276.237/0001-78 | H18: Análise de ácidos graxos Immax | I18: Terceiros | J18: 42541 | K18: 6 | L18: 1 | M18: 524 | N18: =M18*L18 -> 524 | P18: 1 | Q18: 0 | R18: 0 | S18: 0 | T18: 0 | U18: =SUM(P18:T18) -> 1 | W18: =$N18*P18 -> 524 | X18: =$N18*Q18 -> 0 | Y18: =$N18*R18 -> 0 | Z18: =$N18*S18 -> 0 | AA18: =$N18*T18 -> 0
A19: NF | B19: 423 | C19: 12 | D19: 24000 | E19: Immax | F19: Clínica Médica Mourão Faccio S/S | G19: 04.404.467/0001-58 | H19: 1ª parcela do contrato de prestação de serviço estudo clínico Immax | I19: Terceiros | J19: 42608 | K19: 8 | L19: 1 | M19: 24000 | N19: =M19*L19 -> 24000 | P19: 1 | Q19: 0 | R19: 0 | S19: 0 | T19: 0 | U19: =SUM(P19:T19) -> 1 | W19: =$N19*P19 -> 24000 | X19: =$N19*Q19 -> 0 | Y19: =$N19*R19 -> 0 | Z19: =$N19*S19 -> 0 | AA19: =$N19*T19 -> 0
A20: NF | B20: 776332 | C20: 13 | D20: 105.6 | E20: Immax | F20: Contabilista Papelaria e informática | G20: 77.765.840/0001-70 | H20: Materiais | I20: Material | J20: 42633 | K20: 9 | L20: 1 | M20: 105.6 | N20: =M20*L20 -> 105.6 | P20: 1 | Q20: 0 | R20: 0 | S20: 0 | T20: 0 | U20: =SUM(P20:T20) -> 1 | W20: =$N20*P20 -> 105.6 | X20: =$N20*Q20 -> 0 | Y20: =$N20*R20 -> 0 | Z20: =$N20*S20 -> 0 | AA20: =$N20*T20 -> 0
A21: NF | B21: 5270 | C21: 14 | D21: 1323.55 | E21: Immax | F21: Medicalcom Hospitalares Eireli - ME | G21: 21.059.832/0001-53 | H21: Balança de controle corporal - estudo clínico Immax | I21: Material | J21: 42520 | K21: 5 | L21: 1 | M21: 1323.55 | N21: =M21*L21 -> 1323.55 | P21: 1 | Q21: 0 | R21: 0 | S21: 0 | T21: 0 | U21: =SUM(P21:T21) -> 1 | W21: =$N21*P21 -> 1323.55 | X21: =$N21*Q21 -> 0 | Y21: =$N21*R21 -> 0 | Z21: =$N21*S21 -> 0 | AA21: =$N21*T21 -> 0
A22: NF | B22: 6739 | C22: 15 | D22: 240 | E22: Leites terapêuticos | F22: Comercial Brey Ltda | G22: 02.608.645/0001-37 | H22: Seladora de bancada - Leites terapêuticos | I22: Material | J22: 42675 | K22: 11 | L22: 1 | M22: 240 | N22: =M22*L22 -> 240 | P22: 1 | Q22: 0 | R22: 0 | S22: 0 | T22: 0 | U22: =SUM(P22:T22) -> 1 | W22: =$N22*P22 -> 240 | X22: =$N22*Q22 -> 0 | Y22: =$N22*R22 -> 0 | Z22: =$N22*S22 -> 0 | AA22: =$N22*T22 -> 0
... A24: NF | B24: 2162 | C24: 17 | D24: 127.68 | E24: Alzheimer, Bemmax, Immax | F24: Nutrihealth Comercio de Produtos Alimentícios Eireli ME | G24: 14.492.128/0001-89 | H24: Compra de produtos concorrentes | I24: Material | J24: 42706 | K24: 12 | L24: 1 | M24: 127.68 | N24: =M24*L24 -> 127.68 | P24: 1 | Q24: 0 | R24: 0 | S24: 0 | T24: 0 | U24: =SUM(P24:T24) -> 1 | W24: =$N24*P24 -> 127.68 | X24: =$N24*Q24 -> 0 | Y24: =$N24*R24 -> 0 | Z24: =$N24*S24 -> 0 | AA24: =$N24*T24 -> 0
A25: Invoice | B25: 422135 | C25: 18 | D25: 41.25 | E25: Trophic Junior | F25: Covance - The Development Service Company | H25: Densidade volumétrica Trophic Junior | I25: Material | J25: 42605 | K25: 8 | L25: 1 | M25: 41.25 | N25: =M25*L25 -> 41.25 | P25: 1 | Q25: 0 | R25: 0 | S25: 0 | T25: 0 | U25: =SUM(P25:T25) -> 1 | W25: =$N25*P25 -> 41.25 | X25: =$N25*Q25 -> 0 | Y25: =$N25*R25 -> 0 | Z25: =$N25*S25 -> 0 | AA25: =$N25*T25 -> 0
A26: Expresso | B26: Conhec. Aéreo 9692285061 | C26: 19 | D26: 436.44 | E26: Trophic Junior | H26: Envio de amostras de T. Junior para o exterior (Stern) | I26: Material | J26: 42576 | K26: 7 | L26: 1 | M26: 436.44 | N26: =M26*L26 -> 436.44 | P26: 1 | Q26: 0 | R26: 0 | S26: 0 | T26: 0 | U26: =SUM(P26:T26) -> 1 | W26: =$N26*P26 -> 436.44 | X26: =$N26*Q26 -> 0 | Y26: =$N26*R26 -> 0 | Z26: =$N26*S26 -> 0 | AA26: =$N26*T26 -> 0
A27: NF | B27: 5542 | C27: 20 | D27: 3220 | E27: Trophic Junior e mix 16006 | F27: Laboratório Alac Ltda | G27: 94.088.952/0001-52 | H27: Análise de micronutrentes T. Junior (mix 16006) | I27: Terceiros | J27: 42506 | K27: 5 | L27: 0.357195 | M27: 3220 | N27: =M27*L27 -> 1150.1679 | P27: 0.5 | Q27: 0.5 | R27: 0 | S27: 0 | T27: 0 | U27: =SUM(P27:T27) -> 1 | W27: =$N27*P27 -> 575.08395 | X27: =$N27*Q27 -> 575.08395 | Y27: =$N27*R27 -> 0 | Z27: =$N27*S27 -> 0 | AA27: =$N27*T27 -> 0
A28: Fatura | B28: AWB 6152 6505 2282 | C28: 21 | D28: 107.33 | E28: Mix de minerais 16006 | F28: FedEx | G28: 00.676.486/0001-82 | H28: Recebimento de amostra de mix 16006 | I28: Material | J28: 42432 | K28: 3 | L28: 1 | M28: 107.33 | N28: =M28*L28 -> 107.33 | P28: 0 | Q28: 1 | R28: 0 | S28: 0 | T28: 0 | U28: =SUM(P28:T28) -> 1 | W28: =$N28*P28 -> 0 | X28: =$N28*Q28 -> 107.33 | Y28: =$N28*R28 -> 0 | Z28: =$N28*S28 -> 0 | AA28: =$N28*T28 -> 0
A29: NF | B29: 2177 | C29: 22 | D29: 415.6 | E29: PHA Costantino | F29: A. Costantino & C. spa | H29: Recebimento de amostra de PHA Costantino | I29: Material | J29: 42719 | K29: 12 | L29: 1 | M29: 415.6 | N29: =M29*L29 -> 415.6 | P29: 0 | Q29: 1 | R29: 0 | S29: 0 | T29: 0 | U29: =SUM(P29:T29) -> 1 | W29: =$N29*P29 -> 0 | X29: =$N29*Q29 -> 415.6 | Y29: =$N29*R29 -> 0 | Z29: =$N29*S29 -> 0 | AA29: =$N29*T29 -> 0
A30: NF | B30: 27824 | C30: 23 | D30: 950 | E30: Vital Rice | F30: Labor Tres Laboratórios e Consultoria Técnica Ltda | G30: 02.021.076/0001-29 | H30: Análises físico-químicas e microbiológicas Vital Rice | I30: Terceiros | J30: 42647 | K30: 10 | L30: 1 | M30: 950 | N30: =M30*L30 -> 950 | P30: 1 | Q30: 0 | R30: 0 | S30: 0 | T30: 0 | U30: =SUM(P30:T30) -> 1 | W30: =$N30*P30 -> 950 | X30: =$N30*Q30 -> 0 | Y30: =$N30*R30 -> 0 | Z30: =$N30*S30 -> 0 | AA30: =$N30*T30 -> 0
A31: Cupom fiscal | B31: 71047 | C31: 24 | D31: 77.49 | E31: Vital Rice Complete | F31: Callfarma | G31: 08.011.373/0001-70 | H31: Compra de produtos concorrentes | I31: Material | J31: 42664 | K31: 10 | L31: 1 | M31: 77.49 | N31: =M31*L31 -> 77.49 | P31: 1 | Q31: 0 | R31: 0 | S31: 0 | T31: 0 | U31: =SUM(P31:T31) -> 1 | W31: =$N31*P31 -> 77.49 | X31: =$N31*Q31 -> 0 | Y31: =$N31*R31 -> 0 | Z31: =$N31*S31 -> 0 | AA31: =$N31*T31 -> 0
A32: Recibo | B32: 2358 | C32: 25 | D32: 574 | E32: Vital Rice Complete | F32: Associação Paranaense de Cultura - APC | G32: 76.659.820/0003-13 | H32: Teste de bancada na PUC-PR | I32: Terceiros | J32: 42398 | K32: 1 | L32: 1 | M32: 574 | N32: =M32*L32 -> 574 | P32: 1 | Q32: 0 | R32: 0 | S32: 0 | T32: 0 | U32: =SUM(P32:T32) -> 1 | W32: =$N32*P32 -> 574 | X32: =$N32*Q32 -> 0 | Y32: =$N32*R32 -> 0 | Z32: =$N32*S32 -> 0 | AA32: =$N32*T32 -> 0
A33: Recibo | B33: 2389 | C33: 26 | D33: 210 | E33: Vital Rice Complete | F33: Associação Paranaense de Cultura - APC | G33: 76.659.820/0003-13 | H33: Teste de bancada na PUC-PR | I33: Terceiros | J33: 42416 | K33: 2 | L33: 1 | M33: 210 | N33: =M33*L33 -> 210 | P33: 1 | Q33: 0 | R33: 0 | S33: 0 | T33: 0 | U33: =SUM(P33:T33) -> 1 | W33: =$N33*P33 -> 210 | X33: =$N33*Q33 -> 0 | Y33: =$N33*R33 -> 0 | Z33: =$N33*S33 -> 0 | AA33: =$N33*T33 -> 0
A34: NF | B34: 7567 | C34: 27 | D34: 450 | E34: Vital Rice Complete | F34: Laboratório Alac Ltda | G34: 94.088.952/0001-52 | H34: Teste de alergênicos lecitina de soja em pó | I34: Terceiros | J34: 42548 | K34: 6 | L34: 1 | M34: 450 | N34: =M34*L34 -> 450 | P34: 1 | Q34: 0 | R34: 0 | S34: 0 | T34: 0 | U34: =SUM(P34:T34) -> 1 | W34: =$N34*P34 -> 450 | X34: =$N34*Q34 -> 0 | Y34: =$N34*R34 -> 0 | Z34: =$N34*S34 -> 0 | AA34: =$N34*T34 -> 0
A35: Cupons fiscais | C35: 28 | D35: 315.63 | E35: Feira de nutrição enteral | H35: Gastos em Feira de Nutrição Enteral (Felanpe) para prospecção de novos projetos | I35: Material | J35: 42667 | K35: 10 | L35: 1 | M35: 315.63 | N35: =M35*L35 -> 315.63 | P35: 1 | Q35: 0 | R35: 0 | S35: 0 | T35: 0 | U35: =SUM(P35:T35) -> 1 | W35: =$N35*P35 -> 315.63 | X35: =$N35*Q35 -> 0 | Y35: =$N35*R35 -> 0 | Z35: =$N35*S35 -> 0 | AA35: =$N35*T35 -> 0
A36: NF | B36: 158262 | C36: 29 | D36: 25.18 | E36: Caseinato de cálcio Fonterra | F36: Castrolanda | G36: 76.108.349/0014-28 | H36: Envio de 24 amostras de T. Fiber para a Prodiet | I36: Material | J36: 42554 | K36: 7 | L36: 1 | M36: 25.18 | N36: =M36*L36 -> 25.18 | P36: 0 | Q36: 1 | R36: 0 | S36: 0 | T36: 0 | U36: =SUM(P36:T36) -> 1 | W36: =$N36*P36 -> 0 | X36: =$N36*Q36 -> 25.18 | Y36: =$N36*R36 -> 0 | Z36: =$N36*S36 -> 0 | AA36: =$N36*T36 -> 0
A37: NF | B37: 84232 | C37: 30 | D37: 956.4 | E37: Immax, L-leucina | F37: Fundação de desenv. Da pesquisa do agronegócio - FUNDEPAG | G37: 50.276.237/0001-78 | H37: Análises físico-químicas Immax | I37: Terceiros | J37: 42681 | K37: 11 | L37: 1 | M37: 956.4 | N37: =M37*L37 -> 956.4 | P37: 0.5 | Q37: 0.5 | R37: 0 | S37: 0 | T37: 0 | U37: =SUM(P37:T37) -> 1 | W37: =$N37*P37 -> 478.2 | X37: =$N37*Q37 -> 478.2 | Y37: =$N37*R37 -> 0 | Z37: =$N37*S37 -> 0 | AA37: =$N37*T37 -> 0
A38: NF | B38: 15516 | C38: 31 | D38: 1772.25 | E38: Mix 150243, PHA Friesl, T. Infant | F38: Laboratório Alac Ltda | G38: 94.088.952/0001-52 | H38: Análises vitaminas T. Infant nova fórmula; alergênico PHA | I38: Terceiros | J38: 42733 | K38: 12 | L38: 1 | M38: 1772.25 | N38: =M38*L38 -> 1772.25 | P38: 0 | Q38: 0.66666667 | R38: 0.33333333 | S38: 0 | T38: 0 | U38: =SUM(P38:T38) -> 1 | W38: =$N38*P38 -> 0 | X38: =$N38*Q38 -> 1181.5 | Y38: =$N38*R38 -> 590.75 | Z38: =$N38*S38 -> 0 | AA38: =$N38*T38 -> 0
A39: NF | B39: 27583 | C39: 32 | D39: 305 | E39: T. Infant, MPC Fonterra, Loremalt 2030M, Açúcar K, mix 150243 | F39: Labor Tres Laboratórios e Consultoria Técnica Ltda | G39: 02.021.076/0001-29 | H39: FQ T. Infant nova fórmula | I39: Terceiros | J39: 42615 | K39: 9 | L39: 1 | M39: 305 | N39: =M39*L39 -> 305 | P39: 0 | Q39: 0.8 | R39: 0.2 | S39: 0 | T39: 0 | U39: =SUM(P39:T39) -> 1 | W39: =$N39*P39 -> 0 | X39: =$N39*Q39 -> 244 | Y39: =$N39*R39 -> 61 | Z39: =$N39*S39 -> 0 | AA39: =$N39*T39 -> 0
A40: NF | B40: 13354 | C40: 33 | D40: 1344.25 | E40: T. EP e mix 152349 | F40: Laboratório Alac Ltda | G40: 94.088.952/0001-52 | H40: Analisa os testes dos produtos e dá assistência na parametrização do produto e dos novos testes a serem feitos. Faz acompanhamento técnico de todos os projetos de pesquisa e desenvolvimento. | I40: Terceiros | J40: 42683 | K40: 11 | L40: 1 | M40: 1344.25 | N40: =M40*L40 -> 1344.25 | P40: 0 | Q40: 0.5 | R40: 0.5 | S40: 0 | T40: 0 | U40: =SUM(P40:T40) -> 1 | W40: =$N40*P40 -> 0 | X40: =$N40*Q40 -> 672.125 | Y40: =$N40*R40 -> 672.125 | Z40: =$N40*S40 -> 0 | AA40: =$N40*T40 -> 0
A41: NF | B41: 8891 | C41: 34 | D41: 4254.3 | E41: Bio e Pept. (red. Na e P); T. Junior, mix 16006, mix 151160 | F41: Laboratório Alac Ltda | G41: 94.088.952/0001-52 | H41: Análises micronut. Bio, Pept., T. Fiber e T. Junior | I41: Terceiros | J41: 42578 | K41: 7 | L41: 1 | M41: 4254.3 | N41: =M41*L41 -> 4254.3 | P41: 0.04 | Q41: 0.08 | R41: 0.88 | S41: 0 | T41: 0 | U41: =SUM(P41:T41) -> 1 | W41: =$N41*P41 -> 170.172 | X41: =$N41*Q41 -> 340.344 | Y41: =$N41*R41 -> 3743.784 | Z41: =$N41*S41 -> 0 | AA41: =$N41*T41 -> 0
...

Sheet (a) Investimentos (2)
A1: PRODIET
A2: Anexo II - Investimentos - Terceiros
A3: INOVAÇÃO TECNOLÓGICA 2016 | J3: Valores
I4: Material | J4: =SUMIF($I$8:$I$115,I4,$N$8:$N$115) -> 16180.07
I5: Terceiros | J5: =SUMIF($I$8:$I$115,I5,$N$8:$N$115) -> 257166.12
D6: =SUBTOTAL(9,D8:D114) -> 632430.95 | N6: =SUBTOTAL(9,N8:N114) -> 257166.12 | P6: Participação nos projetos | U6: =SUM(U8:U90)/COUNT(U8:U90) -> 1 | W6: Dispêndio (R$) por projeto
A7: Tipo | B7: Documento | C7: Controle DOCS | D7: Total NF | E7: PRODUTOS | F7: RECURSO | G7: CPF / CNPJ | H7: ATIVIDADE | I7: NATUREZA | J7: DATA | K7: Mês | L7: QTD | M7: UNITÁRIO | N7: TOTAL | P7: Novos Produtos | Q7: Novas matérias-primas | R7: Melhoria de Produto | S7: Melhoria de Processo | T7: ILSI | U7: Total | W7: Novos Produtos | X7: Novas matérias-primas | Y7: Melhoria de Produto | Z7: Melhoria de Processo | AA7: ILSI
A8: NF | B8: 34840 | C8: 1 | D8: 1303.4 | E8: Bemmax, Peptimax | F8: Bioagri Analises de alimentos Ltda | G8: 00.000.410/0001-32 | H8: Análise de ácidos graxos | I8: Terceiros | J8: 42500 | K8: 5 | L8: 1 | M8: 1303.4 | N8: =M8*L8 -> 1303.4 | P8: 0.5 | Q8: 0 | R8: 0 | S8: 0.5 | T8: 0 | U8: =SUM(P8:T8) -> 1 | W8: =$N8*P8 -> 651.7 | X8: =$N8*Q8 -> 0 | Y8: =$N8*R8 -> 0 | Z8: =$N8*S8 -> 651.7 | AA8: =$N8*T8 -> 0
A9: Bilhete e-ticket | B9: 577 0005868279 | C9: 2 | D9: 579.24 | E9: Immax | F9: Azul linhas aéreas | H9: Passagens Hellin IDA e VOLTA Ribeirão Preto | I9: Material | J9: 42641 | K9: 9 | L9: 1 | M9: 579.24 | N9: =M9*L9 -> 579.24 | P9: 1 | Q9: 0 | R9: 0 | S9: 0 | T9: 0 | U9: =SUM(P9:T9) -> 1 | W9: =$N9*P9 -> 579.24 | X9: =$N9*Q9 -> 0 | Y9: =$N9*R9 -> 0 | Z9: =$N9*S9 -> 0 | AA9: =$N9*T9 -> 0
A10: Cupons fiscais | C10: 2 | D10: 138.01 | E10: Immax | F10: Diversos | H10: Alimentação e táxi Hellin Ribeirão Preto | I10: Material | J10: 42641 | K10: 9 | L10: 1 | M10: 138.01 | N10: =M10*L10 -> 138.01 | P10: 1 | Q10: 0 | R10: 0 | S10: 0 | T10: 0 | U10: =SUM(P10:T10) -> 1 | W10: =$N10*P10 -> 138.01 | X10: =$N10*Q10 -> 0 | Y10: =$N10*R10 -> 0 | Z10: =$N10*S10 -> 0 | AA10: =$N10*T10 -> 0
A11: NF | B11: 98 | C11: 4 | D11: 12042 | E11: Immax | F11: Oraculum Inteligência em Nutrição e Saúde Ltda - ME | G11: 21.213.714/0001-58 | H11: Desenvolvimento de receitas Immax | I11: Terceiros | J11: 42628 | K11: 9 | L11: 1 | M11: 12042 | N11: =M11*L11 -> 12042 | P11: 1 | Q11: 0 | R11: 0 | S11: 0 | T11: 0 | U11: =SUM(P11:T11) -> 1 | W11: =$N11*P11 -> 12042 | X11: =$N11*Q11 -> 0 | Y11: =$N11*R11 -> 0 | Z11: =$N11*S11 -> 0 | AA11: =$N11*T11 -> 0
A12: NF | B12: 11849 | C12: 5 | D12: 877.5 | E12: Immax | F12: Impressione Impressão Digital Ltda - ME | G12: 12.457.568/0001-15 | H12: Immax | I12: Material | J12: 42529 | K12: 6 | L12: 1 | M12: 877.5 | N12: =M12*L12 -> 877.5 | P12: 1 | Q12: 0 | R12: 0 | S12: 0 | T12: 0 | U12: =SUM(P12:T12) -> 1 | W12: =$N12*P12 -> 877.5 | X12: =$N12*Q12 -> 0 | Y12: =$N12*R12 -> 0 | Z12: =$N12*S12 -> 0 | AA12: =$N12*T12 -> 0
A13: NF | B13: 9354 | C13: 6 | D13: 1230 | E13: Immax | F13: Laboratório Alac Ltda | G13: 94.088.952/0001-52 | H13: Análise de micronutrientes Immax | I13: Terceiros | J13: 42587 | K13: 8 | L13: 1 | M13: 1230 | N13: =M13*L13 -> 1230 | P13: 1 | Q13: 0 | R13: 0 | S13: 0 | T13: 0 | U13: =SUM(P13:T13) -> 1 | W13: =$N13*P13 -> 1230 | X13: =$N13*Q13 -> 0 | Y13: =$N13*R13 -> 0 | Z13: =$N13*S13 -> 0 | AA13: =$N13*T13 -> 0
A14: NF | B14: 81028 | C14: 7 | D14: 2401 | E14: Immax | F14: Fundação de desenv. Da pesquisa do agronegócio - FUNDEPAG | G14: 50.276.237/0001-78 | H14: Análises físico-químicas Immax | I14: Terceiros | J14: 42565 | K14: 7 | L14: 1 | M14: 2401 | N14: =M14*L14 -> 2401 | P14: 1 | Q14: 0 | R14: 0 | S14: 0 | T14: 0 | U14: =SUM(P14:T14) -> 1 | W14: =$N14*P14 -> 2401 | X14: =$N14*Q14 -> 0 | Y14: =$N14*R14 -> 0 | Z14: =$N14*S14 -> 0 | AA14: =$N14*T14 -> 0
A15: NF | B15: 81357 | C15: 8 | D15: 2401 | E15: Immax | F15: Fundação de desenv. Da pesquisa do agronegócio - FUNDEPAG | G15: 50.276.237/0001-78 | H15: Análises físico-químicas Immax | I15: Terceiros | J15: 42585 | K15: 8 | L15: 1 | M15: 2401 | N15: =M15*L15 -> 2401 | P15: 1 | Q15: 0 | R15: 0 | S15: 0 | T15: 0 | U15: =SUM(P15:T15) -> 1 | W15: =$N15*P15 -> 2401 | X15: =$N15*Q15 -> 0 | Y15: =$N15*R15 -> 0 | Z15: =$N15*S15 -> 0 | AA15: =$N15*T15 -> 0
A16: NF | B16: 38 | C16: 9 | D16: 1000 | E16: Immax | F16: Sandra Marcia da Silva de Souza - ME | G16: 13.807.270/0001-50 | H16: Immax | I16: Material | J16: 42611 | K16: 8 | L16: 1 | M16: 1000 | N16: =M16*L16 -> 1000 | P16: 1 | Q16: 0 | R16: 0 | S16: 0 | T16: 0 | U16: =SUM(P16:T16) -> 1 | W16: =$N16*P16 -> 1000 | X16: =$N16*Q16 -> 0 | Y16: =$N16*R16 -> 0 | Z16: =$N16*S16 -> 0 | AA16: =$N16*T16 -> 0
A17: NF | B17: 48 | C17: 10 | D17: 89 | E17: Immax | F17: Sandra Marcia da Silva de Souza - ME | G17: 13.807.270/0001-50 | H17: Immax | I17: Material | J17: 42654 | K17: 10 | L17: 1 | M17: 89 | N17: =M17*L17 -> 89 | P17: 1 | Q17: 0 | R17: 0 | S17: 0 | T17: 0 | U17: =SUM(P17:T17) -> 1 | W17: =$N17*P17 -> 89 | X17: =$N17*Q17 -> 0 | Y17: =$N17*R17 -> 0 | Z17: =$N17*S17 -> 0 | AA17: =$N17*T17 -> 0
A18: NF | B18: 80303 | C18: 11 | D18: 524 | E18: Immax | F18: Fundação de desenv. Da pesquisa do agronegócio - FUNDEPAG | G18: 50.276.237/0001-78 | H18: Análise de ácidos graxos Immax | I18: Terceiros | J18: 42541 | K18: 6 | L18: 1 | M18: 524 | N18: =M18*L18 -> 524 | P18: 1 | Q18: 0 | R18: 0 | S18: 0 | T18: 0 | U18: =SUM(P18:T18) -> 1 | W18: =$N18*P18 -> 524 | X18: =$N18*Q18 -> 0 | Y18: =$N18*R18 -> 0 | Z18: =$N18*S18 -> 0 | AA18: =$N18*T18 -> 0
A19: NF | B19: 423 | C19: 12 | D19: 24000 | E19: Immax | F19: Clínica Médica Mourão Faccio S/S | G19: 04.404.467/0001-58 | H19: 1ª parcela do contrato de prestação de serviço estudo clínico Immax | I19: Terceiros | J19: 42608 | K19: 8 | L19: 1 | M19: 24000 | N19: =M19*L19 -> 24000 | P19: 1 | Q19: 0 | R19: 0 | S19: 0 | T19: 0 | U19: =SUM(P19:T19) -> 1 | W19: =$N19*P19 -> 24000 | X19: =$N19*Q19 -> 0 | Y19: =$N19*R19 -> 0 | Z19: =$N19*S19 -> 0 | AA19: =$N19*T19 -> 0
A20: NF | B20: 776332 | C20: 13 | D20: 105.6 | E20: Immax | F20: Contabilista Papelaria e informática | G20: 77.765.840/0001-70 | H20: Materiais | I20: Material | J20: 42633 | K20: 9 | L20: 1 | M20: 105.6 | N20: =M20*L20 -> 105.6 | P20: 1 | Q20: 0 | R20: 0 | S20: 0 | T20: 0 | U20: =SUM(P20:T20) -> 1 | W20: =$N20*P20 -> 105.6 | X20: =$N20*Q20 -> 0 | Y20: =$N20*R20 -> 0 | Z20: =$N20*S20 -> 0 | AA20: =$N20*T20 -> 0
A21: NF | B21: 5270 | C21: 14 | D21: 1323.55 | E21: Immax | F21: Medicalcom Hospitalares Eireli - ME | G21: 21.059.832/0001-53 | H21: Balança de controle corporal - estudo clínico Immax | I21: Material | J21: 42520 | K21: 5 | L21: 1 | M21: 1323.55 | N21: =M21*L21 -> 1323.55 | P21: 1 | Q21: 0 | R21: 0 | S21: 0 | T21: 0 | U21: =SUM(P21:T21) -> 1 | W21: =$N21*P21 -> 1323.55 | X21: =$N21*Q21 -> 0 | Y21: =$N21*R21 -> 0 | Z21: =$N21*S21 -> 0 | AA21: =$N21*T21 -> 0
A22: NF | B22: 6739 | C22: 15 | D22: 240 | E22: Leites terapêuticos | F22: Comercial Brey Ltda | G22: 02.608.645/0001-37 | H22: Seladora de bancada - Leites terapêuticos | I22: Material | J22: 42675 | K22: 11 | L22: 1 | M22: 240 | N22: =M22*L22 -> 240 | P22: 1 | Q22: 0 | R22: 0 | S22: 0 | T22: 0 | U22: =SUM(P22:T22) -> 1 | W22: =$N22*P22 -> 240 | X22: =$N22*Q22 -> 0 | Y22: =$N22*R22 -> 0 | Z22: =$N22*S22 -> 0 | AA22: =$N22*T22 -> 0
... A24: NF | B24: 2162 | C24: 17 | D24: 127.68 | E24: Alzheimer, Bemmax, Immax | F24: Nutrihealth Comercio de Produtos Alimentícios Eireli ME | G24: 14.492.128/0001-89 | H24: Compra de produtos concorrentes | I24: Material | J24: 42706 | K24: 12 | L24: 1 | M24: 127.68 | N24: =M24*L24 -> 127.68 | P24: 1 | Q24: 0 | R24: 0 | S24: 0 | T24: 0 | U24: =SUM(P24:T24) -> 1 | W24: =$N24*P24 -> 127.68 | X24: =$N24*Q24 -> 0 | Y24: =$N24*R24 -> 0 | Z24: =$N24*S24 -> 0 | AA24: =$N24*T24 -> 0
A25: Invoice | B25: 422135 | C25: 18 | D25: 41.25 | E25: Trophic Junior | F25: Covance - The Development Service Company | H25: Densidade volumétrica Trophic Junior | I25: Material | J25: 42605 | K25: 8 | L25: 1 | M25: 41.25 | N25: =M25*L25 -> 41.25 | P25: 1 | Q25: 0 | R25: 0 | S25: 0 | T25: 0 | U25: =SUM(P25:T25) -> 1 | W25: =$N25*P25 -> 41.25 | X25: =$N25*Q25 -> 0 | Y25: =$N25*R25 -> 0 | Z25: =$N25*S25 -> 0 | AA25: =$N25*T25 -> 0
A26: Expresso | B26: Conhec. Aéreo 9692285061 | C26: 19 | D26: 436.44 | E26: Trophic Junior | H26: Envio de amostras de T. Junior para o exterior (Stern) | I26: Material | J26: 42576 | K26: 7 | L26: 1 | M26: 436.44 | N26: =M26*L26 -> 436.44 | P26: 1 | Q26: 0 | R26: 0 | S26: 0 | T26: 0 | U26: =SUM(P26:T26) -> 1 | W26: =$N26*P26 -> 436.44 | X26: =$N26*Q26 -> 0 | Y26: =$N26*R26 -> 0 | Z26: =$N26*S26 -> 0 | AA26: =$N26*T26 -> 0
A27: NF | B27: 5542 | C27: 20 | D27: 3220 | E27: Trophic Junior e mix 16006 | F27: Laboratório Alac Ltda | G27: 94.088.952/0001-52 | H27: Análise de micronutrentes T. Junior (mix 16006) | I27: Terceiros | J27: 42506 | K27: 5 | L27: 0.357195 | M27: 3220 | N27: =M27*L27 -> 1150.1679 | P27: 0.5 | Q27: 0.5 | R27: 0 | S27: 0 | T27: 0 | U27: =SUM(P27:T27) -> 1 | W27: =$N27*P27 -> 575.08395 | X27: =$N27*Q27 -> 575.08395 | Y27: =$N27*R27 -> 0 | Z27: =$N27*S27 -> 0 | AA27: =$N27*T27 -> 0
A28: Fatura | B28: AWB 6152 6505 2282 | C28: 21 | D28: 107.33 | E28: Mix de minerais 16006 | F28: FedEx | G28: 00.676.486/0001-82 | H28: Recebimento de amostra de mix 16006 | I28: Material | J28: 42432 | K28: 3 | L28: 1 | M28: 107.33 | N28: =M28*L28 -> 107.33 | P28: 0 | Q28: 1 | R28: 0 | S28: 0 | T28: 0 | U28: =SUM(P28:T28) -> 1 | W28: =$N28*P28 -> 0 | X28: =$N28*Q28 -> 107.33 | Y28: =$N28*R28 -> 0 | Z28: =$N28*S28 -> 0 | AA28: =$N28*T28 -> 0
A29: NF | B29: 2177 | C29: 22 | D29: 415.6 | E29: PHA Costantino | F29: A. Costantino & C. spa | H29: Recebimento de amostra de PHA Costantino | I29: Material | J29: 42719 | K29: 12 | L29: 1 | M29: 415.6 | N29: =M29*L29 -> 415.6 | P29: 0 | Q29: 1 | R29: 0 | S29: 0 | T29: 0 | U29: =SUM(P29:T29) -> 1 | W29: =$N29*P29 -> 0 | X29: =$N29*Q29 -> 415.6 | Y29: =$N29*R29 -> 0 | Z29: =$N29*S29 -> 0 | AA29: =$N29*T29 -> 0
A30: NF | B30: 27824 | C30: 23 | D30: 950 | E30: Vital Rice | F30: Labor Tres Laboratórios e Consultoria Técnica Ltda | G30: 02.021.076/0001-29 | H30: Análises físico-químicas e microbiológicas Vital Rice | I30: Terceiros | J30: 42647 | K30: 10 | L30: 1 | M30: 950 | N30: =M30*L30 -> 950 | P30: 1 | Q30: 0 | R30: 0 | S30: 0 | T30: 0 | U30: =SUM(P30:T30) -> 1 | W30: =$N30*P30 -> 950 | X30: =$N30*Q30 -> 0 | Y30: =$N30*R30 -> 0 | Z30: =$N30*S30 -> 0 | AA30: =$N30*T30 -> 0
A31: Cupom fiscal | B31: 71047 | C31: 24 | D31: 77.49 | E31: Vital Rice Complete | F31: Callfarma | G31: 08.011.373/0001-70 | H31: Compra de produtos concorrentes | I31: Material | J31: 42664 | K31: 10 | L31: 1 | M31: 77.49 | N31: =M31*L31 -> 77.49 | P31: 1 | Q31: 0 | R31: 0 | S31: 0 | T31: 0 | U31: =SUM(P31:T31) -> 1 | W31: =$N31*P31 -> 77.49 | X31: =$N31*Q31 -> 0 | Y31: =$N31*R31 -> 0 | Z31: =$N31*S31 -> 0 | AA31: =$N31*T31 -> 0
A32: Recibo | B32: 2358 | C32: 25 | D32: 574 | E32: Vital Rice Complete | F32: Associação Paranaense de Cultura - APC | G32: 76.659.820/0003-13 | H32: Teste de bancada na PUC-PR | I32: Terceiros | J32: 42398 | K32: 1 | L32: 1 | M32: 574 | N32: =M32*L32 -> 574 | P32: 1 | Q32: 0 | R32: 0 | S32: 0 | T32: 0 | U32: =SUM(P32:T32) -> 1 | W32: =$N32*P32 -> 574 | X32: =$N32*Q32 -> 0 | Y32: =$N32*R32 -> 0 | Z32: =$N32*S32 -> 0 | AA32: =$N32*T32 -> 0
A33: Recibo | B33: 2389 | C33: 26 | D33: 210 | E33: Vital Rice Complete | F33: Associação Paranaense de Cultura - APC | G33: 76.659.820/0003-13 | H33: Teste de bancada na PUC-PR | I33: Terceiros | J33: 42416 | K33: 2 | L33: 1 | M33: 210 | N33: =M33*L33 -> 210 | P33: 1 | Q33: 0 | R33: 0 | S33: 0 | T33: 0 | U33: =SUM(P33:T33) -> 1 | W33: =$N33*P33 -> 210 | X33: =$N33*Q33 -> 0 | Y33: =$N33*R33 -> 0 | Z33: =$N33*S33 -> 0 | AA33: =$N33*T33 -> 0
A34: NF | B34: 7567 | C34: 27 | D34: 450 | E34: Vital Rice Complete | F34: Laboratório Alac Ltda | G34: 94.088.952/0001-52 | H34: Teste de alergênicos lecitina de soja em pó | I34: Terceiros | J34: 42548 | K34: 6 | L34: 1 | M34: 450 | N34: =M34*L34 -> 450 | P34: 1 | Q34: 0 | R34: 0 | S34: 0 | T34: 0 | U34: =SUM(P34:T34) -> 1 | W34: =$N34*P34 -> 450 | X34: =$N34*Q34 -> 0 | Y34: =$N34*R34 -> 0 | Z34: =$N34*S34 -> 0 | AA34: =$N34*T34 -> 0
A35: Cupons fiscais | C35: 28 | D35: 315.63 | E35: Feira de nutrição enteral | H35: Gastos em Feira de Nutrição Enteral (Felanpe) para prospecção de novos projetos | I35: Material | J35: 42667 | K35: 10 | L35: 1 | M35: 315.63 | N35: =M35*L35 -> 315.63 | P35: 1 | Q35: 0 | R35: 0 | S35: 0 | T35: 0 | U35: =SUM(P35:T35) -> 1 | W35: =$N35*P35 -> 315.63 | X35: =$N35*Q35 -> 0 | Y35: =$N35*R35 -> 0 | Z35: =$N35*S35 -> 0 | AA35: =$N35*T35 -> 0
A36: NF | B36: 158262 | C36: 29 | D36: 25.18 | E36: Caseinato de cálcio Fonterra | F36: Castrolanda | G36: 76.108.349/0014-28 | H36: Envio de 24 amostras de T. Fiber para a Prodiet | I36: Material | J36: 42554 | K36: 7 | L36: 1 | M36: 25.18 | N36: =M36*L36 -> 25.18 | P36: 0 | Q36: 1 | R36: 0 | S36: 0 | T36: 0 | U36: =SUM(P36:T36) -> 1 | W36: =$N36*P36 -> 0 | X36: =$N36*Q36 -> 25.18 | Y36: =$N36*R36 -> 0 | Z36: =$N36*S36 -> 0 | AA36: =$N36*T36 -> 0
A37: NF | B37: 84232 | C37: 30 | D37: 956.4 | E37: Immax, L-leucina | F37: Fundação de desenv. Da pesquisa do agronegócio - FUNDEPAG | G37: 50.276.237/0001-78 | H37: Análises físico-químicas Immax | I37: Terceiros | J37: 42681 | K37: 11 | L37: 1 | M37: 956.4 | N37: =M37*L37 -> 956.4 | P37: 0.5 | Q37: 0.5 | R37: 0 | S37: 0 | T37: 0 | U37: =SUM(P37:T37) -> 1 | W37: =$N37*P37 -> 478.2 | X37: =$N37*Q37 -> 478.2 | Y37: =$N37*R37 -> 0 | Z37: =$N37*S37 -> 0 | AA37: =$N37*T37 -> 0
A38: NF | B38: 15516 | C38: 31 | D38: 1772.25 | E38: Mix 150243, PHA Friesl, T. Infant | F38: Laboratório Alac Ltda | G38: 94.088.952/0001-52 | H38: Análises vitaminas T. Infant nova fórmula; alergênico PHA | I38: Terceiros | J38: 42733 | K38: 12 | L38: 1 | M38: 1772.25 | N38: =M38*L38 -> 1772.25 | P38: 0 | Q38: 0.66666667 | R38: 0.33333333 | S38: 0 | T38: 0 | U38: =SUM(P38:T38) -> 1 | W38: =$N38*P38 -> 0 | X38: =$N38*Q38 -> 1181.5 | Y38: =$N38*R38 -> 590.75 | Z38: =$N38*S38 -> 0 | AA38: =$N38*T38 -> 0
A39: NF | B39: 27583 | C39: 32 | D39: 305 | E39: T. Infant, MPC Fonterra, Loremalt 2030M, Açúcar K, mix 150243 | F39: Labor Tres Laboratórios e Consultoria Técnica Ltda | G39: 02.021.076/0001-29 | H39: FQ T. Infant nova fórmula | I39: Terceiros | J39: 42615 | K39: 9 | L39: 1 | M39: 305 | N39: =M39*L39 -> 305 | P39: 0 | Q39: 0.8 | R39: 0.2 | S39: 0 | T39: 0 | U39: =SUM(P39:T39) -> 1 | W39: =$N39*P39 -> 0 | X39: =$N39*Q39 -> 244 | Y39: =$N39*R39 -> 61 | Z39: =$N39*S39 -> 0 | AA39: =$N39*T39 -> 0
A40: NF | B40: 13354 | C40: 33 | D40: 1344.25 | E40: T. EP e mix 152349 | F40: Laboratório Alac Ltda | G40: 94.088.952/0001-52 | H40: Analisa os testes dos produtos e dá assistência na parametrização do produto e dos novos testes a serem feitos. Faz acompanhamento técnico de todos os projetos de pesquisa e desenvolvimento. | I40: Terceiros | J40: 42683 | K40: 11 | L40: 1 | M40: 1344.25 | N40: =M40*L40 -> 1344.25 | P40: 0 | Q40: 0.5 | R40: 0.5 | S40: 0 | T40: 0 | U40: =SUM(P40:T40) -> 1 | W40: =$N40*P40 -> 0 | X40: =$N40*Q40 -> 672.125 | Y40: =$N40*R40 -> 672.125 | Z40: =$N40*S40 -> 0 | AA40: =$N40*T40 -> 0
A41: NF | B41: 8891 | C41: 34 | D41: 4254.3 | E41: Bio e Pept. (red. Na e P); T. Junior, mix 16006, mix 151160 | F41: Laboratório Alac Ltda | G41: 94.088.952/0001-52 | H41: Análises micronut. Bio, Pept., T. Fiber e T. Junior | I41: Terceiros | J41: 42578 | K41: 7 | L41: 1 | M41: 4254.3 | N41: =M41*L41 -> 4254.3 | P41: 0.04 | Q41: 0.08 | R41: 0.88 | S41: 0 | T41: 0 | U41: =SUM(P41:T41) -> 1 | W41: =$N41*P41 -> 170.172 | X41: =$N41*Q41 -> 340.344 | Y41: =$N41*R41 -> 3743.784 | Z41: =$N41*S41 -> 0 | AA41: =$N41*T41 -> 0
...

Sheet (b) Timesheet consolidado
A1: PRODIET
A2: Anexo III - Timesheets consolidados
A3: INOVAÇÃO TECNOLÓGICA 2016
A4: Apontamento de horas [e cálculo do custo] do pessoal com dedicação parcial à inovação tecnológica
F7: =SUBTOTAL(9,F9:F71) -> 8.7458333 | G7: =SUBTOTAL(9,G9:G71) -> 209.9 | K7: =SUBTOTAL(9,K9:K71) -> 6980.2545
A8: Funcionário | B8: Projeto | C8: Data | D8: Início | E8: Fim | F8: Horas totais | G8: Horas totais [2] | H8: Descrição | I8: Mês | J8: Custo/Hora | K8: Custo Total
A9: Franciele Guedes | B9: Bemmax | C9: 42415 | D9: 0.34375 | E9: 0.75 | F9: =E9-D9 -> 0.40625 | G9: =F9*24 -> 9.75 | H9: Pesagem | I9: =MONTH(C9) -> 2 | J9: =VLOOKUP(A9,Salários!$A$35:$P$42,I9+4,FALSE) -> 31.118786 | K9: =J9*G9 -> 303.40817
A10: Franciele Guedes | B10: Bemmax | C10: 42416 | D10: 0.34375 | E10: 0.41666667 | F10: =E10-D10 -> 0.072916667 | G10: =F10*24 -> 1.75 | H10: Pesagem | I10: =MONTH(C10) -> 2 | J10: =VLOOKUP(A10,Salários!$A$35:$P$42,I10+4,FALSE) -> 31.118786 | K10: =J10*G10 -> 54.457876
A11: Franciele Guedes | B11: Bemmax | C11: 42436 | D11: 0.29861111 | E11: 0.70833333 | F11: =E11-D11 -> 0.40972222 | G11: =F11*24 -> 9.8333333 | H11: Produção | I11: =MONTH(C11) -> 3 | J11: =VLOOKUP(A11,Salários!$A$35:$P$42,I11+4,FALSE) -> 27.059814 | K11: =J11*G11 -> 266.08817
A12: Franciele Guedes | B12: Trophic Junior | C12: 42458 | D12: 0.47569444 | E12: 0.52083333 | F12: =E12-D12 -> 0.045138889 | G12: =F12*24 -> 1.0833333 | H12: Pesagem | I12: =MONTH(C12) -> 3 | J12: =VLOOKUP(A12,Salários!$A$35:$P$42,I12+4,FALSE) -> 27.059814 | K12: =J12*G12 -> 29.314799
A13: Franciele Guedes | B13: Trophic Basic - primeira produção Prodiet | C13: 42468 | D13: 0.34375 | E13: 0.75 | F13: =E13-D13 -> 0.40625 | G13: =F13*24 -> 9.75 | H13: Pesagem | I13: =MONTH(C13) -> 4 | J13: =VLOOKUP(A13,Salários!$A$35:$P$42,I13+4,FALSE) -> 31.118786 | K13: =J13*G13 -> 303.40817
A14: Franciele Guedes | B14: Trophic Basic - primeira produção Prodiet | C14: 42472 | D14: 0.35763889 | E14: 0.43055556 | F14: =E14-D14 -> 0.072916667 | G14: =F14*24 -> 1.75 | H14: Pesagem | I14: =MONTH(C14) -> 4 | J14: =VLOOKUP(A14,Salários!$A$35:$P$42,I14+4,FALSE) -> 31.118786 | K14: =J14*G14 -> 54.457876
A15: Franciele Guedes | B15: Trophic Basic - primeira produção Prodiet | C15: 42480 | D15: 0.65972222 | E15: 0.78125 | F15: =E15-D15 -> 0.12152778 | G15: =F15*24 -> 2.9166667 | H15: Produção | I15: =MONTH(C15) -> 4 | J15: =VLOOKUP(A15,Salários!$A$35:$P$42,I15+4,FALSE) -> 31.118786 | K15: =J15*G15 -> 90.763127
A16: Franciele Guedes | B16: Immax | C16: 42521 | D16: 0.58333333 | E16: 0.75 | F16: =E16-D16 -> 0.16666667 | G16: =F16*24 -> 4 | H16: Pesagem | I16: =MONTH(C16) -> 5 | J16: =VLOOKUP(A16,Salários!$A$35:$P$42,I16+4,FALSE) -> 28.289806 | K16: =J16*G16 -> 113.15922
A17: Franciele Guedes | B17: Immax | C17: 42522 | D17: 0.45138889 | E17: 0.5375 | F17: =E17-D17 -> 0.086111111 | G17: =F17*24 -> 2.0666667 | H17: Piloto pó | I17: =MONTH(C17) -> 6 | J17: =VLOOKUP(A17,Salários!$A$35:$P$42,I17+4,FALSE) -> 28.289806 | K17: =J17*G17 -> 58.465599
A18: Franciele Guedes | B18: Vital Rice | C18: 42550 | D18: 0.39930556 | E18: 0.49652778 | F18: =E18-D18 -> 0.097222222 | G18: =F18*24 -> 2.3333333 | H18: Pesagem | I18: =MONTH(C18) -> 6 | J18: =VLOOKUP(A18,Salários!$A$35:$P$42,I18+4,FALSE) -> 28.289806 | K18: =J18*G18 -> 66.009547
